{"recv_ts": 1786689859963468, "venue": "polymarket", "raw": "{\"id\":\"3578413\",\"question\":\"FC Barcelona vs. Athletic Club: FC Barcelona O/U 3.5 Corners\",\"market\":\"0x032326bec4ca459ac04765f546fc2ee0eff0d1c89411f970567e2b225dd5a92e\",\"slug\":\"lal-bar-bil-2026-08-27-corners-team-home-3pt5\",\"description\":\"In the upcoming La Liga game between FC Barcelona and Athletic Club, scheduled for August 27, 2026 at 3:00 PM ET: This market will resolve to \\\"Over\\\" if FC Barcelona takes 4 or more corners within the first 90 minutes of regular play plus stoppage time. If FC Barcelona takes fewer than 4 corners within the first 90 minutes of regular play plus stoppage time, this market will resolve to \\\"Under\\\". This market is based solely on corners taken by FC Barcelona, not the combined number of corners taken by both teams. Markets on number of corners refer to corners taken, not corners awarded. Corners awarded but not taken will not count. Corners awarded during extra time or penalty shootouts do not count. If the game is postponed, this market will remain open until the game has been completed. If the game is canceled entirely, with no make-up game, this market will resolve 50-50. The primary resolution source for this market is the official statistics of the event as recognized by the governing body or event organizers. However, if the governing body or event organizers have not published final match statistics within 24 hours after the event's conclusion, a consensus of credible reporting may be used instead. All markets will settle based on the official final result as recognized by the governing body or event organizers. Revisions to officially declared final scores made after market resolution will not be accounted for in determining the outcome.\",\"assets_ids\":[\"70186121691863860883553250551358688537158112837509592296678189737248866108610\",\"113515859619917074430348640431510768649951603673646786911061181675582439197761\"],\"outcomes\":[\"Over\",\"Under\"],\"event_message\":{\"id\":\"847345\",\"ticker\":\"lal-bar-bil-2026-08-27-total-corners\",\"slug\":\"lal-bar-bil-2026-08-27-total-corners\",\"title\":\"FC Barcelona vs. Athletic Club - Total Corners\",\"description\":\"Total corners markets for the La Liga game between FC Barcelona and Athletic Club, scheduled for August 27, 2026 at 3:00 PM ET.\"},\"timestamp\":\"1786689859771\",\"event_type\":\"new_market\",\"tags\":[],\"condition_id\":\"0x032326bec4ca459ac04765f546fc2ee0eff0d1c89411f970567e2b225dd5a92e\",\"active\":false,\"clob_token_ids\":[\"70186121691863860883553250551358688537158112837509592296678189737248866108610\",\"113515859619917074430348640431510768649951603673646786911061181675582439197761\"],\"sports_market_type\":\"soccer_team_total_corners\",\"line\":\"3.5\",\"game_start_time\":\"2026-08-27 19:00:00+00\",\"order_price_min_tick_size\":\"0.01\",\"group_item_title\":\"FC Barcelona Corners: O/U 3.5\",\"taker_base_fee\":\"1000\",\"fees_enabled\":true,\"fee_schedule\":{\"exponent\":\"1\",\"rate\":\"0.05\",\"taker_only\":true,\"rebate_rate\":\"0.15\"}}"}
{"recv_ts": 1786689860054885, "venue": "polymarket", "raw": "{\"id\":\"3578417\",\"question\":\"FC Barcelona vs. Athletic Club: Athletic Club O/U 3.5 Corners\",\"market\":\"0xfb9535401ef52c9d5c313415b05999445cb5d32bd6367b3e257c68436799f5e8\",\"slug\":\"lal-bar-bil-2026-08-27-corners-team-away-3pt5\",\"description\":\"In the upcoming La Liga game between FC Barcelona and Athletic Club, scheduled for August 27, 2026 at 3:00 PM ET: This market will resolve to \\\"Over\\\" if Athletic Club takes 4 or more corners within the first 90 minutes of regular play plus stoppage time. If Athletic Club takes fewer than 4 corners within the first 90 minutes of regular play plus stoppage time, this market will resolve to \\\"Under\\\". This market is based solely on corners taken by Athletic Club, not the combined number of corners taken by both teams. Markets on number of corners refer to corners taken, not corners awarded. Corners awarded but not taken will not count. Corners awarded during extra time or penalty shootouts do not count. If the game is postponed, this market will remain open until the game has been completed. If the game is canceled entirely, with no make-up game, this market will resolve 50-50. The primary resolution source for this market is the official statistics of the event as recognized by the governing body or event organizers. However, if the governing body or event organizers have not published final match statistics within 24 hours after the event's conclusion, a consensus of credible reporting may be used instead. All markets will settle based on the official final result as recognized by the governing body or event organizers. Revisions to officially declared final scores made after market resolution will not be accounted for in determining the outcome.\",\"assets_ids\":[\"28639452937026914057744120004222514606699695721556488493344807570453852780107\",\"2662888896150634749017221214214492966893563120289150027907180983120591894068\"],\"outcomes\":[\"Over\",\"Under\"],\"event_message\":{\"id\":\"847345\",\"ticker\":\"lal-bar-bil-2026-08-27-total-corners\",\"slug\":\"lal-bar-bil-2026-08-27-total-corners\",\"title\":\"FC Barcelona vs. Athletic Club - Total Corners\",\"description\":\"Total corners markets for the La Liga game between FC Barcelona and Athletic Club, scheduled for August 27, 2026 at 3:00 PM ET.\"},\"timestamp\":\"1786689859773\",\"event_type\":\"new_market\",\"tags\":[],\"condition_id\":\"0xfb9535401ef52c9d5c313415b05999445cb5d32bd6367b3e257c68436799f5e8\",\"active\":false,\"clob_token_ids\":[\"28639452937026914057744120004222514606699695721556488493344807570453852780107\",\"2662888896150634749017221214214492966893563120289150027907180983120591894068\"],\"sports_market_type\":\"soccer_team_total_corners\",\"line\":\"3.5\",\"game_start_time\":\"2026-08-27 19:00:00+00\",\"order_price_min_tick_size\":\"0.01\",\"group_item_title\":\"Athletic Club Corners: O/U 3.5\",\"taker_base_fee\":\"1000\",\"fees_enabled\":true,\"fee_schedule\":{\"exponent\":\"1\",\"rate\":\"0.05\",\"taker_only\":true,\"rebate_rate\":\"0.15\"}}"}
{"recv_ts": 1786689860147035, "venue": "polymarket", "raw": "{\"id\":\"3578409\",\"question\":\"FC Barcelona vs. Athletic Club: 2nd Half O/U 3.5 Total Corners\",\"market\":\"0xe8d6ebc7d4fadfbfe032328419fa2d16280ad905694ee4325744723d02b8d6b3\",\"slug\":\"lal-bar-bil-2026-08-27-corners-second-half-total-3pt5\",\"description\":\"In the upcoming La Liga game between FC Barcelona and Athletic Club, scheduled for August 27, 2026 at 3:00 PM ET: This market will resolve to \\\"Over\\\" if there are 4 or more total corners taken by both teams in the second half. If the total number of second-half corners is fewer than 4, this market will resolve to \\\"Under\\\". This market refers only to corners taken after the second half begins and before the end of the first 90 minutes of regular play plus second-half stoppage time. First-half corners, extra time, and penalty shootouts do not count. Markets on number of corners refer to corners taken, not corners awarded. Corners awarded but not taken will not count. If the game is postponed, this market will remain open until the game has been completed. If the game is canceled entirely, with no make-up game, this market will resolve 50-50. The primary resolution source for this market is the official statistics of the event as recognized by the governing body or event organizers. However, if the governing body or event organizers have not published final match statistics within 24 hours after the event's conclusion, a consensus of credible reporting may be used instead. All markets will settle based on the official final result as recognized by the governing body or event organizers. Revisions to officially declared final scores made after market resolution will not be accounted for in determining the outcome.\",\"assets_ids\":[\"15777409803810392845542475464009191759671073950027744312089755112131009410438\",\"15219840920175201584874424780771649641689337040305474699748114831234369101711\"],\"outcomes\":[\"Over\",\"Under\"],\"event_message\":{\"id\":\"847345\",\"ticker\":\"lal-bar-bil-2026-08-27-total-corners\",\"slug\":\"lal-bar-bil-2026-08-27-total-corners\",\"title\":\"FC Barcelona vs. Athletic Club - Total Corners\",\"description\":\"Total corners markets for the La Liga game between FC Barcelona and Athletic Club, scheduled for August 27, 2026 at 3:00 PM ET.\"},\"timestamp\":\"1786689859774\",\"event_type\":\"new_market\",\"tags\":[],\"condition_id\":\"0xe8d6ebc7d4fadfbfe032328419fa2d16280ad905694ee4325744723d02b8d6b3\",\"active\":false,\"clob_token_ids\":[\"15777409803810392845542475464009191759671073950027744312089755112131009410438\",\"15219840920175201584874424780771649641689337040305474699748114831234369101711\"],\"sports_market_type\":\"soccer_second_half_total_corners\",\"line\":\"3.5\",\"game_start_time\":\"2026-08-27 19:00:00+00\",\"order_price_min_tick_size\":\"0.01\",\"group_item_title\":\"2nd Half Total Corners: O/U 3.5\",\"taker_base_fee\":\"1000\",\"fees_enabled\":true,\"fee_schedule\":{\"exponent\":\"1\",\"rate\":\"0.05\",\"taker_only\":true,\"rebate_rate\":\"0.15\"}}"}
{"recv_ts": 1786689860147161, "venue": "polymarket", "raw": "{\"id\":\"3578418\",\"question\":\"FC Barcelona vs. Athletic Club: Athletic Club O/U 4.5 Corners\",\"market\":\"0x542e57eb6bef524031d5de5c90d94665ab37edb1e254c754d89cf672d538a501\",\"slug\":\"lal-bar-bil-2026-08-27-corners-team-away-4pt5\",\"description\":\"In the upcoming La Liga game between FC Barcelona and Athletic Club, scheduled for August 27, 2026 at 3:00 PM ET: This market will resolve to \\\"Over\\\" if Athletic Club takes 5 or more corners within the first 90 minutes of regular play plus stoppage time. If Athletic Club takes fewer than 5 corners within the first 90 minutes of regular play plus stoppage time, this market will resolve to \\\"Under\\\". This market is based solely on corners taken by Athletic Club, not the combined number of corners taken by both teams. Markets on number of corners refer to corners taken, not corners awarded. Corners awarded but not taken will not count. Corners awarded during extra time or penalty shootouts do not count. If the game is postponed, this market will remain open until the game has been completed. If the game is canceled entirely, with no make-up game, this market will resolve 50-50. The primary resolution source for this market is the official statistics of the event as recognized by the governing body or event organizers. However, if the governing body or event organizers have not published final match statistics within 24 hours after the event's conclusion, a consensus of credible reporting may be used instead. All markets will settle based on the official final result as recognized by the governing body or event organizers. Revisions to officially declared final scores made after market resolution will not be accounted for in determining the outcome.\",\"assets_ids\":[\"48713780202614564093054081189204769552835995178872088133807608870614034055039\",\"41604061287565066865045986858403392102528305666427858162087620429182032465428\"],\"outcomes\":[\"Over\",\"Under\"],\"event_message\":{\"id\":\"847345\",\"ticker\":\"lal-bar-bil-2026-08-27-total-corners\",\"slug\":\"lal-bar-bil-2026-08-27-total-corners\",\"title\":\"FC Barcelona vs. Athletic Club - Total Corners\",\"description\":\"Total corners markets for the La Liga game between FC Barcelona and Athletic Club, scheduled for August 27, 2026 at 3:00 PM ET.\"},\"timestamp\":\"1786689859803\",\"event_type\":\"new_market\",\"tags\":[],\"condition_id\":\"0x542e57eb6bef524031d5de5c90d94665ab37edb1e254c754d89cf672d538a501\",\"active\":false,\"clob_token_ids\":[\"48713780202614564093054081189204769552835995178872088133807608870614034055039\",\"41604061287565066865045986858403392102528305666427858162087620429182032465428\"],\"sports_market_type\":\"soccer_team_total_corners\",\"line\":\"4.5\",\"game_start_time\":\"2026-08-27 19:00:00+00\",\"order_price_min_tick_size\":\"0.01\",\"group_item_title\":\"Athletic Club Corners: O/U 4.5\",\"taker_base_fee\":\"1000\",\"fees_enabled\":true,\"fee_schedule\":{\"exponent\":\"1\",\"rate\":\"0.05\",\"taker_only\":true,\"rebate_rate\":\"0.15\"}}"}
{"recv_ts": 1786689860864329, "venue": "polymarket", "raw": "{\"market\":\"0x60c2c085ee8c16bc8f2419739a94971d4c9d00f637ead10fc0f540afa1be64e8\",\"price_changes\":[{\"asset_id\":\"90869494087977018607792751230236923002303032923064138180950209430688758061828\",\"price\":\"0.983\",\"size\":\"41346.44\",\"side\":\"SELL\",\"hash\":\"8dcc21baa7d8313920dbd64e285bf88cb282c599\",\"best_bid\":\"0.979\",\"best_ask\":\"0.98\"},{\"asset_id\":\"105426373826369935595603860663411604941599130211176020843036778867927711117332\",\"price\":\"0.017\",\"size\":\"41346.44\",\"side\":\"BUY\",\"hash\":\"f570954183753d3cc9841e272c03184e12c90d1d\",\"best_bid\":\"0.02\",\"best_ask\":\"0.021\"}],\"timestamp\":\"1786689860856\",\"event_type\":\"price_change\"}"}
{"recv_ts": 1786689861053003, "venue": "polymarket", "raw": "{\"market\":\"0x60c2c085ee8c16bc8f2419739a94971d4c9d00f637ead10fc0f540afa1be64e8\",\"price_changes\":[{\"asset_id\":\"90869494087977018607792751230236923002303032923064138180950209430688758061828\",\"price\":\"0.983\",\"size\":\"41361.44\",\"side\":\"SELL\",\"hash\":\"63903a2e94cc6331a34e0c9c7f6518e8b76c21fe\",\"best_bid\":\"0.979\",\"best_ask\":\"0.98\"},{\"asset_id\":\"105426373826369935595603860663411604941599130211176020843036778867927711117332\",\"price\":\"0.017\",\"size\":\"41361.44\",\"side\":\"BUY\",\"hash\":\"7836c59114788ae83e0f145860f02478ef74ebd1\",\"best_bid\":\"0.02\",\"best_ask\":\"0.021\"}],\"timestamp\":\"1786689861045\",\"event_type\":\"price_change\"}"}
{"recv_ts": 1786689861747373, "venue": "polymarket", "raw": "{\"id\":\"3578410\",\"question\":\"FC Barcelona vs. Athletic Club: 2nd Half O/U 4.5 Total Corners\",\"market\":\"0xcdb258f62d5b8cbc1a350b29a0f8a2e0719ed2a2fc87eb055a08be0bbad6cc9d\",\"slug\":\"lal-bar-bil-2026-08-27-corners-second-half-total-4pt5\",\"description\":\"In the upcoming La Liga game between FC Barcelona and Athletic Club, scheduled for August 27, 2026 at 3:00 PM ET: This market will resolve to \\\"Over\\\" if there are 5 or more total corners taken by both teams in the second half. If the total number of second-half corners is fewer than 5, this market will resolve to \\\"Under\\\". This market refers only to corners taken after the second half begins and before the end of the first 90 minutes of regular play plus second-half stoppage time. First-half corners, extra time, and penalty shootouts do not count. Markets on number of corners refer to corners taken, not corners awarded. Corners awarded but not taken will not count. If the game is postponed, this market will remain open until the game has been completed. If the game is canceled entirely, with no make-up game, this market will resolve 50-50. The primary resolution source for this market is the official statistics of the event as recognized by the governing body or event organizers. However, if the governing body or event organizers have not published final match statistics within 24 hours after the event's conclusion, a consensus of credible reporting may be used instead. All markets will settle based on the official final result as recognized by the governing body or event organizers. Revisions to officially declared final scores made after market resolution will not be accounted for in determining the outcome.\",\"assets_ids\":[\"77359994883763006810561117622523991960418888484212008937438943818283425048671\",\"81582375112410885756100090601631069738170408585942096009969203032925338475081\"],\"outcomes\":[\"Over\",\"Under\"],\"event_message\":{\"id\":\"847345\",\"ticker\":\"lal-bar-bil-2026-08-27-total-corners\",\"slug\":\"lal-bar-bil-2026-08-27-total-corners\",\"title\":\"FC Barcelona vs. Athletic Club - Total Corners\",\"description\":\"Total corners markets for the La Liga game between FC Barcelona and Athletic Club, scheduled for August 27, 2026 at 3:00 PM ET.\"},\"timestamp\":\"1786689861603\",\"event_type\":\"new_market\",\"tags\":[],\"condition_id\":\"0xcdb258f62d5b8cbc1a350b29a0f8a2e0719ed2a2fc87eb055a08be0bbad6cc9d\",\"active\":false,\"clob_token_ids\":[\"77359994883763006810561117622523991960418888484212008937438943818283425048671\",\"81582375112410885756100090601631069738170408585942096009969203032925338475081\"],\"sports_market_type\":\"soccer_second_half_total_corners\",\"line\":\"4.5\",\"game_start_time\":\"2026-08-27 19:00:00+00\",\"order_price_min_tick_size\":\"0.01\",\"group_item_title\":\"2nd Half Total Corners: O/U 4.5\",\"taker_base_fee\":\"1000\",\"fees_enabled\":true,\"fee_schedule\":{\"exponent\":\"1\",\"rate\":\"0.05\",\"taker_only\":true,\"rebate_rate\":\"0.15\"}}"}
{"recv_ts": 1786689861747464, "venue": "polymarket", "raw": "{\"id\":\"3578411\",\"question\":\"FC Barcelona vs. Athletic Club: 2nd Half O/U 5.5 Total Corners\",\"market\":\"0x845a508cb0484f74564b691f5a821a6f6e643ed0be3872b4d4a49d2bdd54258c\",\"slug\":\"lal-bar-bil-2026-08-27-corners-second-half-total-5pt5\",\"description\":\"In the upcoming La Liga game between FC Barcelona and Athletic Club, scheduled for August 27, 2026 at 3:00 PM ET: This market will resolve to \\\"Over\\\" if there are 6 or more total corners taken by both teams in the second half. If the total number of second-half corners is fewer than 6, this market will resolve to \\\"Under\\\". This market refers only to corners taken after the second half begins and before the end of the first 90 minutes of regular play plus second-half stoppage time. First-half corners, extra time, and penalty shootouts do not count. Markets on number of corners refer to corners taken, not corners awarded. Corners awarded but not taken will not count. If the game is postponed, this market will remain open until the game has been completed. If the game is canceled entirely, with no make-up game, this market will resolve 50-50. The primary resolution source for this market is the official statistics of the event as recognized by the governing body or event organizers. However, if the governing body or event organizers have not published final match statistics within 24 hours after the event's conclusion, a consensus of credible reporting may be used instead. All markets will settle based on the official final result as recognized by the governing body or event organizers. Revisions to officially declared final scores made after market resolution will not be accounted for in determining the outcome.\",\"assets_ids\":[\"89181607323870214704270727818721620726033633290835942922680158525408553131625\",\"100564571472049963264348729377517323319648762580399562139164142457371438201666\"],\"outcomes\":[\"Over\",\"Under\"],\"event_message\":{\"id\":\"847345\",\"ticker\":\"lal-bar-bil-2026-08-27-total-corners\",\"slug\":\"lal-bar-bil-2026-08-27-total-corners\",\"title\":\"FC Barcelona vs. Athletic Club - Total Corners\",\"description\":\"Total corners markets for the La Liga game between FC Barcelona and Athletic Club, scheduled for August 27, 2026 at 3:00 PM ET.\"},\"timestamp\":\"1786689861610\",\"event_type\":\"new_market\",\"tags\":[],\"condition_id\":\"0x845a508cb0484f74564b691f5a821a6f6e643ed0be3872b4d4a49d2bdd54258c\",\"active\":false,\"clob_token_ids\":[\"89181607323870214704270727818721620726033633290835942922680158525408553131625\",\"100564571472049963264348729377517323319648762580399562139164142457371438201666\"],\"sports_market_type\":\"soccer_second_half_total_corners\",\"line\":\"5.5\",\"game_start_time\":\"2026-08-27 19:00:00+00\",\"order_price_min_tick_size\":\"0.01\",\"group_item_title\":\"2nd Half Total Corners: O/U 5.5\",\"taker_base_fee\":\"1000\",\"fees_enabled\":true,\"fee_schedule\":{\"exponent\":\"1\",\"rate\":\"0.05\",\"taker_only\":true,\"rebate_rate\":\"0.15\"}}"}
{"recv_ts": 1786689861839014, "venue": "polymarket", "raw": "{\"id\":\"3578412\",\"question\":\"FC Barcelona vs. Athletic Club: FC Barcelona O/U 2.5 Corners\",\"market\":\"0xfcbef811b99a54cb3ff1c3fbc50431eaaff63c6cf42ca5536467a8690afd429e\",\"slug\":\"lal-bar-bil-2026-08-27-corners-team-home-2pt5\",\"description\":\"In the upcoming La Liga game between FC Barcelona and Athletic Club, scheduled for August 27, 2026 at 3:00 PM ET: This market will resolve to \\\"Over\\\" if FC Barcelona takes 3 or more corners within the first 90 minutes of regular play plus stoppage time. If FC Barcelona takes fewer than 3 corners within the first 90 minutes of regular play plus stoppage time, this market will resolve to \\\"Under\\\". This market is based solely on corners taken by FC Barcelona, not the combined number of corners taken by both teams. Markets on number of corners refer to corners taken, not corners awarded. Corners awarded but not taken will not count. Corners awarded during extra time or penalty shootouts do not count. If the game is postponed, this market will remain open until the game has been completed. If the game is canceled entirely, with no make-up game, this market will resolve 50-50. The primary resolution source for this market is the official statistics of the event as recognized by the governing body or event organizers. However, if the governing body or event organizers have not published final match statistics within 24 hours after the event's conclusion, a consensus of credible reporting may be used instead. All markets will settle based on the official final result as recognized by the governing body or event organizers. Revisions to officially declared final scores made after market resolution will not be accounted for in determining the outcome.\",\"assets_ids\":[\"100929304566224360559567712158768911638754152237041596099057396640536471234557\",\"43662759036506673662522084308519779951003483198761723410092705514649802342242\"],\"outcomes\":[\"Over\",\"Under\"],\"event_message\":{\"id\":\"847345\",\"ticker\":\"lal-bar-bil-2026-08-27-total-corners\",\"slug\":\"lal-bar-bil-2026-08-27-total-corners\",\"title\":\"FC Barcelona vs. Athletic Club - Total Corners\",\"description\":\"Total corners markets for the La Liga game between FC Barcelona and Athletic Club, scheduled for August 27, 2026 at 3:00 PM ET.\"},\"timestamp\":\"1786689861606\",\"event_type\":\"new_market\",\"tags\":[],\"condition_id\":\"0xfcbef811b99a54cb3ff1c3fbc50431eaaff63c6cf42ca5536467a8690afd429e\",\"active\":false,\"clob_token_ids\":[\"100929304566224360559567712158768911638754152237041596099057396640536471234557\",\"43662759036506673662522084308519779951003483198761723410092705514649802342242\"],\"sports_market_type\":\"soccer_team_total_corners\",\"line\":\"2.5\",\"game_start_time\":\"2026-08-27 19:00:00+00\",\"order_price_min_tick_size\":\"0.01\",\"group_item_title\":\"FC Barcelona Corners: O/U 2.5\",\"taker_base_fee\":\"1000\",\"fees_enabled\":true,\"fee_schedule\":{\"exponent\":\"1\",\"rate\":\"0.05\",\"taker_only\":true,\"rebate_rate\":\"0.15\"}}"}
{"recv_ts": 1786689861903237, "venue": "polymarket", "raw": "{\"id\":\"3578415\",\"question\":\"FC Barcelona vs. Athletic Club: FC Barcelona O/U 5.5 Corners\",\"market\":\"0x9debca1ab6274435ee66bd73d578e853385335daca6be8e0aea3bd342a083b62\",\"slug\":\"lal-bar-bil-2026-08-27-corners-team-home-5pt5\",\"description\":\"In the upcoming La Liga game between FC Barcelona and Athletic Club, scheduled for August 27, 2026 at 3:00 PM ET: This market will resolve to \\\"Over\\\" if FC Barcelona takes 6 or more corners within the first 90 minutes of regular play plus stoppage time. If FC Barcelona takes fewer than 6 corners within the first 90 minutes of regular play plus stoppage time, this market will resolve to \\\"Under\\\". This market is based solely on corners taken by FC Barcelona, not the combined number of corners taken by both teams. Markets on number of corners refer to corners taken, not corners awarded. Corners awarded but not taken will not count. Corners awarded during extra time or penalty shootouts do not count. If the game is postponed, this market will remain open until the game has been completed. If the game is canceled entirely, with no make-up game, this market will resolve 50-50. The primary resolution source for this market is the official statistics of the event as recognized by the governing body or event organizers. However, if the governing body or event organizers have not published final match statistics within 24 hours after the event's conclusion, a consensus of credible reporting may be used instead. All markets will settle based on the official final result as recognized by the governing body or event organizers. Revisions to officially declared final scores made after market resolution will not be accounted for in determining the outcome.\",\"assets_ids\":[\"89623832579307598577606555202226524604443534398079929856852029920903642518636\",\"34784466764552587913638829113043839727589583162416716524266697353878946193605\"],\"outcomes\":[\"Over\",\"Under\"],\"event_message\":{\"id\":\"847345\",\"ticker\":\"lal-bar-bil-2026-08-27-total-corners\",\"slug\":\"lal-bar-bil-2026-08-27-total-corners\",\"title\":\"FC Barcelona vs. Athletic Club - Total Corners\",\"description\":\"Total corners markets for the La Liga game between FC Barcelona and Athletic Club, scheduled for August 27, 2026 at 3:00 PM ET.\"},\"timestamp\":\"1786689861613\",\"event_type\":\"new_market\",\"tags\":[],\"condition_id\":\"0x9debca1ab6274435ee66bd73d578e853385335daca6be8e0aea3bd342a083b62\",\"active\":false,\"clob_token_ids\":[\"89623832579307598577606555202226524604443534398079929856852029920903642518636\",\"34784466764552587913638829113043839727589583162416716524266697353878946193605\"],\"sports_market_type\":\"soccer_team_total_corners\",\"line\":\"5.5\",\"game_start_time\":\"2026-08-27 19:00:00+00\",\"order_price_min_tick_size\":\"0.01\",\"group_item_title\":\"FC Barcelona Corners: O/U 5.5\",\"taker_base_fee\":\"1000\",\"fees_enabled\":true,\"fee_schedule\":{\"exponent\":\"1\",\"rate\":\"0.05\",\"taker_only\":true,\"rebate_rate\":\"0.15\"}}"}
{"recv_ts": 1786689861933632, "venue": "polymarket", "raw": "{\"id\":\"3578406\",\"question\":\"FC Barcelona vs. Athletic Club: 1st Half O/U 3.5 Total Corners\",\"market\":\"0xc7989cfc939d37d446a3556d756bded8f6e5e940b4f2af2c5e303fee21ae64d5\",\"slug\":\"lal-bar-bil-2026-08-27-corners-first-half-total-3pt5\",\"description\":\"In the upcoming La Liga game between FC Barcelona and Athletic Club, scheduled for August 27, 2026 at 3:00 PM ET: This market will resolve to \\\"Over\\\" if there are 4 or more total corners taken by both teams in the first half. If the total number of first-half corners is fewer than 4, this market will resolve to \\\"Under\\\". This market refers only to corners taken within the first 45 minutes of regular play plus first-half stoppage time. Second-half corners, extra time, and penalty shootouts do not count. Markets on number of corners refer to corners taken, not corners awarded. Corners awarded but not taken will not count. If the game is postponed, this market will remain open until the game has been completed. If the game is canceled entirely, with no make-up game, this market will resolve 50-50. The primary resolution source for this market is the official statistics of the event as recognized by the governing body or event organizers. However, if the governing body or event organizers have not published final match statistics within 24 hours after the event's conclusion, a consensus of credible reporting may be used instead. All markets will settle based on the official final result as recognized by the governing body or event organizers. Revisions to officially declared final scores made after market resolution will not be accounted for in determining the outcome.\",\"assets_ids\":[\"11257341325208683206800768785751336188480881751173294615280321716835388786058\",\"8251621167970689072931023585330734490844010446551720527931102482074801046133\"],\"outcomes\":[\"Over\",\"Under\"],\"event_message\":{\"id\":\"847345\",\"ticker\":\"lal-bar-bil-2026-08-27-total-corners\",\"slug\":\"lal-bar-bil-2026-08-27-total-corners\",\"title\":\"FC Barcelona vs. Athletic Club - Total Corners\",\"description\":\"Total corners markets for the La Liga game between FC Barcelona and Athletic Club, scheduled for August 27, 2026 at 3:00 PM ET.\"},\"timestamp\":\"1786689861616\",\"event_type\":\"new_market\",\"tags\":[],\"condition_id\":\"0xc7989cfc939d37d446a3556d756bded8f6e5e940b4f2af2c5e303fee21ae64d5\",\"active\":false,\"clob_token_ids\":[\"11257341325208683206800768785751336188480881751173294615280321716835388786058\",\"8251621167970689072931023585330734490844010446551720527931102482074801046133\"],\"sports_market_type\":\"soccer_first_half_total_corners\",\"line\":\"3.5\",\"game_start_time\":\"2026-08-27 19:00:00+00\",\"order_price_min_tick_size\":\"0.01\",\"group_item_title\":\"1st Half Total Corners: O/U 3.5\",\"taker_base_fee\":\"1000\",\"fees_enabled\":true,\"fee_schedule\":{\"exponent\":\"1\",\"rate\":\"0.05\",\"taker_only\":true,\"rebate_rate\":\"0.15\"}}"}
{"recv_ts": 1786689862862573, "venue": "polymarket", "raw": "{\"market\":\"0x60c2c085ee8c16bc8f2419739a94971d4c9d00f637ead10fc0f540afa1be64e8\",\"price_changes\":[{\"asset_id\":\"105426373826369935595603860663411604941599130211176020843036778867927711117332\",\"price\":\"0.02\",\"size\":\"9006.06\",\"side\":\"BUY\",\"hash\":\"e1cf2494bb332b637a8922247db331d67b9fdd8e\",\"best_bid\":\"0.02\",\"best_ask\":\"0.021\"},{\"asset_id\":\"90869494087977018607792751230236923002303032923064138180950209430688758061828\",\"price\":\"0.98\",\"size\":\"9006.06\",\"side\":\"SELL\",\"hash\":\"623e1544e1fb7a967350cb657d442537e002d0ad\",\"best_bid\":\"0.979\",\"best_ask\":\"0.98\"}],\"timestamp\":\"1786689862854\",\"event_type\":\"price_change\"}"}
{"recv_ts": 1786689863116393, "venue": "polymarket", "raw": "{\"market\":\"0xd595eb9b81885ff018738300c79047e3ec89e87294424f57a29a7fa9162bf116\",\"price_changes\":[{\"asset_id\":\"57216272564529548464686463691236811991956032201293786790337952253964682584376\",\"price\":\"0.983\",\"size\":\"616.67\",\"side\":\"SELL\",\"hash\":\"387b2225ecfc5f3d0c5419a7fd7fc618f3c1aecd\",\"best_bid\":\"0.963\",\"best_ask\":\"0.964\"},{\"asset_id\":\"5161623255678193352839985156330393796378434470119114669671615782853260939535\",\"price\":\"0.017\",\"size\":\"616.67\",\"side\":\"BUY\",\"hash\":\"e64ba70bc72519588db75715a31166429e1da815\",\"best_bid\":\"0.036\",\"best_ask\":\"0.037\"}],\"timestamp\":\"1786689863109\",\"event_type\":\"price_change\"}"}
{"recv_ts": 1786689863309954, "venue": "polymarket", "raw": "{\"market\":\"0xd595eb9b81885ff018738300c79047e3ec89e87294424f57a29a7fa9162bf116\",\"price_changes\":[{\"asset_id\":\"57216272564529548464686463691236811991956032201293786790337952253964682584376\",\"price\":\"0.983\",\"size\":\"625.67\",\"side\":\"SELL\",\"hash\":\"a19f120fd4e55004dd60923461f9562be372e745\",\"best_bid\":\"0.963\",\"best_ask\":\"0.964\"},{\"asset_id\":\"5161623255678193352839985156330393796378434470119114669671615782853260939535\",\"price\":\"0.017\",\"size\":\"625.67\",\"side\":\"BUY\",\"hash\":\"e1fc0939dac5fc706851cebb30fcc96b311611c5\",\"best_bid\":\"0.036\",\"best_ask\":\"0.037\"}],\"timestamp\":\"1786689863302\",\"event_type\":\"price_change\"}"}
{"recv_ts": 1786689863684345, "venue": "polymarket", "raw": "{\"id\":\"3578416\",\"question\":\"FC Barcelona vs. Athletic Club: Athletic Club O/U 2.5 Corners\",\"market\":\"0xd1c2238c3c52ca3e52639d6f2ed9934ff38e2b6bc947b5a599e62c257affbed1\",\"slug\":\"lal-bar-bil-2026-08-27-corners-team-away-2pt5\",\"description\":\"In the upcoming La Liga game between FC Barcelona and Athletic Club, scheduled for August 27, 2026 at 3:00 PM ET: This market will resolve to \\\"Over\\\" if Athletic Club takes 3 or more corners within the first 90 minutes of regular play plus stoppage time. If Athletic Club takes fewer than 3 corners within the first 90 minutes of regular play plus stoppage time, this market will resolve to \\\"Under\\\". This market is based solely on corners taken by Athletic Club, not the combined number of corners taken by both teams. Markets on number of corners refer to corners taken, not corners awarded. Corners awarded but not taken will not count. Corners awarded during extra time or penalty shootouts do not count. If the game is postponed, this market will remain open until the game has been completed. If the game is canceled entirely, with no make-up game, this market will resolve 50-50. The primary resolution source for this market is the official statistics of the event as recognized by the governing body or event organizers. However, if the governing body or event organizers have not published final match statistics within 24 hours after the event's conclusion, a consensus of credible reporting may be used instead. All markets will settle based on the official final result as recognized by the governing body or event organizers. Revisions to officially declared final scores made after market resolution will not be accounted for in determining the outcome.\",\"assets_ids\":[\"104696832153519606989650256384604035312693318371529400304851402832724476143097\",\"102468460453411656763704780799351450490917982138124568437352895561314952188716\"],\"outcomes\":[\"Over\",\"Under\"],\"event_message\":{\"id\":\"847345\",\"ticker\":\"lal-bar-bil-2026-08-27-total-corners\",\"slug\":\"lal-bar-bil-2026-08-27-total-corners\",\"title\":\"FC Barcelona vs. Athletic Club - Total Corners\",\"description\":\"Total corners markets for the La Liga game between FC Barcelona and Athletic Club, scheduled for August 27, 2026 at 3:00 PM ET.\"},\"timestamp\":\"1786689863485\",\"event_type\":\"new_market\",\"tags\":[],\"condition_id\":\"0xd1c2238c3c52ca3e52639d6f2ed9934ff38e2b6bc947b5a599e62c257affbed1\",\"active\":false,\"clob_token_ids\":[\"104696832153519606989650256384604035312693318371529400304851402832724476143097\",\"102468460453411656763704780799351450490917982138124568437352895561314952188716\"],\"sports_market_type\":\"soccer_team_total_corners\",\"line\":\"2.5\",\"game_start_time\":\"2026-08-27 19:00:00+00\",\"order_price_min_tick_size\":\"0.01\",\"group_item_title\":\"Athletic Club Corners: O/U 2.5\",\"taker_base_fee\":\"1000\",\"fees_enabled\":true,\"fee_schedule\":{\"exponent\":\"1\",\"rate\":\"0.05\",\"taker_only\":true,\"rebate_rate\":\"0.15\"}}"}
{"recv_ts": 1786689863719186, "venue": "polymarket", "raw": "{\"id\":\"3578421\",\"question\":\"FC Barcelona vs. Athletic Club: Team to Take First Corner\",\"market\":\"0xf3a9f310ada06d4d3aec9f74ddfcfca7d0ed49bf8fd7e56e6ea64977e40a66f1\",\"slug\":\"lal-bar-bil-2026-08-27-first-corner\",\"description\":\"In the upcoming La Liga game between FC Barcelona and Athletic Club, scheduled for August 27, 2026 at 3:00 PM ET: This market will resolve to the team that takes the first corner in the game within the first 90 minutes of regular play plus stoppage time. If no corner is taken within that timeframe, this market will resolve 50-50. Markets on number of corners refer to corners taken, not corners awarded. Corners awarded but not taken will not count. Corners awarded during extra time or penalty shootouts do not count. If the game is postponed, this market will remain open until the game has been completed. If the game is canceled entirely, with no make-up game, this market will resolve 50-50. The primary resolution source for this market is the official statistics of the event as recognized by the governing body or event organizers. However, if the governing body or event organizers have not published final match statistics within 24 hours after the event's conclusion, a consensus of credible reporting may be used instead. All markets will settle based on the official final result as recognized by the governing body or event organizers. Revisions to officially declared final scores made after market resolution will not be accounted for in determining the outcome.\",\"assets_ids\":[\"47010705866171289606672181169683957648195142546523103932985058166471658335302\",\"42879433571111396315268724476558128079077915445237409890243720522290410366824\"],\"outcomes\":[\"FC Barcelona\",\"Athletic Club\"],\"event_message\":{\"id\":\"847345\",\"ticker\":\"lal-bar-bil-2026-08-27-total-corners\",\"slug\":\"lal-bar-bil-2026-08-27-total-corners\",\"title\":\"FC Barcelona vs. Athletic Club - Total Corners\",\"description\":\"Total corners markets for the La Liga game between FC Barcelona and Athletic Club, scheduled for August 27, 2026 at 3:00 PM ET.\"},\"timestamp\":\"1786689863488\",\"event_type\":\"new_market\",\"tags\":[],\"condition_id\":\"0xf3a9f310ada06d4d3aec9f74ddfcfca7d0ed49bf8fd7e56e6ea64977e40a66f1\",\"active\":false,\"clob_token_ids\":[\"47010705866171289606672181169683957648195142546523103932985058166471658335302\",\"42879433571111396315268724476558128079077915445237409890243720522290410366824\"],\"sports_market_type\":\"soccer_first_corner\",\"line\":\"\",\"game_start_time\":\"2026-08-27 19:00:00+00\",\"order_price_min_tick_size\":\"0.01\",\"group_item_title\":\"Team to Take First Corner\",\"taker_base_fee\":\"1000\",\"fees_enabled\":true,\"fee_schedule\":{\"exponent\":\"1\",\"rate\":\"0.05\",\"taker_only\":true,\"rebate_rate\":\"0.15\"}}"}
{"recv_ts": 1786689863719274, "venue": "polymarket", "raw": "{\"market\":\"0xbb4d51e6364066d92eb6f9b8413dd7193de70966736044463b205834805a1f3b\",\"price_changes\":[{\"asset_id\":\"10991849228756847439673778874175365458450913336396982752046655649803657501964\",\"price\":\"0.1\",\"size\":\"27202.32\",\"side\":\"SELL\",\"hash\":\"e6f168452ce06a2a9f08a46bfd728ad02af5262b\",\"best_bid\":\"0.06\",\"best_ask\":\"0.07\"},{\"asset_id\":\"106181075047366745139197108801635573283215248045056329679360376976893016488727\",\"price\":\"0.9\",\"size\":\"27202.32\",\"side\":\"BUY\",\"hash\":\"8193d031d6e68f7230c99426d1a7ed562d018506\",\"best_bid\":\"0.93\",\"best_ask\":\"0.94\"}],\"timestamp\":\"1786689863568\",\"event_type\":\"price_change\"}"}
{"recv_ts": 1786689863719296, "venue": "polymarket", "raw": "{\"market\":\"0xbb4d51e6364066d92eb6f9b8413dd7193de70966736044463b205834805a1f3b\",\"price_changes\":[{\"asset_id\":\"10991849228756847439673778874175365458450913336396982752046655649803657501964\",\"price\":\"0.11\",\"size\":\"40044.04\",\"side\":\"SELL\",\"hash\":\"e6f168452ce06a2a9f08a46bfd728ad02af5262b\",\"best_bid\":\"0.06\",\"best_ask\":\"0.07\"},{\"asset_id\":\"106181075047366745139197108801635573283215248045056329679360376976893016488727\",\"price\":\"0.89\",\"size\":\"40044.04\",\"side\":\"BUY\",\"hash\":\"8193d031d6e68f7230c99426d1a7ed562d018506\",\"best_bid\":\"0.93\",\"best_ask\":\"0.94\"}],\"timestamp\":\"1786689863568\",\"event_type\":\"price_change\"}"}
{"recv_ts": 1786689863777115, "venue": "polymarket", "raw": "{\"market\":\"0xbb4d51e6364066d92eb6f9b8413dd7193de70966736044463b205834805a1f3b\",\"price_changes\":[{\"asset_id\":\"10991849228756847439673778874175365458450913336396982752046655649803657501964\",\"price\":\"0.11\",\"size\":\"40444.04\",\"side\":\"SELL\",\"hash\":\"933ff4e98cceeb775a352272d5553d55cc37c8d7\",\"best_bid\":\"0.06\",\"best_ask\":\"0.07\"},{\"asset_id\":\"106181075047366745139197108801635573283215248045056329679360376976893016488727\",\"price\":\"0.89\",\"size\":\"40444.04\",\"side\":\"BUY\",\"hash\":\"5205929143434708f818120922b1f8fa1db6f10b\",\"best_bid\":\"0.93\",\"best_ask\":\"0.94\"}],\"timestamp\":\"1786689863648\",\"event_type\":\"price_change\"}"}
{"recv_ts": 1786689863777455, "venue": "polymarket", "raw": "{\"market\":\"0xbb4d51e6364066d92eb6f9b8413dd7193de70966736044463b205834805a1f3b\",\"price_changes\":[{\"asset_id\":\"10991849228756847439673778874175365458450913336396982752046655649803657501964\",\"price\":\"0.1\",\"size\":\"27402.32\",\"side\":\"SELL\",\"hash\":\"55d4bf31ecb2a67ecd3488f8b86efc2a2144449b\",\"best_bid\":\"0.06\",\"best_ask\":\"0.07\"},{\"asset_id\":\"106181075047366745139197108801635573283215248045056329679360376976893016488727\",\"price\":\"0.9\",\"size\":\"27402.32\",\"side\":\"BUY\",\"hash\":\"a8c486ff2afeb1fe312d149de21d04b0372886c4\",\"best_bid\":\"0.93\",\"best_ask\":\"0.94\"}],\"timestamp\":\"1786689863649\",\"event_type\":\"price_change\"}"}
{"recv_ts": 1786689863812915, "venue": "polymarket", "raw": "{\"id\":\"3578408\",\"question\":\"FC Barcelona vs. Athletic Club: 1st Half O/U 5.5 Total Corners\",\"market\":\"0xdc485e166f4d5f65f654c57b413c67370d734c978b4c36830f4374d082c28609\",\"slug\":\"lal-bar-bil-2026-08-27-corners-first-half-total-5pt5\",\"description\":\"In the upcoming La Liga game between FC Barcelona and Athletic Club, scheduled for August 27, 2026 at 3:00 PM ET: This market will resolve to \\\"Over\\\" if there are 6 or more total corners taken by both teams in the first half. If the total number of first-half corners is fewer than 6, this market will resolve to \\\"Under\\\". This market refers only to corners taken within the first 45 minutes of regular play plus first-half stoppage time. Second-half corners, extra time, and penalty shootouts do not count. Markets on number of corners refer to corners taken, not corners awarded. Corners awarded but not taken will not count. If the game is postponed, this market will remain open until the game has been completed. If the game is canceled entirely, with no make-up game, this market will resolve 50-50. The primary resolution source for this market is the official statistics of the event as recognized by the governing body or event organizers. However, if the governing body or event organizers have not published final match statistics within 24 hours after the event's conclusion, a consensus of credible reporting may be used instead. All markets will settle based on the official final result as recognized by the governing body or event organizers. Revisions to officially declared final scores made after market resolution will not be accounted for in determining the outcome.\",\"assets_ids\":[\"58932369992081990455676034825700990416293285636693162457418208259649530741712\",\"97113869967191047737125884788396045301185707123473181520096617671168206839761\"],\"outcomes\":[\"Over\",\"Under\"],\"event_message\":{\"id\":\"847345\",\"ticker\":\"lal-bar-bil-2026-08-27-total-corners\",\"slug\":\"lal-bar-bil-2026-08-27-total-corners\",\"title\":\"FC Barcelona vs. Athletic Club - Total Corners\",\"description\":\"Total corners markets for the La Liga game between FC Barcelona and Athletic Club, scheduled for August 27, 2026 at 3:00 PM ET.\"},\"timestamp\":\"1786689863772\",\"event_type\":\"new_market\",\"tags\":[],\"condition_id\":\"0xdc485e166f4d5f65f654c57b413c67370d734c978b4c36830f4374d082c28609\",\"active\":false,\"clob_token_ids\":[\"58932369992081990455676034825700990416293285636693162457418208259649530741712\",\"97113869967191047737125884788396045301185707123473181520096617671168206839761\"],\"sports_market_type\":\"soccer_first_half_total_corners\",\"line\":\"5.5\",\"game_start_time\":\"2026-08-27 19:00:00+00\",\"order_price_min_tick_size\":\"0.01\",\"group_item_title\":\"1st Half Total Corners: O/U 5.5\",\"taker_base_fee\":\"1000\",\"fees_enabled\":true,\"fee_schedule\":{\"exponent\":\"1\",\"rate\":\"0.05\",\"taker_only\":true,\"rebate_rate\":\"0.15\"}}"}
{"recv_ts": 1786689865008544, "venue": "polymarket", "raw": "{\"market\":\"0xbb4d51e6364066d92eb6f9b8413dd7193de70966736044463b205834805a1f3b\",\"price_changes\":[{\"asset_id\":\"10991849228756847439673778874175365458450913336396982752046655649803657501964\",\"price\":\"0.02\",\"size\":\"46556.69\",\"side\":\"BUY\",\"hash\":\"480a0386658ae3e65909d6896f4b78fd6f24e8b9\",\"best_bid\":\"0.06\",\"best_ask\":\"0.07\"},{\"asset_id\":\"106181075047366745139197108801635573283215248045056329679360376976893016488727\",\"price\":\"0.98\",\"size\":\"46556.69\",\"side\":\"SELL\",\"hash\":\"1c3d74c565c4e71bf81dd8ddda802c8283ca2e6a\",\"best_bid\":\"0.93\",\"best_ask\":\"0.94\"}],\"timestamp\":\"1786689865001\",\"event_type\":\"price_change\"}"}
{"recv_ts": 1786689866199510, "venue": "polymarket", "raw": "{\"market\":\"0xd9fb1184af0064e5e34b129f5b79afa5a17b7e32f2953ab05efed82315fee6d4\",\"price_changes\":[{\"asset_id\":\"90772332434487149264114862115632028379978765245278600275169585501290867536237\",\"price\":\"0.96\",\"size\":\"38245.56\",\"side\":\"BUY\",\"hash\":\"3c658ad6d47a9ea28f0057c814aa019c6499ba5e\",\"best_bid\":\"0.962\",\"best_ask\":\"0.964\"},{\"asset_id\":\"94559586571241563470235664821564670251180951772614764383113614156422396181162\",\"price\":\"0.04\",\"size\":\"38245.56\",\"side\":\"SELL\",\"hash\":\"d42b9b93041133e6f0b5283c975ebd5f812b00cf\",\"best_bid\":\"0.036\",\"best_ask\":\"0.038\"}],\"timestamp\":\"1786689866192\",\"event_type\":\"price_change\"}"}
{"recv_ts": 1786689866222826, "venue": "polymarket", "raw": "{\"market\":\"0xbb4d51e6364066d92eb6f9b8413dd7193de70966736044463b205834805a1f3b\",\"price_changes\":[{\"asset_id\":\"106181075047366745139197108801635573283215248045056329679360376976893016488727\",\"price\":\"0.91\",\"size\":\"157692.46\",\"side\":\"BUY\",\"hash\":\"089ee161e5a0968d5b99d1f36d0923d18e7bd10f\",\"best_bid\":\"0.93\",\"best_ask\":\"0.94\"},{\"asset_id\":\"10991849228756847439673778874175365458450913336396982752046655649803657501964\",\"price\":\"0.09\",\"size\":\"157692.46\",\"side\":\"SELL\",\"hash\":\"cedd4082a1ed2a93f06408990bfb72e583613ba7\",\"best_bid\":\"0.06\",\"best_ask\":\"0.07\"}],\"timestamp\":\"1786689866215\",\"event_type\":\"price_change\"}"}
{"recv_ts": 1786689866228418, "venue": "polymarket", "raw": "{\"market\":\"0xbb4d51e6364066d92eb6f9b8413dd7193de70966736044463b205834805a1f3b\",\"price_changes\":[{\"asset_id\":\"10991849228756847439673778874175365458450913336396982752046655649803657501964\",\"price\":\"0.05\",\"size\":\"456872.25\",\"side\":\"BUY\",\"hash\":\"da9bdff60ac6b82f8333821cf9e04c34d9a58fbd\",\"best_bid\":\"0.06\",\"best_ask\":\"0.07\"},{\"asset_id\":\"106181075047366745139197108801635573283215248045056329679360376976893016488727\",\"price\":\"0.95\",\"size\":\"456872.25\",\"side\":\"SELL\",\"hash\":\"e739a69826447ac5b50fa347cb4f129d0bd6ee5f\",\"best_bid\":\"0.93\",\"best_ask\":\"0.94\"}],\"timestamp\":\"1786689866221\",\"event_type\":\"price_change\"}"}
{"recv_ts": 1786689866422358, "venue": "polymarket", "raw": "{\"market\":\"0xd9fb1184af0064e5e34b129f5b79afa5a17b7e32f2953ab05efed82315fee6d4\",\"price_changes\":[{\"asset_id\":\"94559586571241563470235664821564670251180951772614764383113614156422396181162\",\"price\":\"0.034\",\"size\":\"14272.12\",\"side\":\"BUY\",\"hash\":\"04df46befe7eba92c988271235df9a12b955eb4d\",\"best_bid\":\"0.036\",\"best_ask\":\"0.038\"},{\"asset_id\":\"90772332434487149264114862115632028379978765245278600275169585501290867536237\",\"price\":\"0.966\",\"size\":\"14272.12\",\"side\":\"SELL\",\"hash\":\"3931ba861a45a11a078e95b24e2060fecd711a24\",\"best_bid\":\"0.962\",\"best_ask\":\"0.964\"}],\"timestamp\":\"1786689866415\",\"event_type\":\"price_change\"}"}
{"recv_ts": 1786689866818414, "venue": "polymarket", "raw": "{\"market\":\"0xd595eb9b81885ff018738300c79047e3ec89e87294424f57a29a7fa9162bf116\",\"price_changes\":[{\"asset_id\":\"57216272564529548464686463691236811991956032201293786790337952253964682584376\",\"price\":\"0.961\",\"size\":\"41133.18\",\"side\":\"BUY\",\"hash\":\"92b4f9015a598b70b4fd4091110dc3ec4100766a\",\"best_bid\":\"0.963\",\"best_ask\":\"0.964\"},{\"asset_id\":\"5161623255678193352839985156330393796378434470119114669671615782853260939535\",\"price\":\"0.039\",\"size\":\"41133.18\",\"side\":\"SELL\",\"hash\":\"3f7b5f5e8d9efb10a5035ed57efd3506d26999fb\",\"best_bid\":\"0.036\",\"best_ask\":\"0.037\"}],\"timestamp\":\"1786689866810\",\"event_type\":\"price_change\"}"}
{"recv_ts": 1786689866888067, "venue": "polymarket", "raw": "{\"market\":\"0xd595eb9b81885ff018738300c79047e3ec89e87294424f57a29a7fa9162bf116\",\"price_changes\":[{\"asset_id\":\"57216272564529548464686463691236811991956032201293786790337952253964682584376\",\"price\":\"0.96\",\"size\":\"115\",\"side\":\"BUY\",\"hash\":\"76d8208969830102623d1ea179a1f28fd276d0ea\",\"best_bid\":\"0.963\",\"best_ask\":\"0.964\"},{\"asset_id\":\"5161623255678193352839985156330393796378434470119114669671615782853260939535\",\"price\":\"0.04\",\"size\":\"115\",\"side\":\"SELL\",\"hash\":\"d97fe87a1b2107026a6acc3f0a7b1d8d9daad57e\",\"best_bid\":\"0.036\",\"best_ask\":\"0.037\"}],\"timestamp\":\"1786689866880\",\"event_type\":\"price_change\"}"}
{"recv_ts": 1786689866964315, "venue": "polymarket", "raw": "{\"market\":\"0xd595eb9b81885ff018738300c79047e3ec89e87294424f57a29a7fa9162bf116\",\"price_changes\":[{\"asset_id\":\"57216272564529548464686463691236811991956032201293786790337952253964682584376\",\"price\":\"0.959\",\"size\":\"330\",\"side\":\"BUY\",\"hash\":\"0d44425a18413b77f215eb86c7e9a1a3cf82c885\",\"best_bid\":\"0.963\",\"best_ask\":\"0.964\"},{\"asset_id\":\"5161623255678193352839985156330393796378434470119114669671615782853260939535\",\"price\":\"0.041\",\"size\":\"330\",\"side\":\"SELL\",\"hash\":\"da699dfbbf92880574b32457632939f797d68297\",\"best_bid\":\"0.036\",\"best_ask\":\"0.037\"}],\"timestamp\":\"1786689866957\",\"event_type\":\"price_change\"}"}
{"recv_ts": 1786689868788169, "venue": "polymarket", "raw": "{\"market\":\"0xd595eb9b81885ff018738300c79047e3ec89e87294424f57a29a7fa9162bf116\",\"price_changes\":[{\"asset_id\":\"57216272564529548464686463691236811991956032201293786790337952253964682584376\",\"price\":\"0.963\",\"size\":\"12870.97\",\"side\":\"BUY\",\"hash\":\"ebbcf3a22a2da301d48604d0ea7788a4b0b51769\",\"best_bid\":\"0.963\",\"best_ask\":\"0.964\"},{\"asset_id\":\"5161623255678193352839985156330393796378434470119114669671615782853260939535\",\"price\":\"0.037\",\"size\":\"12870.97\",\"side\":\"SELL\",\"hash\":\"0ce391a8cc32d8553fdbe2fece8451b35f102bcd\",\"best_bid\":\"0.036\",\"best_ask\":\"0.037\"}],\"timestamp\":\"1786689868780\",\"event_type\":\"price_change\"}"}
{"recv_ts": 1786689869009555, "venue": "polymarket", "raw": "{\"market\":\"0x747dc809fb79e1b05be09c42d6179459a58de2ef3e40f02484a4e1260f741f75\",\"price_changes\":[{\"asset_id\":\"7305630249804085635496399869905769372294302716159034447326228509068694952392\",\"price\":\"0.5\",\"size\":\"538.5\",\"side\":\"BUY\",\"hash\":\"f5ccbe8d35b8832e32c443d0f7c440eb7a82de0f\",\"best_bid\":\"0.95\",\"best_ask\":\"0.96\"},{\"asset_id\":\"107505882767731489358349912513945399560393482969656700824895970500493757150417\",\"price\":\"0.5\",\"size\":\"538.5\",\"side\":\"SELL\",\"hash\":\"2fd3f13191d619bf036265c349a79605bf72d60e\",\"best_bid\":\"0.04\",\"best_ask\":\"0.05\"}],\"timestamp\":\"1786689869002\",\"event_type\":\"price_change\"}"}
{"recv_ts": 1786689869012484, "venue": "polymarket", "raw": "{\"market\":\"0x60c2c085ee8c16bc8f2419739a94971d4c9d00f637ead10fc0f540afa1be64e8\",\"price_changes\":[{\"asset_id\":\"90869494087977018607792751230236923002303032923064138180950209430688758061828\",\"price\":\"0.4\",\"size\":\"6635.7\",\"side\":\"BUY\",\"hash\":\"f5f198769bb924baf3038f1bb2e42973b852e295\",\"best_bid\":\"0.979\",\"best_ask\":\"0.98\"},{\"asset_id\":\"105426373826369935595603860663411604941599130211176020843036778867927711117332\",\"price\":\"0.6\",\"size\":\"6635.7\",\"side\":\"SELL\",\"hash\":\"36d5c4446cd2b409359c2abbbef6f434372fd3ad\",\"best_bid\":\"0.02\",\"best_ask\":\"0.021\"}],\"timestamp\":\"1786689869000\",\"event_type\":\"price_change\"}"}
{"recv_ts": 1786689869031111, "venue": "polymarket", "raw": "{\"market\":\"0x60c2c085ee8c16bc8f2419739a94971d4c9d00f637ead10fc0f540afa1be64e8\",\"price_changes\":[{\"asset_id\":\"90869494087977018607792751230236923002303032923064138180950209430688758061828\",\"price\":\"0.2\",\"size\":\"22780.12\",\"side\":\"BUY\",\"hash\":\"a38a02493c33a545297814d0bf2405431cf43551\",\"best_bid\":\"0.979\",\"best_ask\":\"0.98\"},{\"asset_id\":\"105426373826369935595603860663411604941599130211176020843036778867927711117332\",\"price\":\"0.8\",\"size\":\"22780.12\",\"side\":\"SELL\",\"hash\":\"c74f7b46f4b3d6aec9a335d0671477241d809a3e\",\"best_bid\":\"0.02\",\"best_ask\":\"0.021\"}],\"timestamp\":\"1786689869005\",\"event_type\":\"price_change\"}"}
{"recv_ts": 1786689869102440, "venue": "polymarket", "raw": "{\"market\":\"0x60c2c085ee8c16bc8f2419739a94971d4c9d00f637ead10fc0f540afa1be64e8\",\"price_changes\":[{\"asset_id\":\"90869494087977018607792751230236923002303032923064138180950209430688758061828\",\"price\":\"0.3\",\"size\":\"10210.63\",\"side\":\"BUY\",\"hash\":\"4bf6640158d80a3813803b95f1284e0266fe78c4\",\"best_bid\":\"0.979\",\"best_ask\":\"0.98\"},{\"asset_id\":\"105426373826369935595603860663411604941599130211176020843036778867927711117332\",\"price\":\"0.7\",\"size\":\"10210.63\",\"side\":\"SELL\",\"hash\":\"2f657b6cf49e484917965ebfb5567d2816896a92\",\"best_bid\":\"0.02\",\"best_ask\":\"0.021\"}],\"timestamp\":\"1786689869037\",\"event_type\":\"price_change\"}"}
{"recv_ts": 1786689869102515, "venue": "polymarket", "raw": "{\"market\":\"0x60c2c085ee8c16bc8f2419739a94971d4c9d00f637ead10fc0f540afa1be64e8\",\"price_changes\":[{\"asset_id\":\"105426373826369935595603860663411604941599130211176020843036778867927711117332\",\"price\":\"0.02\",\"size\":\"9016.06\",\"side\":\"BUY\",\"hash\":\"9e98cc4c36a2593c4feb5721552366fc63c8d5b3\",\"best_bid\":\"0.02\",\"best_ask\":\"0.021\"},{\"asset_id\":\"90869494087977018607792751230236923002303032923064138180950209430688758061828\",\"price\":\"0.98\",\"size\":\"9016.06\",\"side\":\"SELL\",\"hash\":\"9716270567d1675f9bd4796f6eaf531b3f580450\",\"best_bid\":\"0.979\",\"best_ask\":\"0.98\"}],\"timestamp\":\"1786689869043\",\"event_type\":\"price_change\"}"}
{"recv_ts": 1786689869245142, "venue": "polymarket", "raw": "{\"market\":\"0xbb4d51e6364066d92eb6f9b8413dd7193de70966736044463b205834805a1f3b\",\"price_changes\":[{\"asset_id\":\"106181075047366745139197108801635573283215248045056329679360376976893016488727\",\"price\":\"0.91\",\"size\":\"157892.46\",\"side\":\"BUY\",\"hash\":\"402d10dcf64162794575c4b6d27e63947ffd3e77\",\"best_bid\":\"0.93\",\"best_ask\":\"0.94\"},{\"asset_id\":\"10991849228756847439673778874175365458450913336396982752046655649803657501964\",\"price\":\"0.09\",\"size\":\"157892.46\",\"side\":\"SELL\",\"hash\":\"d04c2effa67d4e6a15036706edef3b9f0098fa06\",\"best_bid\":\"0.06\",\"best_ask\":\"0.07\"}],\"timestamp\":\"1786689869237\",\"event_type\":\"price_change\"}"}
{"recv_ts": 1786689869246529, "venue": "polymarket", "raw": "{\"market\":\"0xbb4d51e6364066d92eb6f9b8413dd7193de70966736044463b205834805a1f3b\",\"price_changes\":[{\"asset_id\":\"10991849228756847439673778874175365458450913336396982752046655649803657501964\",\"price\":\"0.05\",\"size\":\"457072.25\",\"side\":\"BUY\",\"hash\":\"d2ea34e9a1412ff972a00b8d9a88e009a5d86506\",\"best_bid\":\"0.06\",\"best_ask\":\"0.07\"},{\"asset_id\":\"106181075047366745139197108801635573283215248045056329679360376976893016488727\",\"price\":\"0.95\",\"size\":\"457072.25\",\"side\":\"SELL\",\"hash\":\"88b9940e99b0c606caebcf3963b333f9bd33a081\",\"best_bid\":\"0.93\",\"best_ask\":\"0.94\"}],\"timestamp\":\"1786689869239\",\"event_type\":\"price_change\"}"}
{"recv_ts": 1786689869802656, "venue": "polymarket", "raw": "{\"market\":\"0xd595eb9b81885ff018738300c79047e3ec89e87294424f57a29a7fa9162bf116\",\"price_changes\":[{\"asset_id\":\"57216272564529548464686463691236811991956032201293786790337952253964682584376\",\"price\":\"0.963\",\"size\":\"12970.7\",\"side\":\"BUY\",\"hash\":\"6a3d098921784ffe345e0c0e8217669ca9bb578e\",\"best_bid\":\"0.963\",\"best_ask\":\"0.964\"},{\"asset_id\":\"5161623255678193352839985156330393796378434470119114669671615782853260939535\",\"price\":\"0.037\",\"size\":\"12970.7\",\"side\":\"SELL\",\"hash\":\"eab730c15f93002068782fa9a572a7641d07f0be\",\"best_bid\":\"0.036\",\"best_ask\":\"0.037\"}],\"timestamp\":\"1786689869795\",\"event_type\":\"price_change\"}"}
{"recv_ts": 1786689870009207, "venue": "polymarket", "raw": "{\"market\":\"0xd595eb9b81885ff018738300c79047e3ec89e87294424f57a29a7fa9162bf116\",\"price_changes\":[{\"asset_id\":\"57216272564529548464686463691236811991956032201293786790337952253964682584376\",\"price\":\"0.5\",\"size\":\"179.77\",\"side\":\"BUY\",\"hash\":\"1c780ff096fef05bbfdc02b4329a82314f538d04\",\"best_bid\":\"0.963\",\"best_ask\":\"0.964\"},{\"asset_id\":\"5161623255678193352839985156330393796378434470119114669671615782853260939535\",\"price\":\"0.5\",\"size\":\"179.77\",\"side\":\"SELL\",\"hash\":\"8c8e27e7d5a9b36a28984117c7b51e04cf4f0eaa\",\"best_bid\":\"0.036\",\"best_ask\":\"0.037\"}],\"timestamp\":\"1786689870000\",\"event_type\":\"price_change\"}"}
{"recv_ts": 1786689871773822, "venue": "polymarket", "raw": "{\"market\":\"0x747dc809fb79e1b05be09c42d6179459a58de2ef3e40f02484a4e1260f741f75\",\"asset_id\":\"107505882767731489358349912513945399560393482969656700824895970500493757150417\",\"best_bid\":\"0.04\",\"best_ask\":\"0.05\",\"spread\":\"0.01\",\"timestamp\":\"1786689871766\",\"event_type\":\"best_bid_ask\"}"}
{"recv_ts": 1786689871773905, "venue": "polymarket", "raw": "{\"market\":\"0x747dc809fb79e1b05be09c42d6179459a58de2ef3e40f02484a4e1260f741f75\",\"price_changes\":[{\"asset_id\":\"7305630249804085635496399869905769372294302716159034447326228509068694952392\",\"price\":\"0.96\",\"size\":\"322638.54\",\"side\":\"SELL\",\"hash\":\"935670b7b2a35f2237e0d0f12ed8537671865e16\",\"best_bid\":\"0.95\",\"best_ask\":\"0.96\"},{\"asset_id\":\"107505882767731489358349912513945399560393482969656700824895970500493757150417\",\"price\":\"0.04\",\"size\":\"322638.54\",\"side\":\"BUY\",\"hash\":\"9a0fbe8e0f2774fb57c8adbbedb6aafb55c26ee1\",\"best_bid\":\"0.04\",\"best_ask\":\"0.05\"}],\"timestamp\":\"1786689871766\",\"event_type\":\"price_change\"}"}
{"recv_ts": 1786689871774755, "venue": "polymarket", "raw": "{\"market\":\"0x747dc809fb79e1b05be09c42d6179459a58de2ef3e40f02484a4e1260f741f75\",\"asset_id\":\"107505882767731489358349912513945399560393482969656700824895970500493757150417\",\"bids\":[{\"price\":\"0.01\",\"size\":\"1052481.46\"},{\"price\":\"0.02\",\"size\":\"323833.54\"},{\"price\":\"0.03\",\"size\":\"355611.26\"},{\"price\":\"0.04\",\"size\":\"322638.54\"}],\"asks\":[{\"price\":\"0.99\",\"size\":\"6805.16\"},{\"price\":\"0.98\",\"size\":\"2429.55\"},{\"price\":\"0.97\",\"size\":\"4338.76\"},{\"price\":\"0.96\",\"size\":\"518\"},{\"price\":\"0.95\",\"size\":\"2300\"},{\"price\":\"0.93\",\"size\":\"1866.72\"},{\"price\":\"0.92\",\"size\":\"128\"},{\"price\":\"0.91\",\"size\":\"5.47\"},{\"price\":\"0.9\",\"size\":\"16301.03\"},{\"price\":\"0.89\",\"size\":\"909.09\"},{\"price\":\"0.86\",\"size\":\"25678.57\"},{\"price\":\"0.84\",\"size\":\"1064\"},{\"price\":\"0.83\",\"size\":\"657\"},{\"price\":\"0.81\",\"size\":\"526.31\"},{\"price\":\"0.8\",\"size\":\"14900\"},{\"price\":\"0.77\",\"size\":\"500\"},{\"price\":\"0.76\",\"size\":\"986.66\"},{\"price\":\"0.75\",\"size\":\"27.77\"},{\"price\":\"0.72\",\"size\":\"36.42\"},{\"price\":\"0.71\",\"size\":\"327.58\"},{\"price\":\"0.7\",\"size\":\"9200\"},{\"price\":\"0.68\",\"size\":\"32\"},{\"price\":\"0.66\",\"size\":\"271.7\"},{\"price\":\"0.64\",\"size\":\"300\"},{\"price\":\"0.62\",\"size\":\"223.68\"},{\"price\":\"0.6\",\"size\":\"5638\"},{\"price\":\"0.59\",\"size\":\"84\"},{\"price\":\"0.58\",\"size\":\"83\"},{\"price\":\"0.57\",\"size\":\"174.41\"},{\"price\":\"0.56\",\"size\":\"200\"},{\"price\":\"0.55\",\"size\":\"45\"},{\"price\":\"0.52\",\"size\":\"145.83\"},{\"price\":\"0.5\",\"size\":\"538.5\"},{\"price\":\"0.49\",\"size\":\"380\"},{\"price\":\"0.48\",\"size\":\"6\"},{\"price\":\"0.47\",\"size\":\"422.64\"},{\"price\":\"0.46\",\"size\":\"400\"},{\"price\":\"0.45\",\"size\":\"555.55\"},{\"price\":\"0.44\",\"size\":\"11.36\"},{\"price\":\"0.43\",\"size\":\"200\"},{\"price\":\"0.42\",\"size\":\"308.26\"},{\"price\":\"0.41\",\"size\":\"58.82\"},{\"price\":\"0.4\",\"size\":\"803\"},{\"price\":\"0.39\",\"size\":\"200\"},{\"price\":\"0.37\",\"size\":\"50\"},{\"price\":\"0.36\",\"size\":\"22.94\"},{\"price\":\"0.35\",\"size\":\"785\"},{\"price\":\"0.34\",\"size\":\"1000\"},{\"price\":\"0.33\",\"size\":\"400\"},{\"price\":\"0.32\",\"size\":\"91.66\"},{\"price\":\"0.31\",\"size\":\"735.63\"},{\"price\":\"0.3\",\"size\":\"312\"},{\"price\":\"0.29\",\"size\":\"100\"},{\"price\":\"0.27\",\"size\":\"450\"},{\"price\":\"0.26\",\"size\":\"30\"},{\"price\":\"0.25\",\"size\":\"1542.28\"},{\"price\":\"0.23\",\"size\":\"222.72\"},{\"price\":\"0.22\",\"size\":\"11\"},{\"price\":\"0.21\",\"size\":\"794.22\"},{\"price\":\"0.2\",\"size\":\"116891.1\"},{\"price\":\"0.19\",\"size\":\"68254.91\"},{\"price\":\"0.18\",\"size\":\"2383.62\"},{\"price\":\"0.17\",\"size\":\"200\"},{\"price\":\"0.16\",\"size\":\"271.43\"},{\"price\":\"0.15\",\"size\":\"7424.22\"},{\"price\":\"0.14\",\"size\":\"11135.84\"},{\"price\":\"0.13\",\"size\":\"1454.48\"},{\"price\":\"0.12\",\"size\":\"3796.46\"},{\"price\":\"0.11\",\"size\":\"12763.27\"},{\"price\":\"0.1\",\"size\":\"22931.43\"},{\"price\":\"0.09\",\"size\":\"20975.48\"},{\"price\":\"0.08\",\"size\":\"12916.1\"},{\"price\":\"0.07\",\"size\":\"92149.11\"},{\"price\":\"0.06\",\"size\":\"122527.12\"},{\"price\":\"0.05\",\"size\":\"268648.35\"}],\"hash\":\"9a0fbe8e0f2774fb57c8adbbedb6aafb55c26ee1\",\"timestamp\":\"1786689871766\",\"event_type\":\"book\"}"}
{"recv_ts": 1786689871866680, "venue": "polymarket", "raw": "{\"market\":\"0x747dc809fb79e1b05be09c42d6179459a58de2ef3e40f02484a4e1260f741f75\",\"price_changes\":[{\"asset_id\":\"7305630249804085635496399869905769372294302716159034447326228509068694952392\",\"price\":\"0.94\",\"size\":\"122287.12\",\"side\":\"BUY\",\"hash\":\"2639831691438d9342985a7d4ce3d7d3b1abe264\",\"best_bid\":\"0.95\",\"best_ask\":\"0.96\"},{\"asset_id\":\"107505882767731489358349912513945399560393482969656700824895970500493757150417\",\"price\":\"0.06\",\"size\":\"122287.12\",\"side\":\"SELL\",\"hash\":\"609f55ceaeaec158af69b9ec8fa06b1c48196503\",\"best_bid\":\"0.04\",\"best_ask\":\"0.05\"}],\"timestamp\":\"1786689871795\",\"event_type\":\"price_change\"}"}
{"recv_ts": 1786689871866757, "venue": "polymarket", "raw": "{\"market\":\"0x747dc809fb79e1b05be09c42d6179459a58de2ef3e40f02484a4e1260f741f75\",\"price_changes\":[{\"asset_id\":\"107505882767731489358349912513945399560393482969656700824895970500493757150417\",\"price\":\"0.02\",\"size\":\"323633.54\",\"side\":\"BUY\",\"hash\":\"859a79e19b8bc14504c8d7160cdf2361089e1b0c\",\"best_bid\":\"0.04\",\"best_ask\":\"0.05\"},{\"asset_id\":\"7305630249804085635496399869905769372294302716159034447326228509068694952392\",\"price\":\"0.98\",\"size\":\"323633.54\",\"side\":\"SELL\",\"hash\":\"31c0069d236f4eb2c3612742a540c99ed10cea62\",\"best_bid\":\"0.95\",\"best_ask\":\"0.96\"}],\"timestamp\":\"1786689871796\",\"event_type\":\"price_change\"}"}
{"recv_ts": 1786689871866978, "venue": "polymarket", "raw": "{\"market\":\"0x747dc809fb79e1b05be09c42d6179459a58de2ef3e40f02484a4e1260f741f75\",\"price_changes\":[{\"asset_id\":\"7305630249804085635496399869905769372294302716159034447326228509068694952392\",\"price\":\"0.94\",\"size\":\"122087.12\",\"side\":\"BUY\",\"hash\":\"2524d7fad23e8fd71a5c8d69ef9bf51a5b3a2280\",\"best_bid\":\"0.95\",\"best_ask\":\"0.96\"},{\"asset_id\":\"107505882767731489358349912513945399560393482969656700824895970500493757150417\",\"price\":\"0.06\",\"size\":\"122087.12\",\"side\":\"SELL\",\"hash\":\"2a74cbe9b4e87d6f7b3ed6d67102159bf6779250\",\"best_bid\":\"0.04\",\"best_ask\":\"0.05\"}],\"timestamp\":\"1786689871799\",\"event_type\":\"price_change\"}"}
{"recv_ts": 1786689871867005, "venue": "polymarket", "raw": "{\"market\":\"0x747dc809fb79e1b05be09c42d6179459a58de2ef3e40f02484a4e1260f741f75\",\"price_changes\":[{\"asset_id\":\"107505882767731489358349912513945399560393482969656700824895970500493757150417\",\"price\":\"0.02\",\"size\":\"323393.54\",\"side\":\"BUY\",\"hash\":\"b701a142240bb99bf97d63c38dacca64aac57f69\",\"best_bid\":\"0.04\",\"best_ask\":\"0.05\"},{\"asset_id\":\"7305630249804085635496399869905769372294302716159034447326228509068694952392\",\"price\":\"0.98\",\"size\":\"323393.54\",\"side\":\"SELL\",\"hash\":\"999d22d2b31662c67364d026cc276f81ccc4566b\",\"best_bid\":\"0.95\",\"best_ask\":\"0.96\"}],\"timestamp\":\"1786689871800\",\"event_type\":\"price_change\"}"}
{"recv_ts": 1786689871867135, "venue": "polymarket", "raw": "{\"market\":\"0x747dc809fb79e1b05be09c42d6179459a58de2ef3e40f02484a4e1260f741f75\",\"price_changes\":[{\"asset_id\":\"7305630249804085635496399869905769372294302716159034447326228509068694952392\",\"price\":\"0.94\",\"size\":\"122327.12\",\"side\":\"BUY\",\"hash\":\"cf7d254595a79b67677c789f9631d1a9badc4568\",\"best_bid\":\"0.95\",\"best_ask\":\"0.96\"},{\"asset_id\":\"107505882767731489358349912513945399560393482969656700824895970500493757150417\",\"price\":\"0.06\",\"size\":\"122327.12\",\"side\":\"SELL\",\"hash\":\"2b7e7ee592a6e1d37aed31215a712f3278487d89\",\"best_bid\":\"0.04\",\"best_ask\":\"0.05\"}],\"timestamp\":\"1786689871825\",\"event_type\":\"price_change\"}"}
{"recv_ts": 1786689871867151, "venue": "polymarket", "raw": "{\"market\":\"0x747dc809fb79e1b05be09c42d6179459a58de2ef3e40f02484a4e1260f741f75\",\"price_changes\":[{\"asset_id\":\"107505882767731489358349912513945399560393482969656700824895970500493757150417\",\"price\":\"0.02\",\"size\":\"323593.54\",\"side\":\"BUY\",\"hash\":\"e538ec7fbb1d9c03ac9efee430fe91bf18c0b945\",\"best_bid\":\"0.04\",\"best_ask\":\"0.05\"},{\"asset_id\":\"7305630249804085635496399869905769372294302716159034447326228509068694952392\",\"price\":\"0.98\",\"size\":\"323593.54\",\"side\":\"SELL\",\"hash\":\"6b9a68f6c1544e1b670b331523050b0c8333d0b5\",\"best_bid\":\"0.95\",\"best_ask\":\"0.96\"}],\"timestamp\":\"1786689871827\",\"event_type\":\"price_change\"}"}
{"recv_ts": 1786689871867162, "venue": "polymarket", "raw": "{\"market\":\"0x747dc809fb79e1b05be09c42d6179459a58de2ef3e40f02484a4e1260f741f75\",\"price_changes\":[{\"asset_id\":\"7305630249804085635496399869905769372294302716159034447326228509068694952392\",\"price\":\"0.94\",\"size\":\"122527.12\",\"side\":\"BUY\",\"hash\":\"e3f53c9a0023d79625ed48f3dcc4698b823172ae\",\"best_bid\":\"0.95\",\"best_ask\":\"0.96\"},{\"asset_id\":\"107505882767731489358349912513945399560393482969656700824895970500493757150417\",\"price\":\"0.06\",\"size\":\"122527.12\",\"side\":\"SELL\",\"hash\":\"8c319dd6cbec7e6011e783784e85f71834def55c\",\"best_bid\":\"0.04\",\"best_ask\":\"0.05\"}],\"timestamp\":\"1786689871830\",\"event_type\":\"price_change\"}"}
{"recv_ts": 1786689871867173, "venue": "polymarket", "raw": "{\"market\":\"0x747dc809fb79e1b05be09c42d6179459a58de2ef3e40f02484a4e1260f741f75\",\"price_changes\":[{\"asset_id\":\"107505882767731489358349912513945399560393482969656700824895970500493757150417\",\"price\":\"0.02\",\"size\":\"323833.54\",\"side\":\"BUY\",\"hash\":\"4e472e844bd75ba8975f044f8e01fc1a4a22a11b\",\"best_bid\":\"0.04\",\"best_ask\":\"0.05\"},{\"asset_id\":\"7305630249804085635496399869905769372294302716159034447326228509068694952392\",\"price\":\"0.98\",\"size\":\"323833.54\",\"side\":\"SELL\",\"hash\":\"0dfa6a79a780bb790a3d9c58c887cc9dbd229bf9\",\"best_bid\":\"0.95\",\"best_ask\":\"0.96\"}],\"timestamp\":\"1786689871835\",\"event_type\":\"price_change\"}"}
{"recv_ts": 1786689872007481, "venue": "polymarket", "raw": "{\"market\":\"0x6bd56627aa21311850825edb27e53434a0e17a4f782be0086bc07f71eee00d0d\",\"price_changes\":[{\"asset_id\":\"87073899845581463485186346288398658568334162612963837182986759797304993556208\",\"price\":\"0.4\",\"size\":\"2250\",\"side\":\"BUY\",\"hash\":\"793b9d51d32ee3acfcc36bd3595d8e15cec34aed\",\"best_bid\":\"0.92\",\"best_ask\":\"0.93\"},{\"asset_id\":\"350977769852917329387037893294763093471844346281449484439085576212613048126\",\"price\":\"0.6\",\"size\":\"2250\",\"side\":\"SELL\",\"hash\":\"90b966a5bf0e161e4b4223b6f1b82d0de61f291b\",\"best_bid\":\"0.07\",\"best_ask\":\"0.08\"}],\"timestamp\":\"1786689872000\",\"event_type\":\"price_change\"}"}
{"recv_ts": 1786689872009953, "venue": "polymarket", "raw": "{\"market\":\"0x6bd56627aa21311850825edb27e53434a0e17a4f782be0086bc07f71eee00d0d\",\"price_changes\":[{\"asset_id\":\"87073899845581463485186346288398658568334162612963837182986759797304993556208\",\"price\":\"0.3\",\"size\":\"5000\",\"side\":\"BUY\",\"hash\":\"a5a3eb1d1facc54abe1b85ba85c2c42e0fd49f48\",\"best_bid\":\"0.92\",\"best_ask\":\"0.93\"},{\"asset_id\":\"350977769852917329387037893294763093471844346281449484439085576212613048126\",\"price\":\"0.7\",\"size\":\"5000\",\"side\":\"SELL\",\"hash\":\"f11c8c0782300e9d00773f6bdd543f4f9bb696b1\",\"best_bid\":\"0.07\",\"best_ask\":\"0.08\"}],\"timestamp\":\"1786689872001\",\"event_type\":\"price_change\"}"}
{"recv_ts": 1786689872010503, "venue": "polymarket", "raw": "{\"market\":\"0x6bd56627aa21311850825edb27e53434a0e17a4f782be0086bc07f71eee00d0d\",\"price_changes\":[{\"asset_id\":\"87073899845581463485186346288398658568334162612963837182986759797304993556208\",\"price\":\"0.2\",\"size\":\"6350\",\"side\":\"BUY\",\"hash\":\"aba57893a844a7f362d51a58f0e8f7def1a29deb\",\"best_bid\":\"0.92\",\"best_ask\":\"0.93\"},{\"asset_id\":\"350977769852917329387037893294763093471844346281449484439085576212613048126\",\"price\":\"0.8\",\"size\":\"6350\",\"side\":\"SELL\",\"hash\":\"ef37d7f71d03f0e41024313e379681d3987789a3\",\"best_bid\":\"0.07\",\"best_ask\":\"0.08\"}],\"timestamp\":\"1786689872002\",\"event_type\":\"price_change\"}"}
{"recv_ts": 1786689872373597, "venue": "polymarket", "raw": "{\"market\":\"0x747dc809fb79e1b05be09c42d6179459a58de2ef3e40f02484a4e1260f741f75\",\"price_changes\":[{\"asset_id\":\"107505882767731489358349912513945399560393482969656700824895970500493757150417\",\"price\":\"0.04\",\"size\":\"322438.54\",\"side\":\"BUY\",\"hash\":\"76535da6936713422bee6d6c4f7847b18e6afa34\",\"best_bid\":\"0.04\",\"best_ask\":\"0.05\"},{\"asset_id\":\"7305630249804085635496399869905769372294302716159034447326228509068694952392\",\"price\":\"0.96\",\"size\":\"322438.54\",\"side\":\"SELL\",\"hash\":\"20bac060cf3bb7c15f8a8b7b1fd46ee8961df010\",\"best_bid\":\"0.95\",\"best_ask\":\"0.96\"}],\"timestamp\":\"1786689872366\",\"event_type\":\"price_change\"}"}
{"recv_ts": 1786689872466168, "venue": "polymarket", "raw": "{\"market\":\"0x60c2c085ee8c16bc8f2419739a94971d4c9d00f637ead10fc0f540afa1be64e8\",\"price_changes\":[{\"asset_id\":\"90869494087977018607792751230236923002303032923064138180950209430688758061828\",\"price\":\"0.4\",\"size\":\"10635.7\",\"side\":\"BUY\",\"hash\":\"39bed492ecbdd35d4077aaa081b295d0f56ad360\",\"best_bid\":\"0.979\",\"best_ask\":\"0.98\"},{\"asset_id\":\"105426373826369935595603860663411604941599130211176020843036778867927711117332\",\"price\":\"0.6\",\"size\":\"10635.7\",\"side\":\"SELL\",\"hash\":\"76ed0d1b417006dc8c4aa52fb13425261c22fd8d\",\"best_bid\":\"0.02\",\"best_ask\":\"0.021\"}],\"timestamp\":\"1786689872456\",\"event_type\":\"price_change\"}"}
{"recv_ts": 1786689872466444, "venue": "polymarket", "raw": "{\"market\":\"0x60c2c085ee8c16bc8f2419739a94971d4c9d00f637ead10fc0f540afa1be64e8\",\"price_changes\":[{\"asset_id\":\"90869494087977018607792751230236923002303032923064138180950209430688758061828\",\"price\":\"0.3\",\"size\":\"15876.63\",\"side\":\"BUY\",\"hash\":\"ff3830632ee505015a8417d616c652f9925a745e\",\"best_bid\":\"0.979\",\"best_ask\":\"0.98\"},{\"asset_id\":\"105426373826369935595603860663411604941599130211176020843036778867927711117332\",\"price\":\"0.7\",\"size\":\"15876.63\",\"side\":\"SELL\",\"hash\":\"72e31925f7d717a5d3ec7efd47f57308da416d30\",\"best_bid\":\"0.02\",\"best_ask\":\"0.021\"}],\"timestamp\":\"1786689872456\",\"event_type\":\"price_change\"}"}
{"recv_ts": 1786689872467079, "venue": "polymarket", "raw": "{\"market\":\"0x60c2c085ee8c16bc8f2419739a94971d4c9d00f637ead10fc0f540afa1be64e8\",\"price_changes\":[{\"asset_id\":\"90869494087977018607792751230236923002303032923064138180950209430688758061828\",\"price\":\"0.2\",\"size\":\"31780.12\",\"side\":\"BUY\",\"hash\":\"0299154c93f865d7738003084b44bb2873d362e5\",\"best_bid\":\"0.979\",\"best_ask\":\"0.98\"},{\"asset_id\":\"105426373826369935595603860663411604941599130211176020843036778867927711117332\",\"price\":\"0.8\",\"size\":\"31780.12\",\"side\":\"SELL\",\"hash\":\"c3d8076922ada68e3475855ed062df9bcd88805d\",\"best_bid\":\"0.02\",\"best_ask\":\"0.021\"}],\"timestamp\":\"1786689872457\",\"event_type\":\"price_change\"}"}
{"recv_ts": 1786689872554847, "venue": "polymarket", "raw": "{\"market\":\"0x747dc809fb79e1b05be09c42d6179459a58de2ef3e40f02484a4e1260f741f75\",\"price_changes\":[{\"asset_id\":\"107505882767731489358349912513945399560393482969656700824895970500493757150417\",\"price\":\"0.04\",\"size\":\"322638.54\",\"side\":\"BUY\",\"hash\":\"b416bf2df1b7853862ca10db4c3e098db2a48d21\",\"best_bid\":\"0.04\",\"best_ask\":\"0.05\"},{\"asset_id\":\"7305630249804085635496399869905769372294302716159034447326228509068694952392\",\"price\":\"0.96\",\"size\":\"322638.54\",\"side\":\"SELL\",\"hash\":\"728c9dd9738ceffa7a2c6fceeb292c33f14be570\",\"best_bid\":\"0.95\",\"best_ask\":\"0.96\"}],\"timestamp\":\"1786689872543\",\"event_type\":\"price_change\"}"}
{"recv_ts": 1786689872603433, "venue": "polymarket", "raw": "{\"market\":\"0x747dc809fb79e1b05be09c42d6179459a58de2ef3e40f02484a4e1260f741f75\",\"price_changes\":[{\"asset_id\":\"7305630249804085635496399869905769372294302716159034447326228509068694952392\",\"price\":\"0.95\",\"size\":\"268448.35\",\"side\":\"BUY\",\"hash\":\"256825230a14a80c32513f6f16d08f4c90110429\",\"best_bid\":\"0.95\",\"best_ask\":\"0.96\"},{\"asset_id\":\"107505882767731489358349912513945399560393482969656700824895970500493757150417\",\"price\":\"0.05\",\"size\":\"268448.35\",\"side\":\"SELL\",\"hash\":\"58556610e04bdb0524166343be52781970e07a6e\",\"best_bid\":\"0.04\",\"best_ask\":\"0.05\"}],\"timestamp\":\"1786689872596\",\"event_type\":\"price_change\"}"}
{"recv_ts": 1786689872833728, "venue": "polymarket", "raw": "{\"market\":\"0x747dc809fb79e1b05be09c42d6179459a58de2ef3e40f02484a4e1260f741f75\",\"price_changes\":[{\"asset_id\":\"7305630249804085635496399869905769372294302716159034447326228509068694952392\",\"price\":\"0.95\",\"size\":\"268648.35\",\"side\":\"BUY\",\"hash\":\"45811e2959c642a7df8e866ce4287ff1343c0e99\",\"best_bid\":\"0.95\",\"best_ask\":\"0.96\"},{\"asset_id\":\"107505882767731489358349912513945399560393482969656700824895970500493757150417\",\"price\":\"0.05\",\"size\":\"268648.35\",\"side\":\"SELL\",\"hash\":\"54b748ea7e33fbbdc0655459a0c0d2b3b102232e\",\"best_bid\":\"0.04\",\"best_ask\":\"0.05\"}],\"timestamp\":\"1786689872824\",\"event_type\":\"price_change\"}"}
{"recv_ts": 1786689874009501, "venue": "polymarket", "raw": "{\"market\":\"0xd9fb1184af0064e5e34b129f5b79afa5a17b7e32f2953ab05efed82315fee6d4\",\"price_changes\":[{\"asset_id\":\"94559586571241563470235664821564670251180951772614764383113614156422396181162\",\"price\":\"0.006\",\"size\":\"68660.56\",\"side\":\"BUY\",\"hash\":\"f6ea8a87dde0deae0d87b7d316749557545e3f21\",\"best_bid\":\"0.036\",\"best_ask\":\"0.038\"},{\"asset_id\":\"90772332434487149264114862115632028379978765245278600275169585501290867536237\",\"price\":\"0.994\",\"size\":\"68660.56\",\"side\":\"SELL\",\"hash\":\"24d1e431cdd278ba9b0f7b55200d4eb7d5102e1f\",\"best_bid\":\"0.962\",\"best_ask\":\"0.964\"}],\"timestamp\":\"1786689874001\",\"event_type\":\"price_change\"}"}
{"recv_ts": 1786689874325711, "venue": "polymarket", "raw": "{\"market\":\"0xd9fb1184af0064e5e34b129f5b79afa5a17b7e32f2953ab05efed82315fee6d4\",\"price_changes\":[{\"asset_id\":\"94559586571241563470235664821564670251180951772614764383113614156422396181162\",\"price\":\"0.006\",\"size\":\"81994.56\",\"side\":\"BUY\",\"hash\":\"8beadf95d88fb764e39330627346b37be8c2aed0\",\"best_bid\":\"0.036\",\"best_ask\":\"0.038\"},{\"asset_id\":\"90772332434487149264114862115632028379978765245278600275169585501290867536237\",\"price\":\"0.994\",\"size\":\"81994.56\",\"side\":\"SELL\",\"hash\":\"2711a1e175e404b44c86f345a5233b7d4ed2f8af\",\"best_bid\":\"0.962\",\"best_ask\":\"0.964\"}],\"timestamp\":\"1786689874318\",\"event_type\":\"price_change\"}"}
{"recv_ts": 1786689875678111, "venue": "polymarket", "raw": "{\"market\":\"0x6bd56627aa21311850825edb27e53434a0e17a4f782be0086bc07f71eee00d0d\",\"price_changes\":[{\"asset_id\":\"87073899845581463485186346288398658568334162612963837182986759797304993556208\",\"price\":\"0.3\",\"size\":\"10666\",\"side\":\"BUY\",\"hash\":\"c755673ff085f6a6851a2fb5049f647250efdd05\",\"best_bid\":\"0.92\",\"best_ask\":\"0.93\"},{\"asset_id\":\"350977769852917329387037893294763093471844346281449484439085576212613048126\",\"price\":\"0.7\",\"size\":\"10666\",\"side\":\"SELL\",\"hash\":\"8995fab13185934d4f266d9c3903770729880d9f\",\"best_bid\":\"0.07\",\"best_ask\":\"0.08\"}],\"timestamp\":\"1786689875670\",\"event_type\":\"price_change\"}"}
{"recv_ts": 1786689875679100, "venue": "polymarket", "raw": "{\"market\":\"0x6bd56627aa21311850825edb27e53434a0e17a4f782be0086bc07f71eee00d0d\",\"price_changes\":[{\"asset_id\":\"87073899845581463485186346288398658568334162612963837182986759797304993556208\",\"price\":\"0.4\",\"size\":\"6250\",\"side\":\"BUY\",\"hash\":\"94eef5600fee187421b745ed3de3c53ecab6e6fa\",\"best_bid\":\"0.92\",\"best_ask\":\"0.93\"},{\"asset_id\":\"350977769852917329387037893294763093471844346281449484439085576212613048126\",\"price\":\"0.6\",\"size\":\"6250\",\"side\":\"SELL\",\"hash\":\"d1869cf1a54004d2a8b214508bf93aa1bdb30ebb\",\"best_bid\":\"0.07\",\"best_ask\":\"0.08\"}],\"timestamp\":\"1786689875671\",\"event_type\":\"price_change\"}"}
{"recv_ts": 1786689875679589, "venue": "polymarket", "raw": "{\"market\":\"0x6bd56627aa21311850825edb27e53434a0e17a4f782be0086bc07f71eee00d0d\",\"price_changes\":[{\"asset_id\":\"87073899845581463485186346288398658568334162612963837182986759797304993556208\",\"price\":\"0.2\",\"size\":\"15350\",\"side\":\"BUY\",\"hash\":\"6cfa725fe02ed616994dfa3362077ace2a2b53e7\",\"best_bid\":\"0.92\",\"best_ask\":\"0.93\"},{\"asset_id\":\"350977769852917329387037893294763093471844346281449484439085576212613048126\",\"price\":\"0.8\",\"size\":\"15350\",\"side\":\"SELL\",\"hash\":\"7576dec22d9cad88c9f2cdf3300c1cf65b08bae7\",\"best_bid\":\"0.07\",\"best_ask\":\"0.08\"}],\"timestamp\":\"1786689875672\",\"event_type\":\"price_change\"}"}
{"recv_ts": 1786689876024372, "venue": "polymarket", "raw": "{\"market\":\"0xd9fb1184af0064e5e34b129f5b79afa5a17b7e32f2953ab05efed82315fee6d4\",\"price_changes\":[{\"asset_id\":\"94559586571241563470235664821564670251180951772614764383113614156422396181162\",\"price\":\"0.002\",\"size\":\"1229918.5\",\"side\":\"BUY\",\"hash\":\"d78701b3a022f08a011a7c543067f2d5d9a19f02\",\"best_bid\":\"0.036\",\"best_ask\":\"0.038\"},{\"asset_id\":\"90772332434487149264114862115632028379978765245278600275169585501290867536237\",\"price\":\"0.998\",\"size\":\"1229918.5\",\"side\":\"SELL\",\"hash\":\"e4fc81bf972160b0db6c3d67a299e4c50cd466d1\",\"best_bid\":\"0.962\",\"best_ask\":\"0.964\"}],\"timestamp\":\"1786689876009\",\"event_type\":\"price_change\"}"}
{"recv_ts": 1786689876024683, "venue": "polymarket", "raw": "{\"market\":\"0xd9fb1184af0064e5e34b129f5b79afa5a17b7e32f2953ab05efed82315fee6d4\",\"price_changes\":[{\"asset_id\":\"94559586571241563470235664821564670251180951772614764383113614156422396181162\",\"price\":\"0.003\",\"size\":\"795322.17\",\"side\":\"BUY\",\"hash\":\"d78701b3a022f08a011a7c543067f2d5d9a19f02\",\"best_bid\":\"0.036\",\"best_ask\":\"0.038\"},{\"asset_id\":\"90772332434487149264114862115632028379978765245278600275169585501290867536237\",\"price\":\"0.997\",\"size\":\"795322.17\",\"side\":\"SELL\",\"hash\":\"e4fc81bf972160b0db6c3d67a299e4c50cd466d1\",\"best_bid\":\"0.962\",\"best_ask\":\"0.964\"}],\"timestamp\":\"1786689876009\",\"event_type\":\"price_change\"}"}
{"recv_ts": 1786689876024780, "venue": "polymarket", "raw": "{\"market\":\"0xd9fb1184af0064e5e34b129f5b79afa5a17b7e32f2953ab05efed82315fee6d4\",\"price_changes\":[{\"asset_id\":\"94559586571241563470235664821564670251180951772614764383113614156422396181162\",\"price\":\"0.008\",\"size\":\"103010.37\",\"side\":\"BUY\",\"hash\":\"d78701b3a022f08a011a7c543067f2d5d9a19f02\",\"best_bid\":\"0.036\",\"best_ask\":\"0.038\"},{\"asset_id\":\"90772332434487149264114862115632028379978765245278600275169585501290867536237\",\"price\":\"0.992\",\"size\":\"103010.37\",\"side\":\"SELL\",\"hash\":\"e4fc81bf972160b0db6c3d67a299e4c50cd466d1\",\"best_bid\":\"0.962\",\"best_ask\":\"0.964\"}],\"timestamp\":\"1786689876009\",\"event_type\":\"price_change\"}"}
{"recv_ts": 1786689876141624, "venue": "polymarket", "raw": "{\"market\":\"0x747dc809fb79e1b05be09c42d6179459a58de2ef3e40f02484a4e1260f741f75\",\"price_changes\":[{\"asset_id\":\"7305630249804085635496399869905769372294302716159034447326228509068694952392\",\"price\":\"0.5\",\"size\":\"2938.5\",\"side\":\"BUY\",\"hash\":\"01652c60d45fafbcdb81a9ffa2ef0b56b0ad3fd5\",\"best_bid\":\"0.95\",\"best_ask\":\"0.96\"},{\"asset_id\":\"107505882767731489358349912513945399560393482969656700824895970500493757150417\",\"price\":\"0.5\",\"size\":\"2938.5\",\"side\":\"SELL\",\"hash\":\"f547fd64b2d8257eee07cdbb04648cc054294777\",\"best_bid\":\"0.04\",\"best_ask\":\"0.05\"}],\"timestamp\":\"1786689876134\",\"event_type\":\"price_change\"}"}
{"recv_ts": 1786689876265936, "venue": "polymarket", "raw": "{\"market\":\"0xd595eb9b81885ff018738300c79047e3ec89e87294424f57a29a7fa9162bf116\",\"price_changes\":[{\"asset_id\":\"57216272564529548464686463691236811991956032201293786790337952253964682584376\",\"price\":\"0.5\",\"size\":\"2579.77\",\"side\":\"BUY\",\"hash\":\"065828f79758fcaa2749b757f14426e813c036a1\",\"best_bid\":\"0.963\",\"best_ask\":\"0.964\"},{\"asset_id\":\"5161623255678193352839985156330393796378434470119114669671615782853260939535\",\"price\":\"0.5\",\"size\":\"2579.77\",\"side\":\"SELL\",\"hash\":\"c2efc750647deb81fc4e64ff9f6814c8aa20d73f\",\"best_bid\":\"0.036\",\"best_ask\":\"0.037\"}],\"timestamp\":\"1786689876258\",\"event_type\":\"price_change\"}"}
{"recv_ts": 1786689876522647, "venue": "polymarket", "raw": "{\"market\":\"0xd9fb1184af0064e5e34b129f5b79afa5a17b7e32f2953ab05efed82315fee6d4\",\"price_changes\":[{\"asset_id\":\"94559586571241563470235664821564670251180951772614764383113614156422396181162\",\"price\":\"0.002\",\"size\":\"1229962.64\",\"side\":\"BUY\",\"hash\":\"1640cfd369d78959a6f6859a1b2168e555362591\",\"best_bid\":\"0.036\",\"best_ask\":\"0.038\"},{\"asset_id\":\"90772332434487149264114862115632028379978765245278600275169585501290867536237\",\"price\":\"0.998\",\"size\":\"1229962.64\",\"side\":\"SELL\",\"hash\":\"80eb237aff8cc788d0c8a033218055de06a3eae0\",\"best_bid\":\"0.962\",\"best_ask\":\"0.964\"}],\"timestamp\":\"1786689876515\",\"event_type\":\"price_change\"}"}
{"recv_ts": 1786689876522776, "venue": "polymarket", "raw": "{\"market\":\"0xd9fb1184af0064e5e34b129f5b79afa5a17b7e32f2953ab05efed82315fee6d4\",\"price_changes\":[{\"asset_id\":\"94559586571241563470235664821564670251180951772614764383113614156422396181162\",\"price\":\"0.008\",\"size\":\"103042.34\",\"side\":\"BUY\",\"hash\":\"cf32956f60e919650cee72c524a9eee1787ae385\",\"best_bid\":\"0.036\",\"best_ask\":\"0.038\"},{\"asset_id\":\"90772332434487149264114862115632028379978765245278600275169585501290867536237\",\"price\":\"0.992\",\"size\":\"103042.34\",\"side\":\"SELL\",\"hash\":\"0cd2ff495c32e8699374a3bbb1afe6dfe56ae5f4\",\"best_bid\":\"0.962\",\"best_ask\":\"0.964\"}],\"timestamp\":\"1786689876516\",\"event_type\":\"price_change\"}"}
{"recv_ts": 1786689876524469, "venue": "polymarket", "raw": "{\"market\":\"0xd9fb1184af0064e5e34b129f5b79afa5a17b7e32f2953ab05efed82315fee6d4\",\"price_changes\":[{\"asset_id\":\"94559586571241563470235664821564670251180951772614764383113614156422396181162\",\"price\":\"0.003\",\"size\":\"795351.37\",\"side\":\"BUY\",\"hash\":\"44f217cb3e9e9e1a5a5878f962cbe3993bb5d708\",\"best_bid\":\"0.036\",\"best_ask\":\"0.038\"},{\"asset_id\":\"90772332434487149264114862115632028379978765245278600275169585501290867536237\",\"price\":\"0.997\",\"size\":\"795351.37\",\"side\":\"SELL\",\"hash\":\"04dd184e467ceb153fb69040586c60ee60ad1b51\",\"best_bid\":\"0.962\",\"best_ask\":\"0.964\"}],\"timestamp\":\"1786689876517\",\"event_type\":\"price_change\"}"}
{"recv_ts": 1786689877672479, "venue": "polymarket", "raw": "{\"market\":\"0xbb4d51e6364066d92eb6f9b8413dd7193de70966736044463b205834805a1f3b\",\"price_changes\":[{\"asset_id\":\"106181075047366745139197108801635573283215248045056329679360376976893016488727\",\"price\":\"0.92\",\"size\":\"181308.7\",\"side\":\"BUY\",\"hash\":\"e271280076679b64ab4ad6291c7fc1a115848938\",\"best_bid\":\"0.93\",\"best_ask\":\"0.94\"},{\"asset_id\":\"10991849228756847439673778874175365458450913336396982752046655649803657501964\",\"price\":\"0.08\",\"size\":\"181308.7\",\"side\":\"SELL\",\"hash\":\"0b69939d271af88f4e569ef07c5e695d97d17f38\",\"best_bid\":\"0.06\",\"best_ask\":\"0.07\"}],\"timestamp\":\"1786689877664\",\"event_type\":\"price_change\"}"}
{"recv_ts": 1786689879009439, "venue": "polymarket", "raw": "{\"market\":\"0xd9fb1184af0064e5e34b129f5b79afa5a17b7e32f2953ab05efed82315fee6d4\",\"price_changes\":[{\"asset_id\":\"90772332434487149264114862115632028379978765245278600275169585501290867536237\",\"price\":\"0.956\",\"size\":\"21313.88\",\"side\":\"BUY\",\"hash\":\"c2bb7bb1af37c106e7dfedcbb2ea1884b017fddd\",\"best_bid\":\"0.962\",\"best_ask\":\"0.964\"},{\"asset_id\":\"94559586571241563470235664821564670251180951772614764383113614156422396181162\",\"price\":\"0.044\",\"size\":\"21313.88\",\"side\":\"SELL\",\"hash\":\"63bcb0b8f415a221689de4e6a5e87d1e82457086\",\"best_bid\":\"0.036\",\"best_ask\":\"0.038\"}],\"timestamp\":\"1786689879001\",\"event_type\":\"price_change\"}"}
{"recv_ts": 1786689879124095, "venue": "polymarket", "raw": "{\"market\":\"0xd9fb1184af0064e5e34b129f5b79afa5a17b7e32f2953ab05efed82315fee6d4\",\"price_changes\":[{\"asset_id\":\"90772332434487149264114862115632028379978765245278600275169585501290867536237\",\"price\":\"0.956\",\"size\":\"21513.88\",\"side\":\"BUY\",\"hash\":\"e9f0870bcdef9615a3631f26257ce4af4f252c92\",\"best_bid\":\"0.962\",\"best_ask\":\"0.964\"},{\"asset_id\":\"94559586571241563470235664821564670251180951772614764383113614156422396181162\",\"price\":\"0.044\",\"size\":\"21513.88\",\"side\":\"SELL\",\"hash\":\"3c2d31c7a7b3935f62598ff5e871f9f82e950e2a\",\"best_bid\":\"0.036\",\"best_ask\":\"0.038\"}],\"timestamp\":\"1786689879117\",\"event_type\":\"price_change\"}"}
{"recv_ts": 1786689880008727, "venue": "polymarket", "raw": "{\"market\":\"0x6bd56627aa21311850825edb27e53434a0e17a4f782be0086bc07f71eee00d0d\",\"price_changes\":[{\"asset_id\":\"87073899845581463485186346288398658568334162612963837182986759797304993556208\",\"price\":\"0.1\",\"size\":\"1150\",\"side\":\"BUY\",\"hash\":\"63e8f54245d288b85f5226a0f037ca9fd2fca412\",\"best_bid\":\"0.92\",\"best_ask\":\"0.93\"},{\"asset_id\":\"350977769852917329387037893294763093471844346281449484439085576212613048126\",\"price\":\"0.9\",\"size\":\"1150\",\"side\":\"SELL\",\"hash\":\"30ea2873d70367a04b7bf7916c7628c459c1dcdd\",\"best_bid\":\"0.07\",\"best_ask\":\"0.08\"}],\"timestamp\":\"1786689880000\",\"event_type\":\"price_change\"}"}
{"recv_ts": 1786689880012193, "venue": "polymarket", "raw": "{\"market\":\"0x6bd56627aa21311850825edb27e53434a0e17a4f782be0086bc07f71eee00d0d\",\"price_changes\":[{\"asset_id\":\"87073899845581463485186346288398658568334162612963837182986759797304993556208\",\"price\":\"0.4\",\"size\":\"5000\",\"side\":\"BUY\",\"hash\":\"7b1dd16aa2163bc5a5ecbf7d88944d33b72456a9\",\"best_bid\":\"0.92\",\"best_ask\":\"0.93\"},{\"asset_id\":\"350977769852917329387037893294763093471844346281449484439085576212613048126\",\"price\":\"0.6\",\"size\":\"5000\",\"side\":\"SELL\",\"hash\":\"92eca9d2b56d46c4c07b10d2a42be4ff4b1a2e49\",\"best_bid\":\"0.07\",\"best_ask\":\"0.08\"}],\"timestamp\":\"1786689880002\",\"event_type\":\"price_change\"}"}
{"recv_ts": 1786689880012248, "venue": "polymarket", "raw": "{\"market\":\"0x6bd56627aa21311850825edb27e53434a0e17a4f782be0086bc07f71eee00d0d\",\"price_changes\":[{\"asset_id\":\"87073899845581463485186346288398658568334162612963837182986759797304993556208\",\"price\":\"0.2\",\"size\":\"10350\",\"side\":\"BUY\",\"hash\":\"8e337ab13403822b7070dcf53184d0944efd7f72\",\"best_bid\":\"0.92\",\"best_ask\":\"0.93\"},{\"asset_id\":\"350977769852917329387037893294763093471844346281449484439085576212613048126\",\"price\":\"0.8\",\"size\":\"10350\",\"side\":\"SELL\",\"hash\":\"3dc499b22439a2b1c1ebe9c420ac74d788c44a4b\",\"best_bid\":\"0.07\",\"best_ask\":\"0.08\"}],\"timestamp\":\"1786689880003\",\"event_type\":\"price_change\"}"}
{"recv_ts": 1786689880012267, "venue": "polymarket", "raw": "{\"market\":\"0x6bd56627aa21311850825edb27e53434a0e17a4f782be0086bc07f71eee00d0d\",\"price_changes\":[{\"asset_id\":\"87073899845581463485186346288398658568334162612963837182986759797304993556208\",\"price\":\"0.3\",\"size\":\"7666\",\"side\":\"BUY\",\"hash\":\"8e337ab13403822b7070dcf53184d0944efd7f72\",\"best_bid\":\"0.92\",\"best_ask\":\"0.93\"},{\"asset_id\":\"350977769852917329387037893294763093471844346281449484439085576212613048126\",\"price\":\"0.7\",\"size\":\"7666\",\"side\":\"SELL\",\"hash\":\"3dc499b22439a2b1c1ebe9c420ac74d788c44a4b\",\"best_bid\":\"0.07\",\"best_ask\":\"0.08\"}],\"timestamp\":\"1786689880003\",\"event_type\":\"price_change\"}"}
{"recv_ts": 1786689882777821, "venue": "polymarket", "raw": "{\"market\":\"0x6bd56627aa21311850825edb27e53434a0e17a4f782be0086bc07f71eee00d0d\",\"price_changes\":[{\"asset_id\":\"87073899845581463485186346288398658568334162612963837182986759797304993556208\",\"price\":\"0.4\",\"size\":\"6250\",\"side\":\"BUY\",\"hash\":\"15c9810736e88d8f85644d08bb74fd497eb56626\",\"best_bid\":\"0.92\",\"best_ask\":\"0.93\"},{\"asset_id\":\"350977769852917329387037893294763093471844346281449484439085576212613048126\",\"price\":\"0.6\",\"size\":\"6250\",\"side\":\"SELL\",\"hash\":\"73d53986bd45c49934d27ecd74e657a1c41f5546\",\"best_bid\":\"0.07\",\"best_ask\":\"0.08\"}],\"timestamp\":\"1786689882770\",\"event_type\":\"price_change\"}"}
{"recv_ts": 1786689882778013, "venue": "polymarket", "raw": "{\"market\":\"0x6bd56627aa21311850825edb27e53434a0e17a4f782be0086bc07f71eee00d0d\",\"price_changes\":[{\"asset_id\":\"87073899845581463485186346288398658568334162612963837182986759797304993556208\",\"price\":\"0.1\",\"size\":\"13150\",\"side\":\"BUY\",\"hash\":\"f76455f0f52703fe91d6457dab4b1b8985d615e7\",\"best_bid\":\"0.92\",\"best_ask\":\"0.93\"},{\"asset_id\":\"350977769852917329387037893294763093471844346281449484439085576212613048126\",\"price\":\"0.9\",\"size\":\"13150\",\"side\":\"SELL\",\"hash\":\"e8f5fbda2608ceef2849d44dcd45562aa9544004\",\"best_bid\":\"0.07\",\"best_ask\":\"0.08\"}],\"timestamp\":\"1786689882770\",\"event_type\":\"price_change\"}"}
{"recv_ts": 1786689882778657, "venue": "polymarket", "raw": "{\"market\":\"0x6bd56627aa21311850825edb27e53434a0e17a4f782be0086bc07f71eee00d0d\",\"price_changes\":[{\"asset_id\":\"87073899845581463485186346288398658568334162612963837182986759797304993556208\",\"price\":\"0.2\",\"size\":\"15350\",\"side\":\"BUY\",\"hash\":\"134bcc6777b24ffecd5bec43012c1b866edf28e6\",\"best_bid\":\"0.92\",\"best_ask\":\"0.93\"},{\"asset_id\":\"350977769852917329387037893294763093471844346281449484439085576212613048126\",\"price\":\"0.8\",\"size\":\"15350\",\"side\":\"SELL\",\"hash\":\"d015418d8c47f973c9dce428bb6ab220a3ef3ebe\",\"best_bid\":\"0.07\",\"best_ask\":\"0.08\"}],\"timestamp\":\"1786689882771\",\"event_type\":\"price_change\"}"}
{"recv_ts": 1786689882780287, "venue": "polymarket", "raw": "{\"market\":\"0x6bd56627aa21311850825edb27e53434a0e17a4f782be0086bc07f71eee00d0d\",\"price_changes\":[{\"asset_id\":\"87073899845581463485186346288398658568334162612963837182986759797304993556208\",\"price\":\"0.3\",\"size\":\"10666\",\"side\":\"BUY\",\"hash\":\"1bd51c6a04110d8e25646d61b14bceba9f68dfba\",\"best_bid\":\"0.92\",\"best_ask\":\"0.93\"},{\"asset_id\":\"350977769852917329387037893294763093471844346281449484439085576212613048126\",\"price\":\"0.7\",\"size\":\"10666\",\"side\":\"SELL\",\"hash\":\"8989698de7cdf2c84f6d3b5190d45d271f49baac\",\"best_bid\":\"0.07\",\"best_ask\":\"0.08\"}],\"timestamp\":\"1786689882772\",\"event_type\":\"price_change\"}"}
{"recv_ts": 1786689885260497, "venue": "polymarket", "raw": "{\"market\":\"0xbb4d51e6364066d92eb6f9b8413dd7193de70966736044463b205834805a1f3b\",\"price_changes\":[{\"asset_id\":\"106181075047366745139197108801635573283215248045056329679360376976893016488727\",\"price\":\"0.92\",\"size\":\"181908.7\",\"side\":\"BUY\",\"hash\":\"0f52425a90e38a0863fc399339d35ed493313a04\",\"best_bid\":\"0.93\",\"best_ask\":\"0.94\"},{\"asset_id\":\"10991849228756847439673778874175365458450913336396982752046655649803657501964\",\"price\":\"0.08\",\"size\":\"181908.7\",\"side\":\"SELL\",\"hash\":\"45f1f2d68cbd2892a93769231c77e2f0c6ab620b\",\"best_bid\":\"0.06\",\"best_ask\":\"0.07\"}],\"timestamp\":\"1786689885253\",\"event_type\":\"price_change\"}"}
{"recv_ts": 1786689887444145, "venue": "polymarket", "raw": "{\"market\":\"0xd9fb1184af0064e5e34b129f5b79afa5a17b7e32f2953ab05efed82315fee6d4\",\"price_changes\":[{\"asset_id\":\"94559586571241563470235664821564670251180951772614764383113614156422396181162\",\"price\":\"0.034\",\"size\":\"14472.12\",\"side\":\"BUY\",\"hash\":\"62833208669bfa0a87006361d90d811fb5bcc656\",\"best_bid\":\"0.036\",\"best_ask\":\"0.038\"},{\"asset_id\":\"90772332434487149264114862115632028379978765245278600275169585501290867536237\",\"price\":\"0.966\",\"size\":\"14472.12\",\"side\":\"SELL\",\"hash\":\"c9224bb1bb60164163d69e74ce50b76abe00a61c\",\"best_bid\":\"0.962\",\"best_ask\":\"0.964\"}],\"timestamp\":\"1786689887436\",\"event_type\":\"price_change\"}"}
{"recv_ts": 1786689887662340, "venue": "polymarket", "raw": "{\"market\":\"0xd9fb1184af0064e5e34b129f5b79afa5a17b7e32f2953ab05efed82315fee6d4\",\"price_changes\":[{\"asset_id\":\"90772332434487149264114862115632028379978765245278600275169585501290867536237\",\"price\":\"0.96\",\"size\":\"38445.56\",\"side\":\"BUY\",\"hash\":\"df57758c4a0d0a26af970823ba6ce60325436ab0\",\"best_bid\":\"0.962\",\"best_ask\":\"0.964\"},{\"asset_id\":\"94559586571241563470235664821564670251180951772614764383113614156422396181162\",\"price\":\"0.04\",\"size\":\"38445.56\",\"side\":\"SELL\",\"hash\":\"05df5fa523a18b9be6d57581dc7ea5bb63fbf408\",\"best_bid\":\"0.036\",\"best_ask\":\"0.038\"}],\"timestamp\":\"1786689887655\",\"event_type\":\"price_change\"}"}
{"recv_ts": 1786689888009725, "venue": "polymarket", "raw": "{\"market\":\"0xd9fb1184af0064e5e34b129f5b79afa5a17b7e32f2953ab05efed82315fee6d4\",\"price_changes\":[{\"asset_id\":\"90772332434487149264114862115632028379978765245278600275169585501290867536237\",\"price\":\"0.6\",\"size\":\"100.92\",\"side\":\"BUY\",\"hash\":\"8763e57f87adeeb4193cd2fcc8a660de0ed771cc\",\"best_bid\":\"0.962\",\"best_ask\":\"0.964\"},{\"asset_id\":\"94559586571241563470235664821564670251180951772614764383113614156422396181162\",\"price\":\"0.4\",\"size\":\"100.92\",\"side\":\"SELL\",\"hash\":\"6ffd5e48e48266c59bec6d83c6691080110bfd72\",\"best_bid\":\"0.036\",\"best_ask\":\"0.038\"}],\"timestamp\":\"1786689888001\",\"event_type\":\"price_change\"}"}
{"recv_ts": 1786689890010204, "venue": "polymarket", "raw": "{\"market\":\"0xbb4d51e6364066d92eb6f9b8413dd7193de70966736044463b205834805a1f3b\",\"price_changes\":[{\"asset_id\":\"106181075047366745139197108801635573283215248045056329679360376976893016488727\",\"price\":\"0.78\",\"size\":\"662.76\",\"side\":\"BUY\",\"hash\":\"ce9eeff994bff9d74d25ec1bce03fcc13e11a07e\",\"best_bid\":\"0.93\",\"best_ask\":\"0.94\"},{\"asset_id\":\"10991849228756847439673778874175365458450913336396982752046655649803657501964\",\"price\":\"0.22\",\"size\":\"662.76\",\"side\":\"SELL\",\"hash\":\"f9b36e5a4613e29f0b4ea07790b5d64d973e3340\",\"best_bid\":\"0.06\",\"best_ask\":\"0.07\"}],\"timestamp\":\"1786689890002\",\"event_type\":\"price_change\"}"}
{"recv_ts": 1786689890010787, "venue": "polymarket", "raw": "{\"market\":\"0xbb4d51e6364066d92eb6f9b8413dd7193de70966736044463b205834805a1f3b\",\"price_changes\":[{\"asset_id\":\"106181075047366745139197108801635573283215248045056329679360376976893016488727\",\"price\":\"0.62\",\"size\":\"262.62\",\"side\":\"BUY\",\"hash\":\"ce9eeff994bff9d74d25ec1bce03fcc13e11a07e\",\"best_bid\":\"0.93\",\"best_ask\":\"0.94\"},{\"asset_id\":\"10991849228756847439673778874175365458450913336396982752046655649803657501964\",\"price\":\"0.38\",\"size\":\"262.62\",\"side\":\"SELL\",\"hash\":\"f9b36e5a4613e29f0b4ea07790b5d64d973e3340\",\"best_bid\":\"0.06\",\"best_ask\":\"0.07\"}],\"timestamp\":\"1786689890002\",\"event_type\":\"price_change\"}"}
{"recv_ts": 1786689890011626, "venue": "polymarket", "raw": "{\"market\":\"0xbb4d51e6364066d92eb6f9b8413dd7193de70966736044463b205834805a1f3b\",\"price_changes\":[{\"asset_id\":\"106181075047366745139197108801635573283215248045056329679360376976893016488727\",\"price\":\"0.7\",\"size\":\"25207.26\",\"side\":\"BUY\",\"hash\":\"9219f5393b9c03970aa82c43349db2ecd4e7b811\",\"best_bid\":\"0.93\",\"best_ask\":\"0.94\"},{\"asset_id\":\"10991849228756847439673778874175365458450913336396982752046655649803657501964\",\"price\":\"0.3\",\"size\":\"25207.26\",\"side\":\"SELL\",\"hash\":\"e0fdad968217656c83e966802f2fc08c14f6da43\",\"best_bid\":\"0.06\",\"best_ask\":\"0.07\"}],\"timestamp\":\"1786689890003\",\"event_type\":\"price_change\"}"}
{"recv_ts": 1786689890381538, "venue": "polymarket", "raw": "{\"market\":\"0xbb4d51e6364066d92eb6f9b8413dd7193de70966736044463b205834805a1f3b\",\"price_changes\":[{\"asset_id\":\"106181075047366745139197108801635573283215248045056329679360376976893016488727\",\"price\":\"0.78\",\"size\":\"1304.76\",\"side\":\"BUY\",\"hash\":\"d1025d96daf4c9bb860714b318263163d84c9770\",\"best_bid\":\"0.93\",\"best_ask\":\"0.94\"},{\"asset_id\":\"10991849228756847439673778874175365458450913336396982752046655649803657501964\",\"price\":\"0.22\",\"size\":\"1304.76\",\"side\":\"SELL\",\"hash\":\"c66e4e61f4ec5d5fcd66cfef1c2f8f9845a0340e\",\"best_bid\":\"0.06\",\"best_ask\":\"0.07\"}],\"timestamp\":\"1786689890372\",\"event_type\":\"price_change\"}"}
{"recv_ts": 1786689890381856, "venue": "polymarket", "raw": "{\"market\":\"0xbb4d51e6364066d92eb6f9b8413dd7193de70966736044463b205834805a1f3b\",\"price_changes\":[{\"asset_id\":\"106181075047366745139197108801635573283215248045056329679360376976893016488727\",\"price\":\"0.7\",\"size\":\"25922.26\",\"side\":\"BUY\",\"hash\":\"a203048196c8bfcca02098e9922a8ef94bf16047\",\"best_bid\":\"0.93\",\"best_ask\":\"0.94\"},{\"asset_id\":\"10991849228756847439673778874175365458450913336396982752046655649803657501964\",\"price\":\"0.3\",\"size\":\"25922.26\",\"side\":\"SELL\",\"hash\":\"70e4e37722c767b1fe7ea752c0fdfff088d31d9e\",\"best_bid\":\"0.06\",\"best_ask\":\"0.07\"}],\"timestamp\":\"1786689890373\",\"event_type\":\"price_change\"}"}
{"recv_ts": 1786689890382489, "venue": "polymarket", "raw": "{\"market\":\"0xbb4d51e6364066d92eb6f9b8413dd7193de70966736044463b205834805a1f3b\",\"price_changes\":[{\"asset_id\":\"106181075047366745139197108801635573283215248045056329679360376976893016488727\",\"price\":\"0.62\",\"size\":\"1069.62\",\"side\":\"BUY\",\"hash\":\"b99b2ce887175a8c3e69f2c19454e24d8e29e4fc\",\"best_bid\":\"0.93\",\"best_ask\":\"0.94\"},{\"asset_id\":\"10991849228756847439673778874175365458450913336396982752046655649803657501964\",\"price\":\"0.38\",\"size\":\"1069.62\",\"side\":\"SELL\",\"hash\":\"5eef0a1db789bff60edaa9ffa5d0d7c06322d44c\",\"best_bid\":\"0.06\",\"best_ask\":\"0.07\"}],\"timestamp\":\"1786689890374\",\"event_type\":\"price_change\"}"}
{"recv_ts": 1786689891008446, "venue": "polymarket", "raw": "{\"market\":\"0x60c2c085ee8c16bc8f2419739a94971d4c9d00f637ead10fc0f540afa1be64e8\",\"price_changes\":[{\"asset_id\":\"90869494087977018607792751230236923002303032923064138180950209430688758061828\",\"price\":\"0.965\",\"size\":\"16100.4\",\"side\":\"BUY\",\"hash\":\"8b0a4eb82b6ee7d7ef6cc48d9903869501442129\",\"best_bid\":\"0.979\",\"best_ask\":\"0.98\"},{\"asset_id\":\"105426373826369935595603860663411604941599130211176020843036778867927711117332\",\"price\":\"0.035\",\"size\":\"16100.4\",\"side\":\"SELL\",\"hash\":\"5e392b654c0be22af675448d9535009f50036065\",\"best_bid\":\"0.02\",\"best_ask\":\"0.021\"}],\"timestamp\":\"1786689891000\",\"event_type\":\"price_change\"}"}
{"recv_ts": 1786689891009921, "venue": "polymarket", "raw": "{\"market\":\"0x60c2c085ee8c16bc8f2419739a94971d4c9d00f637ead10fc0f540afa1be64e8\",\"price_changes\":[{\"asset_id\":\"105426373826369935595603860663411604941599130211176020843036778867927711117332\",\"price\":\"0.011\",\"size\":\"53757.82\",\"side\":\"BUY\",\"hash\":\"3d43c46ef503a528e52715012a84ab462c86acf0\",\"best_bid\":\"0.02\",\"best_ask\":\"0.021\"},{\"asset_id\":\"90869494087977018607792751230236923002303032923064138180950209430688758061828\",\"price\":\"0.989\",\"size\":\"53757.82\",\"side\":\"SELL\",\"hash\":\"8b0a4eb82b6ee7d7ef6cc48d9903869501442129\",\"best_bid\":\"0.979\",\"best_ask\":\"0.98\"}],\"timestamp\":\"1786689891001\",\"event_type\":\"price_change\"}"}
{"recv_ts": 1786689891061942, "venue": "polymarket", "raw": "{\"market\":\"0x60c2c085ee8c16bc8f2419739a94971d4c9d00f637ead10fc0f540afa1be64e8\",\"price_changes\":[{\"asset_id\":\"105426373826369935595603860663411604941599130211176020843036778867927711117332\",\"price\":\"0.011\",\"size\":\"53957.82\",\"side\":\"BUY\",\"hash\":\"e13d4188230a8f21b6f373271b95dd216381d342\",\"best_bid\":\"0.02\",\"best_ask\":\"0.021\"},{\"asset_id\":\"90869494087977018607792751230236923002303032923064138180950209430688758061828\",\"price\":\"0.989\",\"size\":\"53957.82\",\"side\":\"SELL\",\"hash\":\"aef359f7b760cd7215fe37395a55bfbda4e991d1\",\"best_bid\":\"0.979\",\"best_ask\":\"0.98\"}],\"timestamp\":\"1786689891052\",\"event_type\":\"price_change\"}"}
{"recv_ts": 1786689891062431, "venue": "polymarket", "raw": "{\"market\":\"0x60c2c085ee8c16bc8f2419739a94971d4c9d00f637ead10fc0f540afa1be64e8\",\"price_changes\":[{\"asset_id\":\"90869494087977018607792751230236923002303032923064138180950209430688758061828\",\"price\":\"0.965\",\"size\":\"16300.4\",\"side\":\"BUY\",\"hash\":\"be16b6cf534c0ecb3cec8795adf911e700b6ce04\",\"best_bid\":\"0.979\",\"best_ask\":\"0.98\"},{\"asset_id\":\"105426373826369935595603860663411604941599130211176020843036778867927711117332\",\"price\":\"0.035\",\"size\":\"16300.4\",\"side\":\"SELL\",\"hash\":\"5bcef74f5f5a70c55197a18b984ebcbe302d9fe6\",\"best_bid\":\"0.02\",\"best_ask\":\"0.021\"}],\"timestamp\":\"1786689891054\",\"event_type\":\"price_change\"}"}
{"recv_ts": 1786689891511255, "venue": "polymarket", "raw": "{\"market\":\"0xd9fb1184af0064e5e34b129f5b79afa5a17b7e32f2953ab05efed82315fee6d4\",\"price_changes\":[{\"asset_id\":\"90772332434487149264114862115632028379978765245278600275169585501290867536237\",\"price\":\"0.6\",\"size\":\"516.92\",\"side\":\"BUY\",\"hash\":\"7b7fe61cd0fdfaf3c1dcce21d755fc135a4433c1\",\"best_bid\":\"0.962\",\"best_ask\":\"0.964\"},{\"asset_id\":\"94559586571241563470235664821564670251180951772614764383113614156422396181162\",\"price\":\"0.4\",\"size\":\"516.92\",\"side\":\"SELL\",\"hash\":\"a47bd8abe904d2abaf2fc4dc64c48e297e46c92c\",\"best_bid\":\"0.036\",\"best_ask\":\"0.038\"}],\"timestamp\":\"1786689891504\",\"event_type\":\"price_change\"}"}
{"recv_ts": 1786689895016889, "venue": "polymarket", "raw": "{\"market\":\"0xd9fb1184af0064e5e34b129f5b79afa5a17b7e32f2953ab05efed82315fee6d4\",\"price_changes\":[{\"asset_id\":\"90772332434487149264114862115632028379978765245278600275169585501290867536237\",\"price\":\"0.2\",\"size\":\"5255\",\"side\":\"BUY\",\"hash\":\"79bfaf75adf8e769eb44aaff8dff5ef31ae35fb5\",\"best_bid\":\"0.962\",\"best_ask\":\"0.964\"},{\"asset_id\":\"94559586571241563470235664821564670251180951772614764383113614156422396181162\",\"price\":\"0.8\",\"size\":\"5255\",\"side\":\"SELL\",\"hash\":\"7263d9a20c4c4d2c2e968c5d5a74a06f10ec7e81\",\"best_bid\":\"0.036\",\"best_ask\":\"0.038\"}],\"timestamp\":\"1786689895000\",\"event_type\":\"price_change\"}"}
{"recv_ts": 1786689895017262, "venue": "polymarket", "raw": "{\"market\":\"0xd9fb1184af0064e5e34b129f5b79afa5a17b7e32f2953ab05efed82315fee6d4\",\"price_changes\":[{\"asset_id\":\"90772332434487149264114862115632028379978765245278600275169585501290867536237\",\"price\":\"0.3\",\"size\":\"3000\",\"side\":\"BUY\",\"hash\":\"79bfaf75adf8e769eb44aaff8dff5ef31ae35fb5\",\"best_bid\":\"0.962\",\"best_ask\":\"0.964\"},{\"asset_id\":\"94559586571241563470235664821564670251180951772614764383113614156422396181162\",\"price\":\"0.7\",\"size\":\"3000\",\"side\":\"SELL\",\"hash\":\"7263d9a20c4c4d2c2e968c5d5a74a06f10ec7e81\",\"best_bid\":\"0.036\",\"best_ask\":\"0.038\"}],\"timestamp\":\"1786689895000\",\"event_type\":\"price_change\"}"}
{"recv_ts": 1786689895017316, "venue": "polymarket", "raw": "{\"market\":\"0xd9fb1184af0064e5e34b129f5b79afa5a17b7e32f2953ab05efed82315fee6d4\",\"price_changes\":[{\"asset_id\":\"90772332434487149264114862115632028379978765245278600275169585501290867536237\",\"price\":\"0.4\",\"size\":\"1280\",\"side\":\"BUY\",\"hash\":\"0d1b12b37a3ec690b656466aa82165a23112713b\",\"best_bid\":\"0.962\",\"best_ask\":\"0.964\"},{\"asset_id\":\"94559586571241563470235664821564670251180951772614764383113614156422396181162\",\"price\":\"0.6\",\"size\":\"1280\",\"side\":\"SELL\",\"hash\":\"8eca0928e191ee9e6a1f02e3071a1b35490cc112\",\"best_bid\":\"0.036\",\"best_ask\":\"0.038\"}],\"timestamp\":\"1786689895001\",\"event_type\":\"price_change\"}"}
{"recv_ts": 1786689896535900, "venue": "polymarket", "raw": "{\"market\":\"0xd9fb1184af0064e5e34b129f5b79afa5a17b7e32f2953ab05efed82315fee6d4\",\"price_changes\":[{\"asset_id\":\"90772332434487149264114862115632028379978765245278600275169585501290867536237\",\"price\":\"0.4\",\"size\":\"5280\",\"side\":\"BUY\",\"hash\":\"79b5ae29e79d61ba5b218e29142b462242938560\",\"best_bid\":\"0.962\",\"best_ask\":\"0.964\"},{\"asset_id\":\"94559586571241563470235664821564670251180951772614764383113614156422396181162\",\"price\":\"0.6\",\"size\":\"5280\",\"side\":\"SELL\",\"hash\":\"f01fd7105ee70e75cdcc69258850646e398052e3\",\"best_bid\":\"0.036\",\"best_ask\":\"0.038\"}],\"timestamp\":\"1786689896528\",\"event_type\":\"price_change\"}"}
{"recv_ts": 1786689896536268, "venue": "polymarket", "raw": "{\"market\":\"0xd9fb1184af0064e5e34b129f5b79afa5a17b7e32f2953ab05efed82315fee6d4\",\"price_changes\":[{\"asset_id\":\"90772332434487149264114862115632028379978765245278600275169585501290867536237\",\"price\":\"0.3\",\"size\":\"8666\",\"side\":\"BUY\",\"hash\":\"9ef2b7c16bd39413b0da30cc7b7ae0b9b029f446\",\"best_bid\":\"0.962\",\"best_ask\":\"0.964\"},{\"asset_id\":\"94559586571241563470235664821564670251180951772614764383113614156422396181162\",\"price\":\"0.7\",\"size\":\"8666\",\"side\":\"SELL\",\"hash\":\"71997d8bb84b952477870a4d464b50964de95749\",\"best_bid\":\"0.036\",\"best_ask\":\"0.038\"}],\"timestamp\":\"1786689896529\",\"event_type\":\"price_change\"}"}
{"recv_ts": 1786689896537134, "venue": "polymarket", "raw": "{\"market\":\"0xd9fb1184af0064e5e34b129f5b79afa5a17b7e32f2953ab05efed82315fee6d4\",\"price_changes\":[{\"asset_id\":\"90772332434487149264114862115632028379978765245278600275169585501290867536237\",\"price\":\"0.2\",\"size\":\"14255\",\"side\":\"BUY\",\"hash\":\"b855b405a8985eee8d17e704b3a097ef938766ad\",\"best_bid\":\"0.962\",\"best_ask\":\"0.964\"},{\"asset_id\":\"94559586571241563470235664821564670251180951772614764383113614156422396181162\",\"price\":\"0.8\",\"size\":\"14255\",\"side\":\"SELL\",\"hash\":\"50a3d98d711ba865fe9b00c9700a0d1d64145b59\",\"best_bid\":\"0.036\",\"best_ask\":\"0.038\"}],\"timestamp\":\"1786689896530\",\"event_type\":\"price_change\"}"}
{"recv_ts": 1786689900788917, "venue": "polymarket", "raw": "{\"market\":\"0xd595eb9b81885ff018738300c79047e3ec89e87294424f57a29a7fa9162bf116\",\"price_changes\":[{\"asset_id\":\"57216272564529548464686463691236811991956032201293786790337952253964682584376\",\"price\":\"0.963\",\"size\":\"12870.97\",\"side\":\"BUY\",\"hash\":\"9a74217befb0587a8eec8f5f563d8f496e2583cc\",\"best_bid\":\"0.963\",\"best_ask\":\"0.964\"},{\"asset_id\":\"5161623255678193352839985156330393796378434470119114669671615782853260939535\",\"price\":\"0.037\",\"size\":\"12870.97\",\"side\":\"SELL\",\"hash\":\"2994eafc18720d2234ab348181884c0c7e03cab4\",\"best_bid\":\"0.036\",\"best_ask\":\"0.037\"}],\"timestamp\":\"1786689900778\",\"event_type\":\"price_change\"}"}
{"recv_ts": 1786689901809843, "venue": "polymarket", "raw": "{\"market\":\"0xd595eb9b81885ff018738300c79047e3ec89e87294424f57a29a7fa9162bf116\",\"price_changes\":[{\"asset_id\":\"57216272564529548464686463691236811991956032201293786790337952253964682584376\",\"price\":\"0.963\",\"size\":\"12970.67\",\"side\":\"BUY\",\"hash\":\"d8bfb335106ced8573f404677c5db633db1c0958\",\"best_bid\":\"0.963\",\"best_ask\":\"0.964\"},{\"asset_id\":\"5161623255678193352839985156330393796378434470119114669671615782853260939535\",\"price\":\"0.037\",\"size\":\"12970.67\",\"side\":\"SELL\",\"hash\":\"06ded7dc60989035cac241d1d301e1711e67b29d\",\"best_bid\":\"0.036\",\"best_ask\":\"0.037\"}],\"timestamp\":\"1786689901801\",\"event_type\":\"price_change\"}"}
{"recv_ts": 1786689902411130, "venue": "polymarket", "raw": "{\"market\":\"0xd9fb1184af0064e5e34b129f5b79afa5a17b7e32f2953ab05efed82315fee6d4\",\"price_changes\":[{\"asset_id\":\"90772332434487149264114862115632028379978765245278600275169585501290867536237\",\"price\":\"0.96\",\"size\":\"38440.56\",\"side\":\"BUY\",\"hash\":\"8ff827909873b8c679e576caa39a506d998ed177\",\"best_bid\":\"0.962\",\"best_ask\":\"0.964\"},{\"asset_id\":\"94559586571241563470235664821564670251180951772614764383113614156422396181162\",\"price\":\"0.04\",\"size\":\"38440.56\",\"side\":\"SELL\",\"hash\":\"4a19ef41f843256ae6c0a3b217155ebd9501c4e2\",\"best_bid\":\"0.036\",\"best_ask\":\"0.038\"}],\"timestamp\":\"1786689902403\",\"event_type\":\"price_change\"}"}
{"recv_ts": 1786689904150932, "venue": "polymarket", "raw": "{\"market\":\"0xd9fb1184af0064e5e34b129f5b79afa5a17b7e32f2953ab05efed82315fee6d4\",\"price_changes\":[{\"asset_id\":\"90772332434487149264114862115632028379978765245278600275169585501290867536237\",\"price\":\"0.64\",\"size\":\"0\",\"side\":\"BUY\",\"hash\":\"9d448cbeb9607e6b817bd91c8597512256821c42\",\"best_bid\":\"0.962\",\"best_ask\":\"0.964\"},{\"asset_id\":\"94559586571241563470235664821564670251180951772614764383113614156422396181162\",\"price\":\"0.36\",\"size\":\"0\",\"side\":\"SELL\",\"hash\":\"8baa289437931092f9c796105fa962628f285b93\",\"best_bid\":\"0.036\",\"best_ask\":\"0.038\"}],\"timestamp\":\"1786689904142\",\"event_type\":\"price_change\"}"}
{"recv_ts": 1786689904154297, "venue": "polymarket", "raw": "{\"market\":\"0xd9fb1184af0064e5e34b129f5b79afa5a17b7e32f2953ab05efed82315fee6d4\",\"price_changes\":[{\"asset_id\":\"90772332434487149264114862115632028379978765245278600275169585501290867536237\",\"price\":\"0.65\",\"size\":\"280\",\"side\":\"BUY\",\"hash\":\"b1afb478a8eb24fdfbf664cd69eb2988dde2fe0a\",\"best_bid\":\"0.962\",\"best_ask\":\"0.964\"},{\"asset_id\":\"94559586571241563470235664821564670251180951772614764383113614156422396181162\",\"price\":\"0.35\",\"size\":\"280\",\"side\":\"SELL\",\"hash\":\"c2912a91aef17b78451fecd94fa31dd63afa0c65\",\"best_bid\":\"0.036\",\"best_ask\":\"0.038\"}],\"timestamp\":\"1786689904146\",\"event_type\":\"price_change\"}"}
{"recv_ts": 1786689905011802, "venue": "polymarket", "raw": "{\"market\":\"0x60c2c085ee8c16bc8f2419739a94971d4c9d00f637ead10fc0f540afa1be64e8\",\"price_changes\":[{\"asset_id\":\"90869494087977018607792751230236923002303032923064138180950209430688758061828\",\"price\":\"0.5\",\"size\":\"4284.53\",\"side\":\"BUY\",\"hash\":\"4c48364e5854b921cf1a2bed2b4460aa230fc96c\",\"best_bid\":\"0.979\",\"best_ask\":\"0.98\"},{\"asset_id\":\"105426373826369935595603860663411604941599130211176020843036778867927711117332\",\"price\":\"0.5\",\"size\":\"4284.53\",\"side\":\"SELL\",\"hash\":\"baebedc73e082126478d964db570d476279a1c82\",\"best_bid\":\"0.02\",\"best_ask\":\"0.021\"}],\"timestamp\":\"1786689905003\",\"event_type\":\"price_change\"}"}
{"recv_ts": 1786689905620331, "venue": "polymarket", "raw": "{\"market\":\"0x60c2c085ee8c16bc8f2419739a94971d4c9d00f637ead10fc0f540afa1be64e8\",\"price_changes\":[{\"asset_id\":\"105426373826369935595603860663411604941599130211176020843036778867927711117332\",\"price\":\"0.004\",\"size\":\"175575\",\"side\":\"BUY\",\"hash\":\"60afcec28b308c1217fe67943c1ce6f848580182\",\"best_bid\":\"0.02\",\"best_ask\":\"0.021\"},{\"asset_id\":\"90869494087977018607792751230236923002303032923064138180950209430688758061828\",\"price\":\"0.996\",\"size\":\"175575\",\"side\":\"SELL\",\"hash\":\"aa021be2379c40e7bcb61fdb31af2b4957f8b558\",\"best_bid\":\"0.979\",\"best_ask\":\"0.98\"}],\"timestamp\":\"1786689905611\",\"event_type\":\"price_change\"}"}
{"recv_ts": 1786689905620450, "venue": "polymarket", "raw": "{\"market\":\"0x60c2c085ee8c16bc8f2419739a94971d4c9d00f637ead10fc0f540afa1be64e8\",\"price_changes\":[{\"asset_id\":\"105426373826369935595603860663411604941599130211176020843036778867927711117332\",\"price\":\"0.007\",\"size\":\"66868.47\",\"side\":\"BUY\",\"hash\":\"14df381fc0499d31f98e5f8b1887a7459eabcdf4\",\"best_bid\":\"0.02\",\"best_ask\":\"0.021\"},{\"asset_id\":\"90869494087977018607792751230236923002303032923064138180950209430688758061828\",\"price\":\"0.993\",\"size\":\"66868.47\",\"side\":\"SELL\",\"hash\":\"524e33a10ba62618bffd8290eae3f4607a3aec69\",\"best_bid\":\"0.979\",\"best_ask\":\"0.98\"}],\"timestamp\":\"1786689905611\",\"event_type\":\"price_change\"}"}
{"recv_ts": 1786689905622343, "venue": "polymarket", "raw": "{\"market\":\"0x60c2c085ee8c16bc8f2419739a94971d4c9d00f637ead10fc0f540afa1be64e8\",\"price_changes\":[{\"asset_id\":\"105426373826369935595603860663411604941599130211176020843036778867927711117332\",\"price\":\"0.013\",\"size\":\"13249.11\",\"side\":\"BUY\",\"hash\":\"8a2793b0a64b5edb52688d0fc563ed3385242c1b\",\"best_bid\":\"0.02\",\"best_ask\":\"0.021\"},{\"asset_id\":\"90869494087977018607792751230236923002303032923064138180950209430688758061828\",\"price\":\"0.987\",\"size\":\"13249.11\",\"side\":\"SELL\",\"hash\":\"60327c8949b2c3d616c1fefb943b40357103c5b3\",\"best_bid\":\"0.979\",\"best_ask\":\"0.98\"}],\"timestamp\":\"1786689905612\",\"event_type\":\"price_change\"}"}
{"recv_ts": 1786689905623496, "venue": "polymarket", "raw": "{\"market\":\"0x60c2c085ee8c16bc8f2419739a94971d4c9d00f637ead10fc0f540afa1be64e8\",\"price_changes\":[{\"asset_id\":\"105426373826369935595603860663411604941599130211176020843036778867927711117332\",\"price\":\"0.01\",\"size\":\"153506.93\",\"side\":\"BUY\",\"hash\":\"f71f0240efba0123d87a4d1d33933069fe2ebc8d\",\"best_bid\":\"0.02\",\"best_ask\":\"0.021\"},{\"asset_id\":\"90869494087977018607792751230236923002303032923064138180950209430688758061828\",\"price\":\"0.99\",\"size\":\"153506.93\",\"side\":\"SELL\",\"hash\":\"a4fc6776aa5da6e0ace300f70122f2b912026b79\",\"best_bid\":\"0.979\",\"best_ask\":\"0.98\"}],\"timestamp\":\"1786689905613\",\"event_type\":\"price_change\"}"}
{"recv_ts": 1786689905623518, "venue": "polymarket", "raw": "{\"market\":\"0x60c2c085ee8c16bc8f2419739a94971d4c9d00f637ead10fc0f540afa1be64e8\",\"price_changes\":[{\"asset_id\":\"105426373826369935595603860663411604941599130211176020843036778867927711117332\",\"price\":\"0.001\",\"size\":\"5811306.39\",\"side\":\"BUY\",\"hash\":\"d8ca540d7f1fc58cdea6361e2b80e2eb14e263ce\",\"best_bid\":\"0.02\",\"best_ask\":\"0.021\"},{\"asset_id\":\"90869494087977018607792751230236923002303032923064138180950209430688758061828\",\"price\":\"0.999\",\"size\":\"5811306.39\",\"side\":\"SELL\",\"hash\":\"4ded895f668a3cbd1452d15ae24fab288a5a33b2\",\"best_bid\":\"0.979\",\"best_ask\":\"0.98\"}],\"timestamp\":\"1786689905614\",\"event_type\":\"price_change\"}"}
{"recv_ts": 1786689907827646, "venue": "polymarket", "raw": "{\"market\":\"0xd595eb9b81885ff018738300c79047e3ec89e87294424f57a29a7fa9162bf116\",\"price_changes\":[{\"asset_id\":\"57216272564529548464686463691236811991956032201293786790337952253964682584376\",\"price\":\"0.961\",\"size\":\"41128.18\",\"side\":\"BUY\",\"hash\":\"b807b1ab194448003db67ea21af4eb87c3610fa4\",\"best_bid\":\"0.963\",\"best_ask\":\"0.964\"},{\"asset_id\":\"5161623255678193352839985156330393796378434470119114669671615782853260939535\",\"price\":\"0.039\",\"size\":\"41128.18\",\"side\":\"SELL\",\"hash\":\"aa20a2f54c8056e7ae6145ce39c408b18709d55a\",\"best_bid\":\"0.036\",\"best_ask\":\"0.037\"}],\"timestamp\":\"1786689907819\",\"event_type\":\"price_change\"}"}
{"recv_ts": 1786689907896424, "venue": "polymarket", "raw": "{\"market\":\"0xd595eb9b81885ff018738300c79047e3ec89e87294424f57a29a7fa9162bf116\",\"price_changes\":[{\"asset_id\":\"57216272564529548464686463691236811991956032201293786790337952253964682584376\",\"price\":\"0.96\",\"size\":\"100\",\"side\":\"BUY\",\"hash\":\"53194b1323ce207fc0d3d044bad5cea5974efc4a\",\"best_bid\":\"0.963\",\"best_ask\":\"0.964\"},{\"asset_id\":\"5161623255678193352839985156330393796378434470119114669671615782853260939535\",\"price\":\"0.04\",\"size\":\"100\",\"side\":\"SELL\",\"hash\":\"4f405eea311d3538a8b3ca31a062ae0c963781fa\",\"best_bid\":\"0.036\",\"best_ask\":\"0.037\"}],\"timestamp\":\"1786689907888\",\"event_type\":\"price_change\"}"}
{"recv_ts": 1786689907959451, "venue": "polymarket", "raw": "{\"market\":\"0xd595eb9b81885ff018738300c79047e3ec89e87294424f57a29a7fa9162bf116\",\"price_changes\":[{\"asset_id\":\"57216272564529548464686463691236811991956032201293786790337952253964682584376\",\"price\":\"0.959\",\"size\":\"300\",\"side\":\"BUY\",\"hash\":\"edf6ba780439a69d7a1cfc6181f7ef8befdbdcf9\",\"best_bid\":\"0.963\",\"best_ask\":\"0.964\"},{\"asset_id\":\"5161623255678193352839985156330393796378434470119114669671615782853260939535\",\"price\":\"0.041\",\"size\":\"300\",\"side\":\"SELL\",\"hash\":\"9a4f52e4f6da7dd485b22002c51fe4c7d663b949\",\"best_bid\":\"0.036\",\"best_ask\":\"0.037\"}],\"timestamp\":\"1786689907950\",\"event_type\":\"price_change\"}"}
{"recv_ts": 1786689908010257, "venue": "polymarket", "raw": "{\"market\":\"0x60c2c085ee8c16bc8f2419739a94971d4c9d00f637ead10fc0f540afa1be64e8\",\"price_changes\":[{\"asset_id\":\"105426373826369935595603860663411604941599130211176020843036778867927711117332\",\"price\":\"0.004\",\"size\":\"158575\",\"side\":\"BUY\",\"hash\":\"cb6d0a5b9c1f6beb0c4bdfa86493588d4fdcb1f0\",\"best_bid\":\"0.02\",\"best_ask\":\"0.021\"},{\"asset_id\":\"90869494087977018607792751230236923002303032923064138180950209430688758061828\",\"price\":\"0.996\",\"size\":\"158575\",\"side\":\"SELL\",\"hash\":\"d0a343c657dd8d2fefd2216faeea1b94c8811681\",\"best_bid\":\"0.979\",\"best_ask\":\"0.98\"}],\"timestamp\":\"1786689908001\",\"event_type\":\"price_change\"}"}
{"recv_ts": 1786689908010324, "venue": "polymarket", "raw": "{\"market\":\"0x60c2c085ee8c16bc8f2419739a94971d4c9d00f637ead10fc0f540afa1be64e8\",\"price_changes\":[{\"asset_id\":\"105426373826369935595603860663411604941599130211176020843036778867927711117332\",\"price\":\"0.001\",\"size\":\"5726306.39\",\"side\":\"BUY\",\"hash\":\"cb6d0a5b9c1f6beb0c4bdfa86493588d4fdcb1f0\",\"best_bid\":\"0.02\",\"best_ask\":\"0.021\"},{\"asset_id\":\"90869494087977018607792751230236923002303032923064138180950209430688758061828\",\"price\":\"0.999\",\"size\":\"5726306.39\",\"side\":\"SELL\",\"hash\":\"d0a343c657dd8d2fefd2216faeea1b94c8811681\",\"best_bid\":\"0.979\",\"best_ask\":\"0.98\"}],\"timestamp\":\"1786689908001\",\"event_type\":\"price_change\"}"}
{"recv_ts": 1786689908015019, "venue": "polymarket", "raw": "{\"market\":\"0x60c2c085ee8c16bc8f2419739a94971d4c9d00f637ead10fc0f540afa1be64e8\",\"price_changes\":[{\"asset_id\":\"105426373826369935595603860663411604941599130211176020843036778867927711117332\",\"price\":\"0.007\",\"size\":\"59153.47\",\"side\":\"BUY\",\"hash\":\"cb6d0a5b9c1f6beb0c4bdfa86493588d4fdcb1f0\",\"best_bid\":\"0.02\",\"best_ask\":\"0.021\"},{\"asset_id\":\"90869494087977018607792751230236923002303032923064138180950209430688758061828\",\"price\":\"0.993\",\"size\":\"59153.47\",\"side\":\"SELL\",\"hash\":\"d0a343c657dd8d2fefd2216faeea1b94c8811681\",\"best_bid\":\"0.979\",\"best_ask\":\"0.98\"}],\"timestamp\":\"1786689908001\",\"event_type\":\"price_change\"}"}
{"recv_ts": 1786689908015072, "venue": "polymarket", "raw": "{\"market\":\"0x60c2c085ee8c16bc8f2419739a94971d4c9d00f637ead10fc0f540afa1be64e8\",\"price_changes\":[{\"asset_id\":\"105426373826369935595603860663411604941599130211176020843036778867927711117332\",\"price\":\"0.01\",\"size\":\"149206.93\",\"side\":\"BUY\",\"hash\":\"5484a2834a32a4ea129966d64371c51964c60920\",\"best_bid\":\"0.02\",\"best_ask\":\"0.021\"},{\"asset_id\":\"90869494087977018607792751230236923002303032923064138180950209430688758061828\",\"price\":\"0.99\",\"size\":\"149206.93\",\"side\":\"SELL\",\"hash\":\"57d0dd88c0a43373a45b9a5c365169c9fbe62ef7\",\"best_bid\":\"0.979\",\"best_ask\":\"0.98\"}],\"timestamp\":\"1786689908002\",\"event_type\":\"price_change\"}"}
{"recv_ts": 1786689910800343, "venue": "polymarket", "raw": "{\"market\":\"0x6bd56627aa21311850825edb27e53434a0e17a4f782be0086bc07f71eee00d0d\",\"price_changes\":[{\"asset_id\":\"350977769852917329387037893294763093471844346281449484439085576212613048126\",\"price\":\"0.08\",\"size\":\"269278.63\",\"side\":\"SELL\",\"hash\":\"d84fd1378a20b7761634d30ddd555001e1fb44e1\",\"best_bid\":\"0.07\",\"best_ask\":\"0.08\"},{\"asset_id\":\"87073899845581463485186346288398658568334162612963837182986759797304993556208\",\"price\":\"0.92\",\"size\":\"269278.63\",\"side\":\"BUY\",\"hash\":\"bb7ddc05df0d82c289ab846fae55ff8b520eee0b\",\"best_bid\":\"0.92\",\"best_ask\":\"0.93\"}],\"timestamp\":\"1786689910791\",\"event_type\":\"price_change\"}"}
{"recv_ts": 1786689912014859, "venue": "polymarket", "raw": "{\"market\":\"0xd9fb1184af0064e5e34b129f5b79afa5a17b7e32f2953ab05efed82315fee6d4\",\"price_changes\":[{\"asset_id\":\"90772332434487149264114862115632028379978765245278600275169585501290867536237\",\"price\":\"0.65\",\"size\":\"50\",\"side\":\"BUY\",\"hash\":\"5ea19c1cfd0bddb811daf5b6459540a49d53ccab\",\"best_bid\":\"0.962\",\"best_ask\":\"0.964\"},{\"asset_id\":\"94559586571241563470235664821564670251180951772614764383113614156422396181162\",\"price\":\"0.35\",\"size\":\"50\",\"side\":\"SELL\",\"hash\":\"0979178db347d8a816b47ec8b7493b9f6ff19569\",\"best_bid\":\"0.036\",\"best_ask\":\"0.038\"}],\"timestamp\":\"1786689912006\",\"event_type\":\"price_change\"}"}
{"recv_ts": 1786689912026402, "venue": "polymarket", "raw": "{\"market\":\"0xd9fb1184af0064e5e34b129f5b79afa5a17b7e32f2953ab05efed82315fee6d4\",\"price_changes\":[{\"asset_id\":\"90772332434487149264114862115632028379978765245278600275169585501290867536237\",\"price\":\"0.64\",\"size\":\"234\",\"side\":\"BUY\",\"hash\":\"a85b67add15b510b93cca07e98ef4d11257b78d7\",\"best_bid\":\"0.962\",\"best_ask\":\"0.964\"},{\"asset_id\":\"94559586571241563470235664821564670251180951772614764383113614156422396181162\",\"price\":\"0.36\",\"size\":\"234\",\"side\":\"SELL\",\"hash\":\"9febad85b5af0c4061e7657bfaf8189e83cd1a51\",\"best_bid\":\"0.036\",\"best_ask\":\"0.038\"}],\"timestamp\":\"1786689912018\",\"event_type\":\"price_change\"}"}
{"recv_ts": 1786689913594670, "venue": "polymarket", "raw": "{\"market\":\"0x60c2c085ee8c16bc8f2419739a94971d4c9d00f637ead10fc0f540afa1be64e8\",\"price_changes\":[{\"asset_id\":\"90869494087977018607792751230236923002303032923064138180950209430688758061828\",\"price\":\"0.5\",\"size\":\"6684.53\",\"side\":\"BUY\",\"hash\":\"4dd3ff632b708cb7273aa207361e07b30a7101af\",\"best_bid\":\"0.979\",\"best_ask\":\"0.98\"},{\"asset_id\":\"105426373826369935595603860663411604941599130211176020843036778867927711117332\",\"price\":\"0.5\",\"size\":\"6684.53\",\"side\":\"SELL\",\"hash\":\"9a322916710378bc0555d50edb33f0dbb9183026\",\"best_bid\":\"0.02\",\"best_ask\":\"0.021\"}],\"timestamp\":\"1786689913585\",\"event_type\":\"price_change\"}"}
{"recv_ts": 1786689914453684, "venue": "polymarket", "raw": "{\"market\":\"0xd9fb1184af0064e5e34b129f5b79afa5a17b7e32f2953ab05efed82315fee6d4\",\"price_changes\":[{\"asset_id\":\"90772332434487149264114862115632028379978765245278600275169585501290867536237\",\"price\":\"0.96\",\"size\":\"38445.56\",\"side\":\"BUY\",\"hash\":\"20d94e6de9009060f3ccbc232c5aaef9c1b178b1\",\"best_bid\":\"0.962\",\"best_ask\":\"0.964\"},{\"asset_id\":\"94559586571241563470235664821564670251180951772614764383113614156422396181162\",\"price\":\"0.04\",\"size\":\"38445.56\",\"side\":\"SELL\",\"hash\":\"e22583773e7ae6c0444223bbc4ae41d832717319\",\"best_bid\":\"0.036\",\"best_ask\":\"0.038\"}],\"timestamp\":\"1786689914445\",\"event_type\":\"price_change\"}"}
{"recv_ts": 1786689918009512, "venue": "polymarket", "raw": "{\"market\":\"0x747dc809fb79e1b05be09c42d6179459a58de2ef3e40f02484a4e1260f741f75\",\"price_changes\":[{\"asset_id\":\"7305630249804085635496399869905769372294302716159034447326228509068694952392\",\"price\":\"0.3\",\"size\":\"6200\",\"side\":\"BUY\",\"hash\":\"d1444d956e1b7df14ebd83fde2163f090861a71b\",\"best_bid\":\"0.95\",\"best_ask\":\"0.96\"},{\"asset_id\":\"107505882767731489358349912513945399560393482969656700824895970500493757150417\",\"price\":\"0.7\",\"size\":\"6200\",\"side\":\"SELL\",\"hash\":\"f317fa70d1de45aec05d3f5ea92d93dfd55ff522\",\"best_bid\":\"0.04\",\"best_ask\":\"0.05\"}],\"timestamp\":\"1786689918000\",\"event_type\":\"price_change\"}"}
{"recv_ts": 1786689918009918, "venue": "polymarket", "raw": "{\"market\":\"0x747dc809fb79e1b05be09c42d6179459a58de2ef3e40f02484a4e1260f741f75\",\"price_changes\":[{\"asset_id\":\"7305630249804085635496399869905769372294302716159034447326228509068694952392\",\"price\":\"0.4\",\"size\":\"4388\",\"side\":\"BUY\",\"hash\":\"558a5a93652c0ccd6de582154ef7a679c5a87fb5\",\"best_bid\":\"0.95\",\"best_ask\":\"0.96\"},{\"asset_id\":\"107505882767731489358349912513945399560393482969656700824895970500493757150417\",\"price\":\"0.6\",\"size\":\"4388\",\"side\":\"SELL\",\"hash\":\"938935b7e4067706322d752055254b379a591697\",\"best_bid\":\"0.04\",\"best_ask\":\"0.05\"}],\"timestamp\":\"1786689918001\",\"event_type\":\"price_change\"}"}
{"recv_ts": 1786689918012588, "venue": "polymarket", "raw": "{\"market\":\"0x747dc809fb79e1b05be09c42d6179459a58de2ef3e40f02484a4e1260f741f75\",\"price_changes\":[{\"asset_id\":\"7305630249804085635496399869905769372294302716159034447326228509068694952392\",\"price\":\"0.2\",\"size\":\"9900\",\"side\":\"BUY\",\"hash\":\"558a5a93652c0ccd6de582154ef7a679c5a87fb5\",\"best_bid\":\"0.95\",\"best_ask\":\"0.96\"},{\"asset_id\":\"107505882767731489358349912513945399560393482969656700824895970500493757150417\",\"price\":\"0.8\",\"size\":\"9900\",\"side\":\"SELL\",\"hash\":\"938935b7e4067706322d752055254b379a591697\",\"best_bid\":\"0.04\",\"best_ask\":\"0.05\"}],\"timestamp\":\"1786689918001\",\"event_type\":\"price_change\"}"}
{"recv_ts": 1786689918012972, "venue": "polymarket", "raw": "{\"market\":\"0x747dc809fb79e1b05be09c42d6179459a58de2ef3e40f02484a4e1260f741f75\",\"price_changes\":[{\"asset_id\":\"7305630249804085635496399869905769372294302716159034447326228509068694952392\",\"price\":\"0.1\",\"size\":\"4301.03\",\"side\":\"BUY\",\"hash\":\"d8e4d1c53c1a94026f40069e66062f801cbe9b59\",\"best_bid\":\"0.95\",\"best_ask\":\"0.96\"},{\"asset_id\":\"107505882767731489358349912513945399560393482969656700824895970500493757150417\",\"price\":\"0.9\",\"size\":\"4301.03\",\"side\":\"SELL\",\"hash\":\"ba97c03f94e43d8b4771cfdce50aba52c6f19123\",\"best_bid\":\"0.04\",\"best_ask\":\"0.05\"}],\"timestamp\":\"1786689918004\",\"event_type\":\"price_change\"}"}
{"recv_ts": 1786689921512827, "venue": "polymarket", "raw": "{\"id\":\"3578441\",\"question\":\"SE Palmeiras vs. Santos FC: Santos FC O/U 1.5\",\"market\":\"0xc03a1ac5442166c4ad5c5d4a1290b64d3a32386f78e7fd6d194925b192eb6f13\",\"slug\":\"brco-pal-san-2026-08-26-team-total-away-1pt5\",\"description\":\"In the upcoming Copa do Brasil game between SE Palmeiras and Santos FC, scheduled for August 26 at 8:30 PM ET: This market will resolve to \\\"Over\\\" if Santos FC score 2 or more goals within the first 90 minutes of regular play plus stoppage time. If Santos FC score less than 2 goals within the first 90 minutes of regular play plus stoppage time, this market will resolve to \\\"Under\\\". This market is based solely on Santos FC's score, not the combined score of both teams. If the game is postponed, this market will remain open until the game has been completed. If the game is canceled entirely, with no make-up game, this market will resolve 50-50. This market refers only to the outcome within the first 90 minutes of regular play plus stoppage time. Extra time and penalty shoot-outs are excluded. The primary resolution source for this market is the official statistics of the event as recognized by the governing body or event organizers. However, if the governing body or event organizers have not published final match statistics within 2 hours after the event's conclusion, a consensus of credible reporting may be used instead. All markets will settle based on the official final result as recognized by the governing body or event organizers. Revisions to officially declared final scores made after market resolution will not be accounted for in determining the outcome.\",\"assets_ids\":[\"78751604775716781920845763610002331854090288284720479508484332594079724735899\",\"38985119030587102354265768644869313448243118045231042939440239915591541124972\"],\"outcomes\":[\"Over\",\"Under\"],\"event_message\":{\"id\":\"847372\",\"ticker\":\"brco-pal-san-2026-08-26-more-markets\",\"slug\":\"brco-pal-san-2026-08-26-more-markets\",\"title\":\"SE Palmeiras vs. Santos FC - More Markets\",\"description\":\"More markets for the Copa do Brasil game, scheduled for August 26 at 8:30 PM ET.\"},\"timestamp\":\"1786689921496\",\"event_type\":\"new_market\",\"tags\":[],\"condition_id\":\"0xc03a1ac5442166c4ad5c5d4a1290b64d3a32386f78e7fd6d194925b192eb6f13\",\"active\":true,\"clob_token_ids\":[\"78751604775716781920845763610002331854090288284720479508484332594079724735899\",\"38985119030587102354265768644869313448243118045231042939440239915591541124972\"],\"sports_market_type\":\"soccer_team_totals\",\"line\":\"1.5\",\"game_start_time\":\"2026-08-27 00:30:00+00\",\"order_price_min_tick_size\":\"0.01\",\"group_item_title\":\"Santos FC O/U 1.5\",\"taker_base_fee\":\"1000\",\"fees_enabled\":true,\"fee_schedule\":{\"exponent\":\"1\",\"rate\":\"0.05\",\"taker_only\":true,\"rebate_rate\":\"0.15\"}}"}
{"recv_ts": 1786689921698131, "venue": "polymarket", "raw": "{\"id\":\"3578426\",\"question\":\"SE Palmeiras vs. Santos FC: O/U 0.5\",\"market\":\"0x5edcb263523cb75f640346e943f032cfcd19592a84eff758c29cad27ef113f1d\",\"slug\":\"brco-pal-san-2026-08-26-total-0pt5\",\"description\":\"In the upcoming Copa do Brasil game between SE Palmeiras and Santos FC, scheduled for August 26 at 8:30 PM ET:\\n\\nThis market will resolve to \\\"Over\\\" if SE Palmeiras and Santos FC combine to score 1 or more goals in this game.\\n\\nIf the combined total is less than 1, this market will resolve to \\\"Under\\\".\\n\\nIf the game is postponed, this market will remain open until the game has been completed. If the game is canceled entirely, with no make-up game, this market will resolve 50\u201350.\\n\\nIf the game is started but not completed, this market will resolve according to the official final score published on cbf.com.br. This market refers only to the outcome within the first 90 minutes of regular play plus stoppage time.\\n\\nThe primary resolution source for this market is the official statistics of the event as recognized by the governing body or event organizers. However, if the governing body or event organizers have not published final match statistics within 2 hours after the event's conclusion, a consensus of credible reporting may be used instead. All markets will settle based on the official final result as recognized by the governing body or event organizers. Revisions to officially declared final scores made after market resolution will not be accounted for in determining the outcome.\",\"assets_ids\":[\"39337449039726023122884366795671562226072803248605294643234500795936368083757\",\"112836827838081820337339155523769187417524647194614233934795079564945235971718\"],\"outcomes\":[\"Over\",\"Under\"],\"event_message\":{\"id\":\"847372\",\"ticker\":\"brco-pal-san-2026-08-26-more-markets\",\"slug\":\"brco-pal-san-2026-08-26-more-markets\",\"title\":\"SE Palmeiras vs. Santos FC - More Markets\",\"description\":\"More markets for the Copa do Brasil game, scheduled for August 26 at 8:30 PM ET.\"},\"timestamp\":\"1786689921505\",\"event_type\":\"new_market\",\"tags\":[],\"condition_id\":\"0x5edcb263523cb75f640346e943f032cfcd19592a84eff758c29cad27ef113f1d\",\"active\":true,\"clob_token_ids\":[\"39337449039726023122884366795671562226072803248605294643234500795936368083757\",\"112836827838081820337339155523769187417524647194614233934795079564945235971718\"],\"sports_market_type\":\"totals\",\"line\":\"0.5\",\"game_start_time\":\"2026-08-27 00:30:00+00\",\"order_price_min_tick_size\":\"0.01\",\"group_item_title\":\"O/U 0.5\",\"taker_base_fee\":\"1000\",\"fees_enabled\":true,\"fee_schedule\":{\"exponent\":\"1\",\"rate\":\"0.05\",\"taker_only\":true,\"rebate_rate\":\"0.15\"}}"}
{"recv_ts": 1786689921698297, "venue": "polymarket", "raw": "{\"id\":\"3578445\",\"question\":\"SE Palmeiras vs. Santos FC: Santos FC 1st Half O/U 0.5\",\"market\":\"0x56df9ce61f6971ff5ef3a28a795fb34b25f061595e44dcbeeb045ea0dae84b66\",\"slug\":\"brco-pal-san-2026-08-26-first-half-team-total-away-0pt5\",\"description\":\"In the upcoming Copa do Brasil game between SE Palmeiras and Santos FC, scheduled for August 26 at 8:30 PM ET: This market will resolve to \\\"Over\\\" if Santos FC score 1 or more goals in the first half (first 45 minutes of regular play plus first-half stoppage time). If Santos FC score less than 1 goals in the first half, this market will resolve to \\\"Under\\\". This market is based solely on Santos FC's first-half score, not the combined score of both teams. If the game is postponed, this market will remain open until the game has been completed. If the game is canceled entirely, with no make-up game, this market will resolve 50-50. This market refers only to the outcome within the first 45 minutes of regular play plus first-half stoppage time. Second-half goals, extra time, and penalty shoot-outs are excluded. The primary resolution source for this market is the official statistics of the event as recognized by the governing body or event organizers. However, if the governing body or event organizers have not published final match statistics within 2 hours after the event's conclusion, a consensus of credible reporting may be used instead. All markets will settle based on the official final result as recognized by the governing body or event organizers. Revisions to officially declared final scores made after market resolution will not be accounted for in determining the outcome.\",\"assets_ids\":[\"24872879274384199625361989517584724832849988101471182325973358005994162828709\",\"6682016640632742644213914311442656145920824951466956908397236301036388421944\"],\"outcomes\":[\"Over\",\"Under\"],\"event_message\":{\"id\":\"847372\",\"ticker\":\"brco-pal-san-2026-08-26-more-markets\",\"slug\":\"brco-pal-san-2026-08-26-more-markets\",\"title\":\"SE Palmeiras vs. Santos FC - More Markets\",\"description\":\"More markets for the Copa do Brasil game, scheduled for August 26 at 8:30 PM ET.\"},\"timestamp\":\"1786689921502\",\"event_type\":\"new_market\",\"tags\":[],\"condition_id\":\"0x56df9ce61f6971ff5ef3a28a795fb34b25f061595e44dcbeeb045ea0dae84b66\",\"active\":true,\"clob_token_ids\":[\"24872879274384199625361989517584724832849988101471182325973358005994162828709\",\"6682016640632742644213914311442656145920824951466956908397236301036388421944\"],\"sports_market_type\":\"soccer_first_half_team_totals\",\"line\":\"0.5\",\"game_start_time\":\"2026-08-27 00:30:00+00\",\"order_price_min_tick_size\":\"0.01\",\"group_item_title\":\"Santos FC 1st Half O/U 0.5\",\"taker_base_fee\":\"1000\",\"fees_enabled\":true,\"fee_schedule\":{\"exponent\":\"1\",\"rate\":\"0.05\",\"taker_only\":true,\"rebate_rate\":\"0.15\"}}"}
{"recv_ts": 1786689921698335, "venue": "polymarket", "raw": "{\"id\":\"3578446\",\"question\":\"SE Palmeiras vs. Santos FC: Santos FC 1st Half O/U 1.5\",\"market\":\"0xfbbf2ce243dc7976205161e34e0653975361b31b646ba744fc179c5be76ce753\",\"slug\":\"brco-pal-san-2026-08-26-first-half-team-total-away-1pt5\",\"description\":\"In the upcoming Copa do Brasil game between SE Palmeiras and Santos FC, scheduled for August 26 at 8:30 PM ET: This market will resolve to \\\"Over\\\" if Santos FC score 2 or more goals in the first half (first 45 minutes of regular play plus first-half stoppage time). If Santos FC score less than 2 goals in the first half, this market will resolve to \\\"Under\\\". This market is based solely on Santos FC's first-half score, not the combined score of both teams. If the game is postponed, this market will remain open until the game has been completed. If the game is canceled entirely, with no make-up game, this market will resolve 50-50. This market refers only to the outcome within the first 45 minutes of regular play plus first-half stoppage time. Second-half goals, extra time, and penalty shoot-outs are excluded. The primary resolution source for this market is the official statistics of the event as recognized by the governing body or event organizers. However, if the governing body or event organizers have not published final match statistics within 2 hours after the event's conclusion, a consensus of credible reporting may be used instead. All markets will settle based on the official final result as recognized by the governing body or event organizers. Revisions to officially declared final scores made after market resolution will not be accounted for in determining the outcome.\",\"assets_ids\":[\"22288202101199319933640462597221235008944258467286481630704727476042673859905\",\"111213923982152508345592803441721014767241130083538202577841255465499831848103\"],\"outcomes\":[\"Over\",\"Under\"],\"event_message\":{\"id\":\"847372\",\"ticker\":\"brco-pal-san-2026-08-26-more-markets\",\"slug\":\"brco-pal-san-2026-08-26-more-markets\",\"title\":\"SE Palmeiras vs. Santos FC - More Markets\",\"description\":\"More markets for the Copa do Brasil game, scheduled for August 26 at 8:30 PM ET.\"},\"timestamp\":\"1786689921502\",\"event_type\":\"new_market\",\"tags\":[],\"condition_id\":\"0xfbbf2ce243dc7976205161e34e0653975361b31b646ba744fc179c5be76ce753\",\"active\":true,\"clob_token_ids\":[\"22288202101199319933640462597221235008944258467286481630704727476042673859905\",\"111213923982152508345592803441721014767241130083538202577841255465499831848103\"],\"sports_market_type\":\"soccer_first_half_team_totals\",\"line\":\"1.5\",\"game_start_time\":\"2026-08-27 00:30:00+00\",\"order_price_min_tick_size\":\"0.01\",\"group_item_title\":\"Santos FC 1st Half O/U 1.5\",\"taker_base_fee\":\"1000\",\"fees_enabled\":true,\"fee_schedule\":{\"exponent\":\"1\",\"rate\":\"0.05\",\"taker_only\":true,\"rebate_rate\":\"0.15\"}}"}
{"recv_ts": 1786689921740804, "venue": "polymarket", "raw": "{\"id\":\"3578444\",\"question\":\"SE Palmeiras vs. Santos FC: SE Palmeiras 1st Half O/U 1.5\",\"market\":\"0x2e3c29318c0bf7352dab531b52c5cb2147ee6fb49e4a1b0a441db80491e9fe5b\",\"slug\":\"brco-pal-san-2026-08-26-first-half-team-total-home-1pt5\",\"description\":\"In the upcoming Copa do Brasil game between SE Palmeiras and Santos FC, scheduled for August 26 at 8:30 PM ET: This market will resolve to \\\"Over\\\" if SE Palmeiras score 2 or more goals in the first half (first 45 minutes of regular play plus first-half stoppage time). If SE Palmeiras score less than 2 goals in the first half, this market will resolve to \\\"Under\\\". This market is based solely on SE Palmeiras's first-half score, not the combined score of both teams. If the game is postponed, this market will remain open until the game has been completed. If the game is canceled entirely, with no make-up game, this market will resolve 50-50. This market refers only to the outcome within the first 45 minutes of regular play plus first-half stoppage time. Second-half goals, extra time, and penalty shoot-outs are excluded. The primary resolution source for this market is the official statistics of the event as recognized by the governing body or event organizers. However, if the governing body or event organizers have not published final match statistics within 2 hours after the event's conclusion, a consensus of credible reporting may be used instead. All markets will settle based on the official final result as recognized by the governing body or event organizers. Revisions to officially declared final scores made after market resolution will not be accounted for in determining the outcome.\",\"assets_ids\":[\"103248998256128467893221406176732626835238212411223616570766651291213191687034\",\"60877794486393039925833800374752069723872707564724651652921932482884960374539\"],\"outcomes\":[\"Over\",\"Under\"],\"event_message\":{\"id\":\"847372\",\"ticker\":\"brco-pal-san-2026-08-26-more-markets\",\"slug\":\"brco-pal-san-2026-08-26-more-markets\",\"title\":\"SE Palmeiras vs. Santos FC - More Markets\",\"description\":\"More markets for the Copa do Brasil game, scheduled for August 26 at 8:30 PM ET.\"},\"timestamp\":\"1786689921508\",\"event_type\":\"new_market\",\"tags\":[],\"condition_id\":\"0x2e3c29318c0bf7352dab531b52c5cb2147ee6fb49e4a1b0a441db80491e9fe5b\",\"active\":true,\"clob_token_ids\":[\"103248998256128467893221406176732626835238212411223616570766651291213191687034\",\"60877794486393039925833800374752069723872707564724651652921932482884960374539\"],\"sports_market_type\":\"soccer_first_half_team_totals\",\"line\":\"1.5\",\"game_start_time\":\"2026-08-27 00:30:00+00\",\"order_price_min_tick_size\":\"0.01\",\"group_item_title\":\"SE Palmeiras 1st Half O/U 1.5\",\"taker_base_fee\":\"1000\",\"fees_enabled\":true,\"fee_schedule\":{\"exponent\":\"1\",\"rate\":\"0.05\",\"taker_only\":true,\"rebate_rate\":\"0.15\"}}"}
{"recv_ts": 1786689921794919, "venue": "polymarket", "raw": "{\"id\":\"3578448\",\"question\":\"SE Palmeiras vs. Santos FC: 2nd Half O/U 0.5\",\"market\":\"0x2889d62a9bdecbd2bb51c5dcf0a4e1772873fb5a0c3b25c066b6ccd722454d44\",\"slug\":\"brco-pal-san-2026-08-26-second-half-total-0pt5\",\"description\":\"In the upcoming Copa do Brasil game between SE Palmeiras and Santos FC, scheduled for August 26 at 8:30 PM ET: This market will resolve to \\\"Over\\\" if SE Palmeiras and Santos FC combine to score 1 or more goals in the second half of regular play plus second-half stoppage time. If the combined second-half total is less than 1 goals, this market will resolve to \\\"Under\\\". If the game is postponed, this market will remain open until the game has been completed. If the game is canceled entirely, with no make-up game, this market will resolve 50-50. This market refers only to the outcome within the second half of regular play plus second-half stoppage time. First-half goals, extra time, and penalty shoot-outs are excluded. The primary resolution source for this market is the official statistics of the event as recognized by the governing body or event organizers. However, if the governing body or event organizers have not published final match statistics within 2 hours after the event's conclusion, a consensus of credible reporting may be used instead. All markets will settle based on the official final result as recognized by the governing body or event organizers. Revisions to officially declared final scores made after market resolution will not be accounted for in determining the outcome.\",\"assets_ids\":[\"39508606369834115450459683358535839284781306935096040796455562455467073188327\",\"90359492631870520075551224701942004503880568360884680418387111755195956753942\"],\"outcomes\":[\"Over\",\"Under\"],\"event_message\":{\"id\":\"847372\",\"ticker\":\"brco-pal-san-2026-08-26-more-markets\",\"slug\":\"brco-pal-san-2026-08-26-more-markets\",\"title\":\"SE Palmeiras vs. Santos FC - More Markets\",\"description\":\"More markets for the Copa do Brasil game, scheduled for August 26 at 8:30 PM ET.\"},\"timestamp\":\"1786689921511\",\"event_type\":\"new_market\",\"tags\":[],\"condition_id\":\"0x2889d62a9bdecbd2bb51c5dcf0a4e1772873fb5a0c3b25c066b6ccd722454d44\",\"active\":true,\"clob_token_ids\":[\"39508606369834115450459683358535839284781306935096040796455562455467073188327\",\"90359492631870520075551224701942004503880568360884680418387111755195956753942\"],\"sports_market_type\":\"second_half_totals\",\"line\":\"0.5\",\"game_start_time\":\"2026-08-27 00:30:00+00\",\"order_price_min_tick_size\":\"0.01\",\"group_item_title\":\"2nd Half O/U 0.5\",\"taker_base_fee\":\"1000\",\"fees_enabled\":true,\"fee_schedule\":{\"exponent\":\"1\",\"rate\":\"0.05\",\"taker_only\":true,\"rebate_rate\":\"0.15\"}}"}
{"recv_ts": 1786689922679588, "venue": "polymarket", "raw": "{\"market\":\"0x747dc809fb79e1b05be09c42d6179459a58de2ef3e40f02484a4e1260f741f75\",\"price_changes\":[{\"asset_id\":\"7305630249804085635496399869905769372294302716159034447326228509068694952392\",\"price\":\"0.2\",\"size\":\"14900\",\"side\":\"BUY\",\"hash\":\"2c88340eeb5ef1ac0f6b2ef175e2b64dc635d676\",\"best_bid\":\"0.95\",\"best_ask\":\"0.96\"},{\"asset_id\":\"107505882767731489358349912513945399560393482969656700824895970500493757150417\",\"price\":\"0.8\",\"size\":\"14900\",\"side\":\"SELL\",\"hash\":\"3275f8653a03186b72cba66a82df0d3acfbb0058\",\"best_bid\":\"0.04\",\"best_ask\":\"0.05\"}],\"timestamp\":\"1786689922671\",\"event_type\":\"price_change\"}"}
{"recv_ts": 1786689922680287, "venue": "polymarket", "raw": "{\"market\":\"0x747dc809fb79e1b05be09c42d6179459a58de2ef3e40f02484a4e1260f741f75\",\"price_changes\":[{\"asset_id\":\"7305630249804085635496399869905769372294302716159034447326228509068694952392\",\"price\":\"0.1\",\"size\":\"16301.03\",\"side\":\"BUY\",\"hash\":\"7766caa8edd00695a02d64e19ac99346c83f9476\",\"best_bid\":\"0.95\",\"best_ask\":\"0.96\"},{\"asset_id\":\"107505882767731489358349912513945399560393482969656700824895970500493757150417\",\"price\":\"0.9\",\"size\":\"16301.03\",\"side\":\"SELL\",\"hash\":\"367cd098578a6733be3e24657448489c53eee740\",\"best_bid\":\"0.04\",\"best_ask\":\"0.05\"}],\"timestamp\":\"1786689922671\",\"event_type\":\"price_change\"}"}
{"recv_ts": 1786689922680682, "venue": "polymarket", "raw": "{\"market\":\"0x747dc809fb79e1b05be09c42d6179459a58de2ef3e40f02484a4e1260f741f75\",\"price_changes\":[{\"asset_id\":\"7305630249804085635496399869905769372294302716159034447326228509068694952392\",\"price\":\"0.3\",\"size\":\"9200\",\"side\":\"BUY\",\"hash\":\"4d47fc13501c9a7c03c39506bade226d5dd6fc4b\",\"best_bid\":\"0.95\",\"best_ask\":\"0.96\"},{\"asset_id\":\"107505882767731489358349912513945399560393482969656700824895970500493757150417\",\"price\":\"0.7\",\"size\":\"9200\",\"side\":\"SELL\",\"hash\":\"cafa5e0b617e0a0a7c7d28eabefcdf18c935c944\",\"best_bid\":\"0.04\",\"best_ask\":\"0.05\"}],\"timestamp\":\"1786689922672\",\"event_type\":\"price_change\"}"}
{"recv_ts": 1786689922681650, "venue": "polymarket", "raw": "{\"market\":\"0x747dc809fb79e1b05be09c42d6179459a58de2ef3e40f02484a4e1260f741f75\",\"price_changes\":[{\"asset_id\":\"7305630249804085635496399869905769372294302716159034447326228509068694952392\",\"price\":\"0.4\",\"size\":\"5638\",\"side\":\"BUY\",\"hash\":\"9a72ae7aa49c90bf856fb2250e5df2c7a13cf5dd\",\"best_bid\":\"0.95\",\"best_ask\":\"0.96\"},{\"asset_id\":\"107505882767731489358349912513945399560393482969656700824895970500493757150417\",\"price\":\"0.6\",\"size\":\"5638\",\"side\":\"SELL\",\"hash\":\"41e3f114cd3efcfd242ff37e0a2ed5595b2308e4\",\"best_bid\":\"0.04\",\"best_ask\":\"0.05\"}],\"timestamp\":\"1786689922673\",\"event_type\":\"price_change\"}"}
{"recv_ts": 1786689923010121, "venue": "polymarket", "raw": "{\"market\":\"0xbb4d51e6364066d92eb6f9b8413dd7193de70966736044463b205834805a1f3b\",\"price_changes\":[{\"asset_id\":\"10991849228756847439673778874175365458450913336396982752046655649803657501964\",\"price\":\"0.04\",\"size\":\"479016.56\",\"side\":\"BUY\",\"hash\":\"9dd2cc4f90e4dcc32f9875b003086ffcd9a6a873\",\"best_bid\":\"0.06\",\"best_ask\":\"0.07\"},{\"asset_id\":\"106181075047366745139197108801635573283215248045056329679360376976893016488727\",\"price\":\"0.96\",\"size\":\"479016.56\",\"side\":\"SELL\",\"hash\":\"a8cc5912148077fa8a9c7b9639fc2ab018d7bff4\",\"best_bid\":\"0.93\",\"best_ask\":\"0.94\"}],\"timestamp\":\"1786689923000\",\"event_type\":\"price_change\"}"}
{"recv_ts": 1786689923012603, "venue": "polymarket", "raw": "{\"market\":\"0xbb4d51e6364066d92eb6f9b8413dd7193de70966736044463b205834805a1f3b\",\"price_changes\":[{\"asset_id\":\"106181075047366745139197108801635573283215248045056329679360376976893016488727\",\"price\":\"0.92\",\"size\":\"181708.7\",\"side\":\"BUY\",\"hash\":\"42d7669c06a73deb7241727a6b489a38aa346399\",\"best_bid\":\"0.93\",\"best_ask\":\"0.94\"},{\"asset_id\":\"10991849228756847439673778874175365458450913336396982752046655649803657501964\",\"price\":\"0.08\",\"size\":\"181708.7\",\"side\":\"SELL\",\"hash\":\"1e54a9a0ee827bd2d943cfbd9001060a8bcfbc0a\",\"best_bid\":\"0.06\",\"best_ask\":\"0.07\"}],\"timestamp\":\"1786689923001\",\"event_type\":\"price_change\"}"}
{"recv_ts": 1786689923082466, "venue": "polymarket", "raw": "{\"id\":\"3578451\",\"question\":\"SE Palmeiras vs. Santos FC: SE Palmeiras 2nd Half O/U 0.5\",\"market\":\"0x2e70c0df8ac984f3533482fc62a77770cfb9cd785ef8afbc0ca7de142ff7136e\",\"slug\":\"brco-pal-san-2026-08-26-second-half-team-total-home-0pt5\",\"description\":\"In the upcoming Copa do Brasil game between SE Palmeiras and Santos FC, scheduled for August 26 at 8:30 PM ET: This market will resolve to \\\"Over\\\" if SE Palmeiras score 1 or more goals in the second half (second 45 minutes of regular play plus second-half stoppage time). If SE Palmeiras score less than 1 goals in the second half, this market will resolve to \\\"Under\\\". This market is based solely on SE Palmeiras's second-half score, not the combined score of both teams. If the game is postponed, this market will remain open until the game has been completed. If the game is canceled entirely, with no make-up game, this market will resolve 50-50. This market refers only to the outcome within the second 45 minutes of regular play plus second-half stoppage time. First-half goals, extra time, and penalty shoot-outs are excluded. The primary resolution source for this market is the official statistics of the event as recognized by the governing body or event organizers. However, if the governing body or event organizers have not published final match statistics within 2 hours after the event's conclusion, a consensus of credible reporting may be used instead. All markets will settle based on the official final result as recognized by the governing body or event organizers. Revisions to officially declared final scores made after market resolution will not be accounted for in determining the outcome.\",\"assets_ids\":[\"19827677769970793175383326216383491015711774584861621646050951945378763729005\",\"110632688308342827866548972791039265332888382974151634911030984058259276907986\"],\"outcomes\":[\"Over\",\"Under\"],\"event_message\":{\"id\":\"847372\",\"ticker\":\"brco-pal-san-2026-08-26-more-markets\",\"slug\":\"brco-pal-san-2026-08-26-more-markets\",\"title\":\"SE Palmeiras vs. Santos FC - More Markets\",\"description\":\"More markets for the Copa do Brasil game, scheduled for August 26 at 8:30 PM ET.\"},\"timestamp\":\"1786689923068\",\"event_type\":\"new_market\",\"tags\":[],\"condition_id\":\"0x2e70c0df8ac984f3533482fc62a77770cfb9cd785ef8afbc0ca7de142ff7136e\",\"active\":true,\"clob_token_ids\":[\"19827677769970793175383326216383491015711774584861621646050951945378763729005\",\"110632688308342827866548972791039265332888382974151634911030984058259276907986\"],\"sports_market_type\":\"soccer_second_half_team_totals\",\"line\":\"0.5\",\"game_start_time\":\"2026-08-27 00:30:00+00\",\"order_price_min_tick_size\":\"0.01\",\"group_item_title\":\"SE Palmeiras 2nd Half O/U 0.5\",\"taker_base_fee\":\"1000\",\"fees_enabled\":true,\"fee_schedule\":{\"exponent\":\"1\",\"rate\":\"0.05\",\"taker_only\":true,\"rebate_rate\":\"0.15\"}}"}
{"recv_ts": 1786689923108640, "venue": "polymarket", "raw": "{\"id\":\"3578453\",\"question\":\"SE Palmeiras vs. Santos FC: Santos FC 2nd Half O/U 0.5\",\"market\":\"0x6ee52a73dcee29d9b31685c7beddad50075db0937986e3f197d9d85716995048\",\"slug\":\"brco-pal-san-2026-08-26-second-half-team-total-away-0pt5\",\"description\":\"In the upcoming Copa do Brasil game between SE Palmeiras and Santos FC, scheduled for August 26 at 8:30 PM ET: This market will resolve to \\\"Over\\\" if Santos FC score 1 or more goals in the second half (second 45 minutes of regular play plus second-half stoppage time). If Santos FC score less than 1 goals in the second half, this market will resolve to \\\"Under\\\". This market is based solely on Santos FC's second-half score, not the combined score of both teams. If the game is postponed, this market will remain open until the game has been completed. If the game is canceled entirely, with no make-up game, this market will resolve 50-50. This market refers only to the outcome within the second 45 minutes of regular play plus second-half stoppage time. First-half goals, extra time, and penalty shoot-outs are excluded. The primary resolution source for this market is the official statistics of the event as recognized by the governing body or event organizers. However, if the governing body or event organizers have not published final match statistics within 2 hours after the event's conclusion, a consensus of credible reporting may be used instead. All markets will settle based on the official final result as recognized by the governing body or event organizers. Revisions to officially declared final scores made after market resolution will not be accounted for in determining the outcome.\",\"assets_ids\":[\"1786398599573735471683853396575419601940657853813312473182947690291307635127\",\"89936352229955442926916201026007487678332592630160591978652155734332224647129\"],\"outcomes\":[\"Over\",\"Under\"],\"event_message\":{\"id\":\"847372\",\"ticker\":\"brco-pal-san-2026-08-26-more-markets\",\"slug\":\"brco-pal-san-2026-08-26-more-markets\",\"title\":\"SE Palmeiras vs. Santos FC - More Markets\",\"description\":\"More markets for the Copa do Brasil game, scheduled for August 26 at 8:30 PM ET.\"},\"timestamp\":\"1786689923070\",\"event_type\":\"new_market\",\"tags\":[],\"condition_id\":\"0x6ee52a73dcee29d9b31685c7beddad50075db0937986e3f197d9d85716995048\",\"active\":true,\"clob_token_ids\":[\"1786398599573735471683853396575419601940657853813312473182947690291307635127\",\"89936352229955442926916201026007487678332592630160591978652155734332224647129\"],\"sports_market_type\":\"soccer_second_half_team_totals\",\"line\":\"0.5\",\"game_start_time\":\"2026-08-27 00:30:00+00\",\"order_price_min_tick_size\":\"0.01\",\"group_item_title\":\"Santos FC 2nd Half O/U 0.5\",\"taker_base_fee\":\"1000\",\"fees_enabled\":true,\"fee_schedule\":{\"exponent\":\"1\",\"rate\":\"0.05\",\"taker_only\":true,\"rebate_rate\":\"0.15\"}}"}
{"recv_ts": 1786689923174512, "venue": "polymarket", "raw": "{\"id\":\"3578427\",\"question\":\"SE Palmeiras vs. Santos FC: O/U 1.5\",\"market\":\"0xc6bae19321e7de344bbc7fcd10ca4ff0b851398ecd4d1fd729411b200a838b6b\",\"slug\":\"brco-pal-san-2026-08-26-total-1pt5\",\"description\":\"In the upcoming Copa do Brasil game between SE Palmeiras and Santos FC, scheduled for August 26 at 8:30 PM ET:\\n\\nThis market will resolve to \\\"Over\\\" if SE Palmeiras and Santos FC combine to score 2 or more goals in this game.\\n\\nIf the combined total is less than 2, this market will resolve to \\\"Under\\\".\\n\\nIf the game is postponed, this market will remain open until the game has been completed. If the game is canceled entirely, with no make-up game, this market will resolve 50\u201350.\\n\\nIf the game is started but not completed, this market will resolve according to the official final score published on cbf.com.br. This market refers only to the outcome within the first 90 minutes of regular play plus stoppage time.\\n\\nThe primary resolution source for this market is the official statistics of the event as recognized by the governing body or event organizers. However, if the governing body or event organizers have not published final match statistics within 2 hours after the event's conclusion, a consensus of credible reporting may be used instead. All markets will settle based on the official final result as recognized by the governing body or event organizers. Revisions to officially declared final scores made after market resolution will not be accounted for in determining the outcome.\",\"assets_ids\":[\"36258667829470568361966042363165645076466878390799290518750711873442260385391\",\"68465739637968463524723438832970248952891962523318784311819030629712978276611\"],\"outcomes\":[\"Over\",\"Under\"],\"event_message\":{\"id\":\"847372\",\"ticker\":\"brco-pal-san-2026-08-26-more-markets\",\"slug\":\"brco-pal-san-2026-08-26-more-markets\",\"title\":\"SE Palmeiras vs. Santos FC - More Markets\",\"description\":\"More markets for the Copa do Brasil game, scheduled for August 26 at 8:30 PM ET.\"},\"timestamp\":\"1786689923076\",\"event_type\":\"new_market\",\"tags\":[],\"condition_id\":\"0xc6bae19321e7de344bbc7fcd10ca4ff0b851398ecd4d1fd729411b200a838b6b\",\"active\":true,\"clob_token_ids\":[\"36258667829470568361966042363165645076466878390799290518750711873442260385391\",\"68465739637968463524723438832970248952891962523318784311819030629712978276611\"],\"sports_market_type\":\"totals\",\"line\":\"1.5\",\"game_start_time\":\"2026-08-27 00:30:00+00\",\"order_price_min_tick_size\":\"0.01\",\"group_item_title\":\"O/U 1.5\",\"taker_base_fee\":\"1000\",\"fees_enabled\":true,\"fee_schedule\":{\"exponent\":\"1\",\"rate\":\"0.05\",\"taker_only\":true,\"rebate_rate\":\"0.15\"}}"}
{"recv_ts": 1786689923199188, "venue": "polymarket", "raw": "{\"id\":\"3578422\",\"question\":\"Spread: SE Palmeiras (-1.5)\",\"market\":\"0x20dbc492a00ecfa23a5a3fa3ed34ef7d79584d16aff6f07090ffb780cda8e77a\",\"slug\":\"brco-pal-san-2026-08-26-spread-home-1pt5\",\"description\":\"In the upcoming Copa do Brasil game, scheduled for August 26 at 8:30 PM ET:\\n\\nThis market will resolve to \\\"SE Palmeiras\\\" if SE Palmeiras win the game by 2 or more goals.\\n\\nOtherwise, this market will resolve to \\\"Santos FC\\\".\\n\\nIf the game is postponed, this market will remain open until the game has been completed. If the game is canceled entirely, with no make-up game, this market will resolve 50\u201350.\\n\\nThis market will resolve according to the official final score published on cbf.com.br. This market refers only to the outcome within the first 90 minutes of regular play plus stoppage time.\\n\\nThe primary resolution source for this market is the official statistics of the event as recognized by the governing body or event organizers. However, if the governing body or event organizers have not published final match statistics within 2 hours after the event's conclusion, a consensus of credible reporting may be used instead. All markets will settle based on the official final result as recognized by the governing body or event organizers. Revisions to officially declared final scores made after market resolution will not be accounted for in determining the outcome.\",\"assets_ids\":[\"23171535346367289824428964759649845851841150654243828088503562490643607249239\",\"29545331816642214589297969077082064577318129285656375934929027640366844469886\"],\"outcomes\":[\"SE Palmeiras\",\"Santos FC\"],\"event_message\":{\"id\":\"847372\",\"ticker\":\"brco-pal-san-2026-08-26-more-markets\",\"slug\":\"brco-pal-san-2026-08-26-more-markets\",\"title\":\"SE Palmeiras vs. Santos FC - More Markets\",\"description\":\"More markets for the Copa do Brasil game, scheduled for August 26 at 8:30 PM ET.\"},\"timestamp\":\"1786689923073\",\"event_type\":\"new_market\",\"tags\":[],\"condition_id\":\"0x20dbc492a00ecfa23a5a3fa3ed34ef7d79584d16aff6f07090ffb780cda8e77a\",\"active\":true,\"clob_token_ids\":[\"23171535346367289824428964759649845851841150654243828088503562490643607249239\",\"29545331816642214589297969077082064577318129285656375934929027640366844469886\"],\"sports_market_type\":\"spreads\",\"line\":\"-1.5\",\"game_start_time\":\"2026-08-27 00:30:00+00\",\"order_price_min_tick_size\":\"0.01\",\"group_item_title\":\"SE Palmeiras (-1.5)\",\"taker_base_fee\":\"1000\",\"fees_enabled\":true,\"fee_schedule\":{\"exponent\":\"1\",\"rate\":\"0.05\",\"taker_only\":true,\"rebate_rate\":\"0.15\"}}"}
{"recv_ts": 1786689923199270, "venue": "polymarket", "raw": "{\"market\":\"0xbb4d51e6364066d92eb6f9b8413dd7193de70966736044463b205834805a1f3b\",\"price_changes\":[{\"asset_id\":\"10991849228756847439673778874175365458450913336396982752046655649803657501964\",\"price\":\"0.02\",\"size\":\"71556.69\",\"side\":\"BUY\",\"hash\":\"cdc9d085bd0478ba0aee7ee1b1bc3d23db51cc31\",\"best_bid\":\"0.06\",\"best_ask\":\"0.07\"},{\"asset_id\":\"106181075047366745139197108801635573283215248045056329679360376976893016488727\",\"price\":\"0.98\",\"size\":\"71556.69\",\"side\":\"SELL\",\"hash\":\"1eded44420a1f5a4018acfa8174610d6e0171308\",\"best_bid\":\"0.93\",\"best_ask\":\"0.94\"}],\"timestamp\":\"1786689923106\",\"event_type\":\"price_change\"}"}
{"recv_ts": 1786689923265787, "venue": "polymarket", "raw": "{\"market\":\"0xbb4d51e6364066d92eb6f9b8413dd7193de70966736044463b205834805a1f3b\",\"price_changes\":[{\"asset_id\":\"106181075047366745139197108801635573283215248045056329679360376976893016488727\",\"price\":\"0.92\",\"size\":\"181908.7\",\"side\":\"BUY\",\"hash\":\"4d7d0e99028ff9f9eaf81d77bb4e67ed7c4ec821\",\"best_bid\":\"0.93\",\"best_ask\":\"0.94\"},{\"asset_id\":\"10991849228756847439673778874175365458450913336396982752046655649803657501964\",\"price\":\"0.08\",\"size\":\"181908.7\",\"side\":\"SELL\",\"hash\":\"37aaf1a0c27c62e9020123a04f1c57d982251a52\",\"best_bid\":\"0.06\",\"best_ask\":\"0.07\"}],\"timestamp\":\"1786689923113\",\"event_type\":\"price_change\"}"}
{"recv_ts": 1786689923265863, "venue": "polymarket", "raw": "{\"market\":\"0xbb4d51e6364066d92eb6f9b8413dd7193de70966736044463b205834805a1f3b\",\"price_changes\":[{\"asset_id\":\"10991849228756847439673778874175365458450913336396982752046655649803657501964\",\"price\":\"0.04\",\"size\":\"479216.56\",\"side\":\"BUY\",\"hash\":\"eccf36bf9ad08804486b36107643fac009ba576a\",\"best_bid\":\"0.06\",\"best_ask\":\"0.07\"},{\"asset_id\":\"106181075047366745139197108801635573283215248045056329679360376976893016488727\",\"price\":\"0.96\",\"size\":\"479216.56\",\"side\":\"SELL\",\"hash\":\"0fcdd5471c1e2bd4492fdd7aad2a8eedb6b980d6\",\"best_bid\":\"0.93\",\"best_ask\":\"0.94\"}],\"timestamp\":\"1786689923113\",\"event_type\":\"price_change\"}"}
{"recv_ts": 1786689923458877, "venue": "polymarket", "raw": "{\"id\":\"3578437\",\"question\":\"SE Palmeiras vs. Santos FC: SE Palmeiras O/U 0.5\",\"market\":\"0xc0146a9384edf8cc0c7f87206e6501fd3d728fc8cbd5089c74e24a3c026b7d56\",\"slug\":\"brco-pal-san-2026-08-26-team-total-home-0pt5\",\"description\":\"In the upcoming Copa do Brasil game between SE Palmeiras and Santos FC, scheduled for August 26 at 8:30 PM ET: This market will resolve to \\\"Over\\\" if SE Palmeiras score 1 or more goals within the first 90 minutes of regular play plus stoppage time. If SE Palmeiras score less than 1 goals within the first 90 minutes of regular play plus stoppage time, this market will resolve to \\\"Under\\\". This market is based solely on SE Palmeiras's score, not the combined score of both teams. If the game is postponed, this market will remain open until the game has been completed. If the game is canceled entirely, with no make-up game, this market will resolve 50-50. This market refers only to the outcome within the first 90 minutes of regular play plus stoppage time. Extra time and penalty shoot-outs are excluded. The primary resolution source for this market is the official statistics of the event as recognized by the governing body or event organizers. However, if the governing body or event organizers have not published final match statistics within 2 hours after the event's conclusion, a consensus of credible reporting may be used instead. All markets will settle based on the official final result as recognized by the governing body or event organizers. Revisions to officially declared final scores made after market resolution will not be accounted for in determining the outcome.\",\"assets_ids\":[\"115287074213791177039695837906379293934041121451976006690360690241156758170577\",\"26362312339114562560821316350650251533485560086095686603608368117090582878711\"],\"outcomes\":[\"Over\",\"Under\"],\"event_message\":{\"id\":\"847372\",\"ticker\":\"brco-pal-san-2026-08-26-more-markets\",\"slug\":\"brco-pal-san-2026-08-26-more-markets\",\"title\":\"SE Palmeiras vs. Santos FC - More Markets\",\"description\":\"More markets for the Copa do Brasil game, scheduled for August 26 at 8:30 PM ET.\"},\"timestamp\":\"1786689923335\",\"event_type\":\"new_market\",\"tags\":[],\"condition_id\":\"0xc0146a9384edf8cc0c7f87206e6501fd3d728fc8cbd5089c74e24a3c026b7d56\",\"active\":true,\"clob_token_ids\":[\"115287074213791177039695837906379293934041121451976006690360690241156758170577\",\"26362312339114562560821316350650251533485560086095686603608368117090582878711\"],\"sports_market_type\":\"soccer_team_totals\",\"line\":\"0.5\",\"game_start_time\":\"2026-08-27 00:30:00+00\",\"order_price_min_tick_size\":\"0.01\",\"group_item_title\":\"SE Palmeiras O/U 0.5\",\"taker_base_fee\":\"1000\",\"fees_enabled\":true,\"fee_schedule\":{\"exponent\":\"1\",\"rate\":\"0.05\",\"taker_only\":true,\"rebate_rate\":\"0.15\"}}"}
{"recv_ts": 1786689923536873, "venue": "polymarket", "raw": "{\"id\":\"3578436\",\"question\":\"SE Palmeiras vs. Santos FC: 1st Half O/U 2.5\",\"market\":\"0x01ee3fbfb41ae6fe00e11d5c772570ac639c0a47e8e9170bccb6b42abb185aec\",\"slug\":\"brco-pal-san-2026-08-26-first-half-total-2pt5\",\"description\":\"In the upcoming Copa do Brasil game between SE Palmeiras and Santos FC, scheduled for August 26 at 8:30 PM ET: This market will resolve to \\\"Over\\\" if SE Palmeiras and Santos FC combine to score 3 or more goals in the first half (first 45 minutes of regular play plus first-half stoppage time). If the combined first-half total is less than 3 goals, this market will resolve to \\\"Under\\\". If the game is postponed, this market will remain open until the game has been completed. If the game is canceled entirely, with no make-up game, this market will resolve 50-50. This market refers only to the outcome within the first 45 minutes of regular play plus first-half stoppage time. Second-half goals, extra time, and penalty shoot-outs are excluded. The primary resolution source for this market is the official statistics of the event as recognized by the governing body or event organizers. However, if the governing body or event organizers have not published final match statistics within 2 hours after the event's conclusion, a consensus of credible reporting may be used instead. All markets will settle based on the official final result as recognized by the governing body or event organizers. Revisions to officially declared final scores made after market resolution will not be accounted for in determining the outcome.\",\"assets_ids\":[\"53032655436717924277121059884054518282507825212114386419085367212565818233352\",\"2318732363897889207267602388194486138102700645820144625124889602466865015806\"],\"outcomes\":[\"Over\",\"Under\"],\"event_message\":{\"id\":\"847372\",\"ticker\":\"brco-pal-san-2026-08-26-more-markets\",\"slug\":\"brco-pal-san-2026-08-26-more-markets\",\"title\":\"SE Palmeiras vs. Santos FC - More Markets\",\"description\":\"More markets for the Copa do Brasil game, scheduled for August 26 at 8:30 PM ET.\"},\"timestamp\":\"1786689923338\",\"event_type\":\"new_market\",\"tags\":[],\"condition_id\":\"0x01ee3fbfb41ae6fe00e11d5c772570ac639c0a47e8e9170bccb6b42abb185aec\",\"active\":true,\"clob_token_ids\":[\"53032655436717924277121059884054518282507825212114386419085367212565818233352\",\"2318732363897889207267602388194486138102700645820144625124889602466865015806\"],\"sports_market_type\":\"first_half_totals\",\"line\":\"2.5\",\"game_start_time\":\"2026-08-27 00:30:00+00\",\"order_price_min_tick_size\":\"0.01\",\"group_item_title\":\"1st Half O/U 2.5\",\"taker_base_fee\":\"1000\",\"fees_enabled\":true,\"fee_schedule\":{\"exponent\":\"1\",\"rate\":\"0.05\",\"taker_only\":true,\"rebate_rate\":\"0.15\"}}"}
{"recv_ts": 1786689923536942, "venue": "polymarket", "raw": "{\"id\":\"3578452\",\"question\":\"SE Palmeiras vs. Santos FC: SE Palmeiras 2nd Half O/U 1.5\",\"market\":\"0x00694b2d8722e2aa484af19b76f9e517c9a0aaef26d6bba7610edee00c2285a3\",\"slug\":\"brco-pal-san-2026-08-26-second-half-team-total-home-1pt5\",\"description\":\"In the upcoming Copa do Brasil game between SE Palmeiras and Santos FC, scheduled for August 26 at 8:30 PM ET: This market will resolve to \\\"Over\\\" if SE Palmeiras score 2 or more goals in the second half (second 45 minutes of regular play plus second-half stoppage time). If SE Palmeiras score less than 2 goals in the second half, this market will resolve to \\\"Under\\\". This market is based solely on SE Palmeiras's second-half score, not the combined score of both teams. If the game is postponed, this market will remain open until the game has been completed. If the game is canceled entirely, with no make-up game, this market will resolve 50-50. This market refers only to the outcome within the second 45 minutes of regular play plus second-half stoppage time. First-half goals, extra time, and penalty shoot-outs are excluded. The primary resolution source for this market is the official statistics of the event as recognized by the governing body or event organizers. However, if the governing body or event organizers have not published final match statistics within 2 hours after the event's conclusion, a consensus of credible reporting may be used instead. All markets will settle based on the official final result as recognized by the governing body or event organizers. Revisions to officially declared final scores made after market resolution will not be accounted for in determining the outcome.\",\"assets_ids\":[\"20793090219322455678303791790786862150698000651956646715169628566881257210496\",\"29153912351743906256030219049152907990609360823357558627359017502186301015742\"],\"outcomes\":[\"Over\",\"Under\"],\"event_message\":{\"id\":\"847372\",\"ticker\":\"brco-pal-san-2026-08-26-more-markets\",\"slug\":\"brco-pal-san-2026-08-26-more-markets\",\"title\":\"SE Palmeiras vs. Santos FC - More Markets\",\"description\":\"More markets for the Copa do Brasil game, scheduled for August 26 at 8:30 PM ET.\"},\"timestamp\":\"1786689923340\",\"event_type\":\"new_market\",\"tags\":[],\"condition_id\":\"0x00694b2d8722e2aa484af19b76f9e517c9a0aaef26d6bba7610edee00c2285a3\",\"active\":true,\"clob_token_ids\":[\"20793090219322455678303791790786862150698000651956646715169628566881257210496\",\"29153912351743906256030219049152907990609360823357558627359017502186301015742\"],\"sports_market_type\":\"soccer_second_half_team_totals\",\"line\":\"1.5\",\"game_start_time\":\"2026-08-27 00:30:00+00\",\"order_price_min_tick_size\":\"0.01\",\"group_item_title\":\"SE Palmeiras 2nd Half O/U 1.5\",\"taker_base_fee\":\"1000\",\"fees_enabled\":true,\"fee_schedule\":{\"exponent\":\"1\",\"rate\":\"0.05\",\"taker_only\":true,\"rebate_rate\":\"0.15\"}}"}
{"recv_ts": 1786689923550569, "venue": "polymarket", "raw": "{\"market\":\"0xd9fb1184af0064e5e34b129f5b79afa5a17b7e32f2953ab05efed82315fee6d4\",\"price_changes\":[{\"asset_id\":\"94559586571241563470235664821564670251180951772614764383113614156422396181162\",\"price\":\"0.012\",\"size\":\"15452\",\"side\":\"BUY\",\"hash\":\"b935d135da28c9f55a292d31096ca8ebf8eb59e8\",\"best_bid\":\"0.036\",\"best_ask\":\"0.038\"},{\"asset_id\":\"90772332434487149264114862115632028379978765245278600275169585501290867536237\",\"price\":\"0.988\",\"size\":\"15452\",\"side\":\"SELL\",\"hash\":\"d5e9c865f9a7d3cf4523dd3288b0167506c0836a\",\"best_bid\":\"0.962\",\"best_ask\":\"0.964\"}],\"timestamp\":\"1786689923535\",\"event_type\":\"price_change\"}"}
{"recv_ts": 1786689923550657, "venue": "polymarket", "raw": "{\"market\":\"0xd9fb1184af0064e5e34b129f5b79afa5a17b7e32f2953ab05efed82315fee6d4\",\"price_changes\":[{\"asset_id\":\"90772332434487149264114862115632028379978765245278600275169585501290867536237\",\"price\":\"0.943\",\"size\":\"6020\",\"side\":\"BUY\",\"hash\":\"d5e9c865f9a7d3cf4523dd3288b0167506c0836a\",\"best_bid\":\"0.962\",\"best_ask\":\"0.964\"},{\"asset_id\":\"94559586571241563470235664821564670251180951772614764383113614156422396181162\",\"price\":\"0.057\",\"size\":\"6020\",\"side\":\"SELL\",\"hash\":\"b935d135da28c9f55a292d31096ca8ebf8eb59e8\",\"best_bid\":\"0.036\",\"best_ask\":\"0.038\"}],\"timestamp\":\"1786689923535\",\"event_type\":\"price_change\"}"}
{"recv_ts": 1786689924082414, "venue": "polymarket", "raw": "{\"market\":\"0xd9fb1184af0064e5e34b129f5b79afa5a17b7e32f2953ab05efed82315fee6d4\",\"price_changes\":[{\"asset_id\":\"94559586571241563470235664821564670251180951772614764383113614156422396181162\",\"price\":\"0.012\",\"size\":\"30452\",\"side\":\"BUY\",\"hash\":\"8387b03ff4d56f43e0ce894e5e5044da5342a529\",\"best_bid\":\"0.036\",\"best_ask\":\"0.038\"},{\"asset_id\":\"90772332434487149264114862115632028379978765245278600275169585501290867536237\",\"price\":\"0.988\",\"size\":\"30452\",\"side\":\"SELL\",\"hash\":\"9d1834129039af70bf5634e27cc989b0243cea35\",\"best_bid\":\"0.962\",\"best_ask\":\"0.964\"}],\"timestamp\":\"1786689924074\",\"event_type\":\"price_change\"}"}
{"recv_ts": 1786689924083244, "venue": "polymarket", "raw": "{\"market\":\"0xd9fb1184af0064e5e34b129f5b79afa5a17b7e32f2953ab05efed82315fee6d4\",\"price_changes\":[{\"asset_id\":\"90772332434487149264114862115632028379978765245278600275169585501290867536237\",\"price\":\"0.943\",\"size\":\"16020\",\"side\":\"BUY\",\"hash\":\"456d1dbbeccefccd9f1797293a5d19781ffebfa4\",\"best_bid\":\"0.962\",\"best_ask\":\"0.964\"},{\"asset_id\":\"94559586571241563470235664821564670251180951772614764383113614156422396181162\",\"price\":\"0.057\",\"size\":\"16020\",\"side\":\"SELL\",\"hash\":\"35762ed6050a05d98729e60de3ccd4d35f3a4d04\",\"best_bid\":\"0.036\",\"best_ask\":\"0.038\"}],\"timestamp\":\"1786689924075\",\"event_type\":\"price_change\"}"}
{"recv_ts": 1786689925339920, "venue": "polymarket", "raw": "{\"id\":\"3578433\",\"question\":\"SE Palmeiras vs. Santos FC: Both Teams to Score in First Half\",\"market\":\"0x8c0d352c8145dc24b5dd418a9be3ba70cf493791fb30337fed8ac8ba49bc931a\",\"slug\":\"brco-pal-san-2026-08-26-btts-first-half\",\"description\":\"In the upcoming Copa do Brasil game between SE Palmeiras and Santos FC, scheduled for August 26 at 8:30 PM ET: This market will resolve to \\\"Yes\\\" if both SE Palmeiras and Santos FC each score at least one goal during the first half (first 45 minutes of regular play plus first-half stoppage time). This market will resolve to \\\"No\\\" if either team fails to score in the first half (i.e., if one or both teams finish the first half with zero goals). If the game is postponed, this market will remain open until the game has been completed. If the game is canceled entirely, with no make-up game, this market will resolve 50-50. This market refers only to the outcome within the first 45 minutes of regular play plus first-half stoppage time. Second-half goals, extra time, and penalty shoot-outs are excluded. The primary resolution source for this market is the official statistics of the event as recognized by the governing body or event organizers. However, if the governing body or event organizers have not published final match statistics within 2 hours after the event's conclusion, a consensus of credible reporting may be used instead. All markets will settle based on the official final result as recognized by the governing body or event organizers. Revisions to officially declared final scores made after market resolution will not be accounted for in determining the outcome.\",\"assets_ids\":[\"7418852208241240143806232303822988348895478550416132064367025343321684023718\",\"5946240140989356692399928882471577414012909151275593246158790637625488220361\"],\"outcomes\":[\"Yes\",\"No\"],\"event_message\":{\"id\":\"847372\",\"ticker\":\"brco-pal-san-2026-08-26-more-markets\",\"slug\":\"brco-pal-san-2026-08-26-more-markets\",\"title\":\"SE Palmeiras vs. Santos FC - More Markets\",\"description\":\"More markets for the Copa do Brasil game, scheduled for August 26 at 8:30 PM ET.\"},\"timestamp\":\"1786689925187\",\"event_type\":\"new_market\",\"tags\":[],\"condition_id\":\"0x8c0d352c8145dc24b5dd418a9be3ba70cf493791fb30337fed8ac8ba49bc931a\",\"active\":true,\"clob_token_ids\":[\"7418852208241240143806232303822988348895478550416132064367025343321684023718\",\"5946240140989356692399928882471577414012909151275593246158790637625488220361\"],\"sports_market_type\":\"both_teams_to_score_first_half\",\"line\":\"\",\"game_start_time\":\"2026-08-27 00:30:00+00\",\"order_price_min_tick_size\":\"0.01\",\"group_item_title\":\"Both Teams to Score in First Half\",\"taker_base_fee\":\"1000\",\"fees_enabled\":true,\"fee_schedule\":{\"exponent\":\"1\",\"rate\":\"0.05\",\"taker_only\":true,\"rebate_rate\":\"0.15\"}}"}
{"recv_ts": 1786689925340028, "venue": "polymarket", "raw": "{\"id\":\"3578432\",\"question\":\"SE Palmeiras vs. Santos FC: Both Teams to Score\",\"market\":\"0x5dd4fa2cec5e3ffeaef382681f4e2ec475c718cc82b936bc2c8608de37b778dc\",\"slug\":\"brco-pal-san-2026-08-26-btts\",\"description\":\"In the upcoming Copa do Brasil game between SE Palmeiras and Santos FC, scheduled for August 26 at 8:30 PM ET:\\n\\nThis market will resolve to \\\"Yes\\\" if both SE Palmeiras and Santos FC each score at least one goal during the game.\\n\\nThis market will resolve to \\\"No\\\" if either team fails to score (i.e., if one or both teams finish with zero goals).\\n\\nIf the game is postponed, this market will remain open until the game has been completed. If the game is canceled entirely, with no make-up game, this market will resolve 50\u201350.\\n\\nIf the game is started but not completed, this market will resolve according to the official final score published on cbf.com.br. This market refers only to the outcome within the first 90 minutes of regular play plus stoppage time.\\n\\nThe primary resolution source for this market is the official statistics of the event as recognized by the governing body or event organizers. However, if the governing body or event organizers have not published final match statistics within 2 hours after the event's conclusion, a consensus of credible reporting may be used instead. All markets will settle based on the official final result as recognized by the governing body or event organizers. Revisions to officially declared final scores made after market resolution will not be accounted for in determining the outcome.\",\"assets_ids\":[\"2041227263750455169464843413019065906302794205624878665655526086021575875008\",\"103628626725294869607105208790859496108622014868249347488650878246406533665620\"],\"outcomes\":[\"Yes\",\"No\"],\"event_message\":{\"id\":\"847372\",\"ticker\":\"brco-pal-san-2026-08-26-more-markets\",\"slug\":\"brco-pal-san-2026-08-26-more-markets\",\"title\":\"SE Palmeiras vs. Santos FC - More Markets\",\"description\":\"More markets for the Copa do Brasil game, scheduled for August 26 at 8:30 PM ET.\"},\"timestamp\":\"1786689925184\",\"event_type\":\"new_market\",\"tags\":[],\"condition_id\":\"0x5dd4fa2cec5e3ffeaef382681f4e2ec475c718cc82b936bc2c8608de37b778dc\",\"active\":true,\"clob_token_ids\":[\"2041227263750455169464843413019065906302794205624878665655526086021575875008\",\"103628626725294869607105208790859496108622014868249347488650878246406533665620\"],\"sports_market_type\":\"both_teams_to_score\",\"line\":\"\",\"game_start_time\":\"2026-08-27 00:30:00+00\",\"order_price_min_tick_size\":\"0.01\",\"group_item_title\":\"Both Teams to Score\",\"taker_base_fee\":\"1000\",\"fees_enabled\":true,\"fee_schedule\":{\"exponent\":\"1\",\"rate\":\"0.05\",\"taker_only\":true,\"rebate_rate\":\"0.15\"}}"}
{"recv_ts": 1786689925340078, "venue": "polymarket", "raw": "{\"market\":\"0xd595eb9b81885ff018738300c79047e3ec89e87294424f57a29a7fa9162bf116\",\"price_changes\":[{\"asset_id\":\"57216272564529548464686463691236811991956032201293786790337952253964682584376\",\"price\":\"0.961\",\"size\":\"41133.18\",\"side\":\"BUY\",\"hash\":\"10e933a656c6fc767eb5fe407f0c4c2213eb74a2\",\"best_bid\":\"0.963\",\"best_ask\":\"0.964\"},{\"asset_id\":\"5161623255678193352839985156330393796378434470119114669671615782853260939535\",\"price\":\"0.039\",\"size\":\"41133.18\",\"side\":\"SELL\",\"hash\":\"222f12f1cd1c4bf8a9583b9cac892fcd4c1ee1f2\",\"best_bid\":\"0.036\",\"best_ask\":\"0.037\"}],\"timestamp\":\"1786689925313\",\"event_type\":\"price_change\"}"}
{"recv_ts": 1786689925415077, "venue": "polymarket", "raw": "{\"market\":\"0xd595eb9b81885ff018738300c79047e3ec89e87294424f57a29a7fa9162bf116\",\"price_changes\":[{\"asset_id\":\"57216272564529548464686463691236811991956032201293786790337952253964682584376\",\"price\":\"0.96\",\"size\":\"115\",\"side\":\"BUY\",\"hash\":\"ba3dda362138333bb43d3a65b65d2ff556301498\",\"best_bid\":\"0.963\",\"best_ask\":\"0.964\"},{\"asset_id\":\"5161623255678193352839985156330393796378434470119114669671615782853260939535\",\"price\":\"0.04\",\"size\":\"115\",\"side\":\"SELL\",\"hash\":\"c459533627e9659df3f26df0111497bd163f5b63\",\"best_bid\":\"0.036\",\"best_ask\":\"0.037\"}],\"timestamp\":\"1786689925387\",\"event_type\":\"price_change\"}"}
{"recv_ts": 1786689925507428, "venue": "polymarket", "raw": "{\"id\":\"3578431\",\"question\":\"SE Palmeiras vs. Santos FC: O/U 5.5\",\"market\":\"0xd15f31609c0a4bc10bd32934d8285af9f4b47fd3d9d462ea49461aad0e8d9e14\",\"slug\":\"brco-pal-san-2026-08-26-total-5pt5\",\"description\":\"In the upcoming Copa do Brasil game between SE Palmeiras and Santos FC, scheduled for August 26 at 8:30 PM ET:\\n\\nThis market will resolve to \\\"Over\\\" if SE Palmeiras and Santos FC combine to score 6 or more goals in this game.\\n\\nIf the combined total is less than 6, this market will resolve to \\\"Under\\\".\\n\\nIf the game is postponed, this market will remain open until the game has been completed. If the game is canceled entirely, with no make-up game, this market will resolve 50\u201350.\\n\\nIf the game is started but not completed, this market will resolve according to the official final score published on cbf.com.br. This market refers only to the outcome within the first 90 minutes of regular play plus stoppage time.\\n\\nThe primary resolution source for this market is the official statistics of the event as recognized by the governing body or event organizers. However, if the governing body or event organizers have not published final match statistics within 2 hours after the event's conclusion, a consensus of credible reporting may be used instead. All markets will settle based on the official final result as recognized by the governing body or event organizers. Revisions to officially declared final scores made after market resolution will not be accounted for in determining the outcome.\",\"assets_ids\":[\"57435947135251598520955137231533450733875941507703632064223442046811579960316\",\"15979628831027856674079988063706459237030706442864664853014011910233508827343\"],\"outcomes\":[\"Over\",\"Under\"],\"event_message\":{\"id\":\"847372\",\"ticker\":\"brco-pal-san-2026-08-26-more-markets\",\"slug\":\"brco-pal-san-2026-08-26-more-markets\",\"title\":\"SE Palmeiras vs. Santos FC - More Markets\",\"description\":\"More markets for the Copa do Brasil game, scheduled for August 26 at 8:30 PM ET.\"},\"timestamp\":\"1786689925436\",\"event_type\":\"new_market\",\"tags\":[],\"condition_id\":\"0xd15f31609c0a4bc10bd32934d8285af9f4b47fd3d9d462ea49461aad0e8d9e14\",\"active\":true,\"clob_token_ids\":[\"57435947135251598520955137231533450733875941507703632064223442046811579960316\",\"15979628831027856674079988063706459237030706442864664853014011910233508827343\"],\"sports_market_type\":\"totals\",\"line\":\"5.5\",\"game_start_time\":\"2026-08-27 00:30:00+00\",\"order_price_min_tick_size\":\"0.01\",\"group_item_title\":\"O/U 5.5\",\"taker_base_fee\":\"1000\",\"fees_enabled\":true,\"fee_schedule\":{\"exponent\":\"1\",\"rate\":\"0.05\",\"taker_only\":true,\"rebate_rate\":\"0.15\"}}"}
{"recv_ts": 1786689925599444, "venue": "polymarket", "raw": "{\"id\":\"3578428\",\"question\":\"SE Palmeiras vs. Santos FC: O/U 2.5\",\"market\":\"0x7779948db4f5628f017e3a1876427fae0e5978b00aa39d94a109d00811c81115\",\"slug\":\"brco-pal-san-2026-08-26-total-2pt5\",\"description\":\"In the upcoming Copa do Brasil game between SE Palmeiras and Santos FC, scheduled for August 26 at 8:30 PM ET:\\n\\nThis market will resolve to \\\"Over\\\" if SE Palmeiras and Santos FC combine to score 3 or more goals in this game.\\n\\nIf the combined total is less than 3, this market will resolve to \\\"Under\\\".\\n\\nIf the game is postponed, this market will remain open until the game has been completed. If the game is canceled entirely, with no make-up game, this market will resolve 50\u201350.\\n\\nIf the game is started but not completed, this market will resolve according to the official final score published on cbf.com.br. This market refers only to the outcome within the first 90 minutes of regular play plus stoppage time.\\n\\nThe primary resolution source for this market is the official statistics of the event as recognized by the governing body or event organizers. However, if the governing body or event organizers have not published final match statistics within 2 hours after the event's conclusion, a consensus of credible reporting may be used instead. All markets will settle based on the official final result as recognized by the governing body or event organizers. Revisions to officially declared final scores made after market resolution will not be accounted for in determining the outcome.\",\"assets_ids\":[\"41379410479999861723255663883604601616872244683984335574301678632143018112267\",\"71718003171645161863057153284466684479710311312853865335866631545976779083743\"],\"outcomes\":[\"Over\",\"Under\"],\"event_message\":{\"id\":\"847372\",\"ticker\":\"brco-pal-san-2026-08-26-more-markets\",\"slug\":\"brco-pal-san-2026-08-26-more-markets\",\"title\":\"SE Palmeiras vs. Santos FC - More Markets\",\"description\":\"More markets for the Copa do Brasil game, scheduled for August 26 at 8:30 PM ET.\"},\"timestamp\":\"1786689925442\",\"event_type\":\"new_market\",\"tags\":[],\"condition_id\":\"0x7779948db4f5628f017e3a1876427fae0e5978b00aa39d94a109d00811c81115\",\"active\":true,\"clob_token_ids\":[\"41379410479999861723255663883604601616872244683984335574301678632143018112267\",\"71718003171645161863057153284466684479710311312853865335866631545976779083743\"],\"sports_market_type\":\"totals\",\"line\":\"2.5\",\"game_start_time\":\"2026-08-27 00:30:00+00\",\"order_price_min_tick_size\":\"0.01\",\"group_item_title\":\"O/U 2.5\",\"taker_base_fee\":\"1000\",\"fees_enabled\":true,\"fee_schedule\":{\"exponent\":\"1\",\"rate\":\"0.05\",\"taker_only\":true,\"rebate_rate\":\"0.15\"}}"}
{"recv_ts": 1786689925638384, "venue": "polymarket", "raw": "{\"id\":\"3578425\",\"question\":\"Spread: Santos FC (-2.5)\",\"market\":\"0x108b22c966c44f252fd4f9b771be6812e1d632f5b6e0380d82c32bbb593344d5\",\"slug\":\"brco-pal-san-2026-08-26-spread-away-2pt5\",\"description\":\"In the upcoming Copa do Brasil game, scheduled for August 26 at 8:30 PM ET:\\n\\nThis market will resolve to \\\"Santos FC\\\" if Santos FC win the game by 3 or more goals.\\n\\nOtherwise, this market will resolve to \\\"SE Palmeiras\\\".\\n\\nIf the game is postponed, this market will remain open until the game has been completed. If the game is canceled entirely, with no make-up game, this market will resolve 50\u201350.\\n\\nThis market will resolve according to the official final score published on cbf.com.br. This market refers only to the outcome within the first 90 minutes of regular play plus stoppage time.\\n\\nThe primary resolution source for this market is the official statistics of the event as recognized by the governing body or event organizers. However, if the governing body or event organizers have not published final match statistics within 2 hours after the event's conclusion, a consensus of credible reporting may be used instead. All markets will settle based on the official final result as recognized by the governing body or event organizers. Revisions to officially declared final scores made after market resolution will not be accounted for in determining the outcome.\",\"assets_ids\":[\"112833304581756837132744533599443705761088192579413295544493366598541887492255\",\"50114042634561878562144775600592325454231725664319948871318777514684327178798\"],\"outcomes\":[\"Santos FC\",\"SE Palmeiras\"],\"event_message\":{\"id\":\"847372\",\"ticker\":\"brco-pal-san-2026-08-26-more-markets\",\"slug\":\"brco-pal-san-2026-08-26-more-markets\",\"title\":\"SE Palmeiras vs. Santos FC - More Markets\",\"description\":\"More markets for the Copa do Brasil game, scheduled for August 26 at 8:30 PM ET.\"},\"timestamp\":\"1786689925441\",\"event_type\":\"new_market\",\"tags\":[],\"condition_id\":\"0x108b22c966c44f252fd4f9b771be6812e1d632f5b6e0380d82c32bbb593344d5\",\"active\":true,\"clob_token_ids\":[\"112833304581756837132744533599443705761088192579413295544493366598541887492255\",\"50114042634561878562144775600592325454231725664319948871318777514684327178798\"],\"sports_market_type\":\"spreads\",\"line\":\"-2.5\",\"game_start_time\":\"2026-08-27 00:30:00+00\",\"order_price_min_tick_size\":\"0.01\",\"group_item_title\":\"Santos FC (-2.5)\",\"taker_base_fee\":\"1000\",\"fees_enabled\":true,\"fee_schedule\":{\"exponent\":\"1\",\"rate\":\"0.05\",\"taker_only\":true,\"rebate_rate\":\"0.15\"}}"}
{"recv_ts": 1786689925691571, "venue": "polymarket", "raw": "{\"id\":\"3578450\",\"question\":\"SE Palmeiras vs. Santos FC: 2nd Half O/U 2.5\",\"market\":\"0xee190eee915822a3f121909d017796f2cccd02d4695a71b9e4fc5a906b018fa5\",\"slug\":\"brco-pal-san-2026-08-26-second-half-total-2pt5\",\"description\":\"In the upcoming Copa do Brasil game between SE Palmeiras and Santos FC, scheduled for August 26 at 8:30 PM ET: This market will resolve to \\\"Over\\\" if SE Palmeiras and Santos FC combine to score 3 or more goals in the second half of regular play plus second-half stoppage time. If the combined second-half total is less than 3 goals, this market will resolve to \\\"Under\\\". If the game is postponed, this market will remain open until the game has been completed. If the game is canceled entirely, with no make-up game, this market will resolve 50-50. This market refers only to the outcome within the second half of regular play plus second-half stoppage time. First-half goals, extra time, and penalty shoot-outs are excluded. The primary resolution source for this market is the official statistics of the event as recognized by the governing body or event organizers. However, if the governing body or event organizers have not published final match statistics within 2 hours after the event's conclusion, a consensus of credible reporting may be used instead. All markets will settle based on the official final result as recognized by the governing body or event organizers. Revisions to officially declared final scores made after market resolution will not be accounted for in determining the outcome.\",\"assets_ids\":[\"56065007592535457410252317099600620320658256638420534376793913491575779170624\",\"31088759441846075654277083568230025640756039430463263761470354068014189517265\"],\"outcomes\":[\"Over\",\"Under\"],\"event_message\":{\"id\":\"847372\",\"ticker\":\"brco-pal-san-2026-08-26-more-markets\",\"slug\":\"brco-pal-san-2026-08-26-more-markets\",\"title\":\"SE Palmeiras vs. Santos FC - More Markets\",\"description\":\"More markets for the Copa do Brasil game, scheduled for August 26 at 8:30 PM ET.\"},\"timestamp\":\"1786689925445\",\"event_type\":\"new_market\",\"tags\":[],\"condition_id\":\"0xee190eee915822a3f121909d017796f2cccd02d4695a71b9e4fc5a906b018fa5\",\"active\":true,\"clob_token_ids\":[\"56065007592535457410252317099600620320658256638420534376793913491575779170624\",\"31088759441846075654277083568230025640756039430463263761470354068014189517265\"],\"sports_market_type\":\"second_half_totals\",\"line\":\"2.5\",\"game_start_time\":\"2026-08-27 00:30:00+00\",\"order_price_min_tick_size\":\"0.01\",\"group_item_title\":\"2nd Half O/U 2.5\",\"taker_base_fee\":\"1000\",\"fees_enabled\":true,\"fee_schedule\":{\"exponent\":\"1\",\"rate\":\"0.05\",\"taker_only\":true,\"rebate_rate\":\"0.15\"}}"}
{"recv_ts": 1786689925691660, "venue": "polymarket", "raw": "{\"market\":\"0xd595eb9b81885ff018738300c79047e3ec89e87294424f57a29a7fa9162bf116\",\"price_changes\":[{\"asset_id\":\"57216272564529548464686463691236811991956032201293786790337952253964682584376\",\"price\":\"0.959\",\"size\":\"330\",\"side\":\"BUY\",\"hash\":\"314bf936cecdc852a2908cdbbb9f79e1cac744a5\",\"best_bid\":\"0.963\",\"best_ask\":\"0.964\"},{\"asset_id\":\"5161623255678193352839985156330393796378434470119114669671615782853260939535\",\"price\":\"0.041\",\"size\":\"330\",\"side\":\"SELL\",\"hash\":\"42b2e6b839d168cb1faf5c49b9c94ca933481189\",\"best_bid\":\"0.036\",\"best_ask\":\"0.037\"}],\"timestamp\":\"1786689925465\",\"event_type\":\"price_change\"}"}
{"recv_ts": 1786689925899003, "venue": "polymarket", "raw": "{\"market\":\"0x6bd56627aa21311850825edb27e53434a0e17a4f782be0086bc07f71eee00d0d\",\"price_changes\":[{\"asset_id\":\"87073899845581463485186346288398658568334162612963837182986759797304993556208\",\"price\":\"0.93\",\"size\":\"136097.66\",\"side\":\"SELL\",\"hash\":\"6e91cecd60ca8f8c999140a48d95c499d87f768f\",\"best_bid\":\"0.92\",\"best_ask\":\"0.93\"},{\"asset_id\":\"350977769852917329387037893294763093471844346281449484439085576212613048126\",\"price\":\"0.07\",\"size\":\"136097.66\",\"side\":\"BUY\",\"hash\":\"f565bddb017b5faa18fb779ad6ccba28d76b077b\",\"best_bid\":\"0.07\",\"best_ask\":\"0.08\"}],\"timestamp\":\"1786689925888\",\"event_type\":\"price_change\"}"}
{"recv_ts": 1786689925981944, "venue": "polymarket", "raw": "{\"market\":\"0x6bd56627aa21311850825edb27e53434a0e17a4f782be0086bc07f71eee00d0d\",\"price_changes\":[{\"asset_id\":\"87073899845581463485186346288398658568334162612963837182986759797304993556208\",\"price\":\"0.93\",\"size\":\"136122.66\",\"side\":\"SELL\",\"hash\":\"b03808bccc7d142e00f6ef1cd39efa32048d0ff1\",\"best_bid\":\"0.92\",\"best_ask\":\"0.93\"},{\"asset_id\":\"350977769852917329387037893294763093471844346281449484439085576212613048126\",\"price\":\"0.07\",\"size\":\"136122.66\",\"side\":\"BUY\",\"hash\":\"e5236006db15d92a2273e9bea615c84851f675eb\",\"best_bid\":\"0.07\",\"best_ask\":\"0.08\"}],\"timestamp\":\"1786689925973\",\"event_type\":\"price_change\"}"}
{"recv_ts": 1786689927011282, "venue": "polymarket", "raw": "{\"market\":\"0xd595eb9b81885ff018738300c79047e3ec89e87294424f57a29a7fa9162bf116\",\"price_changes\":[{\"asset_id\":\"57216272564529548464686463691236811991956032201293786790337952253964682584376\",\"price\":\"0.2\",\"size\":\"0\",\"side\":\"BUY\",\"hash\":\"7b880a0cccc53fd0ce191552406a3b53b3d8c799\",\"best_bid\":\"0.963\",\"best_ask\":\"0.964\"},{\"asset_id\":\"5161623255678193352839985156330393796378434470119114669671615782853260939535\",\"price\":\"0.8\",\"size\":\"0\",\"side\":\"SELL\",\"hash\":\"69198df1c1ad431a1cbbe8769b2cd86d9fdaf55c\",\"best_bid\":\"0.036\",\"best_ask\":\"0.037\"}],\"timestamp\":\"1786689927001\",\"event_type\":\"price_change\"}"}
{"recv_ts": 1786689927012026, "venue": "polymarket", "raw": "{\"market\":\"0xd595eb9b81885ff018738300c79047e3ec89e87294424f57a29a7fa9162bf116\",\"price_changes\":[{\"asset_id\":\"57216272564529548464686463691236811991956032201293786790337952253964682584376\",\"price\":\"0.4\",\"size\":\"88\",\"side\":\"BUY\",\"hash\":\"7b880a0cccc53fd0ce191552406a3b53b3d8c799\",\"best_bid\":\"0.963\",\"best_ask\":\"0.964\"},{\"asset_id\":\"5161623255678193352839985156330393796378434470119114669671615782853260939535\",\"price\":\"0.6\",\"size\":\"88\",\"side\":\"SELL\",\"hash\":\"69198df1c1ad431a1cbbe8769b2cd86d9fdaf55c\",\"best_bid\":\"0.036\",\"best_ask\":\"0.037\"}],\"timestamp\":\"1786689927001\",\"event_type\":\"price_change\"}"}
{"recv_ts": 1786689927012462, "venue": "polymarket", "raw": "{\"market\":\"0xd595eb9b81885ff018738300c79047e3ec89e87294424f57a29a7fa9162bf116\",\"price_changes\":[{\"asset_id\":\"57216272564529548464686463691236811991956032201293786790337952253964682584376\",\"price\":\"0.3\",\"size\":\"354\",\"side\":\"BUY\",\"hash\":\"20a9653ab00455aa53b989560fc5dd5913d91ef7\",\"best_bid\":\"0.963\",\"best_ask\":\"0.964\"},{\"asset_id\":\"5161623255678193352839985156330393796378434470119114669671615782853260939535\",\"price\":\"0.7\",\"size\":\"354\",\"side\":\"SELL\",\"hash\":\"53265d4a60a969a454b037b1a892b35411f27917\",\"best_bid\":\"0.036\",\"best_ask\":\"0.037\"}],\"timestamp\":\"1786689927003\",\"event_type\":\"price_change\"}"}
