{"recv_ts": 1786689747262489, "venue": "polymarket", "raw": "[{\"market\":\"0x747dc809fb79e1b05be09c42d6179459a58de2ef3e40f02484a4e1260f741f75\",\"asset_id\":\"107505882767731489358349912513945399560393482969656700824895970500493757150417\",\"timestamp\":\"1786689743864\",\"hash\":\"45e3f2f2bb44698604d658b6e802c7ee1056962d\",\"bids\":[{\"price\":\"0.01\",\"size\":\"1052481.46\"},{\"price\":\"0.02\",\"size\":\"323815.71\"},{\"price\":\"0.03\",\"size\":\"355611.26\"},{\"price\":\"0.04\",\"size\":\"322661.46\"}],\"asks\":[{\"price\":\"0.99\",\"size\":\"6805.16\"},{\"price\":\"0.98\",\"size\":\"2429.55\"},{\"price\":\"0.97\",\"size\":\"4338.76\"},{\"price\":\"0.96\",\"size\":\"518\"},{\"price\":\"0.95\",\"size\":\"2300\"},{\"price\":\"0.93\",\"size\":\"1866.72\"},{\"price\":\"0.92\",\"size\":\"128\"},{\"price\":\"0.91\",\"size\":\"5.47\"},{\"price\":\"0.9\",\"size\":\"16301.03\"},{\"price\":\"0.89\",\"size\":\"909.09\"},{\"price\":\"0.86\",\"size\":\"25678.57\"},{\"price\":\"0.84\",\"size\":\"1064\"},{\"price\":\"0.83\",\"size\":\"657\"},{\"price\":\"0.81\",\"size\":\"526.31\"},{\"price\":\"0.8\",\"size\":\"14900\"},{\"price\":\"0.77\",\"size\":\"500\"},{\"price\":\"0.76\",\"size\":\"986.66\"},{\"price\":\"0.75\",\"size\":\"27.77\"},{\"price\":\"0.72\",\"size\":\"36.42\"},{\"price\":\"0.71\",\"size\":\"327.58\"},{\"price\":\"0.7\",\"size\":\"9200\"},{\"price\":\"0.68\",\"size\":\"32\"},{\"price\":\"0.66\",\"size\":\"271.7\"},{\"price\":\"0.64\",\"size\":\"300\"},{\"price\":\"0.62\",\"size\":\"223.68\"},{\"price\":\"0.6\",\"size\":\"5638\"},{\"price\":\"0.59\",\"size\":\"84\"},{\"price\":\"0.58\",\"size\":\"83\"},{\"price\":\"0.57\",\"size\":\"174.41\"},{\"price\":\"0.56\",\"size\":\"200\"},{\"price\":\"0.55\",\"size\":\"45\"},{\"price\":\"0.52\",\"size\":\"145.83\"},{\"price\":\"0.5\",\"size\":\"2938.5\"},{\"price\":\"0.49\",\"size\":\"380\"},{\"price\":\"0.48\",\"size\":\"6\"},{\"price\":\"0.47\",\"size\":\"422.64\"},{\"price\":\"0.46\",\"size\":\"400\"},{\"price\":\"0.45\",\"size\":\"555.55\"},{\"price\":\"0.44\",\"size\":\"11.36\"},{\"price\":\"0.43\",\"size\":\"200\"},{\"price\":\"0.42\",\"size\":\"308.26\"},{\"price\":\"0.41\",\"size\":\"58.82\"},{\"price\":\"0.4\",\"size\":\"803\"},{\"price\":\"0.39\",\"size\":\"200\"},{\"price\":\"0.37\",\"size\":\"50\"},{\"price\":\"0.36\",\"size\":\"22.94\"},{\"price\":\"0.35\",\"size\":\"785\"},{\"price\":\"0.34\",\"size\":\"1000\"},{\"price\":\"0.33\",\"size\":\"400\"},{\"price\":\"0.32\",\"size\":\"91.66\"},{\"price\":\"0.31\",\"size\":\"735.63\"},{\"price\":\"0.3\",\"size\":\"312\"},{\"price\":\"0.29\",\"size\":\"100\"},{\"price\":\"0.27\",\"size\":\"450\"},{\"price\":\"0.26\",\"size\":\"30\"},{\"price\":\"0.25\",\"size\":\"1542.28\"},{\"price\":\"0.23\",\"size\":\"222.72\"},{\"price\":\"0.22\",\"size\":\"11\"},{\"price\":\"0.21\",\"size\":\"794.22\"},{\"price\":\"0.2\",\"size\":\"116891.1\"},{\"price\":\"0.19\",\"size\":\"68254.91\"},{\"price\":\"0.18\",\"size\":\"2383.62\"},{\"price\":\"0.17\",\"size\":\"200\"},{\"price\":\"0.16\",\"size\":\"271.43\"},{\"price\":\"0.15\",\"size\":\"7424.22\"},{\"price\":\"0.14\",\"size\":\"11135.84\"},{\"price\":\"0.13\",\"size\":\"1454.48\"},{\"price\":\"0.12\",\"size\":\"3796.46\"},{\"price\":\"0.11\",\"size\":\"12763.27\"},{\"price\":\"0.1\",\"size\":\"22931.43\"},{\"price\":\"0.09\",\"size\":\"20975.48\"},{\"price\":\"0.08\",\"size\":\"12916.1\"},{\"price\":\"0.07\",\"size\":\"92131.28\"},{\"price\":\"0.06\",\"size\":\"122527.12\"},{\"price\":\"0.05\",\"size\":\"268648.35\"}],\"tick_size\":\"0.01\",\"event_type\":\"book\",\"last_trade_price\":\"0.960\"},{\"market\":\"0xd595eb9b81885ff018738300c79047e3ec89e87294424f57a29a7fa9162bf116\",\"asset_id\":\"5161623255678193352839985156330393796378434470119114669671615782853260939535\",\"timestamp\":\"1786689744966\",\"hash\":\"a0f7ccaf890c7a4bf69083c3b0c4db4e976b33c2\",\"bids\":[{\"price\":\"0.001\",\"size\":\"269747.77\"},{\"price\":\"0.002\",\"size\":\"335461.09\"},{\"price\":\"0.003\",\"size\":\"21094.97\"},{\"price\":\"0.004\",\"size\":\"107624.3\"},{\"price\":\"0.005\",\"size\":\"31889.33\"},{\"price\":\"0.006\",\"size\":\"71155.4\"},{\"price\":\"0.007\",\"size\":\"20159.83\"},{\"price\":\"0.008\",\"size\":\"17533\"},{\"price\":\"0.009\",\"size\":\"7877.7\"},{\"price\":\"0.01\",\"size\":\"11404.52\"},{\"price\":\"0.011\",\"size\":\"7009\"},{\"price\":\"0.012\",\"size\":\"933.3\"},{\"price\":\"0.013\",\"size\":\"100\"},{\"price\":\"0.014\",\"size\":\"30100\"},{\"price\":\"0.015\",\"size\":\"24793.12\"},{\"price\":\"0.016\",\"size\":\"585.52\"},{\"price\":\"0.017\",\"size\":\"625.67\"},{\"price\":\"0.018\",\"size\":\"18069.05\"},{\"price\":\"0.019\",\"size\":\"100\"},{\"price\":\"0.02\",\"size\":\"1350\"},{\"price\":\"0.021\",\"size\":\"1688.5\"},{\"price\":\"0.022\",\"size\":\"12100\"},{\"price\":\"0.023\",\"size\":\"8100\"},{\"price\":\"0.024\",\"size\":\"1184\"},{\"price\":\"0.025\",\"size\":\"100\"},{\"price\":\"0.026\",\"size\":\"100\"},{\"price\":\"0.027\",\"size\":\"1894.95\"},{\"price\":\"0.028\",\"size\":\"499.99\"},{\"price\":\"0.029\",\"size\":\"3620.6\"},{\"price\":\"0.03\",\"size\":\"5224.92\"},{\"price\":\"0.031\",\"size\":\"6100\"},{\"price\":\"0.032\",\"size\":\"4671.78\"},{\"price\":\"0.033\",\"size\":\"1475.04\"},{\"price\":\"0.034\",\"size\":\"300\"},{\"price\":\"0.035\",\"size\":\"1124.17\"},{\"price\":\"0.036\",\"size\":\"16543.87\"}],\"asks\":[{\"price\":\"0.999\",\"size\":\"2628339.98\"},{\"price\":\"0.998\",\"size\":\"1032347.14\"},{\"price\":\"0.997\",\"size\":\"20685.8\"},{\"price\":\"0.996\",\"size\":\"65536\"},{\"price\":\"0.995\",\"size\":\"60006.79\"},{\"price\":\"0.994\",\"size\":\"90000\"},{\"price\":\"0.992\",\"size\":\"16384\"},{\"price\":\"0.991\",\"size\":\"40000\"},{\"price\":\"0.99\",\"size\":\"220.76\"},{\"price\":\"0.984\",\"size\":\"8192\"},{\"price\":\"0.979\",\"size\":\"20000\"},{\"price\":\"0.978\",\"size\":\"9.26\"},{\"price\":\"0.968\",\"size\":\"4096\"},{\"price\":\"0.95\",\"size\":\"29460\"},{\"price\":\"0.949\",\"size\":\"33000\"},{\"price\":\"0.948\",\"size\":\"800\"},{\"price\":\"0.936\",\"size\":\"2048\"},{\"price\":\"0.932\",\"size\":\"6000\"},{\"price\":\"0.909\",\"size\":\"9000\"},{\"price\":\"0.9\",\"size\":\"16225\"},{\"price\":\"0.899\",\"size\":\"6.28\"},{\"price\":\"0.872\",\"size\":\"512\"},{\"price\":\"0.86\",\"size\":\"12214.28\"},{\"price\":\"0.81\",\"size\":\"9473.68\"},{\"price\":\"0.809\",\"size\":\"6000\"},{\"price\":\"0.8\",\"size\":\"9000\"},{\"price\":\"0.76\",\"size\":\"7500\"},{\"price\":\"0.757\",\"size\":\"6000\"},{\"price\":\"0.749\",\"size\":\"1000\"},{\"price\":\"0.744\",\"size\":\"256\"},{\"price\":\"0.71\",\"size\":\"5896.55\"},{\"price\":\"0.7\",\"size\":\"6020\"},{\"price\":\"0.66\",\"size\":\"4764.7\"},{\"price\":\"0.61\",\"size\":\"3923.07\"},{\"price\":\"0.6\",\"size\":\"4088\"},{\"price\":\"0.599\",\"size\":\"9000\"},{\"price\":\"0.59\",\"size\":\"27.5\"},{\"price\":\"0.57\",\"size\":\"3139.53\"},{\"price\":\"0.52\",\"size\":\"2625\"},{\"price\":\"0.5\",\"size\":\"2579.77\"},{\"price\":\"0.488\",\"size\":\"128\"},{\"price\":\"0.47\",\"size\":\"4707.54\"},{\"price\":\"0.462\",\"size\":\"82.08\"},{\"price\":\"0.42\",\"size\":\"1706.89\"},{\"price\":\"0.41\",\"size\":\"500\"},{\"price\":\"0.4\",\"size\":\"522\"},{\"price\":\"0.399\",\"size\":\"999.97\"},{\"price\":\"0.39\",\"size\":\"27.5\"},{\"price\":\"0.362\",\"size\":\"22.49\"},{\"price\":\"0.35\",\"size\":\"330\"},{\"price\":\"0.34\",\"size\":\"7\"},{\"price\":\"0.32\",\"size\":\"400\"},{\"price\":\"0.3\",\"size\":\"32\"},{\"price\":\"0.26\",\"size\":\"500\"},{\"price\":\"0.25\",\"size\":\"8496.84\"},{\"price\":\"0.24\",\"size\":\"400\"},{\"price\":\"0.23\",\"size\":\"300\"},{\"price\":\"0.229\",\"size\":\"500\"},{\"price\":\"0.22\",\"size\":\"450\"},{\"price\":\"0.21\",\"size\":\"4147.5\"},{\"price\":\"0.2\",\"size\":\"2637.94\"},{\"price\":\"0.199\",\"size\":\"1524.97\"},{\"price\":\"0.197\",\"size\":\"38.46\"},{\"price\":\"0.19\",\"size\":\"510\"},{\"price\":\"0.18\",\"size\":\"300\"},{\"price\":\"0.16\",\"size\":\"400\"},{\"price\":\"0.155\",\"size\":\"60\"},{\"price\":\"0.15\",\"size\":\"4550.76\"},{\"price\":\"0.149\",\"size\":\"100\"},{\"price\":\"0.14\",\"size\":\"400\"},{\"price\":\"0.139\",\"size\":\"3000\"},{\"price\":\"0.12\",\"size\":\"8.84\"},{\"price\":\"0.103\",\"size\":\"111.48\"},{\"price\":\"0.098\",\"size\":\"3000\"},{\"price\":\"0.097\",\"size\":\"1000\"},{\"price\":\"0.093\",\"size\":\"110.25\"},{\"price\":\"0.088\",\"size\":\"205\"},{\"price\":\"0.085\",\"size\":\"300\"},{\"price\":\"0.083\",\"size\":\"109.05\"},{\"price\":\"0.08\",\"size\":\"32500\"},{\"price\":\"0.079\",\"size\":\"12850\"},{\"price\":\"0.071\",\"size\":\"5.38\"},{\"price\":\"0.07\",\"size\":\"100\"},{\"price\":\"0.069\",\"size\":\"16000\"},{\"price\":\"0.062\",\"size\":\"766.84\"},{\"price\":\"0.061\",\"size\":\"5000\"},{\"price\":\"0.06\",\"size\":\"109.99\"},{\"price\":\"0.059\",\"size\":\"10000\"},{\"price\":\"0.057\",\"size\":\"248.04\"},{\"price\":\"0.056\",\"size\":\"481.65\"},{\"price\":\"0.055\",\"size\":\"10010\"},{\"price\":\"0.053\",\"size\":\"381.74\"},{\"price\":\"0.051\",\"size\":\"100\"},{\"price\":\"0.05\",\"size\":\"115\"},{\"price\":\"0.049\",\"size\":\"1100\"},{\"price\":\"0.048\",\"size\":\"5100\"},{\"price\":\"0.047\",\"size\":\"24.85\"},{\"price\":\"0.046\",\"size\":\"22000\"},{\"price\":\"0.045\",\"size\":\"695\"},{\"price\":\"0.044\",\"size\":\"2119.99\"},{\"price\":\"0.043\",\"size\":\"520\"},{\"price\":\"0.042\",\"size\":\"100\"},{\"price\":\"0.041\",\"size\":\"330\"},{\"price\":\"0.04\",\"size\":\"115\"},{\"price\":\"0.039\",\"size\":\"41133.18\"},{\"price\":\"0.038\",\"size\":\"1668.64\"},{\"price\":\"0.037\",\"size\":\"12970.64\"}],\"tick_size\":\"0.001\",\"event_type\":\"book\",\"last_trade_price\":\"0.037\"},{\"market\":\"0x60c2c085ee8c16bc8f2419739a94971d4c9d00f637ead10fc0f540afa1be64e8\",\"asset_id\":\"105426373826369935595603860663411604941599130211176020843036778867927711117332\",\"timestamp\":\"1786689743594\",\"hash\":\"eea9d8ec0b87c292e08b7cb784fd2c0818c7f321\",\"bids\":[{\"price\":\"0.001\",\"size\":\"5789306.39\"},{\"price\":\"0.002\",\"size\":\"722683.31\"},{\"price\":\"0.003\",\"size\":\"216289.91\"},{\"price\":\"0.004\",\"size\":\"171325\"},{\"price\":\"0.005\",\"size\":\"104005.68\"},{\"price\":\"0.006\",\"size\":\"72053.37\"},{\"price\":\"0.007\",\"size\":\"64868.47\"},{\"price\":\"0.008\",\"size\":\"48749\"},{\"price\":\"0.009\",\"size\":\"1043177.74\"},{\"price\":\"0.01\",\"size\":\"152406.93\"},{\"price\":\"0.011\",\"size\":\"53957.82\"},{\"price\":\"0.012\",\"size\":\"19413.59\"},{\"price\":\"0.013\",\"size\":\"12557.11\"},{\"price\":\"0.014\",\"size\":\"49240\"},{\"price\":\"0.015\",\"size\":\"19192.36\"},{\"price\":\"0.016\",\"size\":\"5125\"},{\"price\":\"0.017\",\"size\":\"41361.44\"},{\"price\":\"0.018\",\"size\":\"3207\"},{\"price\":\"0.019\",\"size\":\"2019.27\"},{\"price\":\"0.02\",\"size\":\"9016.06\"}],\"asks\":[{\"price\":\"0.999\",\"size\":\"11009215.14\"},{\"price\":\"0.998\",\"size\":\"11026.08\"},{\"price\":\"0.997\",\"size\":\"10735.64\"},{\"price\":\"0.996\",\"size\":\"120000\"},{\"price\":\"0.995\",\"size\":\"8.82\"},{\"price\":\"0.99\",\"size\":\"21393.37\"},{\"price\":\"0.989\",\"size\":\"61500\"},{\"price\":\"0.988\",\"size\":\"6.78\"},{\"price\":\"0.979\",\"size\":\"500\"},{\"price\":\"0.97\",\"size\":\"16000.96\"},{\"price\":\"0.969\",\"size\":\"31048.83\"},{\"price\":\"0.967\",\"size\":\"1047.89\"},{\"price\":\"0.966\",\"size\":\"5.68\"},{\"price\":\"0.95\",\"size\":\"31362.5\"},{\"price\":\"0.949\",\"size\":\"30000\"},{\"price\":\"0.94\",\"size\":\"71.42\"},{\"price\":\"0.9\",\"size\":\"66250\"},{\"price\":\"0.899\",\"size\":\"29999.99\"},{\"price\":\"0.898\",\"size\":\"800\"},{\"price\":\"0.89\",\"size\":\"1968.74\"},{\"price\":\"0.88\",\"size\":\"450\"},{\"price\":\"0.879\",\"size\":\"5.05\"},{\"price\":\"0.87\",\"size\":\"21.05\"},{\"price\":\"0.86\",\"size\":\"21049.11\"},{\"price\":\"0.85\",\"size\":\"13400\"},{\"price\":\"0.849\",\"size\":\"9000\"},{\"price\":\"0.84\",\"size\":\"499.98\"},{\"price\":\"0.83\",\"size\":\"16580.88\"},{\"price\":\"0.8\",\"size\":\"36780.12\"},{\"price\":\"0.799\",\"size\":\"10423.82\"},{\"price\":\"0.78\",\"size\":\"4999.9\"},{\"price\":\"0.77\",\"size\":\"11141.3\"},{\"price\":\"0.76\",\"size\":\"7500\"},{\"price\":\"0.759\",\"size\":\"9000\"},{\"price\":\"0.75\",\"size\":\"2512.5\"},{\"price\":\"0.74\",\"size\":\"6899.04\"},{\"price\":\"0.73\",\"size\":\"346.21\"},{\"price\":\"0.71\",\"size\":\"11640.08\"},{\"price\":\"0.7\",\"size\":\"18876.63\"},{\"price\":\"0.699\",\"size\":\"9000\"},{\"price\":\"0.691\",\"size\":\"500\"},{\"price\":\"0.68\",\"size\":\"4404.3\"},{\"price\":\"0.66\",\"size\":\"4764.7\"},{\"price\":\"0.65\",\"size\":\"13660.71\"},{\"price\":\"0.62\",\"size\":\"3371.71\"},{\"price\":\"0.61\",\"size\":\"3923.07\"},{\"price\":\"0.6\",\"size\":\"11885.7\"},{\"price\":\"0.59\",\"size\":\"2746.66\"},{\"price\":\"0.56\",\"size\":\"3068.18\"},{\"price\":\"0.55\",\"size\":\"10012.5\"},{\"price\":\"0.54\",\"size\":\"7000\"},{\"price\":\"0.51\",\"size\":\"2571.42\"},{\"price\":\"0.5\",\"size\":\"6684.53\"},{\"price\":\"0.48\",\"size\":\"1200\"},{\"price\":\"0.47\",\"size\":\"575.25\"},{\"price\":\"0.46\",\"size\":\"9139.04\"},{\"price\":\"0.459\",\"size\":\"500\"},{\"price\":\"0.45\",\"size\":\"1119.98\"},{\"price\":\"0.44\",\"size\":\"110\"},{\"price\":\"0.43\",\"size\":\"105\"},{\"price\":\"0.42\",\"size\":\"120\"},{\"price\":\"0.41\",\"size\":\"1767.96\"},{\"price\":\"0.4\",\"size\":\"4499.79\"},{\"price\":\"0.39\",\"size\":\"3085\"},{\"price\":\"0.38\",\"size\":\"752.77\"},{\"price\":\"0.37\",\"size\":\"70\"},{\"price\":\"0.36\",\"size\":\"865\"},{\"price\":\"0.35\",\"size\":\"3676.35\"},{\"price\":\"0.34\",\"size\":\"1273.55\"},{\"price\":\"0.33\",\"size\":\"2051.99\"},{\"price\":\"0.32\",\"size\":\"70847.99\"},{\"price\":\"0.319\",\"size\":\"7884\"},{\"price\":\"0.31\",\"size\":\"59\"},{\"price\":\"0.3\",\"size\":\"8726.03\"},{\"price\":\"0.299\",\"size\":\"484.6\"},{\"price\":\"0.293\",\"size\":\"500\"},{\"price\":\"0.29\",\"size\":\"11059.5\"},{\"price\":\"0.28\",\"size\":\"5058\"},{\"price\":\"0.27\",\"size\":\"7430\"},{\"price\":\"0.269\",\"size\":\"4509.82\"},{\"price\":\"0.26\",\"size\":\"6096\"},{\"price\":\"0.259\",\"size\":\"5000\"},{\"price\":\"0.25\",\"size\":\"2698.5\"},{\"price\":\"0.249\",\"size\":\"20385.01\"},{\"price\":\"0.24\",\"size\":\"3371.55\"},{\"price\":\"0.239\",\"size\":\"3333\"},{\"price\":\"0.23\",\"size\":\"1282\"},{\"price\":\"0.22\",\"size\":\"2280\"},{\"price\":\"0.219\",\"size\":\"2222\"},{\"price\":\"0.21\",\"size\":\"1645\"},{\"price\":\"0.2\",\"size\":\"13548.01\"},{\"price\":\"0.199\",\"size\":\"9520.8\"},{\"price\":\"0.198\",\"size\":\"800\"},{\"price\":\"0.194\",\"size\":\"500\"},{\"price\":\"0.19\",\"size\":\"1455\"},{\"price\":\"0.18\",\"size\":\"806.1\"},{\"price\":\"0.179\",\"size\":\"13296.68\"},{\"price\":\"0.17\",\"size\":\"1000\"},{\"price\":\"0.16\",\"size\":\"2570.64\"},{\"price\":\"0.159\",\"size\":\"2222\"},{\"price\":\"0.15\",\"size\":\"3089.2\"},{\"price\":\"0.149\",\"size\":\"9771.2\"},{\"price\":\"0.14\",\"size\":\"74.99\"},{\"price\":\"0.139\",\"size\":\"4444\"},{\"price\":\"0.13\",\"size\":\"540\"},{\"price\":\"0.12\",\"size\":\"1112.14\"},{\"price\":\"0.11\",\"size\":\"335.4\"},{\"price\":\"0.103\",\"size\":\"39\"},{\"price\":\"0.1\",\"size\":\"26363.1\"},{\"price\":\"0.099\",\"size\":\"999\"},{\"price\":\"0.095\",\"size\":\"402\"},{\"price\":\"0.09\",\"size\":\"3638.58\"},{\"price\":\"0.08\",\"size\":\"2840\"},{\"price\":\"0.079\",\"size\":\"10\"},{\"price\":\"0.072\",\"size\":\"1000\"},{\"price\":\"0.071\",\"size\":\"1000\"},{\"price\":\"0.07\",\"size\":\"1910\"},{\"price\":\"0.069\",\"size\":\"9852\"},{\"price\":\"0.067\",\"size\":\"2000\"},{\"price\":\"0.065\",\"size\":\"1999.98\"},{\"price\":\"0.06\",\"size\":\"2500\"},{\"price\":\"0.059\",\"size\":\"2000\"},{\"price\":\"0.056\",\"size\":\"3000\"},{\"price\":\"0.055\",\"size\":\"2293.09\"},{\"price\":\"0.052\",\"size\":\"400\"},{\"price\":\"0.051\",\"size\":\"821.49\"},{\"price\":\"0.05\",\"size\":\"152.05\"},{\"price\":\"0.049\",\"size\":\"3318.68\"},{\"price\":\"0.048\",\"size\":\"3000\"},{\"price\":\"0.047\",\"size\":\"614.37\"},{\"price\":\"0.046\",\"size\":\"11703.78\"},{\"price\":\"0.045\",\"size\":\"4279.76\"},{\"price\":\"0.044\",\"size\":\"26946.19\"},{\"price\":\"0.043\",\"size\":\"5409.56\"},{\"price\":\"0.042\",\"size\":\"19000\"},{\"price\":\"0.041\",\"size\":\"10898.83\"},{\"price\":\"0.04\",\"size\":\"26030.22\"},{\"price\":\"0.039\",\"size\":\"5038.42\"},{\"price\":\"0.038\",\"size\":\"2728.11\"},{\"price\":\"0.037\",\"size\":\"1434.29\"},{\"price\":\"0.036\",\"size\":\"123557.63\"},{\"price\":\"0.035\",\"size\":\"16300.4\"},{\"price\":\"0.034\",\"size\":\"17891.14\"},{\"price\":\"0.033\",\"size\":\"4844\"},{\"price\":\"0.032\",\"size\":\"10266.88\"},{\"price\":\"0.031\",\"size\":\"4675.16\"},{\"price\":\"0.03\",\"size\":\"800.57\"},{\"price\":\"0.029\",\"size\":\"11503.32\"},{\"price\":\"0.028\",\"size\":\"300\"},{\"price\":\"0.027\",\"size\":\"14566.87\"},{\"price\":\"0.026\",\"size\":\"8517.74\"},{\"price\":\"0.025\",\"size\":\"4517\"},{\"price\":\"0.024\",\"size\":\"5665.31\"},{\"price\":\"0.023\",\"size\":\"609.88\"},{\"price\":\"0.022\",\"size\":\"1999.81\"},{\"price\":\"0.021\",\"size\":\"366.47\"}],\"tick_size\":\"0.001\",\"event_type\":\"book\",\"last_trade_price\":\"0.980\"},{\"market\":\"0x6bd56627aa21311850825edb27e53434a0e17a4f782be0086bc07f71eee00d0d\",\"asset_id\":\"87073899845581463485186346288398658568334162612963837182986759797304993556208\",\"timestamp\":\"1786689746199\",\"hash\":\"ee10d9ce8d1e81aae96168341a6e1f1eb16b2ef4\",\"bids\":[{\"price\":\"0.01\",\"size\":\"156606.14\"},{\"price\":\"0.02\",\"size\":\"17542.3\"},{\"price\":\"0.03\",\"size\":\"800\"},{\"price\":\"0.05\",\"size\":\"20316.11\"},{\"price\":\"0.06\",\"size\":\"9.37\"},{\"price\":\"0.09\",\"size\":\"12020\"},{\"price\":\"0.1\",\"size\":\"13150\"},{\"price\":\"0.11\",\"size\":\"1818.18\"},{\"price\":\"0.12\",\"size\":\"218.18\"},{\"price\":\"0.14\",\"size\":\"8142.85\"},{\"price\":\"0.15\",\"size\":\"1833.33\"},{\"price\":\"0.19\",\"size\":\"6315.78\"},{\"price\":\"0.2\",\"size\":\"15350\"},{\"price\":\"0.23\",\"size\":\"5217.39\"},{\"price\":\"0.25\",\"size\":\"4900\"},{\"price\":\"0.28\",\"size\":\"4071.42\"},{\"price\":\"0.29\",\"size\":\"12047.41\"},{\"price\":\"0.3\",\"size\":\"10666\"},{\"price\":\"0.33\",\"size\":\"12837.11\"},{\"price\":\"0.35\",\"size\":\"17500\"},{\"price\":\"0.36\",\"size\":\"7465.28\"},{\"price\":\"0.37\",\"size\":\"2756.75\"},{\"price\":\"0.38\",\"size\":\"7708.87\"},{\"price\":\"0.39\",\"size\":\"7275.64\"},{\"price\":\"0.4\",\"size\":\"6250\"},{\"price\":\"0.42\",\"size\":\"15541.6\"},{\"price\":\"0.43\",\"size\":\"5000\"},{\"price\":\"0.44\",\"size\":\"999.99\"},{\"price\":\"0.47\",\"size\":\"2787.23\"},{\"price\":\"0.49\",\"size\":\"500\"},{\"price\":\"0.5\",\"size\":\"2674.62\"},{\"price\":\"0.51\",\"size\":\"14928.16\"},{\"price\":\"0.52\",\"size\":\"3000\"},{\"price\":\"0.56\",\"size\":\"1178.57\"},{\"price\":\"0.58\",\"size\":\"5000\"},{\"price\":\"0.6\",\"size\":\"103895.18\"},{\"price\":\"0.61\",\"size\":\"13000.01\"},{\"price\":\"0.62\",\"size\":\"441\"},{\"price\":\"0.63\",\"size\":\"687.5\"},{\"price\":\"0.64\",\"size\":\"3499.81\"},{\"price\":\"0.66\",\"size\":\"16.66\"},{\"price\":\"0.68\",\"size\":\"499.99\"},{\"price\":\"0.7\",\"size\":\"2270.36\"},{\"price\":\"0.71\",\"size\":\"200\"},{\"price\":\"0.73\",\"size\":\"1000\"},{\"price\":\"0.75\",\"size\":\"2020\"},{\"price\":\"0.76\",\"size\":\"450\"},{\"price\":\"0.77\",\"size\":\"920\"},{\"price\":\"0.78\",\"size\":\"820\"},{\"price\":\"0.79\",\"size\":\"2120\"},{\"price\":\"0.8\",\"size\":\"8257.29\"},{\"price\":\"0.81\",\"size\":\"6262.98\"},{\"price\":\"0.82\",\"size\":\"1243\"},{\"price\":\"0.83\",\"size\":\"10057.82\"},{\"price\":\"0.84\",\"size\":\"2668.5\"},{\"price\":\"0.85\",\"size\":\"4843\"},{\"price\":\"0.86\",\"size\":\"25983.92\"},{\"price\":\"0.87\",\"size\":\"6257.23\"},{\"price\":\"0.88\",\"size\":\"6841.68\"},{\"price\":\"0.89\",\"size\":\"29570\"},{\"price\":\"0.9\",\"size\":\"88175.97\"},{\"price\":\"0.91\",\"size\":\"122650.77\"},{\"price\":\"0.92\",\"size\":\"269218.63\"}],\"asks\":[{\"price\":\"0.99\",\"size\":\"3149725.72\"},{\"price\":\"0.98\",\"size\":\"70301.2\"},{\"price\":\"0.97\",\"size\":\"37268.67\"},{\"price\":\"0.96\",\"size\":\"178251.33\"},{\"price\":\"0.95\",\"size\":\"241275.08\"},{\"price\":\"0.94\",\"size\":\"219525.85\"},{\"price\":\"0.93\",\"size\":\"136122.66\"}],\"tick_size\":\"0.01\",\"event_type\":\"book\",\"last_trade_price\":\"0.080\"},{\"market\":\"0xbb4d51e6364066d92eb6f9b8413dd7193de70966736044463b205834805a1f3b\",\"asset_id\":\"10991849228756847439673778874175365458450913336396982752046655649803657501964\",\"timestamp\":\"1786689732038\",\"hash\":\"b3e490afab67543aa99225b5ec20eb12462c0199\",\"bids\":[{\"price\":\"0.01\",\"size\":\"1177748.4\"},{\"price\":\"0.02\",\"size\":\"71556.69\"},{\"price\":\"0.03\",\"size\":\"254075.97\"},{\"price\":\"0.04\",\"size\":\"479216.56\"},{\"price\":\"0.05\",\"size\":\"457272.25\"},{\"price\":\"0.06\",\"size\":\"273273.61\"}],\"asks\":[{\"price\":\"0.99\",\"size\":\"219340.17\"},{\"price\":\"0.98\",\"size\":\"205148.04\"},{\"price\":\"0.97\",\"size\":\"12664.48\"},{\"price\":\"0.96\",\"size\":\"1920.33\"},{\"price\":\"0.95\",\"size\":\"20936.76\"},{\"price\":\"0.94\",\"size\":\"686.28\"},{\"price\":\"0.92\",\"size\":\"64\"},{\"price\":\"0.91\",\"size\":\"12405.43\"},{\"price\":\"0.9\",\"size\":\"81656.86\"},{\"price\":\"0.89\",\"size\":\"11099.99\"},{\"price\":\"0.87\",\"size\":\"281.25\"},{\"price\":\"0.86\",\"size\":\"8142.85\"},{\"price\":\"0.85\",\"size\":\"185\"},{\"price\":\"0.84\",\"size\":\"32\"},{\"price\":\"0.82\",\"size\":\"654\"},{\"price\":\"0.81\",\"size\":\"6315.78\"},{\"price\":\"0.8\",\"size\":\"43602.27\"},{\"price\":\"0.79\",\"size\":\"177\"},{\"price\":\"0.77\",\"size\":\"5617.39\"},{\"price\":\"0.76\",\"size\":\"24\"},{\"price\":\"0.75\",\"size\":\"1725\"},{\"price\":\"0.73\",\"size\":\"27.5\"},{\"price\":\"0.72\",\"size\":\"4071.42\"},{\"price\":\"0.71\",\"size\":\"20.5\"},{\"price\":\"0.7\",\"size\":\"26499.33\"},{\"price\":\"0.69\",\"size\":\"200\"},{\"price\":\"0.68\",\"size\":\"26.25\"},{\"price\":\"0.67\",\"size\":\"3572.97\"},{\"price\":\"0.66\",\"size\":\"137.08\"},{\"price\":\"0.65\",\"size\":\"1200\"},{\"price\":\"0.64\",\"size\":\"10.25\"},{\"price\":\"0.63\",\"size\":\"240.27\"},{\"price\":\"0.62\",\"size\":\"2684.21\"},{\"price\":\"0.61\",\"size\":\"5800\"},{\"price\":\"0.6\",\"size\":\"19730.87\"},{\"price\":\"0.58\",\"size\":\"2152.28\"},{\"price\":\"0.56\",\"size\":\"200\"},{\"price\":\"0.55\",\"size\":\"1149.98\"},{\"price\":\"0.53\",\"size\":\"2187.23\"},{\"price\":\"0.52\",\"size\":\"267.2\"},{\"price\":\"0.51\",\"size\":\"50\"},{\"price\":\"0.5\",\"size\":\"13272.88\"},{\"price\":\"0.49\",\"size\":\"659.5\"},{\"price\":\"0.48\",\"size\":\"8833.25\"},{\"price\":\"0.46\",\"size\":\"195\"},{\"price\":\"0.45\",\"size\":\"810.27\"},{\"price\":\"0.44\",\"size\":\"36276.62\"},{\"price\":\"0.43\",\"size\":\"399.3\"},{\"price\":\"0.42\",\"size\":\"20209\"},{\"price\":\"0.41\",\"size\":\"32.78\"},{\"price\":\"0.4\",\"size\":\"410.35\"},{\"price\":\"0.39\",\"size\":\"20\"},{\"price\":\"0.38\",\"size\":\"1069.62\"},{\"price\":\"0.37\",\"size\":\"5\"},{\"price\":\"0.36\",\"size\":\"8\"},{\"price\":\"0.35\",\"size\":\"661.73\"},{\"price\":\"0.34\",\"size\":\"9720.45\"},{\"price\":\"0.33\",\"size\":\"590\"},{\"price\":\"0.3\",\"size\":\"25922.26\"},{\"price\":\"0.29\",\"size\":\"809.55\"},{\"price\":\"0.28\",\"size\":\"55\"},{\"price\":\"0.27\",\"size\":\"10\"},{\"price\":\"0.26\",\"size\":\"58.82\"},{\"price\":\"0.25\",\"size\":\"303.18\"},{\"price\":\"0.24\",\"size\":\"473.15\"},{\"price\":\"0.23\",\"size\":\"723.99\"},{\"price\":\"0.22\",\"size\":\"1304.76\"},{\"price\":\"0.21\",\"size\":\"220\"},{\"price\":\"0.2\",\"size\":\"5353.64\"},{\"price\":\"0.19\",\"size\":\"200\"},{\"price\":\"0.18\",\"size\":\"938.71\"},{\"price\":\"0.17\",\"size\":\"5524.53\"},{\"price\":\"0.16\",\"size\":\"1455.35\"},{\"price\":\"0.15\",\"size\":\"4932.56\"},{\"price\":\"0.14\",\"size\":\"1568.97\"},{\"price\":\"0.13\",\"size\":\"2483.5\"},{\"price\":\"0.12\",\"size\":\"2849.25\"},{\"price\":\"0.11\",\"size\":\"40444.04\"},{\"price\":\"0.1\",\"size\":\"27402.32\"},{\"price\":\"0.09\",\"size\":\"157892.46\"},{\"price\":\"0.08\",\"size\":\"181908.7\"},{\"price\":\"0.07\",\"size\":\"202743.09\"}],\"tick_size\":\"0.01\",\"event_type\":\"book\",\"last_trade_price\":\"0.930\"},{\"market\":\"0xd9fb1184af0064e5e34b129f5b79afa5a17b7e32f2953ab05efed82315fee6d4\",\"asset_id\":\"94559586571241563470235664821564670251180951772614764383113614156422396181162\",\"timestamp\":\"1786689747092\",\"hash\":\"33eb7947bf7160952321bc25cf220385e77b34af\",\"bids\":[{\"price\":\"0.001\",\"size\":\"11804648.6\"},{\"price\":\"0.002\",\"size\":\"1229962.64\"},{\"price\":\"0.003\",\"size\":\"795351.37\"},{\"price\":\"0.004\",\"size\":\"147291.26\"},{\"price\":\"0.005\",\"size\":\"1137459.31\"},{\"price\":\"0.006\",\"size\":\"81994.56\"},{\"price\":\"0.007\",\"size\":\"171368.22\"},{\"price\":\"0.008\",\"size\":\"103042.34\"},{\"price\":\"0.009\",\"size\":\"521099.69\"},{\"price\":\"0.01\",\"size\":\"1126639.04\"},{\"price\":\"0.011\",\"size\":\"185318.78\"},{\"price\":\"0.012\",\"size\":\"30452\"},{\"price\":\"0.013\",\"size\":\"3609.61\"},{\"price\":\"0.014\",\"size\":\"3621\"},{\"price\":\"0.015\",\"size\":\"30268.1\"},{\"price\":\"0.016\",\"size\":\"17924.41\"},{\"price\":\"0.017\",\"size\":\"8196.98\"},{\"price\":\"0.018\",\"size\":\"3020\"},{\"price\":\"0.019\",\"size\":\"21020\"},{\"price\":\"0.02\",\"size\":\"24822.18\"},{\"price\":\"0.021\",\"size\":\"14210\"},{\"price\":\"0.022\",\"size\":\"8875\"},{\"price\":\"0.023\",\"size\":\"28255.98\"},{\"price\":\"0.024\",\"size\":\"4721\"},{\"price\":\"0.025\",\"size\":\"56153.99\"},{\"price\":\"0.026\",\"size\":\"10273.96\"},{\"price\":\"0.027\",\"size\":\"12723.39\"},{\"price\":\"0.028\",\"size\":\"6871.15\"},{\"price\":\"0.029\",\"size\":\"1808.46\"},{\"price\":\"0.03\",\"size\":\"11766.73\"},{\"price\":\"0.031\",\"size\":\"9473.54\"},{\"price\":\"0.032\",\"size\":\"21517.27\"},{\"price\":\"0.033\",\"size\":\"30039.02\"},{\"price\":\"0.034\",\"size\":\"14472.12\"},{\"price\":\"0.035\",\"size\":\"55029.86\"},{\"price\":\"0.036\",\"size\":\"72598.77\"}],\"asks\":[{\"price\":\"0.999\",\"size\":\"145711.24\"},{\"price\":\"0.998\",\"size\":\"41295.53\"},{\"price\":\"0.997\",\"size\":\"60679.98\"},{\"price\":\"0.996\",\"size\":\"21391.05\"},{\"price\":\"0.994\",\"size\":\"2500\"},{\"price\":\"0.992\",\"size\":\"4096\"},{\"price\":\"0.991\",\"size\":\"5.2\"},{\"price\":\"0.99\",\"size\":\"10462.86\"},{\"price\":\"0.984\",\"size\":\"2048\"},{\"price\":\"0.98\",\"size\":\"9131.93\"},{\"price\":\"0.979\",\"size\":\"7.83\"},{\"price\":\"0.97\",\"size\":\"13017.5\"},{\"price\":\"0.968\",\"size\":\"1024\"},{\"price\":\"0.95\",\"size\":\"39800\"},{\"price\":\"0.949\",\"size\":\"800\"},{\"price\":\"0.94\",\"size\":\"16.99\"},{\"price\":\"0.936\",\"size\":\"512\"},{\"price\":\"0.93\",\"size\":\"10000\"},{\"price\":\"0.91\",\"size\":\"10060.98\"},{\"price\":\"0.9\",\"size\":\"28970\"},{\"price\":\"0.899\",\"size\":\"5.14\"},{\"price\":\"0.89\",\"size\":\"10000\"},{\"price\":\"0.889\",\"size\":\"70\"},{\"price\":\"0.872\",\"size\":\"128\"},{\"price\":\"0.87\",\"size\":\"10000\"},{\"price\":\"0.86\",\"size\":\"12214.28\"},{\"price\":\"0.85\",\"size\":\"10500\"},{\"price\":\"0.83\",\"size\":\"10000\"},{\"price\":\"0.81\",\"size\":\"19473.68\"},{\"price\":\"0.8\",\"size\":\"14255\"},{\"price\":\"0.79\",\"size\":\"10000\"},{\"price\":\"0.77\",\"size\":\"10000\"},{\"price\":\"0.76\",\"size\":\"7500\"},{\"price\":\"0.75\",\"size\":\"10000\"},{\"price\":\"0.744\",\"size\":\"64\"},{\"price\":\"0.73\",\"size\":\"10000\"},{\"price\":\"0.72\",\"size\":\"611.58\"},{\"price\":\"0.71\",\"size\":\"15896.55\"},{\"price\":\"0.7\",\"size\":\"8666\"},{\"price\":\"0.69\",\"size\":\"10000\"},{\"price\":\"0.67\",\"size\":\"10000\"},{\"price\":\"0.66\",\"size\":\"4764.7\"},{\"price\":\"0.65\",\"size\":\"10750\"},{\"price\":\"0.64\",\"size\":\"14175.35\"},{\"price\":\"0.63\",\"size\":\"10000\"},{\"price\":\"0.61\",\"size\":\"26439.1\"},{\"price\":\"0.6\",\"size\":\"5280\"},{\"price\":\"0.59\",\"size\":\"10000\"},{\"price\":\"0.57\",\"size\":\"24011\"},{\"price\":\"0.55\",\"size\":\"10000\"},{\"price\":\"0.54\",\"size\":\"600\"},{\"price\":\"0.53\",\"size\":\"19641.49\"},{\"price\":\"0.52\",\"size\":\"2701.92\"},{\"price\":\"0.51\",\"size\":\"10000\"},{\"price\":\"0.509\",\"size\":\"30\"},{\"price\":\"0.5\",\"size\":\"4235.12\"},{\"price\":\"0.49\",\"size\":\"16101.32\"},{\"price\":\"0.488\",\"size\":\"32\"},{\"price\":\"0.47\",\"size\":\"12207.54\"},{\"price\":\"0.46\",\"size\":\"600\"},{\"price\":\"0.45\",\"size\":\"15244.32\"},{\"price\":\"0.43\",\"size\":\"10000\"},{\"price\":\"0.42\",\"size\":\"1706.89\"},{\"price\":\"0.41\",\"size\":\"14196.63\"},{\"price\":\"0.4\",\"size\":\"516.92\"},{\"price\":\"0.39\",\"size\":\"10008\"},{\"price\":\"0.38\",\"size\":\"100\"},{\"price\":\"0.37\",\"size\":\"27635.34\"},{\"price\":\"0.369\",\"size\":\"2500\"},{\"price\":\"0.36\",\"size\":\"234\"},{\"price\":\"0.35\",\"size\":\"50\"},{\"price\":\"0.33\",\"size\":\"3336.57\"},{\"price\":\"0.3\",\"size\":\"331.68\"},{\"price\":\"0.29\",\"size\":\"2544.77\"},{\"price\":\"0.28\",\"size\":\"600\"},{\"price\":\"0.27\",\"size\":\"200\"},{\"price\":\"0.26\",\"size\":\"1769.23\"},{\"price\":\"0.25\",\"size\":\"7104.96\"},{\"price\":\"0.249\",\"size\":\"1010\"},{\"price\":\"0.24\",\"size\":\"159.99\"},{\"price\":\"0.22\",\"size\":\"9.8\"},{\"price\":\"0.2\",\"size\":\"34754.14\"},{\"price\":\"0.199\",\"size\":\"2914.99\"},{\"price\":\"0.19\",\"size\":\"364.11\"},{\"price\":\"0.18\",\"size\":\"1026.99\"},{\"price\":\"0.17\",\"size\":\"1770\"},{\"price\":\"0.169\",\"size\":\"1000\"},{\"price\":\"0.168\",\"size\":\"200\"},{\"price\":\"0.165\",\"size\":\"110\"},{\"price\":\"0.16\",\"size\":\"763\"},{\"price\":\"0.151\",\"size\":\"5\"},{\"price\":\"0.15\",\"size\":\"3011.25\"},{\"price\":\"0.149\",\"size\":\"1100\"},{\"price\":\"0.14\",\"size\":\"459.99\"},{\"price\":\"0.13\",\"size\":\"578\"},{\"price\":\"0.128\",\"size\":\"200\"},{\"price\":\"0.12\",\"size\":\"5756.82\"},{\"price\":\"0.117\",\"size\":\"55\"},{\"price\":\"0.111\",\"size\":\"5\"},{\"price\":\"0.11\",\"size\":\"2031\"},{\"price\":\"0.109\",\"size\":\"10\"},{\"price\":\"0.106\",\"size\":\"2900\"},{\"price\":\"0.105\",\"size\":\"450\"},{\"price\":\"0.102\",\"size\":\"450\"},{\"price\":\"0.1\",\"size\":\"4326.1\"},{\"price\":\"0.099\",\"size\":\"300\"},{\"price\":\"0.097\",\"size\":\"410\"},{\"price\":\"0.096\",\"size\":\"221.23\"},{\"price\":\"0.093\",\"size\":\"165.38\"},{\"price\":\"0.091\",\"size\":\"205\"},{\"price\":\"0.09\",\"size\":\"748.31\"},{\"price\":\"0.087\",\"size\":\"100\"},{\"price\":\"0.086\",\"size\":\"276.94\"},{\"price\":\"0.085\",\"size\":\"10\"},{\"price\":\"0.084\",\"size\":\"205\"},{\"price\":\"0.082\",\"size\":\"163.39\"},{\"price\":\"0.08\",\"size\":\"1572.43\"},{\"price\":\"0.078\",\"size\":\"50\"},{\"price\":\"0.076\",\"size\":\"216.45\"},{\"price\":\"0.075\",\"size\":\"6600\"},{\"price\":\"0.071\",\"size\":\"505.38\"},{\"price\":\"0.07\",\"size\":\"457\"},{\"price\":\"0.068\",\"size\":\"629.18\"},{\"price\":\"0.065\",\"size\":\"3180.9\"},{\"price\":\"0.064\",\"size\":\"750\"},{\"price\":\"0.063\",\"size\":\"40\"},{\"price\":\"0.062\",\"size\":\"272.71\"},{\"price\":\"0.061\",\"size\":\"626\"},{\"price\":\"0.06\",\"size\":\"122472.99\"},{\"price\":\"0.059\",\"size\":\"10078.79\"},{\"price\":\"0.058\",\"size\":\"30432.31\"},{\"price\":\"0.057\",\"size\":\"16020\"},{\"price\":\"0.056\",\"size\":\"7996.1\"},{\"price\":\"0.055\",\"size\":\"20\"},{\"price\":\"0.054\",\"size\":\"10430.79\"},{\"price\":\"0.053\",\"size\":\"20604.09\"},{\"price\":\"0.052\",\"size\":\"20\"},{\"price\":\"0.051\",\"size\":\"749.5\"},{\"price\":\"0.05\",\"size\":\"25162.48\"},{\"price\":\"0.049\",\"size\":\"2032.19\"},{\"price\":\"0.048\",\"size\":\"14251.11\"},{\"price\":\"0.047\",\"size\":\"1645\"},{\"price\":\"0.046\",\"size\":\"1394\"},{\"price\":\"0.045\",\"size\":\"9503\"},{\"price\":\"0.044\",\"size\":\"21513.88\"},{\"price\":\"0.043\",\"size\":\"7547\"},{\"price\":\"0.042\",\"size\":\"19085.73\"},{\"price\":\"0.041\",\"size\":\"12979.41\"},{\"price\":\"0.04\",\"size\":\"38445.56\"},{\"price\":\"0.039\",\"size\":\"9777.29\"},{\"price\":\"0.038\",\"size\":\"3012.81\"}],\"tick_size\":\"0.001\",\"event_type\":\"book\",\"last_trade_price\":\"0.038\"}]\n"}
{"recv_ts": 1786689747263026, "venue": "polymarket", "raw": "{\"market\":\"0x6bd56627aa21311850825edb27e53434a0e17a4f782be0086bc07f71eee00d0d\",\"price_changes\":[{\"asset_id\":\"87073899845581463485186346288398658568334162612963837182986759797304993556208\",\"price\":\"0.95\",\"size\":\"241281.01\",\"side\":\"SELL\",\"hash\":\"2c851577e29450fba93f7a338bbbd8fbab3d3f9b\",\"best_bid\":\"0.92\",\"best_ask\":\"0.93\"},{\"asset_id\":\"350977769852917329387037893294763093471844346281449484439085576212613048126\",\"price\":\"0.05\",\"size\":\"241281.01\",\"side\":\"BUY\",\"hash\":\"53f3aba56cd3625518c45d18a0bd3c09a9f0a6a6\",\"best_bid\":\"0.07\",\"best_ask\":\"0.08\"}],\"timestamp\":\"1786689747216\",\"event_type\":\"price_change\"}"}
{"recv_ts": 1786689748421700, "venue": "polymarket", "raw": "{\"market\":\"0x6bd56627aa21311850825edb27e53434a0e17a4f782be0086bc07f71eee00d0d\",\"price_changes\":[{\"asset_id\":\"87073899845581463485186346288398658568334162612963837182986759797304993556208\",\"price\":\"0.93\",\"size\":\"136097.66\",\"side\":\"SELL\",\"hash\":\"4acf5335f1a833b27f2385bbac8ef46772e62ed3\",\"best_bid\":\"0.92\",\"best_ask\":\"0.93\"},{\"asset_id\":\"350977769852917329387037893294763093471844346281449484439085576212613048126\",\"price\":\"0.07\",\"size\":\"136097.66\",\"side\":\"BUY\",\"hash\":\"2386ffeeb8b46dac844807db6fb0c34d3478bd03\",\"best_bid\":\"0.07\",\"best_ask\":\"0.08\"}],\"timestamp\":\"1786689748414\",\"event_type\":\"price_change\"}"}
{"recv_ts": 1786689748491428, "venue": "polymarket", "raw": "{\"market\":\"0x6bd56627aa21311850825edb27e53434a0e17a4f782be0086bc07f71eee00d0d\",\"price_changes\":[{\"asset_id\":\"87073899845581463485186346288398658568334162612963837182986759797304993556208\",\"price\":\"0.93\",\"size\":\"136122.66\",\"side\":\"SELL\",\"hash\":\"ed331b3f99ecbe005e3f805ba52b615bb2908a91\",\"best_bid\":\"0.92\",\"best_ask\":\"0.93\"},{\"asset_id\":\"350977769852917329387037893294763093471844346281449484439085576212613048126\",\"price\":\"0.07\",\"size\":\"136122.66\",\"side\":\"BUY\",\"hash\":\"cdbcb662be3b2d2fe0f5795332f5a5a78361d43a\",\"best_bid\":\"0.07\",\"best_ask\":\"0.08\"}],\"timestamp\":\"1786689748487\",\"event_type\":\"price_change\"}"}
{"recv_ts": 1786689748576996, "venue": "polymarket", "raw": "{\"market\":\"0x6bd56627aa21311850825edb27e53434a0e17a4f782be0086bc07f71eee00d0d\",\"price_changes\":[{\"asset_id\":\"350977769852917329387037893294763093471844346281449484439085576212613048126\",\"price\":\"0.05\",\"size\":\"231282.01\",\"side\":\"BUY\",\"hash\":\"c2eb8a2630ae8b9bc0a035259cd190e0c7b3cb21\",\"best_bid\":\"0.07\",\"best_ask\":\"0.08\"},{\"asset_id\":\"87073899845581463485186346288398658568334162612963837182986759797304993556208\",\"price\":\"0.95\",\"size\":\"231282.01\",\"side\":\"SELL\",\"hash\":\"1ca574fe0b4bad1f2a6aaa70d57d80ba233def8b\",\"best_bid\":\"0.92\",\"best_ask\":\"0.93\"}],\"timestamp\":\"1786689748573\",\"event_type\":\"price_change\"}"}
{"recv_ts": 1786689751005666, "venue": "polymarket", "raw": "{\"market\":\"0x6bd56627aa21311850825edb27e53434a0e17a4f782be0086bc07f71eee00d0d\",\"price_changes\":[{\"asset_id\":\"87073899845581463485186346288398658568334162612963837182986759797304993556208\",\"price\":\"0.1\",\"size\":\"1150\",\"side\":\"BUY\",\"hash\":\"cb47e9644a48d4adf8dd07e1e1ed339ce94a2eee\",\"best_bid\":\"0.92\",\"best_ask\":\"0.93\"},{\"asset_id\":\"350977769852917329387037893294763093471844346281449484439085576212613048126\",\"price\":\"0.9\",\"size\":\"1150\",\"side\":\"SELL\",\"hash\":\"99de94c411d005c1b688d5ee9cccb936fd8dfb40\",\"best_bid\":\"0.07\",\"best_ask\":\"0.08\"}],\"timestamp\":\"1786689751001\",\"event_type\":\"price_change\"}"}
{"recv_ts": 1786689751005750, "venue": "polymarket", "raw": "{\"market\":\"0x6bd56627aa21311850825edb27e53434a0e17a4f782be0086bc07f71eee00d0d\",\"price_changes\":[{\"asset_id\":\"87073899845581463485186346288398658568334162612963837182986759797304993556208\",\"price\":\"0.3\",\"size\":\"7666\",\"side\":\"BUY\",\"hash\":\"cb47e9644a48d4adf8dd07e1e1ed339ce94a2eee\",\"best_bid\":\"0.92\",\"best_ask\":\"0.93\"},{\"asset_id\":\"350977769852917329387037893294763093471844346281449484439085576212613048126\",\"price\":\"0.7\",\"size\":\"7666\",\"side\":\"SELL\",\"hash\":\"99de94c411d005c1b688d5ee9cccb936fd8dfb40\",\"best_bid\":\"0.07\",\"best_ask\":\"0.08\"}],\"timestamp\":\"1786689751001\",\"event_type\":\"price_change\"}"}
{"recv_ts": 1786689751005773, "venue": "polymarket", "raw": "{\"market\":\"0x6bd56627aa21311850825edb27e53434a0e17a4f782be0086bc07f71eee00d0d\",\"price_changes\":[{\"asset_id\":\"87073899845581463485186346288398658568334162612963837182986759797304993556208\",\"price\":\"0.2\",\"size\":\"10350\",\"side\":\"BUY\",\"hash\":\"cb47e9644a48d4adf8dd07e1e1ed339ce94a2eee\",\"best_bid\":\"0.92\",\"best_ask\":\"0.93\"},{\"asset_id\":\"350977769852917329387037893294763093471844346281449484439085576212613048126\",\"price\":\"0.8\",\"size\":\"10350\",\"side\":\"SELL\",\"hash\":\"99de94c411d005c1b688d5ee9cccb936fd8dfb40\",\"best_bid\":\"0.07\",\"best_ask\":\"0.08\"}],\"timestamp\":\"1786689751001\",\"event_type\":\"price_change\"}"}
{"recv_ts": 1786689751006727, "venue": "polymarket", "raw": "{\"market\":\"0x6bd56627aa21311850825edb27e53434a0e17a4f782be0086bc07f71eee00d0d\",\"price_changes\":[{\"asset_id\":\"87073899845581463485186346288398658568334162612963837182986759797304993556208\",\"price\":\"0.4\",\"size\":\"5000\",\"side\":\"BUY\",\"hash\":\"aa5fb2c92c75a6f014733cbaf3f3096f875b89c6\",\"best_bid\":\"0.92\",\"best_ask\":\"0.93\"},{\"asset_id\":\"350977769852917329387037893294763093471844346281449484439085576212613048126\",\"price\":\"0.6\",\"size\":\"5000\",\"side\":\"SELL\",\"hash\":\"0e277e9223ce656c9e23f047fcd33e20a39d8913\",\"best_bid\":\"0.07\",\"best_ask\":\"0.08\"}],\"timestamp\":\"1786689751002\",\"event_type\":\"price_change\"}"}
{"recv_ts": 1786689751010761, "venue": "polymarket", "raw": "{\"market\":\"0x747dc809fb79e1b05be09c42d6179459a58de2ef3e40f02484a4e1260f741f75\",\"price_changes\":[{\"asset_id\":\"7305630249804085635496399869905769372294302716159034447326228509068694952392\",\"price\":\"0.05\",\"size\":\"3400\",\"side\":\"BUY\",\"hash\":\"5b07a6e32c6e86ad31784b673a08e1e50e8d85cf\",\"best_bid\":\"0.95\",\"best_ask\":\"0.96\"},{\"asset_id\":\"107505882767731489358349912513945399560393482969656700824895970500493757150417\",\"price\":\"0.95\",\"size\":\"3400\",\"side\":\"SELL\",\"hash\":\"bf22ced38370facb14b3d15e7ebb205156edd03c\",\"best_bid\":\"0.04\",\"best_ask\":\"0.05\"}],\"timestamp\":\"1786689751005\",\"event_type\":\"price_change\"}"}
{"recv_ts": 1786689753715869, "venue": "polymarket", "raw": "{\"market\":\"0x6bd56627aa21311850825edb27e53434a0e17a4f782be0086bc07f71eee00d0d\",\"price_changes\":[{\"asset_id\":\"350977769852917329387037893294763093471844346281449484439085576212613048126\",\"price\":\"0.05\",\"size\":\"241281.01\",\"side\":\"BUY\",\"hash\":\"363640f2968967dffb263901b62eda6e057780a1\",\"best_bid\":\"0.07\",\"best_ask\":\"0.08\"},{\"asset_id\":\"87073899845581463485186346288398658568334162612963837182986759797304993556208\",\"price\":\"0.95\",\"size\":\"241281.01\",\"side\":\"SELL\",\"hash\":\"6aedd401634fefe14992195840eddd946514251e\",\"best_bid\":\"0.92\",\"best_ask\":\"0.93\"}],\"timestamp\":\"1786689753708\",\"event_type\":\"price_change\"}"}
{"recv_ts": 1786689754625887, "venue": "polymarket", "raw": "{\"market\":\"0x6bd56627aa21311850825edb27e53434a0e17a4f782be0086bc07f71eee00d0d\",\"price_changes\":[{\"asset_id\":\"87073899845581463485186346288398658568334162612963837182986759797304993556208\",\"price\":\"0.4\",\"size\":\"6250\",\"side\":\"BUY\",\"hash\":\"fa56366fadf1f50662e3a915e9b2a9c4453717c8\",\"best_bid\":\"0.92\",\"best_ask\":\"0.93\"},{\"asset_id\":\"350977769852917329387037893294763093471844346281449484439085576212613048126\",\"price\":\"0.6\",\"size\":\"6250\",\"side\":\"SELL\",\"hash\":\"bc4ee02bc3336d359a8ef6917dd60506b6ccc482\",\"best_bid\":\"0.07\",\"best_ask\":\"0.08\"}],\"timestamp\":\"1786689754622\",\"event_type\":\"price_change\"}"}
{"recv_ts": 1786689754626111, "venue": "polymarket", "raw": "{\"market\":\"0x6bd56627aa21311850825edb27e53434a0e17a4f782be0086bc07f71eee00d0d\",\"price_changes\":[{\"asset_id\":\"87073899845581463485186346288398658568334162612963837182986759797304993556208\",\"price\":\"0.3\",\"size\":\"10666\",\"side\":\"BUY\",\"hash\":\"2de60e439cb6318a176ce445995e7d1863032b20\",\"best_bid\":\"0.92\",\"best_ask\":\"0.93\"},{\"asset_id\":\"350977769852917329387037893294763093471844346281449484439085576212613048126\",\"price\":\"0.7\",\"size\":\"10666\",\"side\":\"SELL\",\"hash\":\"579903490adcc718fd70c8675ae15946a66b3825\",\"best_bid\":\"0.07\",\"best_ask\":\"0.08\"}],\"timestamp\":\"1786689754622\",\"event_type\":\"price_change\"}"}
{"recv_ts": 1786689754627036, "venue": "polymarket", "raw": "{\"market\":\"0x6bd56627aa21311850825edb27e53434a0e17a4f782be0086bc07f71eee00d0d\",\"price_changes\":[{\"asset_id\":\"87073899845581463485186346288398658568334162612963837182986759797304993556208\",\"price\":\"0.1\",\"size\":\"13150\",\"side\":\"BUY\",\"hash\":\"19645b48901df6aabd4b6d89dfea81bc14f45558\",\"best_bid\":\"0.92\",\"best_ask\":\"0.93\"},{\"asset_id\":\"350977769852917329387037893294763093471844346281449484439085576212613048126\",\"price\":\"0.9\",\"size\":\"13150\",\"side\":\"SELL\",\"hash\":\"14d4dc85c5497f7f4e45f89982c97bef0fa987b1\",\"best_bid\":\"0.07\",\"best_ask\":\"0.08\"}],\"timestamp\":\"1786689754623\",\"event_type\":\"price_change\"}"}
{"recv_ts": 1786689754628369, "venue": "polymarket", "raw": "{\"market\":\"0x6bd56627aa21311850825edb27e53434a0e17a4f782be0086bc07f71eee00d0d\",\"price_changes\":[{\"asset_id\":\"87073899845581463485186346288398658568334162612963837182986759797304993556208\",\"price\":\"0.2\",\"size\":\"15350\",\"side\":\"BUY\",\"hash\":\"a1e6ffe449c4ce769de6d1220782e1c44052b378\",\"best_bid\":\"0.92\",\"best_ask\":\"0.93\"},{\"asset_id\":\"350977769852917329387037893294763093471844346281449484439085576212613048126\",\"price\":\"0.8\",\"size\":\"15350\",\"side\":\"SELL\",\"hash\":\"c8a8ee238bcb2fc418f0c3e56d404f235d70c8b9\",\"best_bid\":\"0.07\",\"best_ask\":\"0.08\"}],\"timestamp\":\"1786689754624\",\"event_type\":\"price_change\"}"}
{"recv_ts": 1786689754902410, "venue": "polymarket", "raw": "{\"market\":\"0x6bd56627aa21311850825edb27e53434a0e17a4f782be0086bc07f71eee00d0d\",\"price_changes\":[{\"asset_id\":\"350977769852917329387037893294763093471844346281449484439085576212613048126\",\"price\":\"0.04\",\"size\":\"178351.33\",\"side\":\"BUY\",\"hash\":\"81eedfb8c57e004a6083fccb61156a1035a729c3\",\"best_bid\":\"0.07\",\"best_ask\":\"0.08\"},{\"asset_id\":\"87073899845581463485186346288398658568334162612963837182986759797304993556208\",\"price\":\"0.96\",\"size\":\"178351.33\",\"side\":\"SELL\",\"hash\":\"aee2ed7b8691769ee3e8f4aa865f1a68b90a93c2\",\"best_bid\":\"0.92\",\"best_ask\":\"0.93\"}],\"timestamp\":\"1786689754898\",\"event_type\":\"price_change\"}"}
{"recv_ts": 1786689756571146, "venue": "polymarket", "raw": "{\"market\":\"0x747dc809fb79e1b05be09c42d6179459a58de2ef3e40f02484a4e1260f741f75\",\"price_changes\":[{\"asset_id\":\"7305630249804085635496399869905769372294302716159034447326228509068694952392\",\"price\":\"0.05\",\"size\":\"2300\",\"side\":\"BUY\",\"hash\":\"bee0e84670a8560c3b9abebcf2dd485bf3b21814\",\"best_bid\":\"0.95\",\"best_ask\":\"0.96\"},{\"asset_id\":\"107505882767731489358349912513945399560393482969656700824895970500493757150417\",\"price\":\"0.95\",\"size\":\"2300\",\"side\":\"SELL\",\"hash\":\"04725c4145926e25d39aefd96afaae7ba4cf47c6\",\"best_bid\":\"0.04\",\"best_ask\":\"0.05\"}],\"timestamp\":\"1786689756553\",\"event_type\":\"price_change\"}"}
{"recv_ts": 1786689762006421, "venue": "polymarket", "raw": "{\"market\":\"0xbb4d51e6364066d92eb6f9b8413dd7193de70966736044463b205834805a1f3b\",\"price_changes\":[{\"asset_id\":\"106181075047366745139197108801635573283215248045056329679360376976893016488727\",\"price\":\"0.9\",\"size\":\"27202.32\",\"side\":\"BUY\",\"hash\":\"e2ea790c9e6cf6dac169f4250c2033044bd4ac20\",\"best_bid\":\"0.93\",\"best_ask\":\"0.94\"},{\"asset_id\":\"10991849228756847439673778874175365458450913336396982752046655649803657501964\",\"price\":\"0.1\",\"size\":\"27202.32\",\"side\":\"SELL\",\"hash\":\"774a711661e083d6d5081d6f8ef75ff3ff703498\",\"best_bid\":\"0.06\",\"best_ask\":\"0.07\"}],\"timestamp\":\"1786689762001\",\"event_type\":\"price_change\"}"}
{"recv_ts": 1786689762006544, "venue": "polymarket", "raw": "{\"market\":\"0xbb4d51e6364066d92eb6f9b8413dd7193de70966736044463b205834805a1f3b\",\"price_changes\":[{\"asset_id\":\"10991849228756847439673778874175365458450913336396982752046655649803657501964\",\"price\":\"0.05\",\"size\":\"457072.25\",\"side\":\"BUY\",\"hash\":\"774a711661e083d6d5081d6f8ef75ff3ff703498\",\"best_bid\":\"0.06\",\"best_ask\":\"0.07\"},{\"asset_id\":\"106181075047366745139197108801635573283215248045056329679360376976893016488727\",\"price\":\"0.95\",\"size\":\"457072.25\",\"side\":\"SELL\",\"hash\":\"e2ea790c9e6cf6dac169f4250c2033044bd4ac20\",\"best_bid\":\"0.93\",\"best_ask\":\"0.94\"}],\"timestamp\":\"1786689762001\",\"event_type\":\"price_change\"}"}
{"recv_ts": 1786689767013700, "venue": "polymarket", "raw": "{\"market\":\"0xd9fb1184af0064e5e34b129f5b79afa5a17b7e32f2953ab05efed82315fee6d4\",\"price_changes\":[{\"asset_id\":\"90772332434487149264114862115632028379978765245278600275169585501290867536237\",\"price\":\"0.4\",\"size\":\"1280\",\"side\":\"BUY\",\"hash\":\"7ccc44a068da9a441f7979c10c5e7b60cf3ef73c\",\"best_bid\":\"0.962\",\"best_ask\":\"0.964\"},{\"asset_id\":\"94559586571241563470235664821564670251180951772614764383113614156422396181162\",\"price\":\"0.6\",\"size\":\"1280\",\"side\":\"SELL\",\"hash\":\"6bbb0238895f9ec5ebb04bc6ff920a6c1ba73154\",\"best_bid\":\"0.036\",\"best_ask\":\"0.038\"}],\"timestamp\":\"1786689767000\",\"event_type\":\"price_change\"}"}
{"recv_ts": 1786689767014012, "venue": "polymarket", "raw": "{\"market\":\"0xd9fb1184af0064e5e34b129f5b79afa5a17b7e32f2953ab05efed82315fee6d4\",\"price_changes\":[{\"asset_id\":\"90772332434487149264114862115632028379978765245278600275169585501290867536237\",\"price\":\"0.3\",\"size\":\"3000\",\"side\":\"BUY\",\"hash\":\"7d8a7abf137373bf079bd4b8011390e8667745df\",\"best_bid\":\"0.962\",\"best_ask\":\"0.964\"},{\"asset_id\":\"94559586571241563470235664821564670251180951772614764383113614156422396181162\",\"price\":\"0.7\",\"size\":\"3000\",\"side\":\"SELL\",\"hash\":\"7b7065fa68f0a8b0d77126627b4f8af881409fce\",\"best_bid\":\"0.036\",\"best_ask\":\"0.038\"}],\"timestamp\":\"1786689767001\",\"event_type\":\"price_change\"}"}
{"recv_ts": 1786689767014043, "venue": "polymarket", "raw": "{\"market\":\"0xd9fb1184af0064e5e34b129f5b79afa5a17b7e32f2953ab05efed82315fee6d4\",\"price_changes\":[{\"asset_id\":\"90772332434487149264114862115632028379978765245278600275169585501290867536237\",\"price\":\"0.2\",\"size\":\"5255\",\"side\":\"BUY\",\"hash\":\"7d8a7abf137373bf079bd4b8011390e8667745df\",\"best_bid\":\"0.962\",\"best_ask\":\"0.964\"},{\"asset_id\":\"94559586571241563470235664821564670251180951772614764383113614156422396181162\",\"price\":\"0.8\",\"size\":\"5255\",\"side\":\"SELL\",\"hash\":\"7b7065fa68f0a8b0d77126627b4f8af881409fce\",\"best_bid\":\"0.036\",\"best_ask\":\"0.038\"}],\"timestamp\":\"1786689767001\",\"event_type\":\"price_change\"}"}
{"recv_ts": 1786689769007435, "venue": "polymarket", "raw": "{\"market\":\"0xbb4d51e6364066d92eb6f9b8413dd7193de70966736044463b205834805a1f3b\",\"price_changes\":[{\"asset_id\":\"10991849228756847439673778874175365458450913336396982752046655649803657501964\",\"price\":\"0.05\",\"size\":\"456872.25\",\"side\":\"BUY\",\"hash\":\"f82f2adb8169687622fa4fdcb3ffbccdac358284\",\"best_bid\":\"0.06\",\"best_ask\":\"0.07\"},{\"asset_id\":\"106181075047366745139197108801635573283215248045056329679360376976893016488727\",\"price\":\"0.95\",\"size\":\"456872.25\",\"side\":\"SELL\",\"hash\":\"3b15e3389b23aadd0474a5e79fe93d800c0d99f6\",\"best_bid\":\"0.93\",\"best_ask\":\"0.94\"}],\"timestamp\":\"1786689769000\",\"event_type\":\"price_change\"}"}
{"recv_ts": 1786689769008476, "venue": "polymarket", "raw": "{\"market\":\"0xbb4d51e6364066d92eb6f9b8413dd7193de70966736044463b205834805a1f3b\",\"price_changes\":[{\"asset_id\":\"106181075047366745139197108801635573283215248045056329679360376976893016488727\",\"price\":\"0.91\",\"size\":\"157692.46\",\"side\":\"BUY\",\"hash\":\"9d0291ac9c9f3fc4532ec3adbfabe8e14026992d\",\"best_bid\":\"0.93\",\"best_ask\":\"0.94\"},{\"asset_id\":\"10991849228756847439673778874175365458450913336396982752046655649803657501964\",\"price\":\"0.09\",\"size\":\"157692.46\",\"side\":\"SELL\",\"hash\":\"87bcf31a9d0ee843b0017fa532b863937ecdff9e\",\"best_bid\":\"0.06\",\"best_ask\":\"0.07\"}],\"timestamp\":\"1786689769003\",\"event_type\":\"price_change\"}"}
{"recv_ts": 1786689769481506, "venue": "polymarket", "raw": "{\"market\":\"0xd9fb1184af0064e5e34b129f5b79afa5a17b7e32f2953ab05efed82315fee6d4\",\"price_changes\":[{\"asset_id\":\"90772332434487149264114862115632028379978765245278600275169585501290867536237\",\"price\":\"0.2\",\"size\":\"14255\",\"side\":\"BUY\",\"hash\":\"6f76572d24962705892dac6ae51ebab2ec5158e7\",\"best_bid\":\"0.962\",\"best_ask\":\"0.964\"},{\"asset_id\":\"94559586571241563470235664821564670251180951772614764383113614156422396181162\",\"price\":\"0.8\",\"size\":\"14255\",\"side\":\"SELL\",\"hash\":\"77590b66552729e1bcde5dea1a0def03ec52fe29\",\"best_bid\":\"0.036\",\"best_ask\":\"0.038\"}],\"timestamp\":\"1786689769477\",\"event_type\":\"price_change\"}"}
{"recv_ts": 1786689769481823, "venue": "polymarket", "raw": "{\"market\":\"0xd9fb1184af0064e5e34b129f5b79afa5a17b7e32f2953ab05efed82315fee6d4\",\"price_changes\":[{\"asset_id\":\"90772332434487149264114862115632028379978765245278600275169585501290867536237\",\"price\":\"0.3\",\"size\":\"8666\",\"side\":\"BUY\",\"hash\":\"8f1696ecaf70ac4c959d87f372766752bf462dad\",\"best_bid\":\"0.962\",\"best_ask\":\"0.964\"},{\"asset_id\":\"94559586571241563470235664821564670251180951772614764383113614156422396181162\",\"price\":\"0.7\",\"size\":\"8666\",\"side\":\"SELL\",\"hash\":\"36290a619c6a111312c1d2465f6072f9ede9419e\",\"best_bid\":\"0.036\",\"best_ask\":\"0.038\"}],\"timestamp\":\"1786689769478\",\"event_type\":\"price_change\"}"}
{"recv_ts": 1786689769482534, "venue": "polymarket", "raw": "{\"market\":\"0xd9fb1184af0064e5e34b129f5b79afa5a17b7e32f2953ab05efed82315fee6d4\",\"price_changes\":[{\"asset_id\":\"90772332434487149264114862115632028379978765245278600275169585501290867536237\",\"price\":\"0.4\",\"size\":\"5280\",\"side\":\"BUY\",\"hash\":\"a8d43383804b86acf17a26e1d4da7c30ec5e5c8b\",\"best_bid\":\"0.962\",\"best_ask\":\"0.964\"},{\"asset_id\":\"94559586571241563470235664821564670251180951772614764383113614156422396181162\",\"price\":\"0.6\",\"size\":\"5280\",\"side\":\"SELL\",\"hash\":\"e48ca5c27f6975d501043f7e149311d29b9fb441\",\"best_bid\":\"0.036\",\"best_ask\":\"0.038\"}],\"timestamp\":\"1786689769479\",\"event_type\":\"price_change\"}"}
{"recv_ts": 1786689772009724, "venue": "polymarket", "raw": "{\"market\":\"0x60c2c085ee8c16bc8f2419739a94971d4c9d00f637ead10fc0f540afa1be64e8\",\"price_changes\":[{\"asset_id\":\"90869494087977018607792751230236923002303032923064138180950209430688758061828\",\"price\":\"0.85\",\"size\":\"2689.2\",\"side\":\"BUY\",\"hash\":\"d04fbd2c68646b09456c9d15ec825aa00acc8b5a\",\"best_bid\":\"0.979\",\"best_ask\":\"0.98\"},{\"asset_id\":\"105426373826369935595603860663411604941599130211176020843036778867927711117332\",\"price\":\"0.15\",\"size\":\"2689.2\",\"side\":\"SELL\",\"hash\":\"7320c5dc2d062996f2781dc75826284ad4f90db9\",\"best_bid\":\"0.02\",\"best_ask\":\"0.021\"}],\"timestamp\":\"1786689772000\",\"event_type\":\"price_change\"}"}
{"recv_ts": 1786689772806623, "venue": "polymarket", "raw": "{\"market\":\"0xd595eb9b81885ff018738300c79047e3ec89e87294424f57a29a7fa9162bf116\",\"price_changes\":[{\"asset_id\":\"57216272564529548464686463691236811991956032201293786790337952253964682584376\",\"price\":\"0.963\",\"size\":\"12870.97\",\"side\":\"BUY\",\"hash\":\"6073a5f333ff79e1e6177605ed452d04ac1a1c17\",\"best_bid\":\"0.963\",\"best_ask\":\"0.964\"},{\"asset_id\":\"5161623255678193352839985156330393796378434470119114669671615782853260939535\",\"price\":\"0.037\",\"size\":\"12870.97\",\"side\":\"SELL\",\"hash\":\"5774a260f5a96256e23367bc90614b0245405029\",\"best_bid\":\"0.036\",\"best_ask\":\"0.037\"}],\"timestamp\":\"1786689772785\",\"event_type\":\"price_change\"}"}
{"recv_ts": 1786689773167007, "venue": "polymarket", "raw": "{\"market\":\"0x60c2c085ee8c16bc8f2419739a94971d4c9d00f637ead10fc0f540afa1be64e8\",\"price_changes\":[{\"asset_id\":\"90869494087977018607792751230236923002303032923064138180950209430688758061828\",\"price\":\"0.85\",\"size\":\"3089.2\",\"side\":\"BUY\",\"hash\":\"1917263f14c0ef317c060d3bcc6b3d47212dd076\",\"best_bid\":\"0.979\",\"best_ask\":\"0.98\"},{\"asset_id\":\"105426373826369935595603860663411604941599130211176020843036778867927711117332\",\"price\":\"0.15\",\"size\":\"3089.2\",\"side\":\"SELL\",\"hash\":\"c93196000377f72b07abcd1c114897847c920725\",\"best_bid\":\"0.02\",\"best_ask\":\"0.021\"}],\"timestamp\":\"1786689773161\",\"event_type\":\"price_change\"}"}
{"recv_ts": 1786689773811865, "venue": "polymarket", "raw": "{\"market\":\"0xd595eb9b81885ff018738300c79047e3ec89e87294424f57a29a7fa9162bf116\",\"price_changes\":[{\"asset_id\":\"57216272564529548464686463691236811991956032201293786790337952253964682584376\",\"price\":\"0.963\",\"size\":\"12970.7\",\"side\":\"BUY\",\"hash\":\"63cf8606446c585a8c6354c3856f7fc1fc871aa2\",\"best_bid\":\"0.963\",\"best_ask\":\"0.964\"},{\"asset_id\":\"5161623255678193352839985156330393796378434470119114669671615782853260939535\",\"price\":\"0.037\",\"size\":\"12970.7\",\"side\":\"SELL\",\"hash\":\"7f1ac28a095556ffaf323affd498a38397c1be7b\",\"best_bid\":\"0.036\",\"best_ask\":\"0.037\"}],\"timestamp\":\"1786689773807\",\"event_type\":\"price_change\"}"}
{"recv_ts": 1786689774905146, "venue": "polymarket", "raw": "{\"market\":\"0xd9fb1184af0064e5e34b129f5b79afa5a17b7e32f2953ab05efed82315fee6d4\",\"price_changes\":[{\"asset_id\":\"90772332434487149264114862115632028379978765245278600275169585501290867536237\",\"price\":\"0.64\",\"size\":\"0\",\"side\":\"BUY\",\"hash\":\"cb57d5b43d663c7dcd1acf5e9a0705bf1fcad63e\",\"best_bid\":\"0.962\",\"best_ask\":\"0.964\"},{\"asset_id\":\"94559586571241563470235664821564670251180951772614764383113614156422396181162\",\"price\":\"0.36\",\"size\":\"0\",\"side\":\"SELL\",\"hash\":\"e9db65c50d96a0ddd1cbbabc0c57f245e9b6f415\",\"best_bid\":\"0.036\",\"best_ask\":\"0.038\"}],\"timestamp\":\"1786689774897\",\"event_type\":\"price_change\"}"}
{"recv_ts": 1786689775020151, "venue": "polymarket", "raw": "{\"market\":\"0x60c2c085ee8c16bc8f2419739a94971d4c9d00f637ead10fc0f540afa1be64e8\",\"price_changes\":[{\"asset_id\":\"90869494087977018607792751230236923002303032923064138180950209430688758061828\",\"price\":\"0.5\",\"size\":\"4284.53\",\"side\":\"BUY\",\"hash\":\"4a9a1331eedf0a939922408467845910f2fa780d\",\"best_bid\":\"0.979\",\"best_ask\":\"0.98\"},{\"asset_id\":\"105426373826369935595603860663411604941599130211176020843036778867927711117332\",\"price\":\"0.5\",\"size\":\"4284.53\",\"side\":\"SELL\",\"hash\":\"b10f5648e59239d987e063927d003df15019bf67\",\"best_bid\":\"0.02\",\"best_ask\":\"0.021\"}],\"timestamp\":\"1786689775002\",\"event_type\":\"price_change\"}"}
{"recv_ts": 1786689778376228, "venue": "polymarket", "raw": "{\"market\":\"0xd9fb1184af0064e5e34b129f5b79afa5a17b7e32f2953ab05efed82315fee6d4\",\"price_changes\":[{\"asset_id\":\"90772332434487149264114862115632028379978765245278600275169585501290867536237\",\"price\":\"0.65\",\"size\":\"280\",\"side\":\"BUY\",\"hash\":\"000c74783e1a5205d35cc7949677ac4cef6bec12\",\"best_bid\":\"0.962\",\"best_ask\":\"0.964\"},{\"asset_id\":\"94559586571241563470235664821564670251180951772614764383113614156422396181162\",\"price\":\"0.35\",\"size\":\"280\",\"side\":\"SELL\",\"hash\":\"52480516d750cea920ac2ac24041c2a6d1fb7fd4\",\"best_bid\":\"0.036\",\"best_ask\":\"0.038\"}],\"timestamp\":\"1786689778372\",\"event_type\":\"price_change\"}"}
{"recv_ts": 1786689778902421, "venue": "polymarket", "raw": "{\"market\":\"0xd9fb1184af0064e5e34b129f5b79afa5a17b7e32f2953ab05efed82315fee6d4\",\"price_changes\":[{\"asset_id\":\"90772332434487149264114862115632028379978765245278600275169585501290867536237\",\"price\":\"0.96\",\"size\":\"38440.56\",\"side\":\"BUY\",\"hash\":\"c7d38e88c83f1dffe912387fd50a558ad59e1481\",\"best_bid\":\"0.962\",\"best_ask\":\"0.964\"},{\"asset_id\":\"94559586571241563470235664821564670251180951772614764383113614156422396181162\",\"price\":\"0.04\",\"size\":\"38440.56\",\"side\":\"SELL\",\"hash\":\"6624fc6a46d14538b110c736bb1fb847f610610f\",\"best_bid\":\"0.036\",\"best_ask\":\"0.038\"}],\"timestamp\":\"1786689778898\",\"event_type\":\"price_change\"}"}
{"recv_ts": 1786689778970686, "venue": "polymarket", "raw": "{\"market\":\"0xd9fb1184af0064e5e34b129f5b79afa5a17b7e32f2953ab05efed82315fee6d4\",\"price_changes\":[{\"asset_id\":\"90772332434487149264114862115632028379978765245278600275169585501290867536237\",\"price\":\"0.967\",\"size\":\"30019.04\",\"side\":\"SELL\",\"hash\":\"e89fc233f8b2646216f904a20cac312f38d97255\",\"best_bid\":\"0.962\",\"best_ask\":\"0.964\"},{\"asset_id\":\"94559586571241563470235664821564670251180951772614764383113614156422396181162\",\"price\":\"0.033\",\"size\":\"30019.04\",\"side\":\"BUY\",\"hash\":\"3f5f7c36674033ef6e67e64737e9c31ef521f524\",\"best_bid\":\"0.036\",\"best_ask\":\"0.038\"}],\"timestamp\":\"1786689778966\",\"event_type\":\"price_change\"}"}
{"recv_ts": 1786689779179115, "venue": "polymarket", "raw": "{\"market\":\"0x6bd56627aa21311850825edb27e53434a0e17a4f782be0086bc07f71eee00d0d\",\"price_changes\":[{\"asset_id\":\"87073899845581463485186346288398658568334162612963837182986759797304993556208\",\"price\":\"0.95\",\"size\":\"241275.08\",\"side\":\"SELL\",\"hash\":\"5220b64de97549e72f4990e32b6c00a702e67889\",\"best_bid\":\"0.92\",\"best_ask\":\"0.93\"},{\"asset_id\":\"350977769852917329387037893294763093471844346281449484439085576212613048126\",\"price\":\"0.05\",\"size\":\"241275.08\",\"side\":\"BUY\",\"hash\":\"6d31798cf01f35f20da1e0b97408d8ab57ba4d47\",\"best_bid\":\"0.07\",\"best_ask\":\"0.08\"}],\"timestamp\":\"1786689779174\",\"event_type\":\"price_change\"}"}
{"recv_ts": 1786689780011168, "venue": "polymarket", "raw": "{\"market\":\"0x60c2c085ee8c16bc8f2419739a94971d4c9d00f637ead10fc0f540afa1be64e8\",\"price_changes\":[{\"asset_id\":\"90869494087977018607792751230236923002303032923064138180950209430688758061828\",\"price\":\"0.971\",\"size\":\"11263.32\",\"side\":\"BUY\",\"hash\":\"5ddf44c4ff2347bd5fe53db3ff2a2a89e2e0d88c\",\"best_bid\":\"0.979\",\"best_ask\":\"0.98\"},{\"asset_id\":\"105426373826369935595603860663411604941599130211176020843036778867927711117332\",\"price\":\"0.029\",\"size\":\"11263.32\",\"side\":\"SELL\",\"hash\":\"c54d8647fcb394840388de29085317d3517cd530\",\"best_bid\":\"0.02\",\"best_ask\":\"0.021\"}],\"timestamp\":\"1786689780001\",\"event_type\":\"price_change\"}"}
{"recv_ts": 1786689780018304, "venue": "polymarket", "raw": "{\"market\":\"0x60c2c085ee8c16bc8f2419739a94971d4c9d00f637ead10fc0f540afa1be64e8\",\"price_changes\":[{\"asset_id\":\"90869494087977018607792751230236923002303032923064138180950209430688758061828\",\"price\":\"0.5\",\"size\":\"6684.53\",\"side\":\"BUY\",\"hash\":\"e0b6bb2b3d88217ee4480a4e3c89764db51e5740\",\"best_bid\":\"0.979\",\"best_ask\":\"0.98\"},{\"asset_id\":\"105426373826369935595603860663411604941599130211176020843036778867927711117332\",\"price\":\"0.5\",\"size\":\"6684.53\",\"side\":\"SELL\",\"hash\":\"f90347d0b92d94e5de18d0bb6e164e862830be93\",\"best_bid\":\"0.02\",\"best_ask\":\"0.021\"}],\"timestamp\":\"1786689780012\",\"event_type\":\"price_change\"}"}
{"recv_ts": 1786689780070569, "venue": "polymarket", "raw": "{\"market\":\"0x60c2c085ee8c16bc8f2419739a94971d4c9d00f637ead10fc0f540afa1be64e8\",\"price_changes\":[{\"asset_id\":\"90869494087977018607792751230236923002303032923064138180950209430688758061828\",\"price\":\"0.971\",\"size\":\"11503.32\",\"side\":\"BUY\",\"hash\":\"477212a7b1dbd83acf5ec042622bdd1ac43d9fa8\",\"best_bid\":\"0.979\",\"best_ask\":\"0.98\"},{\"asset_id\":\"105426373826369935595603860663411604941599130211176020843036778867927711117332\",\"price\":\"0.029\",\"size\":\"11503.32\",\"side\":\"SELL\",\"hash\":\"fd6acd3b3d0386eb516f3af3d8c82ac84bf54cc8\",\"best_bid\":\"0.02\",\"best_ask\":\"0.021\"}],\"timestamp\":\"1786689780063\",\"event_type\":\"price_change\"}"}
{"recv_ts": 1786689782839870, "venue": "polymarket", "raw": "{\"market\":\"0xd9fb1184af0064e5e34b129f5b79afa5a17b7e32f2953ab05efed82315fee6d4\",\"price_changes\":[{\"asset_id\":\"90772332434487149264114862115632028379978765245278600275169585501290867536237\",\"price\":\"0.65\",\"size\":\"50\",\"side\":\"BUY\",\"hash\":\"764b60fd193ace5e6c290857eb689e14b51188f8\",\"best_bid\":\"0.962\",\"best_ask\":\"0.964\"},{\"asset_id\":\"94559586571241563470235664821564670251180951772614764383113614156422396181162\",\"price\":\"0.35\",\"size\":\"50\",\"side\":\"SELL\",\"hash\":\"de61b86e86c8274f791d80f297ce390dce6054b4\",\"best_bid\":\"0.036\",\"best_ask\":\"0.038\"}],\"timestamp\":\"1786689782835\",\"event_type\":\"price_change\"}"}
{"recv_ts": 1786689782872885, "venue": "polymarket", "raw": "{\"market\":\"0xd9fb1184af0064e5e34b129f5b79afa5a17b7e32f2953ab05efed82315fee6d4\",\"price_changes\":[{\"asset_id\":\"90772332434487149264114862115632028379978765245278600275169585501290867536237\",\"price\":\"0.64\",\"size\":\"234\",\"side\":\"BUY\",\"hash\":\"08016574ec4a608ae7af557e6eba7dcd60dc143a\",\"best_bid\":\"0.962\",\"best_ask\":\"0.964\"},{\"asset_id\":\"94559586571241563470235664821564670251180951772614764383113614156422396181162\",\"price\":\"0.36\",\"size\":\"234\",\"side\":\"SELL\",\"hash\":\"38d6948ab7bd625c54ea8d0284ca0c812aad29c1\",\"best_bid\":\"0.036\",\"best_ask\":\"0.038\"}],\"timestamp\":\"1786689782867\",\"event_type\":\"price_change\"}"}
{"recv_ts": 1786689784006822, "venue": "polymarket", "raw": "{\"market\":\"0xbb4d51e6364066d92eb6f9b8413dd7193de70966736044463b205834805a1f3b\",\"price_changes\":[{\"asset_id\":\"106181075047366745139197108801635573283215248045056329679360376976893016488727\",\"price\":\"0.91\",\"size\":\"157492.46\",\"side\":\"BUY\",\"hash\":\"683a48dace702d5b91f88c5bf292257410ed8f13\",\"best_bid\":\"0.93\",\"best_ask\":\"0.94\"},{\"asset_id\":\"10991849228756847439673778874175365458450913336396982752046655649803657501964\",\"price\":\"0.09\",\"size\":\"157492.46\",\"side\":\"SELL\",\"hash\":\"f1d95679177123f44dbdc64c61d26a7927bbb2ee\",\"best_bid\":\"0.06\",\"best_ask\":\"0.07\"}],\"timestamp\":\"1786689784000\",\"event_type\":\"price_change\"}"}
{"recv_ts": 1786689784006899, "venue": "polymarket", "raw": "{\"market\":\"0xbb4d51e6364066d92eb6f9b8413dd7193de70966736044463b205834805a1f3b\",\"price_changes\":[{\"asset_id\":\"10991849228756847439673778874175365458450913336396982752046655649803657501964\",\"price\":\"0.05\",\"size\":\"456672.25\",\"side\":\"BUY\",\"hash\":\"f1d95679177123f44dbdc64c61d26a7927bbb2ee\",\"best_bid\":\"0.06\",\"best_ask\":\"0.07\"},{\"asset_id\":\"106181075047366745139197108801635573283215248045056329679360376976893016488727\",\"price\":\"0.95\",\"size\":\"456672.25\",\"side\":\"SELL\",\"hash\":\"683a48dace702d5b91f88c5bf292257410ed8f13\",\"best_bid\":\"0.93\",\"best_ask\":\"0.94\"}],\"timestamp\":\"1786689784000\",\"event_type\":\"price_change\"}"}
{"recv_ts": 1786689784143805, "venue": "polymarket", "raw": "{\"market\":\"0xbb4d51e6364066d92eb6f9b8413dd7193de70966736044463b205834805a1f3b\",\"price_changes\":[{\"asset_id\":\"10991849228756847439673778874175365458450913336396982752046655649803657501964\",\"price\":\"0.04\",\"size\":\"469217.56\",\"side\":\"BUY\",\"hash\":\"902fb3acbe3874c44a3c3d3a0cf001705f799149\",\"best_bid\":\"0.06\",\"best_ask\":\"0.07\"},{\"asset_id\":\"106181075047366745139197108801635573283215248045056329679360376976893016488727\",\"price\":\"0.96\",\"size\":\"469217.56\",\"side\":\"SELL\",\"hash\":\"9be3e5a0eca44fb362becea978db9f6e9ed0a7ba\",\"best_bid\":\"0.93\",\"best_ask\":\"0.94\"}],\"timestamp\":\"1786689784137\",\"event_type\":\"price_change\"}"}
{"recv_ts": 1786689787753425, "venue": "polymarket", "raw": "{\"market\":\"0xd595eb9b81885ff018738300c79047e3ec89e87294424f57a29a7fa9162bf116\",\"price_changes\":[{\"asset_id\":\"57216272564529548464686463691236811991956032201293786790337952253964682584376\",\"price\":\"0.961\",\"size\":\"41128.18\",\"side\":\"BUY\",\"hash\":\"fd498c6e5afe8a11a49cee06a787b4c8adbb68a2\",\"best_bid\":\"0.963\",\"best_ask\":\"0.964\"},{\"asset_id\":\"5161623255678193352839985156330393796378434470119114669671615782853260939535\",\"price\":\"0.039\",\"size\":\"41128.18\",\"side\":\"SELL\",\"hash\":\"f5cb752a030b9f5b1205e8904ceca4375748761a\",\"best_bid\":\"0.036\",\"best_ask\":\"0.037\"}],\"timestamp\":\"1786689787748\",\"event_type\":\"price_change\"}"}
{"recv_ts": 1786689787815536, "venue": "polymarket", "raw": "{\"market\":\"0xd595eb9b81885ff018738300c79047e3ec89e87294424f57a29a7fa9162bf116\",\"price_changes\":[{\"asset_id\":\"57216272564529548464686463691236811991956032201293786790337952253964682584376\",\"price\":\"0.96\",\"size\":\"100\",\"side\":\"BUY\",\"hash\":\"9c6428af56a55818b367c215b62a533f0484ca48\",\"best_bid\":\"0.963\",\"best_ask\":\"0.964\"},{\"asset_id\":\"5161623255678193352839985156330393796378434470119114669671615782853260939535\",\"price\":\"0.04\",\"size\":\"100\",\"side\":\"SELL\",\"hash\":\"833c38e6e4e6bf83cdb72fac7dbbca47ac2cde8c\",\"best_bid\":\"0.036\",\"best_ask\":\"0.037\"}],\"timestamp\":\"1786689787810\",\"event_type\":\"price_change\"}"}
{"recv_ts": 1786689787879324, "venue": "polymarket", "raw": "{\"market\":\"0xd595eb9b81885ff018738300c79047e3ec89e87294424f57a29a7fa9162bf116\",\"price_changes\":[{\"asset_id\":\"57216272564529548464686463691236811991956032201293786790337952253964682584376\",\"price\":\"0.959\",\"size\":\"300\",\"side\":\"BUY\",\"hash\":\"dc8b1e527fabce3f9728946df32eeac9f50d35bf\",\"best_bid\":\"0.963\",\"best_ask\":\"0.964\"},{\"asset_id\":\"5161623255678193352839985156330393796378434470119114669671615782853260939535\",\"price\":\"0.041\",\"size\":\"300\",\"side\":\"SELL\",\"hash\":\"0e3b460d629521dbf6d127d2d3ee41e50bb4ebc4\",\"best_bid\":\"0.036\",\"best_ask\":\"0.037\"}],\"timestamp\":\"1786689787874\",\"event_type\":\"price_change\"}"}
{"recv_ts": 1786689789005669, "venue": "polymarket", "raw": "{\"market\":\"0x747dc809fb79e1b05be09c42d6179459a58de2ef3e40f02484a4e1260f741f75\",\"price_changes\":[{\"asset_id\":\"7305630249804085635496399869905769372294302716159034447326228509068694952392\",\"price\":\"0.3\",\"size\":\"6200\",\"side\":\"BUY\",\"hash\":\"c59f8e744da5e086fefabc389145d34e61780804\",\"best_bid\":\"0.95\",\"best_ask\":\"0.96\"},{\"asset_id\":\"107505882767731489358349912513945399560393482969656700824895970500493757150417\",\"price\":\"0.7\",\"size\":\"6200\",\"side\":\"SELL\",\"hash\":\"2fc09c0c6d639221e13c1b3d1f46cf4699c0e2ce\",\"best_bid\":\"0.04\",\"best_ask\":\"0.05\"}],\"timestamp\":\"1786689789000\",\"event_type\":\"price_change\"}"}
{"recv_ts": 1786689789005972, "venue": "polymarket", "raw": "{\"market\":\"0x747dc809fb79e1b05be09c42d6179459a58de2ef3e40f02484a4e1260f741f75\",\"price_changes\":[{\"asset_id\":\"7305630249804085635496399869905769372294302716159034447326228509068694952392\",\"price\":\"0.2\",\"size\":\"9900\",\"side\":\"BUY\",\"hash\":\"f043c2e53103b705b932aa9a57fb6e1be3c2f89b\",\"best_bid\":\"0.95\",\"best_ask\":\"0.96\"},{\"asset_id\":\"107505882767731489358349912513945399560393482969656700824895970500493757150417\",\"price\":\"0.8\",\"size\":\"9900\",\"side\":\"SELL\",\"hash\":\"e57aaa24d8e0f21c6371b68f5718cd1e27f2a7ad\",\"best_bid\":\"0.04\",\"best_ask\":\"0.05\"}],\"timestamp\":\"1786689789001\",\"event_type\":\"price_change\"}"}
{"recv_ts": 1786689789006885, "venue": "polymarket", "raw": "{\"market\":\"0x747dc809fb79e1b05be09c42d6179459a58de2ef3e40f02484a4e1260f741f75\",\"price_changes\":[{\"asset_id\":\"7305630249804085635496399869905769372294302716159034447326228509068694952392\",\"price\":\"0.4\",\"size\":\"4388\",\"side\":\"BUY\",\"hash\":\"f043c2e53103b705b932aa9a57fb6e1be3c2f89b\",\"best_bid\":\"0.95\",\"best_ask\":\"0.96\"},{\"asset_id\":\"107505882767731489358349912513945399560393482969656700824895970500493757150417\",\"price\":\"0.6\",\"size\":\"4388\",\"side\":\"SELL\",\"hash\":\"e57aaa24d8e0f21c6371b68f5718cd1e27f2a7ad\",\"best_bid\":\"0.04\",\"best_ask\":\"0.05\"}],\"timestamp\":\"1786689789001\",\"event_type\":\"price_change\"}"}
{"recv_ts": 1786689789007303, "venue": "polymarket", "raw": "{\"market\":\"0x747dc809fb79e1b05be09c42d6179459a58de2ef3e40f02484a4e1260f741f75\",\"price_changes\":[{\"asset_id\":\"7305630249804085635496399869905769372294302716159034447326228509068694952392\",\"price\":\"0.1\",\"size\":\"4301.03\",\"side\":\"BUY\",\"hash\":\"f043c2e53103b705b932aa9a57fb6e1be3c2f89b\",\"best_bid\":\"0.95\",\"best_ask\":\"0.96\"},{\"asset_id\":\"107505882767731489358349912513945399560393482969656700824895970500493757150417\",\"price\":\"0.9\",\"size\":\"4301.03\",\"side\":\"SELL\",\"hash\":\"e57aaa24d8e0f21c6371b68f5718cd1e27f2a7ad\",\"best_bid\":\"0.04\",\"best_ask\":\"0.05\"}],\"timestamp\":\"1786689789001\",\"event_type\":\"price_change\"}"}
{"recv_ts": 1786689789251634, "venue": "polymarket", "raw": "{\"market\":\"0xbb4d51e6364066d92eb6f9b8413dd7193de70966736044463b205834805a1f3b\",\"price_changes\":[{\"asset_id\":\"10991849228756847439673778874175365458450913336396982752046655649803657501964\",\"price\":\"0.04\",\"size\":\"479216.56\",\"side\":\"BUY\",\"hash\":\"2f1134b723244444ef23d31c948eaa17b3d87a7a\",\"best_bid\":\"0.06\",\"best_ask\":\"0.07\"},{\"asset_id\":\"106181075047366745139197108801635573283215248045056329679360376976893016488727\",\"price\":\"0.96\",\"size\":\"479216.56\",\"side\":\"SELL\",\"hash\":\"ef14674b2370f242786a166bd9f7b71c61481ca7\",\"best_bid\":\"0.93\",\"best_ask\":\"0.94\"}],\"timestamp\":\"1786689789246\",\"event_type\":\"price_change\"}"}
{"recv_ts": 1786689792207392, "venue": "polymarket", "raw": "{\"market\":\"0x747dc809fb79e1b05be09c42d6179459a58de2ef3e40f02484a4e1260f741f75\",\"price_changes\":[{\"asset_id\":\"7305630249804085635496399869905769372294302716159034447326228509068694952392\",\"price\":\"0.1\",\"size\":\"16301.03\",\"side\":\"BUY\",\"hash\":\"f0ac3ea778bf07a8e1454cfa497fdbec74e84e24\",\"best_bid\":\"0.95\",\"best_ask\":\"0.96\"},{\"asset_id\":\"107505882767731489358349912513945399560393482969656700824895970500493757150417\",\"price\":\"0.9\",\"size\":\"16301.03\",\"side\":\"SELL\",\"hash\":\"c95880989bee16c0f0a3c0756f03e457719245b9\",\"best_bid\":\"0.04\",\"best_ask\":\"0.05\"}],\"timestamp\":\"1786689792200\",\"event_type\":\"price_change\"}"}
{"recv_ts": 1786689792207467, "venue": "polymarket", "raw": "{\"market\":\"0x747dc809fb79e1b05be09c42d6179459a58de2ef3e40f02484a4e1260f741f75\",\"price_changes\":[{\"asset_id\":\"7305630249804085635496399869905769372294302716159034447326228509068694952392\",\"price\":\"0.4\",\"size\":\"5638\",\"side\":\"BUY\",\"hash\":\"23aacb66f4307b126fb1013df7a6771a30c1d7f7\",\"best_bid\":\"0.95\",\"best_ask\":\"0.96\"},{\"asset_id\":\"107505882767731489358349912513945399560393482969656700824895970500493757150417\",\"price\":\"0.6\",\"size\":\"5638\",\"side\":\"SELL\",\"hash\":\"f00bcb7bc4fa4d2a16216439cd5f1ea8c9f0236d\",\"best_bid\":\"0.04\",\"best_ask\":\"0.05\"}],\"timestamp\":\"1786689792201\",\"event_type\":\"price_change\"}"}
{"recv_ts": 1786689792207754, "venue": "polymarket", "raw": "{\"market\":\"0x747dc809fb79e1b05be09c42d6179459a58de2ef3e40f02484a4e1260f741f75\",\"price_changes\":[{\"asset_id\":\"7305630249804085635496399869905769372294302716159034447326228509068694952392\",\"price\":\"0.3\",\"size\":\"9200\",\"side\":\"BUY\",\"hash\":\"ab8efe92aab75aa2847e33c371466505c0be31d3\",\"best_bid\":\"0.95\",\"best_ask\":\"0.96\"},{\"asset_id\":\"107505882767731489358349912513945399560393482969656700824895970500493757150417\",\"price\":\"0.7\",\"size\":\"9200\",\"side\":\"SELL\",\"hash\":\"8f03ae7660d453f9b4feae0b03e0d712c6bd5905\",\"best_bid\":\"0.04\",\"best_ask\":\"0.05\"}],\"timestamp\":\"1786689792201\",\"event_type\":\"price_change\"}"}
{"recv_ts": 1786689792208095, "venue": "polymarket", "raw": "{\"market\":\"0x747dc809fb79e1b05be09c42d6179459a58de2ef3e40f02484a4e1260f741f75\",\"price_changes\":[{\"asset_id\":\"7305630249804085635496399869905769372294302716159034447326228509068694952392\",\"price\":\"0.2\",\"size\":\"14900\",\"side\":\"BUY\",\"hash\":\"9333e31a50227baad9b175911fd1a7b1e55ef20d\",\"best_bid\":\"0.95\",\"best_ask\":\"0.96\"},{\"asset_id\":\"107505882767731489358349912513945399560393482969656700824895970500493757150417\",\"price\":\"0.8\",\"size\":\"14900\",\"side\":\"SELL\",\"hash\":\"1364f6378fc2b6a9716e41414d9eb8b84786e3c9\",\"best_bid\":\"0.04\",\"best_ask\":\"0.05\"}],\"timestamp\":\"1786689792202\",\"event_type\":\"price_change\"}"}
{"recv_ts": 1786689793006655, "venue": "polymarket", "raw": "{\"market\":\"0xbb4d51e6364066d92eb6f9b8413dd7193de70966736044463b205834805a1f3b\",\"price_changes\":[{\"asset_id\":\"10991849228756847439673778874175365458450913336396982752046655649803657501964\",\"price\":\"0.03\",\"size\":\"244508.97\",\"side\":\"BUY\",\"hash\":\"1a6d9c2d8d07491b374342629677885b76d13721\",\"best_bid\":\"0.06\",\"best_ask\":\"0.07\"},{\"asset_id\":\"106181075047366745139197108801635573283215248045056329679360376976893016488727\",\"price\":\"0.97\",\"size\":\"244508.97\",\"side\":\"SELL\",\"hash\":\"951f4b4624d264ac36c426bb9682de2d6df7069f\",\"best_bid\":\"0.93\",\"best_ask\":\"0.94\"}],\"timestamp\":\"1786689793000\",\"event_type\":\"price_change\"}"}
{"recv_ts": 1786689794380419, "venue": "polymarket", "raw": "{\"market\":\"0xbb4d51e6364066d92eb6f9b8413dd7193de70966736044463b205834805a1f3b\",\"price_changes\":[{\"asset_id\":\"10991849228756847439673778874175365458450913336396982752046655649803657501964\",\"price\":\"0.03\",\"size\":\"254075.97\",\"side\":\"BUY\",\"hash\":\"46a4ed360644e5e35935748e1614f17cd3c3e619\",\"best_bid\":\"0.06\",\"best_ask\":\"0.07\"},{\"asset_id\":\"106181075047366745139197108801635573283215248045056329679360376976893016488727\",\"price\":\"0.97\",\"size\":\"254075.97\",\"side\":\"SELL\",\"hash\":\"326d7b2fe9cc5910dd8645f5d4e983ed4def5036\",\"best_bid\":\"0.93\",\"best_ask\":\"0.94\"}],\"timestamp\":\"1786689794374\",\"event_type\":\"price_change\"}"}
{"recv_ts": 1786689794415531, "venue": "polymarket", "raw": "{\"market\":\"0xd9fb1184af0064e5e34b129f5b79afa5a17b7e32f2953ab05efed82315fee6d4\",\"price_changes\":[{\"asset_id\":\"90772332434487149264114862115632028379978765245278600275169585501290867536237\",\"price\":\"0.96\",\"size\":\"38445.56\",\"side\":\"BUY\",\"hash\":\"2d080a43b3fb6b04707da5f200d4b2c9e05e718b\",\"best_bid\":\"0.962\",\"best_ask\":\"0.964\"},{\"asset_id\":\"94559586571241563470235664821564670251180951772614764383113614156422396181162\",\"price\":\"0.04\",\"size\":\"38445.56\",\"side\":\"SELL\",\"hash\":\"97b2566d12698ac10d242a77de5815539e8343cd\",\"best_bid\":\"0.036\",\"best_ask\":\"0.038\"}],\"timestamp\":\"1786689794410\",\"event_type\":\"price_change\"}"}
{"recv_ts": 1786689797009125, "venue": "polymarket", "raw": "{\"market\":\"0xd595eb9b81885ff018738300c79047e3ec89e87294424f57a29a7fa9162bf116\",\"price_changes\":[{\"asset_id\":\"57216272564529548464686463691236811991956032201293786790337952253964682584376\",\"price\":\"0.3\",\"size\":\"354\",\"side\":\"BUY\",\"hash\":\"0995562e5023057cc7cbdcee70795582aee342e9\",\"best_bid\":\"0.963\",\"best_ask\":\"0.964\"},{\"asset_id\":\"5161623255678193352839985156330393796378434470119114669671615782853260939535\",\"price\":\"0.7\",\"size\":\"354\",\"side\":\"SELL\",\"hash\":\"2e060b7801937e9639cb6ce7253a1b61974a2aef\",\"best_bid\":\"0.036\",\"best_ask\":\"0.037\"}],\"timestamp\":\"1786689797000\",\"event_type\":\"price_change\"}"}
{"recv_ts": 1786689797010863, "venue": "polymarket", "raw": "{\"market\":\"0xd595eb9b81885ff018738300c79047e3ec89e87294424f57a29a7fa9162bf116\",\"price_changes\":[{\"asset_id\":\"57216272564529548464686463691236811991956032201293786790337952253964682584376\",\"price\":\"0.2\",\"size\":\"0\",\"side\":\"BUY\",\"hash\":\"eef3c4bb50b0dd3a02c82b7dbdff9fe127251f29\",\"best_bid\":\"0.963\",\"best_ask\":\"0.964\"},{\"asset_id\":\"5161623255678193352839985156330393796378434470119114669671615782853260939535\",\"price\":\"0.8\",\"size\":\"0\",\"side\":\"SELL\",\"hash\":\"e8a2ab27bd00925a2cd0b81db0e87f4d8619a7bd\",\"best_bid\":\"0.036\",\"best_ask\":\"0.037\"}],\"timestamp\":\"1786689797001\",\"event_type\":\"price_change\"}"}
{"recv_ts": 1786689797010916, "venue": "polymarket", "raw": "{\"market\":\"0xd595eb9b81885ff018738300c79047e3ec89e87294424f57a29a7fa9162bf116\",\"price_changes\":[{\"asset_id\":\"57216272564529548464686463691236811991956032201293786790337952253964682584376\",\"price\":\"0.4\",\"size\":\"88\",\"side\":\"BUY\",\"hash\":\"96601d6c855be49b786405a5ba98d3a8d488e726\",\"best_bid\":\"0.963\",\"best_ask\":\"0.964\"},{\"asset_id\":\"5161623255678193352839985156330393796378434470119114669671615782853260939535\",\"price\":\"0.6\",\"size\":\"88\",\"side\":\"SELL\",\"hash\":\"f27f077e2ad7f61ed1ef3f5d41cf0705c75dfa16\",\"best_bid\":\"0.036\",\"best_ask\":\"0.037\"}],\"timestamp\":\"1786689797002\",\"event_type\":\"price_change\"}"}
{"recv_ts": 1786689801008270, "venue": "polymarket", "raw": "{\"market\":\"0x6bd56627aa21311850825edb27e53434a0e17a4f782be0086bc07f71eee00d0d\",\"price_changes\":[{\"asset_id\":\"87073899845581463485186346288398658568334162612963837182986759797304993556208\",\"price\":\"0.5\",\"size\":\"274.62\",\"side\":\"BUY\",\"hash\":\"0e4a0b056c72e908c6bd3a4fc9674592b8e991a4\",\"best_bid\":\"0.92\",\"best_ask\":\"0.93\"},{\"asset_id\":\"350977769852917329387037893294763093471844346281449484439085576212613048126\",\"price\":\"0.5\",\"size\":\"274.62\",\"side\":\"SELL\",\"hash\":\"0aacce4acb2249b2d686c62f8ef674a5e909e598\",\"best_bid\":\"0.07\",\"best_ask\":\"0.08\"}],\"timestamp\":\"1786689801001\",\"event_type\":\"price_change\"}"}
{"recv_ts": 1786689801008550, "venue": "polymarket", "raw": "{\"market\":\"0xbb4d51e6364066d92eb6f9b8413dd7193de70966736044463b205834805a1f3b\",\"price_changes\":[{\"asset_id\":\"10991849228756847439673778874175365458450913336396982752046655649803657501964\",\"price\":\"0.03\",\"size\":\"244541.97\",\"side\":\"BUY\",\"hash\":\"29e40aac4ef9c4d8476f29f51b12606a9863a6d5\",\"best_bid\":\"0.06\",\"best_ask\":\"0.07\"},{\"asset_id\":\"106181075047366745139197108801635573283215248045056329679360376976893016488727\",\"price\":\"0.97\",\"size\":\"244541.97\",\"side\":\"SELL\",\"hash\":\"eafcb2ad6078820f4d57270433090bcd5d55b0c8\",\"best_bid\":\"0.93\",\"best_ask\":\"0.94\"}],\"timestamp\":\"1786689801000\",\"event_type\":\"price_change\"}"}
{"recv_ts": 1786689801734448, "venue": "polymarket", "raw": "{\"market\":\"0xd595eb9b81885ff018738300c79047e3ec89e87294424f57a29a7fa9162bf116\",\"price_changes\":[{\"asset_id\":\"57216272564529548464686463691236811991956032201293786790337952253964682584376\",\"price\":\"0.4\",\"size\":\"4088\",\"side\":\"BUY\",\"hash\":\"c6c76147d145b1c74e1fd989cd583db4577d46f6\",\"best_bid\":\"0.963\",\"best_ask\":\"0.964\"},{\"asset_id\":\"5161623255678193352839985156330393796378434470119114669671615782853260939535\",\"price\":\"0.6\",\"size\":\"4088\",\"side\":\"SELL\",\"hash\":\"c8cf4380c01fcd6223286b0545049a0f26a469c2\",\"best_bid\":\"0.036\",\"best_ask\":\"0.037\"}],\"timestamp\":\"1786689801729\",\"event_type\":\"price_change\"}"}
{"recv_ts": 1786689801735891, "venue": "polymarket", "raw": "{\"market\":\"0xd595eb9b81885ff018738300c79047e3ec89e87294424f57a29a7fa9162bf116\",\"price_changes\":[{\"asset_id\":\"57216272564529548464686463691236811991956032201293786790337952253964682584376\",\"price\":\"0.3\",\"size\":\"6020\",\"side\":\"BUY\",\"hash\":\"d954633487b224a50e7b1f0e71445417fb247fc1\",\"best_bid\":\"0.963\",\"best_ask\":\"0.964\"},{\"asset_id\":\"5161623255678193352839985156330393796378434470119114669671615782853260939535\",\"price\":\"0.7\",\"size\":\"6020\",\"side\":\"SELL\",\"hash\":\"fedeb370415cfe69b6323666567cbaadf6085ac3\",\"best_bid\":\"0.036\",\"best_ask\":\"0.037\"}],\"timestamp\":\"1786689801730\",\"event_type\":\"price_change\"}"}
{"recv_ts": 1786689801735939, "venue": "polymarket", "raw": "{\"market\":\"0xd595eb9b81885ff018738300c79047e3ec89e87294424f57a29a7fa9162bf116\",\"price_changes\":[{\"asset_id\":\"57216272564529548464686463691236811991956032201293786790337952253964682584376\",\"price\":\"0.2\",\"size\":\"9000\",\"side\":\"BUY\",\"hash\":\"1b433e67be706b1106c3b267f229aad793b6f6a3\",\"best_bid\":\"0.963\",\"best_ask\":\"0.964\"},{\"asset_id\":\"5161623255678193352839985156330393796378434470119114669671615782853260939535\",\"price\":\"0.8\",\"size\":\"9000\",\"side\":\"SELL\",\"hash\":\"cbfe8fde92188c98cec57e5793295badf6d5ac47\",\"best_bid\":\"0.036\",\"best_ask\":\"0.037\"}],\"timestamp\":\"1786689801730\",\"event_type\":\"price_change\"}"}
{"recv_ts": 1786689802007264, "venue": "polymarket", "raw": "{\"market\":\"0x747dc809fb79e1b05be09c42d6179459a58de2ef3e40f02484a4e1260f741f75\",\"price_changes\":[{\"asset_id\":\"7305630249804085635496399869905769372294302716159034447326228509068694952392\",\"price\":\"0.6\",\"size\":\"387\",\"side\":\"BUY\",\"hash\":\"0daa0be7a34d7c230b3319a33e8d8e3058993158\",\"best_bid\":\"0.95\",\"best_ask\":\"0.96\"},{\"asset_id\":\"107505882767731489358349912513945399560393482969656700824895970500493757150417\",\"price\":\"0.4\",\"size\":\"387\",\"side\":\"SELL\",\"hash\":\"6d2e7285f71d4d879e3f694d04554d6642c5a2d2\",\"best_bid\":\"0.04\",\"best_ask\":\"0.05\"}],\"timestamp\":\"1786689802000\",\"event_type\":\"price_change\"}"}
{"recv_ts": 1786689802275961, "venue": "polymarket", "raw": "{\"market\":\"0xd9fb1184af0064e5e34b129f5b79afa5a17b7e32f2953ab05efed82315fee6d4\",\"price_changes\":[{\"asset_id\":\"94559586571241563470235664821564670251180951772614764383113614156422396181162\",\"price\":\"0.026\",\"size\":\"9673.96\",\"side\":\"BUY\",\"hash\":\"911a9699cda561ad5a1404d69da67ab4af9c15d6\",\"best_bid\":\"0.036\",\"best_ask\":\"0.038\"},{\"asset_id\":\"90772332434487149264114862115632028379978765245278600275169585501290867536237\",\"price\":\"0.974\",\"size\":\"9673.96\",\"side\":\"SELL\",\"hash\":\"2ef35f0d6c9302ec781060c532ed51a0f44a020e\",\"best_bid\":\"0.962\",\"best_ask\":\"0.964\"}],\"timestamp\":\"1786689802269\",\"event_type\":\"price_change\"}"}
{"recv_ts": 1786689802276027, "venue": "polymarket", "raw": "{\"market\":\"0x747dc809fb79e1b05be09c42d6179459a58de2ef3e40f02484a4e1260f741f75\",\"price_changes\":[{\"asset_id\":\"7305630249804085635496399869905769372294302716159034447326228509068694952392\",\"price\":\"0.94\",\"size\":\"121927.12\",\"side\":\"BUY\",\"hash\":\"73863761c591777c7462df2ab9edf2e5ee8e8c44\",\"best_bid\":\"0.95\",\"best_ask\":\"0.96\"},{\"asset_id\":\"107505882767731489358349912513945399560393482969656700824895970500493757150417\",\"price\":\"0.06\",\"size\":\"121927.12\",\"side\":\"SELL\",\"hash\":\"5eeaa309f95c3d36a134b10508b122d4db9188db\",\"best_bid\":\"0.04\",\"best_ask\":\"0.05\"}],\"timestamp\":\"1786689802269\",\"event_type\":\"price_change\"}"}
{"recv_ts": 1786689802276042, "venue": "polymarket", "raw": "{\"market\":\"0xd9fb1184af0064e5e34b129f5b79afa5a17b7e32f2953ab05efed82315fee6d4\",\"price_changes\":[{\"asset_id\":\"90772332434487149264114862115632028379978765245278600275169585501290867536237\",\"price\":\"0.952\",\"size\":\"13651.11\",\"side\":\"BUY\",\"hash\":\"2ef35f0d6c9302ec781060c532ed51a0f44a020e\",\"best_bid\":\"0.962\",\"best_ask\":\"0.964\"},{\"asset_id\":\"94559586571241563470235664821564670251180951772614764383113614156422396181162\",\"price\":\"0.048\",\"size\":\"13651.11\",\"side\":\"SELL\",\"hash\":\"911a9699cda561ad5a1404d69da67ab4af9c15d6\",\"best_bid\":\"0.036\",\"best_ask\":\"0.038\"}],\"timestamp\":\"1786689802269\",\"event_type\":\"price_change\"}"}
{"recv_ts": 1786689802276055, "venue": "polymarket", "raw": "{\"market\":\"0x747dc809fb79e1b05be09c42d6179459a58de2ef3e40f02484a4e1260f741f75\",\"price_changes\":[{\"asset_id\":\"107505882767731489358349912513945399560393482969656700824895970500493757150417\",\"price\":\"0.03\",\"size\":\"355011.26\",\"side\":\"BUY\",\"hash\":\"5eeaa309f95c3d36a134b10508b122d4db9188db\",\"best_bid\":\"0.04\",\"best_ask\":\"0.05\"},{\"asset_id\":\"7305630249804085635496399869905769372294302716159034447326228509068694952392\",\"price\":\"0.97\",\"size\":\"355011.26\",\"side\":\"SELL\",\"hash\":\"73863761c591777c7462df2ab9edf2e5ee8e8c44\",\"best_bid\":\"0.95\",\"best_ask\":\"0.96\"}],\"timestamp\":\"1786689802269\",\"event_type\":\"price_change\"}"}
{"recv_ts": 1786689803211440, "venue": "polymarket", "raw": "{\"market\":\"0xd595eb9b81885ff018738300c79047e3ec89e87294424f57a29a7fa9162bf116\",\"price_changes\":[{\"asset_id\":\"57216272564529548464686463691236811991956032201293786790337952253964682584376\",\"price\":\"0.961\",\"size\":\"41133.18\",\"side\":\"BUY\",\"hash\":\"e127a247aa957f0f1aebe3dd7623e93751fa34d3\",\"best_bid\":\"0.963\",\"best_ask\":\"0.964\"},{\"asset_id\":\"5161623255678193352839985156330393796378434470119114669671615782853260939535\",\"price\":\"0.039\",\"size\":\"41133.18\",\"side\":\"SELL\",\"hash\":\"f7dd1bf544263ed4a6603339234eb75a8508b1b8\",\"best_bid\":\"0.036\",\"best_ask\":\"0.037\"}],\"timestamp\":\"1786689803206\",\"event_type\":\"price_change\"}"}
{"recv_ts": 1786689803292350, "venue": "polymarket", "raw": "{\"market\":\"0xd595eb9b81885ff018738300c79047e3ec89e87294424f57a29a7fa9162bf116\",\"price_changes\":[{\"asset_id\":\"57216272564529548464686463691236811991956032201293786790337952253964682584376\",\"price\":\"0.96\",\"size\":\"115\",\"side\":\"BUY\",\"hash\":\"8356971543d22bc64b088b8d8a1dc4a7f866dc43\",\"best_bid\":\"0.963\",\"best_ask\":\"0.964\"},{\"asset_id\":\"5161623255678193352839985156330393796378434470119114669671615782853260939535\",\"price\":\"0.04\",\"size\":\"115\",\"side\":\"SELL\",\"hash\":\"3d0c98292884fd56c8c5750f7a16687080f46a51\",\"best_bid\":\"0.036\",\"best_ask\":\"0.037\"}],\"timestamp\":\"1786689803286\",\"event_type\":\"price_change\"}"}
{"recv_ts": 1786689803371666, "venue": "polymarket", "raw": "{\"market\":\"0xd595eb9b81885ff018738300c79047e3ec89e87294424f57a29a7fa9162bf116\",\"price_changes\":[{\"asset_id\":\"57216272564529548464686463691236811991956032201293786790337952253964682584376\",\"price\":\"0.959\",\"size\":\"330\",\"side\":\"BUY\",\"hash\":\"7e098f020e2a9bcca95a2b363a39d7128617c303\",\"best_bid\":\"0.963\",\"best_ask\":\"0.964\"},{\"asset_id\":\"5161623255678193352839985156330393796378434470119114669671615782853260939535\",\"price\":\"0.041\",\"size\":\"330\",\"side\":\"SELL\",\"hash\":\"e761e03fb24c99764aa20145e5dee811292a36a9\",\"best_bid\":\"0.036\",\"best_ask\":\"0.037\"}],\"timestamp\":\"1786689803366\",\"event_type\":\"price_change\"}"}
{"recv_ts": 1786689804648922, "venue": "polymarket", "raw": "{\"market\":\"0x747dc809fb79e1b05be09c42d6179459a58de2ef3e40f02484a4e1260f741f75\",\"price_changes\":[{\"asset_id\":\"7305630249804085635496399869905769372294302716159034447326228509068694952392\",\"price\":\"0.6\",\"size\":\"803\",\"side\":\"BUY\",\"hash\":\"fb747531481ebc139f20100a09db8e17f98b14c9\",\"best_bid\":\"0.95\",\"best_ask\":\"0.96\"},{\"asset_id\":\"107505882767731489358349912513945399560393482969656700824895970500493757150417\",\"price\":\"0.4\",\"size\":\"803\",\"side\":\"SELL\",\"hash\":\"34ecdbb00e6812ff8ea422ba474c933a88748dd2\",\"best_bid\":\"0.04\",\"best_ask\":\"0.05\"}],\"timestamp\":\"1786689804642\",\"event_type\":\"price_change\"}"}
{"recv_ts": 1786689804785004, "venue": "polymarket", "raw": "{\"market\":\"0xd595eb9b81885ff018738300c79047e3ec89e87294424f57a29a7fa9162bf116\",\"price_changes\":[{\"asset_id\":\"57216272564529548464686463691236811991956032201293786790337952253964682584376\",\"price\":\"0.963\",\"size\":\"12870.97\",\"side\":\"BUY\",\"hash\":\"888ab38d9364e3242cce6b4ce285c5b795fdbcff\",\"best_bid\":\"0.963\",\"best_ask\":\"0.964\"},{\"asset_id\":\"5161623255678193352839985156330393796378434470119114669671615782853260939535\",\"price\":\"0.037\",\"size\":\"12870.97\",\"side\":\"SELL\",\"hash\":\"4cfa592a082996c84dc6be254aef0f434a30955f\",\"best_bid\":\"0.036\",\"best_ask\":\"0.037\"}],\"timestamp\":\"1786689804778\",\"event_type\":\"price_change\"}"}
{"recv_ts": 1786689805802440, "venue": "polymarket", "raw": "{\"market\":\"0xd595eb9b81885ff018738300c79047e3ec89e87294424f57a29a7fa9162bf116\",\"price_changes\":[{\"asset_id\":\"57216272564529548464686463691236811991956032201293786790337952253964682584376\",\"price\":\"0.963\",\"size\":\"12970.67\",\"side\":\"BUY\",\"hash\":\"6af53c5bb022c9d7f87e179ec3f63bf0e858be7f\",\"best_bid\":\"0.963\",\"best_ask\":\"0.964\"},{\"asset_id\":\"5161623255678193352839985156330393796378434470119114669671615782853260939535\",\"price\":\"0.037\",\"size\":\"12970.67\",\"side\":\"SELL\",\"hash\":\"7a7436f58d69fcd91311fee5564e65ea6789252f\",\"best_bid\":\"0.036\",\"best_ask\":\"0.037\"}],\"timestamp\":\"1786689805797\",\"event_type\":\"price_change\"}"}
{"recv_ts": 1786689805974435, "venue": "polymarket", "raw": "{\"market\":\"0x6bd56627aa21311850825edb27e53434a0e17a4f782be0086bc07f71eee00d0d\",\"price_changes\":[{\"asset_id\":\"87073899845581463485186346288398658568334162612963837182986759797304993556208\",\"price\":\"0.5\",\"size\":\"2674.62\",\"side\":\"BUY\",\"hash\":\"eed20cf3b9ee9ab133958d2dce122976f43e48e5\",\"best_bid\":\"0.92\",\"best_ask\":\"0.93\"},{\"asset_id\":\"350977769852917329387037893294763093471844346281449484439085576212613048126\",\"price\":\"0.5\",\"size\":\"2674.62\",\"side\":\"SELL\",\"hash\":\"e411c96925dbc73a58578e2a56efb47555157b23\",\"best_bid\":\"0.07\",\"best_ask\":\"0.08\"}],\"timestamp\":\"1786689805967\",\"event_type\":\"price_change\"}"}
{"recv_ts": 1786689806009030, "venue": "polymarket", "raw": "{\"market\":\"0xbb4d51e6364066d92eb6f9b8413dd7193de70966736044463b205834805a1f3b\",\"price_changes\":[{\"asset_id\":\"10991849228756847439673778874175365458450913336396982752046655649803657501964\",\"price\":\"0.05\",\"size\":\"456472.25\",\"side\":\"BUY\",\"hash\":\"d010c23cff3142dd776cf55e267654bff5fd8557\",\"best_bid\":\"0.06\",\"best_ask\":\"0.07\"},{\"asset_id\":\"106181075047366745139197108801635573283215248045056329679360376976893016488727\",\"price\":\"0.95\",\"size\":\"456472.25\",\"side\":\"SELL\",\"hash\":\"98244eb641bda4875ec23d8102948bef84804fd0\",\"best_bid\":\"0.93\",\"best_ask\":\"0.94\"}],\"timestamp\":\"1786689806001\",\"event_type\":\"price_change\"}"}
{"recv_ts": 1786689806009127, "venue": "polymarket", "raw": "{\"market\":\"0xd9fb1184af0064e5e34b129f5b79afa5a17b7e32f2953ab05efed82315fee6d4\",\"price_changes\":[{\"asset_id\":\"94559586571241563470235664821564670251180951772614764383113614156422396181162\",\"price\":\"0.024\",\"size\":\"4521\",\"side\":\"BUY\",\"hash\":\"28e9827b211ae7218000d514d45cc54831fc3626\",\"best_bid\":\"0.036\",\"best_ask\":\"0.038\"},{\"asset_id\":\"90772332434487149264114862115632028379978765245278600275169585501290867536237\",\"price\":\"0.976\",\"size\":\"4521\",\"side\":\"SELL\",\"hash\":\"8b70f60f3303b5c0697c075a3bb497f9e41448fc\",\"best_bid\":\"0.962\",\"best_ask\":\"0.964\"}],\"timestamp\":\"1786689806000\",\"event_type\":\"price_change\"}"}
{"recv_ts": 1786689806054766, "venue": "polymarket", "raw": "{\"market\":\"0xd9fb1184af0064e5e34b129f5b79afa5a17b7e32f2953ab05efed82315fee6d4\",\"price_changes\":[{\"asset_id\":\"94559586571241563470235664821564670251180951772614764383113614156422396181162\",\"price\":\"0.024\",\"size\":\"4721\",\"side\":\"BUY\",\"hash\":\"0252146c6372f65527847817048299621e360fba\",\"best_bid\":\"0.036\",\"best_ask\":\"0.038\"},{\"asset_id\":\"90772332434487149264114862115632028379978765245278600275169585501290867536237\",\"price\":\"0.976\",\"size\":\"4721\",\"side\":\"SELL\",\"hash\":\"f1aac48e6a9d08c7de2712d3206070e1489f615d\",\"best_bid\":\"0.962\",\"best_ask\":\"0.964\"}],\"timestamp\":\"1786689806047\",\"event_type\":\"price_change\"}"}
{"recv_ts": 1786689806111167, "venue": "polymarket", "raw": "{\"market\":\"0x6bd56627aa21311850825edb27e53434a0e17a4f782be0086bc07f71eee00d0d\",\"price_changes\":[{\"asset_id\":\"87073899845581463485186346288398658568334162612963837182986759797304993556208\",\"price\":\"0.9\",\"size\":\"78176.97\",\"side\":\"BUY\",\"hash\":\"8e9450bc5d80821363c972b5b034ca60a877fe65\",\"best_bid\":\"0.92\",\"best_ask\":\"0.93\"},{\"asset_id\":\"350977769852917329387037893294763093471844346281449484439085576212613048126\",\"price\":\"0.1\",\"size\":\"78176.97\",\"side\":\"SELL\",\"hash\":\"e9fa0e9bc0b4f95975fa68ccc27e1770c763df63\",\"best_bid\":\"0.07\",\"best_ask\":\"0.08\"}],\"timestamp\":\"1786689806105\",\"event_type\":\"price_change\"}"}
{"recv_ts": 1786689806263857, "venue": "polymarket", "raw": "{\"market\":\"0xbb4d51e6364066d92eb6f9b8413dd7193de70966736044463b205834805a1f3b\",\"price_changes\":[{\"asset_id\":\"10991849228756847439673778874175365458450913336396982752046655649803657501964\",\"price\":\"0.03\",\"size\":\"254075.97\",\"side\":\"BUY\",\"hash\":\"bc1f0bf45e15f17d98651747ad73c8e4d82b6ce8\",\"best_bid\":\"0.06\",\"best_ask\":\"0.07\"},{\"asset_id\":\"106181075047366745139197108801635573283215248045056329679360376976893016488727\",\"price\":\"0.97\",\"size\":\"254075.97\",\"side\":\"SELL\",\"hash\":\"29f92374f9c6c189f7ea97486deb3bd3e018777a\",\"best_bid\":\"0.93\",\"best_ask\":\"0.94\"}],\"timestamp\":\"1786689806256\",\"event_type\":\"price_change\"}"}
{"recv_ts": 1786689806770188, "venue": "polymarket", "raw": "{\"market\":\"0xd9fb1184af0064e5e34b129f5b79afa5a17b7e32f2953ab05efed82315fee6d4\",\"price_changes\":[{\"asset_id\":\"90772332434487149264114862115632028379978765245278600275169585501290867536237\",\"price\":\"0.952\",\"size\":\"13051.11\",\"side\":\"BUY\",\"hash\":\"9cf6791c1d37016383458f1beca41e037015e3dc\",\"best_bid\":\"0.962\",\"best_ask\":\"0.964\"},{\"asset_id\":\"94559586571241563470235664821564670251180951772614764383113614156422396181162\",\"price\":\"0.048\",\"size\":\"13051.11\",\"side\":\"SELL\",\"hash\":\"91feb2dbf206a83614c13ddde876c968dd2dfcde\",\"best_bid\":\"0.036\",\"best_ask\":\"0.038\"}],\"timestamp\":\"1786689806764\",\"event_type\":\"price_change\"}"}
{"recv_ts": 1786689806770266, "venue": "polymarket", "raw": "{\"market\":\"0xd9fb1184af0064e5e34b129f5b79afa5a17b7e32f2953ab05efed82315fee6d4\",\"price_changes\":[{\"asset_id\":\"94559586571241563470235664821564670251180951772614764383113614156422396181162\",\"price\":\"0.026\",\"size\":\"9073.96\",\"side\":\"BUY\",\"hash\":\"91feb2dbf206a83614c13ddde876c968dd2dfcde\",\"best_bid\":\"0.036\",\"best_ask\":\"0.038\"},{\"asset_id\":\"90772332434487149264114862115632028379978765245278600275169585501290867536237\",\"price\":\"0.974\",\"size\":\"9073.96\",\"side\":\"SELL\",\"hash\":\"9cf6791c1d37016383458f1beca41e037015e3dc\",\"best_bid\":\"0.962\",\"best_ask\":\"0.964\"}],\"timestamp\":\"1786689806764\",\"event_type\":\"price_change\"}"}
{"recv_ts": 1786689806770334, "venue": "polymarket", "raw": "{\"market\":\"0x747dc809fb79e1b05be09c42d6179459a58de2ef3e40f02484a4e1260f741f75\",\"price_changes\":[{\"asset_id\":\"7305630249804085635496399869905769372294302716159034447326228509068694952392\",\"price\":\"0.94\",\"size\":\"121327.12\",\"side\":\"BUY\",\"hash\":\"24d95fcac61a9f1805ad14c5aa08161da9d3f228\",\"best_bid\":\"0.95\",\"best_ask\":\"0.96\"},{\"asset_id\":\"107505882767731489358349912513945399560393482969656700824895970500493757150417\",\"price\":\"0.06\",\"size\":\"121327.12\",\"side\":\"SELL\",\"hash\":\"bb940e29b8e2fa88fc67b5c7e9ba0e0123f19a49\",\"best_bid\":\"0.04\",\"best_ask\":\"0.05\"}],\"timestamp\":\"1786689806764\",\"event_type\":\"price_change\"}"}
{"recv_ts": 1786689806770349, "venue": "polymarket", "raw": "{\"market\":\"0x747dc809fb79e1b05be09c42d6179459a58de2ef3e40f02484a4e1260f741f75\",\"price_changes\":[{\"asset_id\":\"107505882767731489358349912513945399560393482969656700824895970500493757150417\",\"price\":\"0.03\",\"size\":\"354411.26\",\"side\":\"BUY\",\"hash\":\"bb940e29b8e2fa88fc67b5c7e9ba0e0123f19a49\",\"best_bid\":\"0.04\",\"best_ask\":\"0.05\"},{\"asset_id\":\"7305630249804085635496399869905769372294302716159034447326228509068694952392\",\"price\":\"0.97\",\"size\":\"354411.26\",\"side\":\"SELL\",\"hash\":\"24d95fcac61a9f1805ad14c5aa08161da9d3f228\",\"best_bid\":\"0.95\",\"best_ask\":\"0.96\"}],\"timestamp\":\"1786689806764\",\"event_type\":\"price_change\"}"}
{"recv_ts": 1786689807005980, "venue": "polymarket", "raw": "{\"market\":\"0x747dc809fb79e1b05be09c42d6179459a58de2ef3e40f02484a4e1260f741f75\",\"price_changes\":[{\"asset_id\":\"7305630249804085635496399869905769372294302716159034447326228509068694952392\",\"price\":\"0.3\",\"size\":\"3534\",\"side\":\"BUY\",\"hash\":\"626ac325d6088941047f592bf88d24881feb93e1\",\"best_bid\":\"0.95\",\"best_ask\":\"0.96\"},{\"asset_id\":\"107505882767731489358349912513945399560393482969656700824895970500493757150417\",\"price\":\"0.7\",\"size\":\"3534\",\"side\":\"SELL\",\"hash\":\"1671f2e1234666850e7278af3affc34c65225433\",\"best_bid\":\"0.04\",\"best_ask\":\"0.05\"}],\"timestamp\":\"1786689807000\",\"event_type\":\"price_change\"}"}
{"recv_ts": 1786689807006160, "venue": "polymarket", "raw": "{\"market\":\"0x747dc809fb79e1b05be09c42d6179459a58de2ef3e40f02484a4e1260f741f75\",\"price_changes\":[{\"asset_id\":\"7305630249804085635496399869905769372294302716159034447326228509068694952392\",\"price\":\"0.2\",\"size\":\"5900\",\"side\":\"BUY\",\"hash\":\"626ac325d6088941047f592bf88d24881feb93e1\",\"best_bid\":\"0.95\",\"best_ask\":\"0.96\"},{\"asset_id\":\"107505882767731489358349912513945399560393482969656700824895970500493757150417\",\"price\":\"0.8\",\"size\":\"5900\",\"side\":\"SELL\",\"hash\":\"1671f2e1234666850e7278af3affc34c65225433\",\"best_bid\":\"0.04\",\"best_ask\":\"0.05\"}],\"timestamp\":\"1786689807000\",\"event_type\":\"price_change\"}"}
{"recv_ts": 1786689807007762, "venue": "polymarket", "raw": "{\"market\":\"0x747dc809fb79e1b05be09c42d6179459a58de2ef3e40f02484a4e1260f741f75\",\"price_changes\":[{\"asset_id\":\"7305630249804085635496399869905769372294302716159034447326228509068694952392\",\"price\":\"0.4\",\"size\":\"1638\",\"side\":\"BUY\",\"hash\":\"37cecad6e9b3d3d085cabe6b99cf7082a27fd873\",\"best_bid\":\"0.95\",\"best_ask\":\"0.96\"},{\"asset_id\":\"107505882767731489358349912513945399560393482969656700824895970500493757150417\",\"price\":\"0.6\",\"size\":\"1638\",\"side\":\"SELL\",\"hash\":\"951fdceb1b45d65875f6ba09cfc09743f47f28ed\",\"best_bid\":\"0.04\",\"best_ask\":\"0.05\"}],\"timestamp\":\"1786689807001\",\"event_type\":\"price_change\"}"}
{"recv_ts": 1786689809623994, "venue": "polymarket", "raw": "{\"market\":\"0x747dc809fb79e1b05be09c42d6179459a58de2ef3e40f02484a4e1260f741f75\",\"price_changes\":[{\"asset_id\":\"107505882767731489358349912513945399560393482969656700824895970500493757150417\",\"price\":\"0.03\",\"size\":\"355011.26\",\"side\":\"BUY\",\"hash\":\"ce9002701b7653a56612bc7855e1c17833f2b415\",\"best_bid\":\"0.04\",\"best_ask\":\"0.05\"},{\"asset_id\":\"7305630249804085635496399869905769372294302716159034447326228509068694952392\",\"price\":\"0.97\",\"size\":\"355011.26\",\"side\":\"SELL\",\"hash\":\"a75593cd7d364f6af714062f65da0a38a124e2cb\",\"best_bid\":\"0.95\",\"best_ask\":\"0.96\"}],\"timestamp\":\"1786689809618\",\"event_type\":\"price_change\"}"}
{"recv_ts": 1786689809629836, "venue": "polymarket", "raw": "{\"market\":\"0x747dc809fb79e1b05be09c42d6179459a58de2ef3e40f02484a4e1260f741f75\",\"price_changes\":[{\"asset_id\":\"7305630249804085635496399869905769372294302716159034447326228509068694952392\",\"price\":\"0.94\",\"size\":\"121927.12\",\"side\":\"BUY\",\"hash\":\"a5ad467cdd2bd7e107f8b4df17f31120e98a6eb6\",\"best_bid\":\"0.95\",\"best_ask\":\"0.96\"},{\"asset_id\":\"107505882767731489358349912513945399560393482969656700824895970500493757150417\",\"price\":\"0.06\",\"size\":\"121927.12\",\"side\":\"SELL\",\"hash\":\"cd48ddaf33975456694784c7fac0216f5ace567b\",\"best_bid\":\"0.04\",\"best_ask\":\"0.05\"}],\"timestamp\":\"1786689809623\",\"event_type\":\"price_change\"}"}
{"recv_ts": 1786689809831242, "venue": "polymarket", "raw": "{\"market\":\"0xd9fb1184af0064e5e34b129f5b79afa5a17b7e32f2953ab05efed82315fee6d4\",\"price_changes\":[{\"asset_id\":\"94559586571241563470235664821564670251180951772614764383113614156422396181162\",\"price\":\"0.026\",\"size\":\"9673.96\",\"side\":\"BUY\",\"hash\":\"04927bc6242e0b0494ec8c695af6adda9584d3ec\",\"best_bid\":\"0.036\",\"best_ask\":\"0.038\"},{\"asset_id\":\"90772332434487149264114862115632028379978765245278600275169585501290867536237\",\"price\":\"0.974\",\"size\":\"9673.96\",\"side\":\"SELL\",\"hash\":\"de163d81d12b8eb32c95ab044734baa83493435b\",\"best_bid\":\"0.962\",\"best_ask\":\"0.964\"}],\"timestamp\":\"1786689809825\",\"event_type\":\"price_change\"}"}
{"recv_ts": 1786689809832129, "venue": "polymarket", "raw": "{\"market\":\"0xd9fb1184af0064e5e34b129f5b79afa5a17b7e32f2953ab05efed82315fee6d4\",\"price_changes\":[{\"asset_id\":\"90772332434487149264114862115632028379978765245278600275169585501290867536237\",\"price\":\"0.952\",\"size\":\"13651.11\",\"side\":\"BUY\",\"hash\":\"377305aa9bb0bda11162857e9ef6e03a043e4e6c\",\"best_bid\":\"0.962\",\"best_ask\":\"0.964\"},{\"asset_id\":\"94559586571241563470235664821564670251180951772614764383113614156422396181162\",\"price\":\"0.048\",\"size\":\"13651.11\",\"side\":\"SELL\",\"hash\":\"4588f157ad9495f0242b68ef483d84e313b573ae\",\"best_bid\":\"0.036\",\"best_ask\":\"0.038\"}],\"timestamp\":\"1786689809827\",\"event_type\":\"price_change\"}"}
{"recv_ts": 1786689810890676, "venue": "polymarket", "raw": "{\"market\":\"0xd9fb1184af0064e5e34b129f5b79afa5a17b7e32f2953ab05efed82315fee6d4\",\"price_changes\":[{\"asset_id\":\"90772332434487149264114862115632028379978765245278600275169585501290867536237\",\"price\":\"0.957\",\"size\":\"5547\",\"side\":\"BUY\",\"hash\":\"846c761e738394ee5826f8788fd5d692a50caaaa\",\"best_bid\":\"0.962\",\"best_ask\":\"0.964\"},{\"asset_id\":\"94559586571241563470235664821564670251180951772614764383113614156422396181162\",\"price\":\"0.043\",\"size\":\"5547\",\"side\":\"SELL\",\"hash\":\"7a0260f4e0de446b699b89201c31bd067bb7cef8\",\"best_bid\":\"0.036\",\"best_ask\":\"0.038\"}],\"timestamp\":\"1786689810884\",\"event_type\":\"price_change\"}"}
{"recv_ts": 1786689811216149, "venue": "polymarket", "raw": "{\"market\":\"0x6bd56627aa21311850825edb27e53434a0e17a4f782be0086bc07f71eee00d0d\",\"price_changes\":[{\"asset_id\":\"87073899845581463485186346288398658568334162612963837182986759797304993556208\",\"price\":\"0.9\",\"size\":\"88175.97\",\"side\":\"BUY\",\"hash\":\"b11a62b674ec6d0b9db412d75c1cdbf426c838e4\",\"best_bid\":\"0.92\",\"best_ask\":\"0.93\"},{\"asset_id\":\"350977769852917329387037893294763093471844346281449484439085576212613048126\",\"price\":\"0.1\",\"size\":\"88175.97\",\"side\":\"SELL\",\"hash\":\"5763da7da39d728236eb619be3d6d88faf3aa509\",\"best_bid\":\"0.07\",\"best_ask\":\"0.08\"}],\"timestamp\":\"1786689811210\",\"event_type\":\"price_change\"}"}
{"recv_ts": 1786689811523462, "venue": "polymarket", "raw": "{\"market\":\"0x6bd56627aa21311850825edb27e53434a0e17a4f782be0086bc07f71eee00d0d\",\"price_changes\":[{\"asset_id\":\"87073899845581463485186346288398658568334162612963837182986759797304993556208\",\"price\":\"0.91\",\"size\":\"120650.77\",\"side\":\"BUY\",\"hash\":\"037a8aa5b5616267a4bc675365d43038730f390a\",\"best_bid\":\"0.92\",\"best_ask\":\"0.93\"},{\"asset_id\":\"350977769852917329387037893294763093471844346281449484439085576212613048126\",\"price\":\"0.09\",\"size\":\"120650.77\",\"side\":\"SELL\",\"hash\":\"c8ac470a9792fc1de86eefbe09d31cc2902b91fa\",\"best_bid\":\"0.07\",\"best_ask\":\"0.08\"}],\"timestamp\":\"1786689811517\",\"event_type\":\"price_change\"}"}
{"recv_ts": 1786689812577072, "venue": "polymarket", "raw": "{\"market\":\"0x747dc809fb79e1b05be09c42d6179459a58de2ef3e40f02484a4e1260f741f75\",\"price_changes\":[{\"asset_id\":\"7305630249804085635496399869905769372294302716159034447326228509068694952392\",\"price\":\"0.3\",\"size\":\"9200\",\"side\":\"BUY\",\"hash\":\"cd71dc97becc322cfc7b11489218a4cdf03fb586\",\"best_bid\":\"0.95\",\"best_ask\":\"0.96\"},{\"asset_id\":\"107505882767731489358349912513945399560393482969656700824895970500493757150417\",\"price\":\"0.7\",\"size\":\"9200\",\"side\":\"SELL\",\"hash\":\"1a0a3e5dccd2c3eccd79e1cf4d1af64d1e756248\",\"best_bid\":\"0.04\",\"best_ask\":\"0.05\"}],\"timestamp\":\"1786689812540\",\"event_type\":\"price_change\"}"}
{"recv_ts": 1786689812577253, "venue": "polymarket", "raw": "{\"market\":\"0x747dc809fb79e1b05be09c42d6179459a58de2ef3e40f02484a4e1260f741f75\",\"price_changes\":[{\"asset_id\":\"7305630249804085635496399869905769372294302716159034447326228509068694952392\",\"price\":\"0.2\",\"size\":\"14900\",\"side\":\"BUY\",\"hash\":\"0d2eaf3c2e73855945d2c4dccb26fe4bd0d9ef60\",\"best_bid\":\"0.95\",\"best_ask\":\"0.96\"},{\"asset_id\":\"107505882767731489358349912513945399560393482969656700824895970500493757150417\",\"price\":\"0.8\",\"size\":\"14900\",\"side\":\"SELL\",\"hash\":\"41ee0bbf311f888b39cdfdce7ebd02bf803e9054\",\"best_bid\":\"0.04\",\"best_ask\":\"0.05\"}],\"timestamp\":\"1786689812540\",\"event_type\":\"price_change\"}"}
{"recv_ts": 1786689812577289, "venue": "polymarket", "raw": "{\"market\":\"0x747dc809fb79e1b05be09c42d6179459a58de2ef3e40f02484a4e1260f741f75\",\"price_changes\":[{\"asset_id\":\"7305630249804085635496399869905769372294302716159034447326228509068694952392\",\"price\":\"0.4\",\"size\":\"5638\",\"side\":\"BUY\",\"hash\":\"9d9bd1f9b99509b176659a00a91e5489534b83ba\",\"best_bid\":\"0.95\",\"best_ask\":\"0.96\"},{\"asset_id\":\"107505882767731489358349912513945399560393482969656700824895970500493757150417\",\"price\":\"0.6\",\"size\":\"5638\",\"side\":\"SELL\",\"hash\":\"52b4a71b76a14ac7eb208357670b2799ee8e95d8\",\"best_bid\":\"0.04\",\"best_ask\":\"0.05\"}],\"timestamp\":\"1786689812541\",\"event_type\":\"price_change\"}"}
{"recv_ts": 1786689813746829, "venue": "polymarket", "raw": "{\"market\":\"0xd9fb1184af0064e5e34b129f5b79afa5a17b7e32f2953ab05efed82315fee6d4\",\"price_changes\":[{\"asset_id\":\"90772332434487149264114862115632028379978765245278600275169585501290867536237\",\"price\":\"0.957\",\"size\":\"7547\",\"side\":\"BUY\",\"hash\":\"8708f556a58bfb99ef55d6d49e5e04359e880bb2\",\"best_bid\":\"0.962\",\"best_ask\":\"0.964\"},{\"asset_id\":\"94559586571241563470235664821564670251180951772614764383113614156422396181162\",\"price\":\"0.043\",\"size\":\"7547\",\"side\":\"SELL\",\"hash\":\"b8a02f9b44b1536ac76dc8ecd44a2d0e54de11c8\",\"best_bid\":\"0.036\",\"best_ask\":\"0.038\"}],\"timestamp\":\"1786689813741\",\"event_type\":\"price_change\"}"}
{"recv_ts": 1786689813941178, "venue": "polymarket", "raw": "{\"market\":\"0x747dc809fb79e1b05be09c42d6179459a58de2ef3e40f02484a4e1260f741f75\",\"price_changes\":[{\"asset_id\":\"107505882767731489358349912513945399560393482969656700824895970500493757150417\",\"price\":\"0.03\",\"size\":\"355611.26\",\"side\":\"BUY\",\"hash\":\"bf60ead175d88db151bd39fe248a8e86e966e0fa\",\"best_bid\":\"0.04\",\"best_ask\":\"0.05\"},{\"asset_id\":\"7305630249804085635496399869905769372294302716159034447326228509068694952392\",\"price\":\"0.97\",\"size\":\"355611.26\",\"side\":\"SELL\",\"hash\":\"62fd57b67600dc123a4ca509da1b8bf93fc00830\",\"best_bid\":\"0.95\",\"best_ask\":\"0.96\"}],\"timestamp\":\"1786689813935\",\"event_type\":\"price_change\"}"}
{"recv_ts": 1786689813941328, "venue": "polymarket", "raw": "{\"market\":\"0xd9fb1184af0064e5e34b129f5b79afa5a17b7e32f2953ab05efed82315fee6d4\",\"price_changes\":[{\"asset_id\":\"94559586571241563470235664821564670251180951772614764383113614156422396181162\",\"price\":\"0.026\",\"size\":\"10273.96\",\"side\":\"BUY\",\"hash\":\"541541855e3bac10d60f6985ceed156572f9ade1\",\"best_bid\":\"0.036\",\"best_ask\":\"0.038\"},{\"asset_id\":\"90772332434487149264114862115632028379978765245278600275169585501290867536237\",\"price\":\"0.974\",\"size\":\"10273.96\",\"side\":\"SELL\",\"hash\":\"eb82283bc48fdf81a5cc13818d5e60a56b4de190\",\"best_bid\":\"0.962\",\"best_ask\":\"0.964\"}],\"timestamp\":\"1786689813936\",\"event_type\":\"price_change\"}"}
{"recv_ts": 1786689813948286, "venue": "polymarket", "raw": "{\"market\":\"0xd9fb1184af0064e5e34b129f5b79afa5a17b7e32f2953ab05efed82315fee6d4\",\"price_changes\":[{\"asset_id\":\"90772332434487149264114862115632028379978765245278600275169585501290867536237\",\"price\":\"0.952\",\"size\":\"14251.11\",\"side\":\"BUY\",\"hash\":\"9d21349ac61e9eeee6a6e35f526f02c54c99a775\",\"best_bid\":\"0.962\",\"best_ask\":\"0.964\"},{\"asset_id\":\"94559586571241563470235664821564670251180951772614764383113614156422396181162\",\"price\":\"0.048\",\"size\":\"14251.11\",\"side\":\"SELL\",\"hash\":\"a8b4c4da3dd8fbe4f643905de16dfc68024a7d13\",\"best_bid\":\"0.036\",\"best_ask\":\"0.038\"}],\"timestamp\":\"1786689813943\",\"event_type\":\"price_change\"}"}
{"recv_ts": 1786689813949810, "venue": "polymarket", "raw": "{\"market\":\"0x747dc809fb79e1b05be09c42d6179459a58de2ef3e40f02484a4e1260f741f75\",\"price_changes\":[{\"asset_id\":\"7305630249804085635496399869905769372294302716159034447326228509068694952392\",\"price\":\"0.94\",\"size\":\"122527.12\",\"side\":\"BUY\",\"hash\":\"1373a063256e8baeca1ba80a6a37f47374f4924e\",\"best_bid\":\"0.95\",\"best_ask\":\"0.96\"},{\"asset_id\":\"107505882767731489358349912513945399560393482969656700824895970500493757150417\",\"price\":\"0.06\",\"size\":\"122527.12\",\"side\":\"SELL\",\"hash\":\"60a04dbdc2a7a32e7ae4232d86e629c0a584ebdb\",\"best_bid\":\"0.04\",\"best_ask\":\"0.05\"}],\"timestamp\":\"1786689813945\",\"event_type\":\"price_change\"}"}
{"recv_ts": 1786689814184153, "venue": "polymarket", "raw": "{\"market\":\"0x6bd56627aa21311850825edb27e53434a0e17a4f782be0086bc07f71eee00d0d\",\"price_changes\":[{\"asset_id\":\"87073899845581463485186346288398658568334162612963837182986759797304993556208\",\"price\":\"0.91\",\"size\":\"122650.77\",\"side\":\"BUY\",\"hash\":\"e2ae5fa06da7ac24e13a5778c8c4b7081b491e3c\",\"best_bid\":\"0.92\",\"best_ask\":\"0.93\"},{\"asset_id\":\"350977769852917329387037893294763093471844346281449484439085576212613048126\",\"price\":\"0.09\",\"size\":\"122650.77\",\"side\":\"SELL\",\"hash\":\"66ad1c172c83920a68a76a9baddb58854619a4a8\",\"best_bid\":\"0.07\",\"best_ask\":\"0.08\"}],\"timestamp\":\"1786689814178\",\"event_type\":\"price_change\"}"}
{"recv_ts": 1786689816027463, "venue": "polymarket", "raw": "{\"market\":\"0xbb4d51e6364066d92eb6f9b8413dd7193de70966736044463b205834805a1f3b\",\"price_changes\":[{\"asset_id\":\"106181075047366745139197108801635573283215248045056329679360376976893016488727\",\"price\":\"0.93\",\"size\":\"202343.09\",\"side\":\"BUY\",\"hash\":\"dde5cabcda0cb9e5d607e535cc984047322e502c\",\"best_bid\":\"0.93\",\"best_ask\":\"0.94\"},{\"asset_id\":\"10991849228756847439673778874175365458450913336396982752046655649803657501964\",\"price\":\"0.07\",\"size\":\"202343.09\",\"side\":\"SELL\",\"hash\":\"98193e1fdb9dff5c97164b0d85bd67fb3390e971\",\"best_bid\":\"0.06\",\"best_ask\":\"0.07\"}],\"timestamp\":\"1786689816016\",\"event_type\":\"price_change\"}"}
{"recv_ts": 1786689816027949, "venue": "polymarket", "raw": "{\"market\":\"0xbb4d51e6364066d92eb6f9b8413dd7193de70966736044463b205834805a1f3b\",\"price_changes\":[{\"asset_id\":\"10991849228756847439673778874175365458450913336396982752046655649803657501964\",\"price\":\"0.06\",\"size\":\"272873.61\",\"side\":\"BUY\",\"hash\":\"98193e1fdb9dff5c97164b0d85bd67fb3390e971\",\"best_bid\":\"0.06\",\"best_ask\":\"0.07\"},{\"asset_id\":\"106181075047366745139197108801635573283215248045056329679360376976893016488727\",\"price\":\"0.94\",\"size\":\"272873.61\",\"side\":\"SELL\",\"hash\":\"dde5cabcda0cb9e5d607e535cc984047322e502c\",\"best_bid\":\"0.93\",\"best_ask\":\"0.94\"}],\"timestamp\":\"1786689816016\",\"event_type\":\"price_change\"}"}
{"recv_ts": 1786689817009681, "venue": "polymarket", "raw": "{\"market\":\"0xbb4d51e6364066d92eb6f9b8413dd7193de70966736044463b205834805a1f3b\",\"price_changes\":[{\"asset_id\":\"106181075047366745139197108801635573283215248045056329679360376976893016488727\",\"price\":\"0.3\",\"size\":\"20833.33\",\"side\":\"BUY\",\"hash\":\"766e4bd6e675e2d82a6fcecdbdce62a7a1f063e0\",\"best_bid\":\"0.93\",\"best_ask\":\"0.94\"},{\"asset_id\":\"10991849228756847439673778874175365458450913336396982752046655649803657501964\",\"price\":\"0.7\",\"size\":\"20833.33\",\"side\":\"SELL\",\"hash\":\"422cb0a63cf8778ac0275b215d15ca5cb25939c3\",\"best_bid\":\"0.06\",\"best_ask\":\"0.07\"}],\"timestamp\":\"1786689817001\",\"event_type\":\"price_change\"}"}
{"recv_ts": 1786689817009773, "venue": "polymarket", "raw": "{\"market\":\"0xbb4d51e6364066d92eb6f9b8413dd7193de70966736044463b205834805a1f3b\",\"price_changes\":[{\"asset_id\":\"106181075047366745139197108801635573283215248045056329679360376976893016488727\",\"price\":\"0.2\",\"size\":\"34602.27\",\"side\":\"BUY\",\"hash\":\"766e4bd6e675e2d82a6fcecdbdce62a7a1f063e0\",\"best_bid\":\"0.93\",\"best_ask\":\"0.94\"},{\"asset_id\":\"10991849228756847439673778874175365458450913336396982752046655649803657501964\",\"price\":\"0.8\",\"size\":\"34602.27\",\"side\":\"SELL\",\"hash\":\"422cb0a63cf8778ac0275b215d15ca5cb25939c3\",\"best_bid\":\"0.06\",\"best_ask\":\"0.07\"}],\"timestamp\":\"1786689817001\",\"event_type\":\"price_change\"}"}
{"recv_ts": 1786689817009795, "venue": "polymarket", "raw": "{\"market\":\"0xbb4d51e6364066d92eb6f9b8413dd7193de70966736044463b205834805a1f3b\",\"price_changes\":[{\"asset_id\":\"106181075047366745139197108801635573283215248045056329679360376976893016488727\",\"price\":\"0.4\",\"size\":\"15730.87\",\"side\":\"BUY\",\"hash\":\"2d0eb4686ce77e51e3d3004938250090e58d61ac\",\"best_bid\":\"0.93\",\"best_ask\":\"0.94\"},{\"asset_id\":\"10991849228756847439673778874175365458450913336396982752046655649803657501964\",\"price\":\"0.6\",\"size\":\"15730.87\",\"side\":\"SELL\",\"hash\":\"31d983777411f4f547e7a3037912ce73237a20cc\",\"best_bid\":\"0.06\",\"best_ask\":\"0.07\"}],\"timestamp\":\"1786689817002\",\"event_type\":\"price_change\"}"}
{"recv_ts": 1786689819010608, "venue": "polymarket", "raw": "{\"market\":\"0x747dc809fb79e1b05be09c42d6179459a58de2ef3e40f02484a4e1260f741f75\",\"price_changes\":[{\"asset_id\":\"7305630249804085635496399869905769372294302716159034447326228509068694952392\",\"price\":\"0.94\",\"size\":\"122287.12\",\"side\":\"BUY\",\"hash\":\"da8bb3d288987269c6e83f1f85c6bacd3b98b8c3\",\"best_bid\":\"0.95\",\"best_ask\":\"0.96\"},{\"asset_id\":\"107505882767731489358349912513945399560393482969656700824895970500493757150417\",\"price\":\"0.06\",\"size\":\"122287.12\",\"side\":\"SELL\",\"hash\":\"c1299374d49bfe4f05197ef7bc79b3825681ee4c\",\"best_bid\":\"0.04\",\"best_ask\":\"0.05\"}],\"timestamp\":\"1786689819001\",\"event_type\":\"price_change\"}"}
{"recv_ts": 1786689819010725, "venue": "polymarket", "raw": "{\"market\":\"0x747dc809fb79e1b05be09c42d6179459a58de2ef3e40f02484a4e1260f741f75\",\"price_changes\":[{\"asset_id\":\"107505882767731489358349912513945399560393482969656700824895970500493757150417\",\"price\":\"0.02\",\"size\":\"323575.71\",\"side\":\"BUY\",\"hash\":\"62a210026a146fd8b93f7907847d511488dd9bdd\",\"best_bid\":\"0.04\",\"best_ask\":\"0.05\"},{\"asset_id\":\"7305630249804085635496399869905769372294302716159034447326228509068694952392\",\"price\":\"0.98\",\"size\":\"323575.71\",\"side\":\"SELL\",\"hash\":\"89a15ca82ea81abfe78228c39dc38b80b80ac13a\",\"best_bid\":\"0.95\",\"best_ask\":\"0.96\"}],\"timestamp\":\"1786689819003\",\"event_type\":\"price_change\"}"}
{"recv_ts": 1786689819105382, "venue": "polymarket", "raw": "{\"market\":\"0x747dc809fb79e1b05be09c42d6179459a58de2ef3e40f02484a4e1260f741f75\",\"price_changes\":[{\"asset_id\":\"7305630249804085635496399869905769372294302716159034447326228509068694952392\",\"price\":\"0.94\",\"size\":\"122527.12\",\"side\":\"BUY\",\"hash\":\"5c30ec0160a309e176b839e3e90f593b068af50b\",\"best_bid\":\"0.95\",\"best_ask\":\"0.96\"},{\"asset_id\":\"107505882767731489358349912513945399560393482969656700824895970500493757150417\",\"price\":\"0.06\",\"size\":\"122527.12\",\"side\":\"SELL\",\"hash\":\"9c2a8b000e824749b74cdddf36bd7a99790e6434\",\"best_bid\":\"0.04\",\"best_ask\":\"0.05\"}],\"timestamp\":\"1786689819099\",\"event_type\":\"price_change\"}"}
{"recv_ts": 1786689819107459, "venue": "polymarket", "raw": "{\"market\":\"0x747dc809fb79e1b05be09c42d6179459a58de2ef3e40f02484a4e1260f741f75\",\"price_changes\":[{\"asset_id\":\"107505882767731489358349912513945399560393482969656700824895970500493757150417\",\"price\":\"0.02\",\"size\":\"323815.71\",\"side\":\"BUY\",\"hash\":\"9bf39e3dbbc51146002fde9f6803cd027eea6e8e\",\"best_bid\":\"0.04\",\"best_ask\":\"0.05\"},{\"asset_id\":\"7305630249804085635496399869905769372294302716159034447326228509068694952392\",\"price\":\"0.98\",\"size\":\"323815.71\",\"side\":\"SELL\",\"hash\":\"c163d56cf1852602189aa0cea0ce137bf046a3cc\",\"best_bid\":\"0.95\",\"best_ask\":\"0.96\"}],\"timestamp\":\"1786689819101\",\"event_type\":\"price_change\"}"}
{"recv_ts": 1786689821256040, "venue": "polymarket", "raw": "{\"id\":\"3578405\",\"question\":\"ZCash Up or Down - August 15, 2:35AM-2:40AM ET\",\"market\":\"0xbd51b85427742610d133d4e45ddcf37f701a1978dbb986b5620f354dbdad9a16\",\"slug\":\"zec-updown-5m-1786775700\",\"description\":\"This market will resolve to \\\"Up\\\" if the time-weighted average price (TWAP) of ZCash, generated by Chainlink, of the time range specified in the title is greater than or equal to the price at the beginning of that range. Otherwise, it will resolve to \\\"Down\\\".\\nThe resolution source for this market is information from Chainlink, specifically the ZEC/USD TWAP data stream available at https://data.chain.link/streams/zec-usd-twap-60s-streams.\\nPlease note that this market is about the price according to the TWAP Chainlink data stream for the asset pair ZEC/USD, not according to any other sources or spot markets.\",\"assets_ids\":[\"36160477710248071309964247737031916230912509937588023409483720416428577322271\",\"44871619973996116270961928938380887088426130315105852837588340600863550330181\"],\"outcomes\":[\"Up\",\"Down\"],\"event_message\":{\"id\":\"847370\",\"ticker\":\"zec-updown-5m-1786775700\",\"slug\":\"zec-updown-5m-1786775700\",\"title\":\"ZCash Up or Down - August 15, 2:35AM-2:40AM ET\",\"description\":\"This market will resolve to \\\"Up\\\" if the time-weighted average price (TWAP) of ZCash, generated by Chainlink, of the time range specified in the title is greater than or equal to the price at the beginning of that range. Otherwise, it will resolve to \\\"Down\\\".\\nThe resolution source for this market is information from Chainlink, specifically the ZEC/USD TWAP data stream available at https://data.chain.link/streams/zec-usd-twap-60s-streams.\\nPlease note that this market is about the price according to the TWAP Chainlink data stream for the asset pair ZEC/USD, not according to any other sources or spot markets.\"},\"timestamp\":\"1786689821237\",\"event_type\":\"new_market\",\"tags\":[],\"condition_id\":\"0xbd51b85427742610d133d4e45ddcf37f701a1978dbb986b5620f354dbdad9a16\",\"active\":false,\"clob_token_ids\":[\"36160477710248071309964247737031916230912509937588023409483720416428577322271\",\"44871619973996116270961928938380887088426130315105852837588340600863550330181\"],\"sports_market_type\":\"\",\"line\":\"\",\"game_start_time\":\"\",\"order_price_min_tick_size\":\"0.01\",\"group_item_title\":\"\",\"taker_base_fee\":\"1000\",\"fees_enabled\":true,\"fee_schedule\":{\"exponent\":\"1\",\"rate\":\"0.07\",\"taker_only\":true,\"rebate_rate\":\"0.2\"}}"}
{"recv_ts": 1786689821531681, "venue": "polymarket", "raw": "{\"id\":\"3578398\",\"question\":\"Ethereum Up or Down - August 15, 2:35AM-2:40AM ET\",\"market\":\"0x20098519d5eec9fb14399544169837371a925db7206e80ec8b5526d38fd0a618\",\"slug\":\"eth-updown-5m-1786775700\",\"description\":\"This market will resolve to \\\"Up\\\" if the time-weighted average price (TWAP) of Ethereum, generated by Chainlink, of the time range specified in the title is greater than or equal to the price at the beginning of that range. Otherwise, it will resolve to \\\"Down\\\".\\nThe resolution source for this market is information from Chainlink, specifically the ETH/USD TWAP data stream available at https://data.chain.link/streams/eth-usd-twap-60s-streams.\\nPlease note that this market is about the price according to the TWAP Chainlink data stream for the asset pair ETH/USD, not according to any other sources or spot markets.\",\"assets_ids\":[\"103912782558820879475830107418667355131558386078497739794606224091132845476757\",\"62175159265855254561310973502079881588599534554216783296539645211944073102939\"],\"outcomes\":[\"Up\",\"Down\"],\"event_message\":{\"id\":\"847364\",\"ticker\":\"eth-updown-5m-1786775700\",\"slug\":\"eth-updown-5m-1786775700\",\"title\":\"Ethereum Up or Down - August 15, 2:35AM-2:40AM ET\",\"description\":\"This market will resolve to \\\"Up\\\" if the time-weighted average price (TWAP) of Ethereum, generated by Chainlink, of the time range specified in the title is greater than or equal to the price at the beginning of that range. Otherwise, it will resolve to \\\"Down\\\".\\nThe resolution source for this market is information from Chainlink, specifically the ETH/USD TWAP data stream available at https://data.chain.link/streams/eth-usd-twap-60s-streams.\\nPlease note that this market is about the price according to the TWAP Chainlink data stream for the asset pair ETH/USD, not according to any other sources or spot markets.\"},\"timestamp\":\"1786689821519\",\"event_type\":\"new_market\",\"tags\":[],\"condition_id\":\"0x20098519d5eec9fb14399544169837371a925db7206e80ec8b5526d38fd0a618\",\"active\":false,\"clob_token_ids\":[\"103912782558820879475830107418667355131558386078497739794606224091132845476757\",\"62175159265855254561310973502079881588599534554216783296539645211944073102939\"],\"sports_market_type\":\"\",\"line\":\"\",\"game_start_time\":\"\",\"order_price_min_tick_size\":\"0.01\",\"group_item_title\":\"\",\"taker_base_fee\":\"1000\",\"fees_enabled\":true,\"fee_schedule\":{\"exponent\":\"1\",\"rate\":\"0.07\",\"taker_only\":true,\"rebate_rate\":\"0.2\"}}"}
{"recv_ts": 1786689821931320, "venue": "polymarket", "raw": "{\"market\":\"0xbb4d51e6364066d92eb6f9b8413dd7193de70966736044463b205834805a1f3b\",\"price_changes\":[{\"asset_id\":\"106181075047366745139197108801635573283215248045056329679360376976893016488727\",\"price\":\"0.2\",\"size\":\"43602.27\",\"side\":\"BUY\",\"hash\":\"7588e51b832c79a4b304b7b6e4e1df2af0e21f87\",\"best_bid\":\"0.93\",\"best_ask\":\"0.94\"},{\"asset_id\":\"10991849228756847439673778874175365458450913336396982752046655649803657501964\",\"price\":\"0.8\",\"size\":\"43602.27\",\"side\":\"SELL\",\"hash\":\"86028124cb236e08205ae0b063832e76764a7152\",\"best_bid\":\"0.06\",\"best_ask\":\"0.07\"}],\"timestamp\":\"1786689821925\",\"event_type\":\"price_change\"}"}
{"recv_ts": 1786689821931481, "venue": "polymarket", "raw": "{\"market\":\"0xbb4d51e6364066d92eb6f9b8413dd7193de70966736044463b205834805a1f3b\",\"price_changes\":[{\"asset_id\":\"106181075047366745139197108801635573283215248045056329679360376976893016488727\",\"price\":\"0.3\",\"size\":\"26499.33\",\"side\":\"BUY\",\"hash\":\"dd6297ab41b14c21ce45ee8ed3b806b558639878\",\"best_bid\":\"0.93\",\"best_ask\":\"0.94\"},{\"asset_id\":\"10991849228756847439673778874175365458450913336396982752046655649803657501964\",\"price\":\"0.7\",\"size\":\"26499.33\",\"side\":\"SELL\",\"hash\":\"2dba2180c810df6a8b5ea4ddf0c728d2539fde70\",\"best_bid\":\"0.06\",\"best_ask\":\"0.07\"}],\"timestamp\":\"1786689821926\",\"event_type\":\"price_change\"}"}
{"recv_ts": 1786689821932215, "venue": "polymarket", "raw": "{\"market\":\"0xbb4d51e6364066d92eb6f9b8413dd7193de70966736044463b205834805a1f3b\",\"price_changes\":[{\"asset_id\":\"106181075047366745139197108801635573283215248045056329679360376976893016488727\",\"price\":\"0.4\",\"size\":\"19730.87\",\"side\":\"BUY\",\"hash\":\"e6aaa4a23c2a8c62bf6a5570a25f678852d4b3f7\",\"best_bid\":\"0.93\",\"best_ask\":\"0.94\"},{\"asset_id\":\"10991849228756847439673778874175365458450913336396982752046655649803657501964\",\"price\":\"0.6\",\"size\":\"19730.87\",\"side\":\"SELL\",\"hash\":\"ef299d4a64763d2c0b3338b5ab66060a12293594\",\"best_bid\":\"0.06\",\"best_ask\":\"0.07\"}],\"timestamp\":\"1786689821926\",\"event_type\":\"price_change\"}"}
{"recv_ts": 1786689822248952, "venue": "polymarket", "raw": "{\"id\":\"3578400\",\"question\":\"BNB Up or Down - August 15, 2:35AM-2:40AM ET\",\"market\":\"0x7ad72b530564f1162d88495501291d995a1c91811aa14d2c1450364ee463a73a\",\"slug\":\"bnb-updown-5m-1786775700\",\"description\":\"This market will resolve to \\\"Up\\\" if the time-weighted average price (TWAP) of BNB, generated by Chainlink, of the time range specified in the title is greater than or equal to the price at the beginning of that range. Otherwise, it will resolve to \\\"Down\\\".\\nThe resolution source for this market is information from Chainlink, specifically the BNB/USD TWAP data stream available at https://data.chain.link/streams/bnb-usd-twap-60s-streams.\\nPlease note that this market is about the price according to the TWAP Chainlink data stream for the asset pair BNB/USD, not according to any other sources or spot markets.\",\"assets_ids\":[\"70460380881653980393170130321943200935751161445405886608543041610169753101278\",\"10004907082036459075033526077349521821829139818575561497071423287588821710212\"],\"outcomes\":[\"Up\",\"Down\"],\"event_message\":{\"id\":\"847367\",\"ticker\":\"bnb-updown-5m-1786775700\",\"slug\":\"bnb-updown-5m-1786775700\",\"title\":\"BNB Up or Down - August 15, 2:35AM-2:40AM ET\",\"description\":\"This market will resolve to \\\"Up\\\" if the time-weighted average price (TWAP) of BNB, generated by Chainlink, of the time range specified in the title is greater than or equal to the price at the beginning of that range. Otherwise, it will resolve to \\\"Down\\\".\\nThe resolution source for this market is information from Chainlink, specifically the BNB/USD TWAP data stream available at https://data.chain.link/streams/bnb-usd-twap-60s-streams.\\nPlease note that this market is about the price according to the TWAP Chainlink data stream for the asset pair BNB/USD, not according to any other sources or spot markets.\"},\"timestamp\":\"1786689822235\",\"event_type\":\"new_market\",\"tags\":[],\"condition_id\":\"0x7ad72b530564f1162d88495501291d995a1c91811aa14d2c1450364ee463a73a\",\"active\":false,\"clob_token_ids\":[\"70460380881653980393170130321943200935751161445405886608543041610169753101278\",\"10004907082036459075033526077349521821829139818575561497071423287588821710212\"],\"sports_market_type\":\"\",\"line\":\"\",\"game_start_time\":\"\",\"order_price_min_tick_size\":\"0.01\",\"group_item_title\":\"\",\"taker_base_fee\":\"1000\",\"fees_enabled\":true,\"fee_schedule\":{\"exponent\":\"1\",\"rate\":\"0.07\",\"taker_only\":true,\"rebate_rate\":\"0.2\"}}"}
{"recv_ts": 1786689822859454, "venue": "polymarket", "raw": "{\"market\":\"0xbb4d51e6364066d92eb6f9b8413dd7193de70966736044463b205834805a1f3b\",\"price_changes\":[{\"asset_id\":\"10991849228756847439673778874175365458450913336396982752046655649803657501964\",\"price\":\"0.06\",\"size\":\"273273.61\",\"side\":\"BUY\",\"hash\":\"4d3c143c0ed4ae0858b4918ad4d4bd918db5b7ed\",\"best_bid\":\"0.06\",\"best_ask\":\"0.07\"},{\"asset_id\":\"106181075047366745139197108801635573283215248045056329679360376976893016488727\",\"price\":\"0.94\",\"size\":\"273273.61\",\"side\":\"SELL\",\"hash\":\"50edda24e0359b66bddd64191ca69ff22e9d614e\",\"best_bid\":\"0.93\",\"best_ask\":\"0.94\"}],\"timestamp\":\"1786689822853\",\"event_type\":\"price_change\"}"}
{"recv_ts": 1786689822866295, "venue": "polymarket", "raw": "{\"market\":\"0xbb4d51e6364066d92eb6f9b8413dd7193de70966736044463b205834805a1f3b\",\"price_changes\":[{\"asset_id\":\"106181075047366745139197108801635573283215248045056329679360376976893016488727\",\"price\":\"0.93\",\"size\":\"202743.09\",\"side\":\"BUY\",\"hash\":\"ff0e9b0debedafd33c067598f58da5529c10cd4d\",\"best_bid\":\"0.93\",\"best_ask\":\"0.94\"},{\"asset_id\":\"10991849228756847439673778874175365458450913336396982752046655649803657501964\",\"price\":\"0.07\",\"size\":\"202743.09\",\"side\":\"SELL\",\"hash\":\"3e0fbc5c66f5104bfb27fcd0e2024c9fa70ecdd6\",\"best_bid\":\"0.06\",\"best_ask\":\"0.07\"}],\"timestamp\":\"1786689822860\",\"event_type\":\"price_change\"}"}
{"recv_ts": 1786689824881688, "venue": "polymarket", "raw": "{\"id\":\"3578402\",\"question\":\"Hyperliquid Up or Down - August 15, 2:35AM-2:40AM ET\",\"market\":\"0x6703c3cf86efa1c8a6b8ddbfc9490e8a6acb64d944a5128d21c8e5341132aff5\",\"slug\":\"hype-updown-5m-1786775700\",\"description\":\"This market will resolve to \\\"Up\\\" if the time-weighted average price (TWAP) of Hyperliquid, generated by Chainlink, of the time range specified in the title is greater than or equal to the price at the beginning of that range. Otherwise, it will resolve to \\\"Down\\\".\\nThe resolution source for this market is information from Chainlink, specifically the HYPE/USD TWAP data stream available at https://data.chain.link/streams/hype-usd-twap-60s-streams.\\nPlease note that this market is about the price according to the TWAP Chainlink data stream for the asset pair HYPE/USD, not according to any other sources or spot markets.\",\"assets_ids\":[\"114514687071377288260846176781083807169854259032707358182142035577269684124318\",\"98864398763528814439660994989773234623012707946119367794284959163337399794038\"],\"outcomes\":[\"Up\",\"Down\"],\"event_message\":{\"id\":\"847368\",\"ticker\":\"hype-updown-5m-1786775700\",\"slug\":\"hype-updown-5m-1786775700\",\"title\":\"Hyperliquid Up or Down - August 15, 2:35AM-2:40AM ET\",\"description\":\"This market will resolve to \\\"Up\\\" if the time-weighted average price (TWAP) of Hyperliquid, generated by Chainlink, of the time range specified in the title is greater than or equal to the price at the beginning of that range. Otherwise, it will resolve to \\\"Down\\\".\\nThe resolution source for this market is information from Chainlink, specifically the HYPE/USD TWAP data stream available at https://data.chain.link/streams/hype-usd-twap-60s-streams.\\nPlease note that this market is about the price according to the TWAP Chainlink data stream for the asset pair HYPE/USD, not according to any other sources or spot markets.\"},\"timestamp\":\"1786689824867\",\"event_type\":\"new_market\",\"tags\":[],\"condition_id\":\"0x6703c3cf86efa1c8a6b8ddbfc9490e8a6acb64d944a5128d21c8e5341132aff5\",\"active\":false,\"clob_token_ids\":[\"114514687071377288260846176781083807169854259032707358182142035577269684124318\",\"98864398763528814439660994989773234623012707946119367794284959163337399794038\"],\"sports_market_type\":\"\",\"line\":\"\",\"game_start_time\":\"\",\"order_price_min_tick_size\":\"0.01\",\"group_item_title\":\"\",\"taker_base_fee\":\"1000\",\"fees_enabled\":true,\"fee_schedule\":{\"exponent\":\"1\",\"rate\":\"0.07\",\"taker_only\":true,\"rebate_rate\":\"0.2\"}}"}
{"recv_ts": 1786689825012927, "venue": "polymarket", "raw": "{\"market\":\"0xd9fb1184af0064e5e34b129f5b79afa5a17b7e32f2953ab05efed82315fee6d4\",\"price_changes\":[{\"asset_id\":\"90772332434487149264114862115632028379978765245278600275169585501290867536237\",\"price\":\"0.5\",\"size\":\"1835.12\",\"side\":\"BUY\",\"hash\":\"be67182163d415bd67c2a261c5064d0b363b4d8a\",\"best_bid\":\"0.962\",\"best_ask\":\"0.964\"},{\"asset_id\":\"94559586571241563470235664821564670251180951772614764383113614156422396181162\",\"price\":\"0.5\",\"size\":\"1835.12\",\"side\":\"SELL\",\"hash\":\"4062031a0152a748f425d4738438acf2813c9e0e\",\"best_bid\":\"0.036\",\"best_ask\":\"0.038\"}],\"timestamp\":\"1786689825003\",\"event_type\":\"price_change\"}"}
{"recv_ts": 1786689827098823, "venue": "polymarket", "raw": "{\"id\":\"3578399\",\"question\":\"Dogecoin Up or Down - August 15, 2:35AM-2:40AM ET\",\"market\":\"0x3dc98db5c16c448b15023babb5e1972a8e8280b25fe6e7fecfad6d9f5a9578b4\",\"slug\":\"doge-updown-5m-1786775700\",\"description\":\"This market will resolve to \\\"Up\\\" if the time-weighted average price (TWAP) of Dogecoin, generated by Chainlink, of the time range specified in the title is greater than or equal to the price at the beginning of that range. Otherwise, it will resolve to \\\"Down\\\".\\nThe resolution source for this market is information from Chainlink, specifically the DOGE/USD TWAP data stream available at https://data.chain.link/streams/doge-usd-twap-60s-streams.\\nPlease note that this market is about the price according to the TWAP Chainlink data stream for the asset pair DOGE/USD, not according to any other sources or spot markets.\",\"assets_ids\":[\"96881312413216014500537959438780832859921442542354440991885275141620976530775\",\"27495190935341023646965233371266282586933236126226685463708576838842750553790\"],\"outcomes\":[\"Up\",\"Down\"],\"event_message\":{\"id\":\"847366\",\"ticker\":\"doge-updown-5m-1786775700\",\"slug\":\"doge-updown-5m-1786775700\",\"title\":\"Dogecoin Up or Down - August 15, 2:35AM-2:40AM ET\",\"description\":\"This market will resolve to \\\"Up\\\" if the time-weighted average price (TWAP) of Dogecoin, generated by Chainlink, of the time range specified in the title is greater than or equal to the price at the beginning of that range. Otherwise, it will resolve to \\\"Down\\\".\\nThe resolution source for this market is information from Chainlink, specifically the DOGE/USD TWAP data stream available at https://data.chain.link/streams/doge-usd-twap-60s-streams.\\nPlease note that this market is about the price according to the TWAP Chainlink data stream for the asset pair DOGE/USD, not according to any other sources or spot markets.\"},\"timestamp\":\"1786689826911\",\"event_type\":\"new_market\",\"tags\":[],\"condition_id\":\"0x3dc98db5c16c448b15023babb5e1972a8e8280b25fe6e7fecfad6d9f5a9578b4\",\"active\":false,\"clob_token_ids\":[\"96881312413216014500537959438780832859921442542354440991885275141620976530775\",\"27495190935341023646965233371266282586933236126226685463708576838842750553790\"],\"sports_market_type\":\"\",\"line\":\"\",\"game_start_time\":\"\",\"order_price_min_tick_size\":\"0.01\",\"group_item_title\":\"\",\"taker_base_fee\":\"1000\",\"fees_enabled\":true,\"fee_schedule\":{\"exponent\":\"1\",\"rate\":\"0.07\",\"taker_only\":true,\"rebate_rate\":\"0.2\"}}"}
{"recv_ts": 1786689827098927, "venue": "polymarket", "raw": "{\"market\":\"0xd595eb9b81885ff018738300c79047e3ec89e87294424f57a29a7fa9162bf116\",\"price_changes\":[{\"asset_id\":\"5161623255678193352839985156330393796378434470119114669671615782853260939535\",\"price\":\"0.024\",\"size\":\"100\",\"side\":\"BUY\",\"hash\":\"1c0b73f900fd009ae4363904216f852dcde0ea06\",\"best_bid\":\"0.036\",\"best_ask\":\"0.037\"},{\"asset_id\":\"57216272564529548464686463691236811991956032201293786790337952253964682584376\",\"price\":\"0.976\",\"size\":\"100\",\"side\":\"SELL\",\"hash\":\"22d96b84fa9b53a999857e2c55510f0f2bb3f9f4\",\"best_bid\":\"0.963\",\"best_ask\":\"0.964\"}],\"timestamp\":\"1786689827000\",\"event_type\":\"price_change\"}"}
{"recv_ts": 1786689828188150, "venue": "polymarket", "raw": "{\"id\":\"3578401\",\"question\":\"Solana Up or Down - August 15, 2:35AM-2:40AM ET\",\"market\":\"0x7198e9c8ce0b8244f4365271c90754d876bcc89101872460b80dd871dcf38689\",\"slug\":\"sol-updown-5m-1786775700\",\"description\":\"This market will resolve to \\\"Up\\\" if the time-weighted average price (TWAP) of Solana, generated by Chainlink, of the time range specified in the title is greater than or equal to the price at the beginning of that range. Otherwise, it will resolve to \\\"Down\\\".\\nThe resolution source for this market is information from Chainlink, specifically the SOL/USD TWAP data stream available at https://data.chain.link/streams/sol-usd-twap-60s-streams.\\nPlease note that this market is about the price according to the TWAP Chainlink data stream for the asset pair SOL/USD, not according to any other sources or spot markets.\",\"assets_ids\":[\"46414693762558792508601914035839124167070473334929875782973524487862599553859\",\"79836191314749552996986622010112579988055459640738543066085607638712678822240\"],\"outcomes\":[\"Up\",\"Down\"],\"event_message\":{\"id\":\"847365\",\"ticker\":\"sol-updown-5m-1786775700\",\"slug\":\"sol-updown-5m-1786775700\",\"title\":\"Solana Up or Down - August 15, 2:35AM-2:40AM ET\",\"description\":\"This market will resolve to \\\"Up\\\" if the time-weighted average price (TWAP) of Solana, generated by Chainlink, of the time range specified in the title is greater than or equal to the price at the beginning of that range. Otherwise, it will resolve to \\\"Down\\\".\\nThe resolution source for this market is information from Chainlink, specifically the SOL/USD TWAP data stream available at https://data.chain.link/streams/sol-usd-twap-60s-streams.\\nPlease note that this market is about the price according to the TWAP Chainlink data stream for the asset pair SOL/USD, not according to any other sources or spot markets.\"},\"timestamp\":\"1786689827887\",\"event_type\":\"new_market\",\"tags\":[],\"condition_id\":\"0x7198e9c8ce0b8244f4365271c90754d876bcc89101872460b80dd871dcf38689\",\"active\":false,\"clob_token_ids\":[\"46414693762558792508601914035839124167070473334929875782973524487862599553859\",\"79836191314749552996986622010112579988055459640738543066085607638712678822240\"],\"sports_market_type\":\"\",\"line\":\"\",\"game_start_time\":\"\",\"order_price_min_tick_size\":\"0.01\",\"group_item_title\":\"\",\"taker_base_fee\":\"1000\",\"fees_enabled\":true,\"fee_schedule\":{\"exponent\":\"1\",\"rate\":\"0.07\",\"taker_only\":true,\"rebate_rate\":\"0.2\"}}"}
{"recv_ts": 1786689828360805, "venue": "polymarket", "raw": "{\"market\":\"0xd595eb9b81885ff018738300c79047e3ec89e87294424f57a29a7fa9162bf116\",\"price_changes\":[{\"asset_id\":\"5161623255678193352839985156330393796378434470119114669671615782853260939535\",\"price\":\"0.024\",\"size\":\"1184\",\"side\":\"BUY\",\"hash\":\"e3c142e0ec5dd61f7b0dd27c392e3b4a5104b986\",\"best_bid\":\"0.036\",\"best_ask\":\"0.037\"},{\"asset_id\":\"57216272564529548464686463691236811991956032201293786790337952253964682584376\",\"price\":\"0.976\",\"size\":\"1184\",\"side\":\"SELL\",\"hash\":\"ea22057c8d1abde3f74c3640113546d5f943dc64\",\"best_bid\":\"0.963\",\"best_ask\":\"0.964\"}],\"timestamp\":\"1786689828353\",\"event_type\":\"price_change\"}"}
{"recv_ts": 1786689829014123, "venue": "polymarket", "raw": "{\"market\":\"0xd9fb1184af0064e5e34b129f5b79afa5a17b7e32f2953ab05efed82315fee6d4\",\"price_changes\":[{\"asset_id\":\"90772332434487149264114862115632028379978765245278600275169585501290867536237\",\"price\":\"0.4\",\"size\":\"4030\",\"side\":\"BUY\",\"hash\":\"537d83722fa29449694a9344a615df6ea4474eb0\",\"best_bid\":\"0.962\",\"best_ask\":\"0.964\"},{\"asset_id\":\"94559586571241563470235664821564670251180951772614764383113614156422396181162\",\"price\":\"0.6\",\"size\":\"4030\",\"side\":\"SELL\",\"hash\":\"668b38478aabb1143fe9600c62d59039c16a6784\",\"best_bid\":\"0.036\",\"best_ask\":\"0.038\"}],\"timestamp\":\"1786689829001\",\"event_type\":\"price_change\"}"}
{"recv_ts": 1786689829014233, "venue": "polymarket", "raw": "{\"market\":\"0xd9fb1184af0064e5e34b129f5b79afa5a17b7e32f2953ab05efed82315fee6d4\",\"price_changes\":[{\"asset_id\":\"90772332434487149264114862115632028379978765245278600275169585501290867536237\",\"price\":\"0.3\",\"size\":\"5666\",\"side\":\"BUY\",\"hash\":\"846052de8d213fb39b2877e10d5804029682e8a4\",\"best_bid\":\"0.962\",\"best_ask\":\"0.964\"},{\"asset_id\":\"94559586571241563470235664821564670251180951772614764383113614156422396181162\",\"price\":\"0.7\",\"size\":\"5666\",\"side\":\"SELL\",\"hash\":\"080b00c9dc9c6f4d21f89789da8fcd7541b41122\",\"best_bid\":\"0.036\",\"best_ask\":\"0.038\"}],\"timestamp\":\"1786689829004\",\"event_type\":\"price_change\"}"}
{"recv_ts": 1786689829014266, "venue": "polymarket", "raw": "{\"market\":\"0xd9fb1184af0064e5e34b129f5b79afa5a17b7e32f2953ab05efed82315fee6d4\",\"price_changes\":[{\"asset_id\":\"90772332434487149264114862115632028379978765245278600275169585501290867536237\",\"price\":\"0.1\",\"size\":\"16970\",\"side\":\"BUY\",\"hash\":\"846052de8d213fb39b2877e10d5804029682e8a4\",\"best_bid\":\"0.962\",\"best_ask\":\"0.964\"},{\"asset_id\":\"94559586571241563470235664821564670251180951772614764383113614156422396181162\",\"price\":\"0.9\",\"size\":\"16970\",\"side\":\"SELL\",\"hash\":\"080b00c9dc9c6f4d21f89789da8fcd7541b41122\",\"best_bid\":\"0.036\",\"best_ask\":\"0.038\"}],\"timestamp\":\"1786689829004\",\"event_type\":\"price_change\"}"}
{"recv_ts": 1786689829014291, "venue": "polymarket", "raw": "{\"market\":\"0xd9fb1184af0064e5e34b129f5b79afa5a17b7e32f2953ab05efed82315fee6d4\",\"price_changes\":[{\"asset_id\":\"90772332434487149264114862115632028379978765245278600275169585501290867536237\",\"price\":\"0.2\",\"size\":\"9255\",\"side\":\"BUY\",\"hash\":\"eb3631445ab87ba73bd0310d956d280d986d96d2\",\"best_bid\":\"0.962\",\"best_ask\":\"0.964\"},{\"asset_id\":\"94559586571241563470235664821564670251180951772614764383113614156422396181162\",\"price\":\"0.8\",\"size\":\"9255\",\"side\":\"SELL\",\"hash\":\"13273f4344f7b7d03e5a68c6dfbfdf855abf74ce\",\"best_bid\":\"0.036\",\"best_ask\":\"0.038\"}],\"timestamp\":\"1786689829005\",\"event_type\":\"price_change\"}"}
{"recv_ts": 1786689830703117, "venue": "polymarket", "raw": "{\"market\":\"0xd9fb1184af0064e5e34b129f5b79afa5a17b7e32f2953ab05efed82315fee6d4\",\"price_changes\":[{\"asset_id\":\"90772332434487149264114862115632028379978765245278600275169585501290867536237\",\"price\":\"0.5\",\"size\":\"4235.12\",\"side\":\"BUY\",\"hash\":\"791cdb75c6fc92e96bca2a10e4c59df7357b10d8\",\"best_bid\":\"0.962\",\"best_ask\":\"0.964\"},{\"asset_id\":\"94559586571241563470235664821564670251180951772614764383113614156422396181162\",\"price\":\"0.5\",\"size\":\"4235.12\",\"side\":\"SELL\",\"hash\":\"bcf2dbee6ff3a23e3848f736f9a9745e9f456a2d\",\"best_bid\":\"0.036\",\"best_ask\":\"0.038\"}],\"timestamp\":\"1786689830697\",\"event_type\":\"price_change\"}"}
{"recv_ts": 1786689830928482, "venue": "polymarket", "raw": "{\"market\":\"0xbb4d51e6364066d92eb6f9b8413dd7193de70966736044463b205834805a1f3b\",\"price_changes\":[{\"asset_id\":\"106181075047366745139197108801635573283215248045056329679360376976893016488727\",\"price\":\"0.9\",\"size\":\"27402.32\",\"side\":\"BUY\",\"hash\":\"16599890c4612ce0a8753ea129f8473209842622\",\"best_bid\":\"0.93\",\"best_ask\":\"0.94\"},{\"asset_id\":\"10991849228756847439673778874175365458450913336396982752046655649803657501964\",\"price\":\"0.1\",\"size\":\"27402.32\",\"side\":\"SELL\",\"hash\":\"6d67f8ed49c308e3ae961ddc3f48f8da5a671019\",\"best_bid\":\"0.06\",\"best_ask\":\"0.07\"}],\"timestamp\":\"1786689830922\",\"event_type\":\"price_change\"}"}
{"recv_ts": 1786689830928766, "venue": "polymarket", "raw": "{\"market\":\"0xbb4d51e6364066d92eb6f9b8413dd7193de70966736044463b205834805a1f3b\",\"price_changes\":[{\"asset_id\":\"10991849228756847439673778874175365458450913336396982752046655649803657501964\",\"price\":\"0.05\",\"size\":\"456672.25\",\"side\":\"BUY\",\"hash\":\"6339a32960f662cf05c84fe5563079b3091c6ef8\",\"best_bid\":\"0.06\",\"best_ask\":\"0.07\"},{\"asset_id\":\"106181075047366745139197108801635573283215248045056329679360376976893016488727\",\"price\":\"0.95\",\"size\":\"456672.25\",\"side\":\"SELL\",\"hash\":\"57d66ee1b580a98403f7bcf43dfb90da0afd45c1\",\"best_bid\":\"0.93\",\"best_ask\":\"0.94\"}],\"timestamp\":\"1786689830923\",\"event_type\":\"price_change\"}"}
{"recv_ts": 1786689831013773, "venue": "polymarket", "raw": "{\"id\":\"3578403\",\"question\":\"XRP Up or Down - August 15, 2:35AM-2:40AM ET\",\"market\":\"0xaa5648a17c8f8398d6f9c991a53e0e5b1ecd961de526d0c972bf477827bc45d1\",\"slug\":\"xrp-updown-5m-1786775700\",\"description\":\"This market will resolve to \\\"Up\\\" if the time-weighted average price (TWAP) of XRP, generated by Chainlink, of the time range specified in the title is greater than or equal to the price at the beginning of that range. Otherwise, it will resolve to \\\"Down\\\".\\nThe resolution source for this market is information from Chainlink, specifically the XRP/USD TWAP data stream available at https://data.chain.link/streams/xrp-usd-twap-60s-streams.\\nPlease note that this market is about the price according to the TWAP Chainlink data stream for the asset pair XRP/USD, not according to any other sources or spot markets.\",\"assets_ids\":[\"2768887617905221163317455105711320250139601673006657091266020946141203773452\",\"86680101815890853727214814903404143683490708060502669890877408897037742052057\"],\"outcomes\":[\"Up\",\"Down\"],\"event_message\":{\"id\":\"847369\",\"ticker\":\"xrp-updown-5m-1786775700\",\"slug\":\"xrp-updown-5m-1786775700\",\"title\":\"XRP Up or Down - August 15, 2:35AM-2:40AM ET\",\"description\":\"This market will resolve to \\\"Up\\\" if the time-weighted average price (TWAP) of XRP, generated by Chainlink, of the time range specified in the title is greater than or equal to the price at the beginning of that range. Otherwise, it will resolve to \\\"Down\\\".\\nThe resolution source for this market is information from Chainlink, specifically the XRP/USD TWAP data stream available at https://data.chain.link/streams/xrp-usd-twap-60s-streams.\\nPlease note that this market is about the price according to the TWAP Chainlink data stream for the asset pair XRP/USD, not according to any other sources or spot markets.\"},\"timestamp\":\"1786689831000\",\"event_type\":\"new_market\",\"tags\":[],\"condition_id\":\"0xaa5648a17c8f8398d6f9c991a53e0e5b1ecd961de526d0c972bf477827bc45d1\",\"active\":false,\"clob_token_ids\":[\"2768887617905221163317455105711320250139601673006657091266020946141203773452\",\"86680101815890853727214814903404143683490708060502669890877408897037742052057\"],\"sports_market_type\":\"\",\"line\":\"\",\"game_start_time\":\"\",\"order_price_min_tick_size\":\"0.01\",\"group_item_title\":\"\",\"taker_base_fee\":\"1000\",\"fees_enabled\":true,\"fee_schedule\":{\"exponent\":\"1\",\"rate\":\"0.07\",\"taker_only\":true,\"rebate_rate\":\"0.2\"}}"}
{"recv_ts": 1786689832009280, "venue": "polymarket", "raw": "{\"id\":\"3578404\",\"question\":\"Bitcoin Up or Down - August 15, 2:35AM-2:40AM ET\",\"market\":\"0xbb5a4ec8765e8324516cd85e26bd5fe255369f4e112af74fde51ef35129f5471\",\"slug\":\"btc-updown-5m-1786775700\",\"description\":\"This market will resolve to \\\"Up\\\" if the time-weighted average price (TWAP) of Bitcoin, generated by Chainlink, of the time range specified in the title is greater than or equal to the price at the beginning of that range. Otherwise, it will resolve to \\\"Down\\\".\\nThe resolution source for this market is information from Chainlink, specifically the BTC/USD TWAP data stream available at https://data.chain.link/streams/btc-usd-twap-60s-streams.\\nPlease note that this market is about the price according to the TWAP Chainlink data stream for the asset pair BTC/USD, not according to any other sources or spot markets.\",\"assets_ids\":[\"84233084765932774490735162902743523745375692597285786695501431666475608284162\",\"61339490021908660171776535725321670404538015020841612911606350361688856750661\"],\"outcomes\":[\"Up\",\"Down\"],\"event_message\":{\"id\":\"847371\",\"ticker\":\"btc-updown-5m-1786775700\",\"slug\":\"btc-updown-5m-1786775700\",\"title\":\"Bitcoin Up or Down - August 15, 2:35AM-2:40AM ET\",\"description\":\"This market will resolve to \\\"Up\\\" if the time-weighted average price (TWAP) of Bitcoin, generated by Chainlink, of the time range specified in the title is greater than or equal to the price at the beginning of that range. Otherwise, it will resolve to \\\"Down\\\".\\nThe resolution source for this market is information from Chainlink, specifically the BTC/USD TWAP data stream available at https://data.chain.link/streams/btc-usd-twap-60s-streams.\\nPlease note that this market is about the price according to the TWAP Chainlink data stream for the asset pair BTC/USD, not according to any other sources or spot markets.\"},\"timestamp\":\"1786689831986\",\"event_type\":\"new_market\",\"tags\":[],\"condition_id\":\"0xbb5a4ec8765e8324516cd85e26bd5fe255369f4e112af74fde51ef35129f5471\",\"active\":false,\"clob_token_ids\":[\"84233084765932774490735162902743523745375692597285786695501431666475608284162\",\"61339490021908660171776535725321670404538015020841612911606350361688856750661\"],\"sports_market_type\":\"\",\"line\":\"\",\"game_start_time\":\"\",\"order_price_min_tick_size\":\"0.01\",\"group_item_title\":\"\",\"taker_base_fee\":\"1000\",\"fees_enabled\":true,\"fee_schedule\":{\"exponent\":\"1\",\"rate\":\"0.07\",\"taker_only\":true,\"rebate_rate\":\"0.2\"}}"}
{"recv_ts": 1786689833007042, "venue": "polymarket", "raw": "{\"market\":\"0x6bd56627aa21311850825edb27e53434a0e17a4f782be0086bc07f71eee00d0d\",\"price_changes\":[{\"asset_id\":\"350977769852917329387037893294763093471844346281449484439085576212613048126\",\"price\":\"0.05\",\"size\":\"241035.08\",\"side\":\"BUY\",\"hash\":\"6c0d7bba6f044e410ac336501a67ceab0c13b85c\",\"best_bid\":\"0.07\",\"best_ask\":\"0.08\"},{\"asset_id\":\"87073899845581463485186346288398658568334162612963837182986759797304993556208\",\"price\":\"0.95\",\"size\":\"241035.08\",\"side\":\"SELL\",\"hash\":\"12591ace522e0d1f227a175bd4690f53b4c34874\",\"best_bid\":\"0.92\",\"best_ask\":\"0.93\"}],\"timestamp\":\"1786689833000\",\"event_type\":\"price_change\"}"}
{"recv_ts": 1786689833007153, "venue": "polymarket", "raw": "{\"market\":\"0x6bd56627aa21311850825edb27e53434a0e17a4f782be0086bc07f71eee00d0d\",\"price_changes\":[{\"asset_id\":\"87073899845581463485186346288398658568334162612963837182986759797304993556208\",\"price\":\"0.91\",\"size\":\"122410.77\",\"side\":\"BUY\",\"hash\":\"12591ace522e0d1f227a175bd4690f53b4c34874\",\"best_bid\":\"0.92\",\"best_ask\":\"0.93\"},{\"asset_id\":\"350977769852917329387037893294763093471844346281449484439085576212613048126\",\"price\":\"0.09\",\"size\":\"122410.77\",\"side\":\"SELL\",\"hash\":\"6c0d7bba6f044e410ac336501a67ceab0c13b85c\",\"best_bid\":\"0.07\",\"best_ask\":\"0.08\"}],\"timestamp\":\"1786689833000\",\"event_type\":\"price_change\"}"}
{"recv_ts": 1786689833086480, "venue": "polymarket", "raw": "{\"market\":\"0x6bd56627aa21311850825edb27e53434a0e17a4f782be0086bc07f71eee00d0d\",\"price_changes\":[{\"asset_id\":\"87073899845581463485186346288398658568334162612963837182986759797304993556208\",\"price\":\"0.91\",\"size\":\"122650.77\",\"side\":\"BUY\",\"hash\":\"9f6360e5fada1277172bf343dcd1bdebe97c6975\",\"best_bid\":\"0.92\",\"best_ask\":\"0.93\"},{\"asset_id\":\"350977769852917329387037893294763093471844346281449484439085576212613048126\",\"price\":\"0.09\",\"size\":\"122650.77\",\"side\":\"SELL\",\"hash\":\"c6d7f96152d1baa316f3d9b0fdc64ba8d0603bf9\",\"best_bid\":\"0.07\",\"best_ask\":\"0.08\"}],\"timestamp\":\"1786689833079\",\"event_type\":\"price_change\"}"}
{"recv_ts": 1786689833087271, "venue": "polymarket", "raw": "{\"market\":\"0x6bd56627aa21311850825edb27e53434a0e17a4f782be0086bc07f71eee00d0d\",\"price_changes\":[{\"asset_id\":\"350977769852917329387037893294763093471844346281449484439085576212613048126\",\"price\":\"0.05\",\"size\":\"241275.08\",\"side\":\"BUY\",\"hash\":\"496dae57114d8e5ca8175eccf5009cda02ead1c8\",\"best_bid\":\"0.07\",\"best_ask\":\"0.08\"},{\"asset_id\":\"87073899845581463485186346288398658568334162612963837182986759797304993556208\",\"price\":\"0.95\",\"size\":\"241275.08\",\"side\":\"SELL\",\"hash\":\"009e2e4a564673d16e65da0b031726211c6ac430\",\"best_bid\":\"0.92\",\"best_ask\":\"0.93\"}],\"timestamp\":\"1786689833080\",\"event_type\":\"price_change\"}"}
{"recv_ts": 1786689833626982, "venue": "polymarket", "raw": "{\"market\":\"0xd9fb1184af0064e5e34b129f5b79afa5a17b7e32f2953ab05efed82315fee6d4\",\"price_changes\":[{\"asset_id\":\"90772332434487149264114862115632028379978765245278600275169585501290867536237\",\"price\":\"0.4\",\"size\":\"5280\",\"side\":\"BUY\",\"hash\":\"2e610dd5a733b0e0d250ff3c27e28759049e0679\",\"best_bid\":\"0.962\",\"best_ask\":\"0.964\"},{\"asset_id\":\"94559586571241563470235664821564670251180951772614764383113614156422396181162\",\"price\":\"0.6\",\"size\":\"5280\",\"side\":\"SELL\",\"hash\":\"4bf0e1f382a03096ae89266c32a7d203c6962d12\",\"best_bid\":\"0.036\",\"best_ask\":\"0.038\"}],\"timestamp\":\"1786689833589\",\"event_type\":\"price_change\"}"}
{"recv_ts": 1786689833627078, "venue": "polymarket", "raw": "{\"market\":\"0xd9fb1184af0064e5e34b129f5b79afa5a17b7e32f2953ab05efed82315fee6d4\",\"price_changes\":[{\"asset_id\":\"90772332434487149264114862115632028379978765245278600275169585501290867536237\",\"price\":\"0.1\",\"size\":\"28970\",\"side\":\"BUY\",\"hash\":\"9b46a825e88a2556d040ddf53b34a9e557bb2ea1\",\"best_bid\":\"0.962\",\"best_ask\":\"0.964\"},{\"asset_id\":\"94559586571241563470235664821564670251180951772614764383113614156422396181162\",\"price\":\"0.9\",\"size\":\"28970\",\"side\":\"SELL\",\"hash\":\"010ef188e95677e43e5c1471b143438796c74c1f\",\"best_bid\":\"0.036\",\"best_ask\":\"0.038\"}],\"timestamp\":\"1786689833590\",\"event_type\":\"price_change\"}"}
{"recv_ts": 1786689833627111, "venue": "polymarket", "raw": "{\"market\":\"0xd9fb1184af0064e5e34b129f5b79afa5a17b7e32f2953ab05efed82315fee6d4\",\"price_changes\":[{\"asset_id\":\"90772332434487149264114862115632028379978765245278600275169585501290867536237\",\"price\":\"0.3\",\"size\":\"8666\",\"side\":\"BUY\",\"hash\":\"bc1334e8af28aec3cd0bfc6cd8370ba3c81d7674\",\"best_bid\":\"0.962\",\"best_ask\":\"0.964\"},{\"asset_id\":\"94559586571241563470235664821564670251180951772614764383113614156422396181162\",\"price\":\"0.7\",\"size\":\"8666\",\"side\":\"SELL\",\"hash\":\"a0895f4aede0ba2211d15ef1b4c7529206926887\",\"best_bid\":\"0.036\",\"best_ask\":\"0.038\"}],\"timestamp\":\"1786689833591\",\"event_type\":\"price_change\"}"}
{"recv_ts": 1786689833627205, "venue": "polymarket", "raw": "{\"market\":\"0xd9fb1184af0064e5e34b129f5b79afa5a17b7e32f2953ab05efed82315fee6d4\",\"price_changes\":[{\"asset_id\":\"90772332434487149264114862115632028379978765245278600275169585501290867536237\",\"price\":\"0.2\",\"size\":\"14255\",\"side\":\"BUY\",\"hash\":\"5d270537aaff164d89b41b483b7404e16e01e68e\",\"best_bid\":\"0.962\",\"best_ask\":\"0.964\"},{\"asset_id\":\"94559586571241563470235664821564670251180951772614764383113614156422396181162\",\"price\":\"0.8\",\"size\":\"14255\",\"side\":\"SELL\",\"hash\":\"bebbc62e716bb2f2ecd3754c55c08b258a14bc72\",\"best_bid\":\"0.036\",\"best_ask\":\"0.038\"}],\"timestamp\":\"1786689833591\",\"event_type\":\"price_change\"}"}
{"recv_ts": 1786689835005726, "venue": "polymarket", "raw": "{\"market\":\"0xd9fb1184af0064e5e34b129f5b79afa5a17b7e32f2953ab05efed82315fee6d4\",\"price_changes\":[{\"asset_id\":\"90772332434487149264114862115632028379978765245278600275169585501290867536237\",\"price\":\"0.93\",\"size\":\"370\",\"side\":\"BUY\",\"hash\":\"89aa74643582282cba8b6dead4bee9d6f80de60b\",\"best_bid\":\"0.962\",\"best_ask\":\"0.964\"},{\"asset_id\":\"94559586571241563470235664821564670251180951772614764383113614156422396181162\",\"price\":\"0.07\",\"size\":\"370\",\"side\":\"SELL\",\"hash\":\"b2db8a1e3d9faeb6ff0a2be655dd6d4153795291\",\"best_bid\":\"0.036\",\"best_ask\":\"0.038\"}],\"timestamp\":\"1786689835000\",\"event_type\":\"price_change\"}"}
{"recv_ts": 1786689835092239, "venue": "polymarket", "raw": "{\"market\":\"0xd9fb1184af0064e5e34b129f5b79afa5a17b7e32f2953ab05efed82315fee6d4\",\"price_changes\":[{\"asset_id\":\"90772332434487149264114862115632028379978765245278600275169585501290867536237\",\"price\":\"0.64\",\"size\":\"0\",\"side\":\"BUY\",\"hash\":\"8778d1de5133549b3bc76f2970b6a91b5f41dd2c\",\"best_bid\":\"0.962\",\"best_ask\":\"0.964\"},{\"asset_id\":\"94559586571241563470235664821564670251180951772614764383113614156422396181162\",\"price\":\"0.36\",\"size\":\"0\",\"side\":\"SELL\",\"hash\":\"f2fc3a89a966363e6267614492ed570a4821b13a\",\"best_bid\":\"0.036\",\"best_ask\":\"0.038\"}],\"timestamp\":\"1786689835086\",\"event_type\":\"price_change\"}"}
{"recv_ts": 1786689835092929, "venue": "polymarket", "raw": "{\"market\":\"0xd9fb1184af0064e5e34b129f5b79afa5a17b7e32f2953ab05efed82315fee6d4\",\"price_changes\":[{\"asset_id\":\"90772332434487149264114862115632028379978765245278600275169585501290867536237\",\"price\":\"0.65\",\"size\":\"280\",\"side\":\"BUY\",\"hash\":\"b68b79d0399fc96ee9336f8fc89d9294874c38f3\",\"best_bid\":\"0.962\",\"best_ask\":\"0.964\"},{\"asset_id\":\"94559586571241563470235664821564670251180951772614764383113614156422396181162\",\"price\":\"0.35\",\"size\":\"280\",\"side\":\"SELL\",\"hash\":\"fd7cfa3ab27efa77915a5b5600db115c7bd653f9\",\"best_bid\":\"0.036\",\"best_ask\":\"0.038\"}],\"timestamp\":\"1786689835087\",\"event_type\":\"price_change\"}"}
{"recv_ts": 1786689835323864, "venue": "polymarket", "raw": "{\"market\":\"0xd9fb1184af0064e5e34b129f5b79afa5a17b7e32f2953ab05efed82315fee6d4\",\"price_changes\":[{\"asset_id\":\"90772332434487149264114862115632028379978765245278600275169585501290867536237\",\"price\":\"0.93\",\"size\":\"457\",\"side\":\"BUY\",\"hash\":\"f18568d88671c949ce63a9a8e873b14328fa6209\",\"best_bid\":\"0.962\",\"best_ask\":\"0.964\"},{\"asset_id\":\"94559586571241563470235664821564670251180951772614764383113614156422396181162\",\"price\":\"0.07\",\"size\":\"457\",\"side\":\"SELL\",\"hash\":\"dcf848a1902eaeb597d7e616286e56abf48b4324\",\"best_bid\":\"0.036\",\"best_ask\":\"0.038\"}],\"timestamp\":\"1786689835318\",\"event_type\":\"price_change\"}"}
{"recv_ts": 1786689835455406, "venue": "polymarket", "raw": "{\"market\":\"0x60c2c085ee8c16bc8f2419739a94971d4c9d00f637ead10fc0f540afa1be64e8\",\"price_changes\":[{\"asset_id\":\"105426373826369935595603860663411604941599130211176020843036778867927711117332\",\"price\":\"0.008\",\"size\":\"38750\",\"side\":\"BUY\",\"hash\":\"56245e9a98be7670297be0743f771634e47d3bdd\",\"best_bid\":\"0.02\",\"best_ask\":\"0.021\"},{\"asset_id\":\"90869494087977018607792751230236923002303032923064138180950209430688758061828\",\"price\":\"0.992\",\"size\":\"38750\",\"side\":\"SELL\",\"hash\":\"2eb325cc735f5dc51b408f58b141422116c199cd\",\"best_bid\":\"0.979\",\"best_ask\":\"0.98\"}],\"timestamp\":\"1786689835449\",\"event_type\":\"price_change\"}"}
{"recv_ts": 1786689836788040, "venue": "polymarket", "raw": "{\"market\":\"0xd595eb9b81885ff018738300c79047e3ec89e87294424f57a29a7fa9162bf116\",\"price_changes\":[{\"asset_id\":\"57216272564529548464686463691236811991956032201293786790337952253964682584376\",\"price\":\"0.963\",\"size\":\"12870.97\",\"side\":\"BUY\",\"hash\":\"78a3365ce8e2df287971364c3e9edab6501382f7\",\"best_bid\":\"0.963\",\"best_ask\":\"0.964\"},{\"asset_id\":\"5161623255678193352839985156330393796378434470119114669671615782853260939535\",\"price\":\"0.037\",\"size\":\"12870.97\",\"side\":\"SELL\",\"hash\":\"3f14d1d03051b722cf633091c1e519b9516d1f60\",\"best_bid\":\"0.036\",\"best_ask\":\"0.037\"}],\"timestamp\":\"1786689836778\",\"event_type\":\"price_change\"}"}
{"recv_ts": 1786689836925895, "venue": "polymarket", "raw": "{\"market\":\"0x6bd56627aa21311850825edb27e53434a0e17a4f782be0086bc07f71eee00d0d\",\"price_changes\":[{\"asset_id\":\"87073899845581463485186346288398658568334162612963837182986759797304993556208\",\"price\":\"0.93\",\"size\":\"136097.66\",\"side\":\"SELL\",\"hash\":\"892d193be4ada13071bf92b9ab9d0139e74225cf\",\"best_bid\":\"0.92\",\"best_ask\":\"0.93\"},{\"asset_id\":\"350977769852917329387037893294763093471844346281449484439085576212613048126\",\"price\":\"0.07\",\"size\":\"136097.66\",\"side\":\"BUY\",\"hash\":\"dc6cd6f3e9fbf2695fcde6b9dd194e758f1d7381\",\"best_bid\":\"0.07\",\"best_ask\":\"0.08\"}],\"timestamp\":\"1786689836913\",\"event_type\":\"price_change\"}"}
{"recv_ts": 1786689837003556, "venue": "polymarket", "raw": "{\"market\":\"0x6bd56627aa21311850825edb27e53434a0e17a4f782be0086bc07f71eee00d0d\",\"price_changes\":[{\"asset_id\":\"87073899845581463485186346288398658568334162612963837182986759797304993556208\",\"price\":\"0.93\",\"size\":\"136122.66\",\"side\":\"SELL\",\"hash\":\"5a659f1182c12312d5d0197a3829fba788408959\",\"best_bid\":\"0.92\",\"best_ask\":\"0.93\"},{\"asset_id\":\"350977769852917329387037893294763093471844346281449484439085576212613048126\",\"price\":\"0.07\",\"size\":\"136122.66\",\"side\":\"BUY\",\"hash\":\"d368663d1d78d05abb203e93fe118de4553046f1\",\"best_bid\":\"0.07\",\"best_ask\":\"0.08\"}],\"timestamp\":\"1786689836996\",\"event_type\":\"price_change\"}"}
{"recv_ts": 1786689837806212, "venue": "polymarket", "raw": "{\"market\":\"0xd595eb9b81885ff018738300c79047e3ec89e87294424f57a29a7fa9162bf116\",\"price_changes\":[{\"asset_id\":\"57216272564529548464686463691236811991956032201293786790337952253964682584376\",\"price\":\"0.963\",\"size\":\"12970.7\",\"side\":\"BUY\",\"hash\":\"b0bbbc1b679821a5b34239a6bda2e9838f049cb1\",\"best_bid\":\"0.963\",\"best_ask\":\"0.964\"},{\"asset_id\":\"5161623255678193352839985156330393796378434470119114669671615782853260939535\",\"price\":\"0.037\",\"size\":\"12970.7\",\"side\":\"SELL\",\"hash\":\"049371e59959fb0fdb10f90a8a20b73e234dd32c\",\"best_bid\":\"0.036\",\"best_ask\":\"0.037\"}],\"timestamp\":\"1786689837800\",\"event_type\":\"price_change\"}"}
{"recv_ts": 1786689840087548, "venue": "polymarket", "raw": "{\"market\":\"0xd9fb1184af0064e5e34b129f5b79afa5a17b7e32f2953ab05efed82315fee6d4\",\"price_changes\":[{\"asset_id\":\"90772332434487149264114862115632028379978765245278600275169585501290867536237\",\"price\":\"0.96\",\"size\":\"38440.56\",\"side\":\"BUY\",\"hash\":\"6d6124e83364cba5723e673687d737ade2af187b\",\"best_bid\":\"0.962\",\"best_ask\":\"0.964\"},{\"asset_id\":\"94559586571241563470235664821564670251180951772614764383113614156422396181162\",\"price\":\"0.04\",\"size\":\"38440.56\",\"side\":\"SELL\",\"hash\":\"a2008a4c14cf283834f09cdd1c2e30dff6d77c63\",\"best_bid\":\"0.036\",\"best_ask\":\"0.038\"}],\"timestamp\":\"1786689840054\",\"event_type\":\"price_change\"}"}
{"recv_ts": 1786689840122478, "venue": "polymarket", "raw": "{\"market\":\"0x747dc809fb79e1b05be09c42d6179459a58de2ef3e40f02484a4e1260f741f75\",\"price_changes\":[{\"asset_id\":\"107505882767731489358349912513945399560393482969656700824895970500493757150417\",\"price\":\"0.04\",\"size\":\"322461.46\",\"side\":\"BUY\",\"hash\":\"eaee190f5fec7f2012c4ae2bd36d395514f35130\",\"best_bid\":\"0.04\",\"best_ask\":\"0.05\"},{\"asset_id\":\"7305630249804085635496399869905769372294302716159034447326228509068694952392\",\"price\":\"0.96\",\"size\":\"322461.46\",\"side\":\"SELL\",\"hash\":\"cbdcb3ff0b7e0cad52d0116ad3b5f9f5f9d97b1e\",\"best_bid\":\"0.95\",\"best_ask\":\"0.96\"}],\"timestamp\":\"1786689840115\",\"event_type\":\"price_change\"}"}
{"recv_ts": 1786689840122556, "venue": "polymarket", "raw": "{\"market\":\"0x747dc809fb79e1b05be09c42d6179459a58de2ef3e40f02484a4e1260f741f75\",\"price_changes\":[{\"asset_id\":\"7305630249804085635496399869905769372294302716159034447326228509068694952392\",\"price\":\"0.95\",\"size\":\"268448.35\",\"side\":\"BUY\",\"hash\":\"cbdcb3ff0b7e0cad52d0116ad3b5f9f5f9d97b1e\",\"best_bid\":\"0.95\",\"best_ask\":\"0.96\"},{\"asset_id\":\"107505882767731489358349912513945399560393482969656700824895970500493757150417\",\"price\":\"0.05\",\"size\":\"268448.35\",\"side\":\"SELL\",\"hash\":\"eaee190f5fec7f2012c4ae2bd36d395514f35130\",\"best_bid\":\"0.04\",\"best_ask\":\"0.05\"}],\"timestamp\":\"1786689840115\",\"event_type\":\"price_change\"}"}
{"recv_ts": 1786689840557675, "venue": "polymarket", "raw": "{\"market\":\"0x60c2c085ee8c16bc8f2419739a94971d4c9d00f637ead10fc0f540afa1be64e8\",\"price_changes\":[{\"asset_id\":\"105426373826369935595603860663411604941599130211176020843036778867927711117332\",\"price\":\"0.008\",\"size\":\"48749\",\"side\":\"BUY\",\"hash\":\"a8925abaa7c2fa3356782de5d63545608332a106\",\"best_bid\":\"0.02\",\"best_ask\":\"0.021\"},{\"asset_id\":\"90869494087977018607792751230236923002303032923064138180950209430688758061828\",\"price\":\"0.992\",\"size\":\"48749\",\"side\":\"SELL\",\"hash\":\"4e3fe0dde7bcae0727b342371b7e5cdf574b030f\",\"best_bid\":\"0.979\",\"best_ask\":\"0.98\"}],\"timestamp\":\"1786689840551\",\"event_type\":\"price_change\"}"}
{"recv_ts": 1786689841915829, "venue": "polymarket", "raw": "{\"market\":\"0x747dc809fb79e1b05be09c42d6179459a58de2ef3e40f02484a4e1260f741f75\",\"price_changes\":[{\"asset_id\":\"107505882767731489358349912513945399560393482969656700824895970500493757150417\",\"price\":\"0.04\",\"size\":\"322661.46\",\"side\":\"BUY\",\"hash\":\"65011272938d5ff01c1e638cb2b5deff6a9bc15a\",\"best_bid\":\"0.04\",\"best_ask\":\"0.05\"},{\"asset_id\":\"7305630249804085635496399869905769372294302716159034447326228509068694952392\",\"price\":\"0.96\",\"size\":\"322661.46\",\"side\":\"SELL\",\"hash\":\"29e95e23ac42d656192a7a252878a8360a3fc0b7\",\"best_bid\":\"0.95\",\"best_ask\":\"0.96\"}],\"timestamp\":\"1786689841909\",\"event_type\":\"price_change\"}"}
{"recv_ts": 1786689842300565, "venue": "polymarket", "raw": "{\"market\":\"0x747dc809fb79e1b05be09c42d6179459a58de2ef3e40f02484a4e1260f741f75\",\"price_changes\":[{\"asset_id\":\"7305630249804085635496399869905769372294302716159034447326228509068694952392\",\"price\":\"0.95\",\"size\":\"268648.35\",\"side\":\"BUY\",\"hash\":\"d5c0b4d5f7b92ac65bb1ddb10ee56717210ac893\",\"best_bid\":\"0.95\",\"best_ask\":\"0.96\"},{\"asset_id\":\"107505882767731489358349912513945399560393482969656700824895970500493757150417\",\"price\":\"0.05\",\"size\":\"268648.35\",\"side\":\"SELL\",\"hash\":\"6e023bd83473ca44ee7123f1040e889ead999244\",\"best_bid\":\"0.04\",\"best_ask\":\"0.05\"}],\"timestamp\":\"1786689842294\",\"event_type\":\"price_change\"}"}
{"recv_ts": 1786689842694126, "venue": "polymarket", "raw": "{\"market\":\"0x747dc809fb79e1b05be09c42d6179459a58de2ef3e40f02484a4e1260f741f75\",\"price_changes\":[{\"asset_id\":\"107505882767731489358349912513945399560393482969656700824895970500493757150417\",\"price\":\"0.02\",\"size\":\"290456.25\",\"side\":\"BUY\",\"hash\":\"161a3a058ab3a3cb78fe2f1ee52864330bb2a0b1\",\"best_bid\":\"0.04\",\"best_ask\":\"0.05\"},{\"asset_id\":\"7305630249804085635496399869905769372294302716159034447326228509068694952392\",\"price\":\"0.98\",\"size\":\"290456.25\",\"side\":\"SELL\",\"hash\":\"d21ce3d3dee4b9d90e998aba789de57fdcb3af08\",\"best_bid\":\"0.95\",\"best_ask\":\"0.96\"}],\"timestamp\":\"1786689842687\",\"event_type\":\"price_change\"}"}
{"recv_ts": 1786689842694684, "venue": "polymarket", "raw": "{\"market\":\"0x747dc809fb79e1b05be09c42d6179459a58de2ef3e40f02484a4e1260f741f75\",\"price_changes\":[{\"asset_id\":\"107505882767731489358349912513945399560393482969656700824895970500493757150417\",\"price\":\"0.03\",\"size\":\"355606.26\",\"side\":\"BUY\",\"hash\":\"161a3a058ab3a3cb78fe2f1ee52864330bb2a0b1\",\"best_bid\":\"0.04\",\"best_ask\":\"0.05\"},{\"asset_id\":\"7305630249804085635496399869905769372294302716159034447326228509068694952392\",\"price\":\"0.97\",\"size\":\"355606.26\",\"side\":\"SELL\",\"hash\":\"d21ce3d3dee4b9d90e998aba789de57fdcb3af08\",\"best_bid\":\"0.95\",\"best_ask\":\"0.96\"}],\"timestamp\":\"1786689842687\",\"event_type\":\"price_change\"}"}
{"recv_ts": 1786689842694714, "venue": "polymarket", "raw": "{\"market\":\"0x747dc809fb79e1b05be09c42d6179459a58de2ef3e40f02484a4e1260f741f75\",\"price_changes\":[{\"asset_id\":\"7305630249804085635496399869905769372294302716159034447326228509068694952392\",\"price\":\"0.93\",\"size\":\"58771.82\",\"side\":\"BUY\",\"hash\":\"d21ce3d3dee4b9d90e998aba789de57fdcb3af08\",\"best_bid\":\"0.95\",\"best_ask\":\"0.96\"},{\"asset_id\":\"107505882767731489358349912513945399560393482969656700824895970500493757150417\",\"price\":\"0.07\",\"size\":\"58771.82\",\"side\":\"SELL\",\"hash\":\"161a3a058ab3a3cb78fe2f1ee52864330bb2a0b1\",\"best_bid\":\"0.04\",\"best_ask\":\"0.05\"}],\"timestamp\":\"1786689842687\",\"event_type\":\"price_change\"}"}
{"recv_ts": 1786689842694730, "venue": "polymarket", "raw": "{\"market\":\"0x747dc809fb79e1b05be09c42d6179459a58de2ef3e40f02484a4e1260f741f75\",\"price_changes\":[{\"asset_id\":\"7305630249804085635496399869905769372294302716159034447326228509068694952392\",\"price\":\"0.94\",\"size\":\"122522.12\",\"side\":\"BUY\",\"hash\":\"d21ce3d3dee4b9d90e998aba789de57fdcb3af08\",\"best_bid\":\"0.95\",\"best_ask\":\"0.96\"},{\"asset_id\":\"107505882767731489358349912513945399560393482969656700824895970500493757150417\",\"price\":\"0.06\",\"size\":\"122522.12\",\"side\":\"SELL\",\"hash\":\"161a3a058ab3a3cb78fe2f1ee52864330bb2a0b1\",\"best_bid\":\"0.04\",\"best_ask\":\"0.05\"}],\"timestamp\":\"1786689842687\",\"event_type\":\"price_change\"}"}
{"recv_ts": 1786689843016937, "venue": "polymarket", "raw": "{\"market\":\"0x60c2c085ee8c16bc8f2419739a94971d4c9d00f637ead10fc0f540afa1be64e8\",\"price_changes\":[{\"asset_id\":\"90869494087977018607792751230236923002303032923064138180950209430688758061828\",\"price\":\"0.2\",\"size\":\"31780.12\",\"side\":\"BUY\",\"hash\":\"00c779a246774a5d3350bac7f77983cc597692d6\",\"best_bid\":\"0.979\",\"best_ask\":\"0.98\"},{\"asset_id\":\"105426373826369935595603860663411604941599130211176020843036778867927711117332\",\"price\":\"0.8\",\"size\":\"31780.12\",\"side\":\"SELL\",\"hash\":\"82cb62a271f5ff3ee5f23affa32b9d01b76bc2e9\",\"best_bid\":\"0.02\",\"best_ask\":\"0.021\"}],\"timestamp\":\"1786689843009\",\"event_type\":\"price_change\"}"}
{"recv_ts": 1786689843025265, "venue": "polymarket", "raw": "{\"market\":\"0x60c2c085ee8c16bc8f2419739a94971d4c9d00f637ead10fc0f540afa1be64e8\",\"price_changes\":[{\"asset_id\":\"90869494087977018607792751230236923002303032923064138180950209430688758061828\",\"price\":\"0.1\",\"size\":\"54250\",\"side\":\"BUY\",\"hash\":\"00c779a246774a5d3350bac7f77983cc597692d6\",\"best_bid\":\"0.979\",\"best_ask\":\"0.98\"},{\"asset_id\":\"105426373826369935595603860663411604941599130211176020843036778867927711117332\",\"price\":\"0.9\",\"size\":\"54250\",\"side\":\"SELL\",\"hash\":\"82cb62a271f5ff3ee5f23affa32b9d01b76bc2e9\",\"best_bid\":\"0.02\",\"best_ask\":\"0.021\"}],\"timestamp\":\"1786689843009\",\"event_type\":\"price_change\"}"}
{"recv_ts": 1786689843026768, "venue": "polymarket", "raw": "{\"market\":\"0x60c2c085ee8c16bc8f2419739a94971d4c9d00f637ead10fc0f540afa1be64e8\",\"price_changes\":[{\"asset_id\":\"90869494087977018607792751230236923002303032923064138180950209430688758061828\",\"price\":\"0.4\",\"size\":\"10635.7\",\"side\":\"BUY\",\"hash\":\"66ad8a9b16ad6b44495e446aaffe984b3cdac71e\",\"best_bid\":\"0.979\",\"best_ask\":\"0.98\"},{\"asset_id\":\"105426373826369935595603860663411604941599130211176020843036778867927711117332\",\"price\":\"0.6\",\"size\":\"10635.7\",\"side\":\"SELL\",\"hash\":\"729f77bc514db95154648ee375d1431563c112d5\",\"best_bid\":\"0.02\",\"best_ask\":\"0.021\"}],\"timestamp\":\"1786689843017\",\"event_type\":\"price_change\"}"}
{"recv_ts": 1786689843029304, "venue": "polymarket", "raw": "{\"market\":\"0x60c2c085ee8c16bc8f2419739a94971d4c9d00f637ead10fc0f540afa1be64e8\",\"price_changes\":[{\"asset_id\":\"90869494087977018607792751230236923002303032923064138180950209430688758061828\",\"price\":\"0.3\",\"size\":\"15876.63\",\"side\":\"BUY\",\"hash\":\"7a633a1408447afa6176ae6090661e959fe46cc6\",\"best_bid\":\"0.979\",\"best_ask\":\"0.98\"},{\"asset_id\":\"105426373826369935595603860663411604941599130211176020843036778867927711117332\",\"price\":\"0.7\",\"size\":\"15876.63\",\"side\":\"SELL\",\"hash\":\"6f5c8542b2dc37c0aeeab8bc5d3b42bcd52aac80\",\"best_bid\":\"0.02\",\"best_ask\":\"0.021\"}],\"timestamp\":\"1786689843020\",\"event_type\":\"price_change\"}"}
{"recv_ts": 1786689843216563, "venue": "polymarket", "raw": "{\"market\":\"0x747dc809fb79e1b05be09c42d6179459a58de2ef3e40f02484a4e1260f741f75\",\"price_changes\":[{\"asset_id\":\"7305630249804085635496399869905769372294302716159034447326228509068694952392\",\"price\":\"0.94\",\"size\":\"122527.12\",\"side\":\"BUY\",\"hash\":\"55c830d588cf96d1969b191c60c6a3145663e008\",\"best_bid\":\"0.95\",\"best_ask\":\"0.96\"},{\"asset_id\":\"107505882767731489358349912513945399560393482969656700824895970500493757150417\",\"price\":\"0.06\",\"size\":\"122527.12\",\"side\":\"SELL\",\"hash\":\"49c13432f26a794d6d8ba2be5bec1a74a33dd7ae\",\"best_bid\":\"0.04\",\"best_ask\":\"0.05\"}],\"timestamp\":\"1786689843210\",\"event_type\":\"price_change\"}"}
{"recv_ts": 1786689843216837, "venue": "polymarket", "raw": "{\"market\":\"0x747dc809fb79e1b05be09c42d6179459a58de2ef3e40f02484a4e1260f741f75\",\"price_changes\":[{\"asset_id\":\"107505882767731489358349912513945399560393482969656700824895970500493757150417\",\"price\":\"0.02\",\"size\":\"323833.54\",\"side\":\"BUY\",\"hash\":\"3a3af0887f5164dea5e284fea566e1bb6bf50ff4\",\"best_bid\":\"0.04\",\"best_ask\":\"0.05\"},{\"asset_id\":\"7305630249804085635496399869905769372294302716159034447326228509068694952392\",\"price\":\"0.98\",\"size\":\"323833.54\",\"side\":\"SELL\",\"hash\":\"3e4b2fdbacaf8a05032651bea803b4c686a1f87b\",\"best_bid\":\"0.95\",\"best_ask\":\"0.96\"}],\"timestamp\":\"1786689843211\",\"event_type\":\"price_change\"}"}
{"recv_ts": 1786689843218174, "venue": "polymarket", "raw": "{\"market\":\"0x747dc809fb79e1b05be09c42d6179459a58de2ef3e40f02484a4e1260f741f75\",\"price_changes\":[{\"asset_id\":\"107505882767731489358349912513945399560393482969656700824895970500493757150417\",\"price\":\"0.03\",\"size\":\"355611.26\",\"side\":\"BUY\",\"hash\":\"d23973e6cd5ce0d6aeb95c7f3678d370c65a3edb\",\"best_bid\":\"0.04\",\"best_ask\":\"0.05\"},{\"asset_id\":\"7305630249804085635496399869905769372294302716159034447326228509068694952392\",\"price\":\"0.97\",\"size\":\"355611.26\",\"side\":\"SELL\",\"hash\":\"17b049a18ebfa3d6357a701ce3f6c3f74ba9ee32\",\"best_bid\":\"0.95\",\"best_ask\":\"0.96\"}],\"timestamp\":\"1786689843211\",\"event_type\":\"price_change\"}"}
{"recv_ts": 1786689843218191, "venue": "polymarket", "raw": "{\"market\":\"0x747dc809fb79e1b05be09c42d6179459a58de2ef3e40f02484a4e1260f741f75\",\"price_changes\":[{\"asset_id\":\"7305630249804085635496399869905769372294302716159034447326228509068694952392\",\"price\":\"0.93\",\"size\":\"92149.11\",\"side\":\"BUY\",\"hash\":\"bb377ac0898df3e7014da627bafb3530790a2823\",\"best_bid\":\"0.95\",\"best_ask\":\"0.96\"},{\"asset_id\":\"107505882767731489358349912513945399560393482969656700824895970500493757150417\",\"price\":\"0.07\",\"size\":\"92149.11\",\"side\":\"SELL\",\"hash\":\"31fea3d36b6f425c5ae9d35df3b29f1ae726ae04\",\"best_bid\":\"0.04\",\"best_ask\":\"0.05\"}],\"timestamp\":\"1786689843212\",\"event_type\":\"price_change\"}"}
{"recv_ts": 1786689844012654, "venue": "polymarket", "raw": "{\"market\":\"0xbb4d51e6364066d92eb6f9b8413dd7193de70966736044463b205834805a1f3b\",\"price_changes\":[{\"asset_id\":\"106181075047366745139197108801635573283215248045056329679360376976893016488727\",\"price\":\"0.5\",\"size\":\"10872.88\",\"side\":\"BUY\",\"hash\":\"2a2696b1a6f240a596e3785f031743043959614d\",\"best_bid\":\"0.93\",\"best_ask\":\"0.94\"},{\"asset_id\":\"10991849228756847439673778874175365458450913336396982752046655649803657501964\",\"price\":\"0.5\",\"size\":\"10872.88\",\"side\":\"SELL\",\"hash\":\"d330ad3f2a629f17a6f333b7610b4bd0203d3049\",\"best_bid\":\"0.06\",\"best_ask\":\"0.07\"}],\"timestamp\":\"1786689844002\",\"event_type\":\"price_change\"}"}
{"recv_ts": 1786689845223452, "venue": "polymarket", "raw": "{\"market\":\"0xd9fb1184af0064e5e34b129f5b79afa5a17b7e32f2953ab05efed82315fee6d4\",\"price_changes\":[{\"asset_id\":\"90772332434487149264114862115632028379978765245278600275169585501290867536237\",\"price\":\"0.65\",\"size\":\"50\",\"side\":\"BUY\",\"hash\":\"95a1eea5ba2d7a3ec945a09b0fbbdb0c34345aba\",\"best_bid\":\"0.962\",\"best_ask\":\"0.964\"},{\"asset_id\":\"94559586571241563470235664821564670251180951772614764383113614156422396181162\",\"price\":\"0.35\",\"size\":\"50\",\"side\":\"SELL\",\"hash\":\"119f450f0153e9ce4b1c27eb9a7da57a8121f401\",\"best_bid\":\"0.036\",\"best_ask\":\"0.038\"}],\"timestamp\":\"1786689845216\",\"event_type\":\"price_change\"}"}
{"recv_ts": 1786689845225531, "venue": "polymarket", "raw": "{\"market\":\"0xd9fb1184af0064e5e34b129f5b79afa5a17b7e32f2953ab05efed82315fee6d4\",\"price_changes\":[{\"asset_id\":\"90772332434487149264114862115632028379978765245278600275169585501290867536237\",\"price\":\"0.64\",\"size\":\"234\",\"side\":\"BUY\",\"hash\":\"fce0a49f6b8d56d9ba845a3827240e7fffe7cc56\",\"best_bid\":\"0.962\",\"best_ask\":\"0.964\"},{\"asset_id\":\"94559586571241563470235664821564670251180951772614764383113614156422396181162\",\"price\":\"0.36\",\"size\":\"234\",\"side\":\"SELL\",\"hash\":\"acfb3701393af4175c74e013d2f82bbea4b24368\",\"best_bid\":\"0.036\",\"best_ask\":\"0.038\"}],\"timestamp\":\"1786689845220\",\"event_type\":\"price_change\"}"}
{"recv_ts": 1786689846459338, "venue": "polymarket", "raw": "{\"market\":\"0xd595eb9b81885ff018738300c79047e3ec89e87294424f57a29a7fa9162bf116\",\"price_changes\":[{\"asset_id\":\"57216272564529548464686463691236811991956032201293786790337952253964682584376\",\"price\":\"0.961\",\"size\":\"41128.18\",\"side\":\"BUY\",\"hash\":\"71605818b61910acef17ba805b5a6f7f3c308586\",\"best_bid\":\"0.963\",\"best_ask\":\"0.964\"},{\"asset_id\":\"5161623255678193352839985156330393796378434470119114669671615782853260939535\",\"price\":\"0.039\",\"size\":\"41128.18\",\"side\":\"SELL\",\"hash\":\"3475b7232ab2ec733838ad9f51191341bf2d5d29\",\"best_bid\":\"0.036\",\"best_ask\":\"0.037\"}],\"timestamp\":\"1786689846451\",\"event_type\":\"price_change\"}"}
{"recv_ts": 1786689846523146, "venue": "polymarket", "raw": "{\"market\":\"0xd595eb9b81885ff018738300c79047e3ec89e87294424f57a29a7fa9162bf116\",\"price_changes\":[{\"asset_id\":\"57216272564529548464686463691236811991956032201293786790337952253964682584376\",\"price\":\"0.96\",\"size\":\"100\",\"side\":\"BUY\",\"hash\":\"4ea80db5e1a6ba4dd7f5fd90a98523e261b802aa\",\"best_bid\":\"0.963\",\"best_ask\":\"0.964\"},{\"asset_id\":\"5161623255678193352839985156330393796378434470119114669671615782853260939535\",\"price\":\"0.04\",\"size\":\"100\",\"side\":\"SELL\",\"hash\":\"d86d8e67dd97da08e54687f6108f79b415441eb3\",\"best_bid\":\"0.036\",\"best_ask\":\"0.037\"}],\"timestamp\":\"1786689846517\",\"event_type\":\"price_change\"}"}
{"recv_ts": 1786689846585585, "venue": "polymarket", "raw": "{\"market\":\"0xd595eb9b81885ff018738300c79047e3ec89e87294424f57a29a7fa9162bf116\",\"price_changes\":[{\"asset_id\":\"57216272564529548464686463691236811991956032201293786790337952253964682584376\",\"price\":\"0.959\",\"size\":\"300\",\"side\":\"BUY\",\"hash\":\"7c33d56346088f24bc2502842322ec0305611b89\",\"best_bid\":\"0.963\",\"best_ask\":\"0.964\"},{\"asset_id\":\"5161623255678193352839985156330393796378434470119114669671615782853260939535\",\"price\":\"0.041\",\"size\":\"300\",\"side\":\"SELL\",\"hash\":\"cf9b5ada82c1b03facb7bf93686bed1f48abbfed\",\"best_bid\":\"0.036\",\"best_ask\":\"0.037\"}],\"timestamp\":\"1786689846576\",\"event_type\":\"price_change\"}"}
{"recv_ts": 1786689848745553, "venue": "polymarket", "raw": "{\"market\":\"0xbb4d51e6364066d92eb6f9b8413dd7193de70966736044463b205834805a1f3b\",\"price_changes\":[{\"asset_id\":\"106181075047366745139197108801635573283215248045056329679360376976893016488727\",\"price\":\"0.5\",\"size\":\"13272.88\",\"side\":\"BUY\",\"hash\":\"e8b691fb9ff9488b81e73b149df7ff2a6d931bb6\",\"best_bid\":\"0.93\",\"best_ask\":\"0.94\"},{\"asset_id\":\"10991849228756847439673778874175365458450913336396982752046655649803657501964\",\"price\":\"0.5\",\"size\":\"13272.88\",\"side\":\"SELL\",\"hash\":\"f7dbae2f69bcd370675742d2a895912a78957d40\",\"best_bid\":\"0.06\",\"best_ask\":\"0.07\"}],\"timestamp\":\"1786689848738\",\"event_type\":\"price_change\"}"}
{"recv_ts": 1786689850012221, "venue": "polymarket", "raw": "{\"market\":\"0x747dc809fb79e1b05be09c42d6179459a58de2ef3e40f02484a4e1260f741f75\",\"price_changes\":[{\"asset_id\":\"107505882767731489358349912513945399560393482969656700824895970500493757150417\",\"price\":\"0.01\",\"size\":\"1025381.46\",\"side\":\"BUY\",\"hash\":\"58357bde87d6c5f4a963194641570929fe98898c\",\"best_bid\":\"0.04\",\"best_ask\":\"0.05\"},{\"asset_id\":\"7305630249804085635496399869905769372294302716159034447326228509068694952392\",\"price\":\"0.99\",\"size\":\"1025381.46\",\"side\":\"SELL\",\"hash\":\"05911af035b99d0d96023e4ec8abf9cfa55d3c25\",\"best_bid\":\"0.95\",\"best_ask\":\"0.96\"}],\"timestamp\":\"1786689850001\",\"event_type\":\"price_change\"}"}
{"recv_ts": 1786689851452587, "venue": "polymarket", "raw": "{\"market\":\"0xd9fb1184af0064e5e34b129f5b79afa5a17b7e32f2953ab05efed82315fee6d4\",\"price_changes\":[{\"asset_id\":\"90772332434487149264114862115632028379978765245278600275169585501290867536237\",\"price\":\"0.64\",\"size\":\"0\",\"side\":\"BUY\",\"hash\":\"aed1d0f31c139e0a7b2944362bc4e59a3c91c7ed\",\"best_bid\":\"0.962\",\"best_ask\":\"0.964\"},{\"asset_id\":\"94559586571241563470235664821564670251180951772614764383113614156422396181162\",\"price\":\"0.36\",\"size\":\"0\",\"side\":\"SELL\",\"hash\":\"5710890980d9526ed5897447e4c527982692f62a\",\"best_bid\":\"0.036\",\"best_ask\":\"0.038\"}],\"timestamp\":\"1786689851445\",\"event_type\":\"price_change\"}"}
{"recv_ts": 1786689851533452, "venue": "polymarket", "raw": "{\"market\":\"0xd9fb1184af0064e5e34b129f5b79afa5a17b7e32f2953ab05efed82315fee6d4\",\"price_changes\":[{\"asset_id\":\"90772332434487149264114862115632028379978765245278600275169585501290867536237\",\"price\":\"0.65\",\"size\":\"280\",\"side\":\"BUY\",\"hash\":\"0dbabd46d573efb6e77d7c594bc06f40752d7f7d\",\"best_bid\":\"0.962\",\"best_ask\":\"0.964\"},{\"asset_id\":\"94559586571241563470235664821564670251180951772614764383113614156422396181162\",\"price\":\"0.35\",\"size\":\"280\",\"side\":\"SELL\",\"hash\":\"321f4d582b26122880f260c7d737e70bfabeb38a\",\"best_bid\":\"0.036\",\"best_ask\":\"0.038\"}],\"timestamp\":\"1786689851527\",\"event_type\":\"price_change\"}"}
{"recv_ts": 1786689852751109, "venue": "polymarket", "raw": "{\"market\":\"0x747dc809fb79e1b05be09c42d6179459a58de2ef3e40f02484a4e1260f741f75\",\"price_changes\":[{\"asset_id\":\"107505882767731489358349912513945399560393482969656700824895970500493757150417\",\"price\":\"0.01\",\"size\":\"1052481.46\",\"side\":\"BUY\",\"hash\":\"cc683053bbba05a525e7b393d72af6d4ea0c92a6\",\"best_bid\":\"0.04\",\"best_ask\":\"0.05\"},{\"asset_id\":\"7305630249804085635496399869905769372294302716159034447326228509068694952392\",\"price\":\"0.99\",\"size\":\"1052481.46\",\"side\":\"SELL\",\"hash\":\"6fa0103b63fe0eac6040e1aaf4a216ba6c310e92\",\"best_bid\":\"0.95\",\"best_ask\":\"0.96\"}],\"timestamp\":\"1786689852744\",\"event_type\":\"price_change\"}"}
{"recv_ts": 1786689855248773, "venue": "polymarket", "raw": "{\"market\":\"0xd9fb1184af0064e5e34b129f5b79afa5a17b7e32f2953ab05efed82315fee6d4\",\"price_changes\":[{\"asset_id\":\"90772332434487149264114862115632028379978765245278600275169585501290867536237\",\"price\":\"0.65\",\"size\":\"50\",\"side\":\"BUY\",\"hash\":\"24ec844ed932df2970e8da4f770487ad0dc788dc\",\"best_bid\":\"0.962\",\"best_ask\":\"0.964\"},{\"asset_id\":\"94559586571241563470235664821564670251180951772614764383113614156422396181162\",\"price\":\"0.35\",\"size\":\"50\",\"side\":\"SELL\",\"hash\":\"703c770016a5c8cda501051620e3be6910dac423\",\"best_bid\":\"0.036\",\"best_ask\":\"0.038\"}],\"timestamp\":\"1786689855242\",\"event_type\":\"price_change\"}"}
{"recv_ts": 1786689855255724, "venue": "polymarket", "raw": "{\"market\":\"0xd9fb1184af0064e5e34b129f5b79afa5a17b7e32f2953ab05efed82315fee6d4\",\"price_changes\":[{\"asset_id\":\"90772332434487149264114862115632028379978765245278600275169585501290867536237\",\"price\":\"0.64\",\"size\":\"234\",\"side\":\"BUY\",\"hash\":\"d38d9e5207dbf991c164725551c078f2b742b013\",\"best_bid\":\"0.962\",\"best_ask\":\"0.964\"},{\"asset_id\":\"94559586571241563470235664821564670251180951772614764383113614156422396181162\",\"price\":\"0.36\",\"size\":\"234\",\"side\":\"SELL\",\"hash\":\"060e94b30b916a9177bafb5cbbedae84e2c3efb4\",\"best_bid\":\"0.036\",\"best_ask\":\"0.038\"}],\"timestamp\":\"1786689855249\",\"event_type\":\"price_change\"}"}
{"recv_ts": 1786689855444503, "venue": "polymarket", "raw": "{\"market\":\"0xd9fb1184af0064e5e34b129f5b79afa5a17b7e32f2953ab05efed82315fee6d4\",\"price_changes\":[{\"asset_id\":\"90772332434487149264114862115632028379978765245278600275169585501290867536237\",\"price\":\"0.96\",\"size\":\"38445.56\",\"side\":\"BUY\",\"hash\":\"5d234bf46c9463d30591de321ad47501f164fd36\",\"best_bid\":\"0.962\",\"best_ask\":\"0.964\"},{\"asset_id\":\"94559586571241563470235664821564670251180951772614764383113614156422396181162\",\"price\":\"0.04\",\"size\":\"38445.56\",\"side\":\"SELL\",\"hash\":\"305e0b0f65fdb33af34cd2cdd928bc57be873b16\",\"best_bid\":\"0.036\",\"best_ask\":\"0.038\"}],\"timestamp\":\"1786689855438\",\"event_type\":\"price_change\"}"}
{"recv_ts": 1786689857199724, "venue": "polymarket", "raw": "{\"id\":\"3578419\",\"question\":\"FC Barcelona vs. Athletic Club: Athletic Club O/U 5.5 Corners\",\"market\":\"0xb6c6dd6368a1afdfb4fe492dd924e15893b37e8ec2373f8fe4da5002b4ec68c5\",\"slug\":\"lal-bar-bil-2026-08-27-corners-team-away-5pt5\",\"description\":\"In the upcoming La Liga game between FC Barcelona and Athletic Club, scheduled for August 27, 2026 at 3:00 PM ET: This market will resolve to \\\"Over\\\" if Athletic Club takes 6 or more corners within the first 90 minutes of regular play plus stoppage time. If Athletic Club takes fewer than 6 corners within the first 90 minutes of regular play plus stoppage time, this market will resolve to \\\"Under\\\". This market is based solely on corners taken by Athletic Club, not the combined number of corners taken by both teams. Markets on number of corners refer to corners taken, not corners awarded. Corners awarded but not taken will not count. Corners awarded during extra time or penalty shootouts do not count. If the game is postponed, this market will remain open until the game has been completed. If the game is canceled entirely, with no make-up game, this market will resolve 50-50. The primary resolution source for this market is the official statistics of the event as recognized by the governing body or event organizers. However, if the governing body or event organizers have not published final match statistics within 24 hours after the event's conclusion, a consensus of credible reporting may be used instead. All markets will settle based on the official final result as recognized by the governing body or event organizers. Revisions to officially declared final scores made after market resolution will not be accounted for in determining the outcome.\",\"assets_ids\":[\"101936677297730053372508929772397594497623598727281658003563663554665335301839\",\"38402160453594942321954381733894265548423515941316083577873573125755500688109\"],\"outcomes\":[\"Over\",\"Under\"],\"event_message\":{\"id\":\"847345\",\"ticker\":\"lal-bar-bil-2026-08-27-total-corners\",\"slug\":\"lal-bar-bil-2026-08-27-total-corners\",\"title\":\"FC Barcelona vs. Athletic Club - Total Corners\",\"description\":\"Total corners markets for the La Liga game between FC Barcelona and Athletic Club, scheduled for August 27, 2026 at 3:00 PM ET.\"},\"timestamp\":\"1786689856954\",\"event_type\":\"new_market\",\"tags\":[],\"condition_id\":\"0xb6c6dd6368a1afdfb4fe492dd924e15893b37e8ec2373f8fe4da5002b4ec68c5\",\"active\":false,\"clob_token_ids\":[\"101936677297730053372508929772397594497623598727281658003563663554665335301839\",\"38402160453594942321954381733894265548423515941316083577873573125755500688109\"],\"sports_market_type\":\"soccer_team_total_corners\",\"line\":\"5.5\",\"game_start_time\":\"2026-08-27 19:00:00+00\",\"order_price_min_tick_size\":\"0.01\",\"group_item_title\":\"Athletic Club Corners: O/U 5.5\",\"taker_base_fee\":\"1000\",\"fees_enabled\":true,\"fee_schedule\":{\"exponent\":\"1\",\"rate\":\"0.05\",\"taker_only\":true,\"rebate_rate\":\"0.15\"}}"}
{"recv_ts": 1786689857199817, "venue": "polymarket", "raw": "{\"id\":\"3578420\",\"question\":\"FC Barcelona vs. Athletic Club: Total Corners Odd or Even?\",\"market\":\"0x16647f325020ac8882e7e1d5c1d38651eda99aaa3becf6d2f7205864c10ca6fc\",\"slug\":\"lal-bar-bil-2026-08-27-corners-odd-even\",\"description\":\"In the upcoming La Liga game between FC Barcelona and Athletic Club, scheduled for August 27, 2026 at 3:00 PM ET: This market will resolve to \\\"Odd\\\" if the total number of corners taken by both teams within the first 90 minutes of regular play plus stoppage time is odd. This market will resolve to \\\"Even\\\" if the total number of corners taken is even. Zero corners is considered even. Markets on number of corners refer to corners taken, not corners awarded. Corners awarded but not taken will not count. Corners awarded during extra time or penalty shootouts do not count. If the game is postponed, this market will remain open until the game has been completed. If the game is canceled entirely, with no make-up game, this market will resolve 50-50. The primary resolution source for this market is the official statistics of the event as recognized by the governing body or event organizers. However, if the governing body or event organizers have not published final match statistics within 24 hours after the event's conclusion, a consensus of credible reporting may be used instead. All markets will settle based on the official final result as recognized by the governing body or event organizers. Revisions to officially declared final scores made after market resolution will not be accounted for in determining the outcome.\",\"assets_ids\":[\"97708246431934669955690365284143549339544539788393071217538177603084287852657\",\"5976463434406152574842510598240607679918315577357823763172233697354792980598\"],\"outcomes\":[\"Odd\",\"Even\"],\"event_message\":{\"id\":\"847345\",\"ticker\":\"lal-bar-bil-2026-08-27-total-corners\",\"slug\":\"lal-bar-bil-2026-08-27-total-corners\",\"title\":\"FC Barcelona vs. Athletic Club - Total Corners\",\"description\":\"Total corners markets for the La Liga game between FC Barcelona and Athletic Club, scheduled for August 27, 2026 at 3:00 PM ET.\"},\"timestamp\":\"1786689856956\",\"event_type\":\"new_market\",\"tags\":[],\"condition_id\":\"0x16647f325020ac8882e7e1d5c1d38651eda99aaa3becf6d2f7205864c10ca6fc\",\"active\":false,\"clob_token_ids\":[\"97708246431934669955690365284143549339544539788393071217538177603084287852657\",\"5976463434406152574842510598240607679918315577357823763172233697354792980598\"],\"sports_market_type\":\"soccer_game_corners_odd_even\",\"line\":\"\",\"game_start_time\":\"2026-08-27 19:00:00+00\",\"order_price_min_tick_size\":\"0.01\",\"group_item_title\":\"Total Corners: Odd or Even\",\"taker_base_fee\":\"1000\",\"fees_enabled\":true,\"fee_schedule\":{\"exponent\":\"1\",\"rate\":\"0.05\",\"taker_only\":true,\"rebate_rate\":\"0.15\"}}"}
{"recv_ts": 1786689859778203, "venue": "polymarket", "raw": "{\"id\":\"3578407\",\"question\":\"FC Barcelona vs. Athletic Club: 1st Half O/U 4.5 Total Corners\",\"market\":\"0xfaf74f53002598059623cd85adea9e10e2d7f357691d83b6a4785776851f44e8\",\"slug\":\"lal-bar-bil-2026-08-27-corners-first-half-total-4pt5\",\"description\":\"In the upcoming La Liga game between FC Barcelona and Athletic Club, scheduled for August 27, 2026 at 3:00 PM ET: This market will resolve to \\\"Over\\\" if there are 5 or more total corners taken by both teams in the first half. If the total number of first-half corners is fewer than 5, this market will resolve to \\\"Under\\\". This market refers only to corners taken within the first 45 minutes of regular play plus first-half stoppage time. Second-half corners, extra time, and penalty shootouts do not count. Markets on number of corners refer to corners taken, not corners awarded. Corners awarded but not taken will not count. If the game is postponed, this market will remain open until the game has been completed. If the game is canceled entirely, with no make-up game, this market will resolve 50-50. The primary resolution source for this market is the official statistics of the event as recognized by the governing body or event organizers. However, if the governing body or event organizers have not published final match statistics within 24 hours after the event's conclusion, a consensus of credible reporting may be used instead. All markets will settle based on the official final result as recognized by the governing body or event organizers. Revisions to officially declared final scores made after market resolution will not be accounted for in determining the outcome.\",\"assets_ids\":[\"20568458601159513430968689163368840792096042451954690301799741368151993706061\",\"57569734541873118607330720628924681462534379884468246813034312896148843878800\"],\"outcomes\":[\"Over\",\"Under\"],\"event_message\":{\"id\":\"847345\",\"ticker\":\"lal-bar-bil-2026-08-27-total-corners\",\"slug\":\"lal-bar-bil-2026-08-27-total-corners\",\"title\":\"FC Barcelona vs. Athletic Club - Total Corners\",\"description\":\"Total corners markets for the La Liga game between FC Barcelona and Athletic Club, scheduled for August 27, 2026 at 3:00 PM ET.\"},\"timestamp\":\"1786689859766\",\"event_type\":\"new_market\",\"tags\":[],\"condition_id\":\"0xfaf74f53002598059623cd85adea9e10e2d7f357691d83b6a4785776851f44e8\",\"active\":false,\"clob_token_ids\":[\"20568458601159513430968689163368840792096042451954690301799741368151993706061\",\"57569734541873118607330720628924681462534379884468246813034312896148843878800\"],\"sports_market_type\":\"soccer_first_half_total_corners\",\"line\":\"4.5\",\"game_start_time\":\"2026-08-27 19:00:00+00\",\"order_price_min_tick_size\":\"0.01\",\"group_item_title\":\"1st Half Total Corners: O/U 4.5\",\"taker_base_fee\":\"1000\",\"fees_enabled\":true,\"fee_schedule\":{\"exponent\":\"1\",\"rate\":\"0.05\",\"taker_only\":true,\"rebate_rate\":\"0.15\"}}"}
{"recv_ts": 1786689859963301, "venue": "polymarket", "raw": "{\"id\":\"3578414\",\"question\":\"FC Barcelona vs. Athletic Club: FC Barcelona O/U 4.5 Corners\",\"market\":\"0x672e07cfd4b75d5e074ccb3cd1003b9246dca108d42822fe6d4c9d81f549a0cf\",\"slug\":\"lal-bar-bil-2026-08-27-corners-team-home-4pt5\",\"description\":\"In the upcoming La Liga game between FC Barcelona and Athletic Club, scheduled for August 27, 2026 at 3:00 PM ET: This market will resolve to \\\"Over\\\" if FC Barcelona takes 5 or more corners within the first 90 minutes of regular play plus stoppage time. If FC Barcelona takes fewer than 5 corners within the first 90 minutes of regular play plus stoppage time, this market will resolve to \\\"Under\\\". This market is based solely on corners taken by FC Barcelona, not the combined number of corners taken by both teams. Markets on number of corners refer to corners taken, not corners awarded. Corners awarded but not taken will not count. Corners awarded during extra time or penalty shootouts do not count. If the game is postponed, this market will remain open until the game has been completed. If the game is canceled entirely, with no make-up game, this market will resolve 50-50. The primary resolution source for this market is the official statistics of the event as recognized by the governing body or event organizers. However, if the governing body or event organizers have not published final match statistics within 24 hours after the event's conclusion, a consensus of credible reporting may be used instead. All markets will settle based on the official final result as recognized by the governing body or event organizers. Revisions to officially declared final scores made after market resolution will not be accounted for in determining the outcome.\",\"assets_ids\":[\"4046393705683552927831985006710048435804322013879407843780293331288209309584\",\"2932489988079332325666651617737100761535701834619798833464685476156833910591\"],\"outcomes\":[\"Over\",\"Under\"],\"event_message\":{\"id\":\"847345\",\"ticker\":\"lal-bar-bil-2026-08-27-total-corners\",\"slug\":\"lal-bar-bil-2026-08-27-total-corners\",\"title\":\"FC Barcelona vs. Athletic Club - Total Corners\",\"description\":\"Total corners markets for the La Liga game between FC Barcelona and Athletic Club, scheduled for August 27, 2026 at 3:00 PM ET.\"},\"timestamp\":\"1786689859768\",\"event_type\":\"new_market\",\"tags\":[],\"condition_id\":\"0x672e07cfd4b75d5e074ccb3cd1003b9246dca108d42822fe6d4c9d81f549a0cf\",\"active\":true,\"clob_token_ids\":[\"4046393705683552927831985006710048435804322013879407843780293331288209309584\",\"2932489988079332325666651617737100761535701834619798833464685476156833910591\"],\"sports_market_type\":\"soccer_team_total_corners\",\"line\":\"4.5\",\"game_start_time\":\"2026-08-27 19:00:00+00\",\"order_price_min_tick_size\":\"0.01\",\"group_item_title\":\"FC Barcelona Corners: O/U 4.5\",\"taker_base_fee\":\"1000\",\"fees_enabled\":true,\"fee_schedule\":{\"exponent\":\"1\",\"rate\":\"0.05\",\"taker_only\":true,\"rebate_rate\":\"0.15\"}}"}
